ts_recv,ts_event,rtype,publisher_id,instrument_id,action,side,depth,price,size,flags,ts_in_delta,sequence,bid_px_00,ask_px_00,bid_sz_00,ask_sz_00,bid_ct_00,ask_ct_00,bid_px_01,ask_px_01,bid_sz_01,ask_sz_01,bid_ct_01,ask_ct_01,bid_px_02,ask_px_02,bid_sz_02,ask_sz_02,bid_ct_02,ask_ct_02,bid_px_03,ask_px_03,bid_sz_03,ask_sz_03,bid_ct_03,ask_ct_03,bid_px_04,ask_px_04,bid_sz_04,ask_sz_04,bid_ct_04,ask_ct_04,bid_px_05,ask_px_05,bid_sz_05,ask_sz_05,bid_ct_05,ask_ct_05,bid_px_06,ask_px_06,bid_sz_06,ask_sz_06,bid_ct_06,ask_ct_06,bid_px_07,ask_px_07,bid_sz_07,ask_sz_07,bid_ct_07,ask_ct_07,bid_px_08,ask_px_08,bid_sz_08,ask_sz_08,bid_ct_08,ask_ct_08,bid_px_09,ask_px_09,bid_sz_09,ask_sz_09,bid_ct_09,ask_ct_09,symbol,best_level_ofi,ofi_level_0,ofi_level_1,ofi_level_2,ofi_level_3,ofi_level_4,ofi_level_5,ofi_level_6,ofi_level_7,ofi_level_8,ofi_level_9,mid_price
2024-10-21T11:54:29.221230963Z,2024-10-21 11:54:29.221064336+00:00,10,2,38,C,B,1,233.62,2,130,166627,11405847,233.67,233.74,139,200,1,1,233.53,233.75,10,1,1,1,233.52,233.77,200,8,1,1,233.48,233.78,28,150,1,2,233.45,233.79,15,29,1,1,233.4,233.8,110,25,2,1,233.39,233.94,10,200,1,1,233.31,233.98,110,44,2,3,233.3,234.0,100,155,1,7,233.25,234.13,55,400,2,1,AAPL,0,0,0,0,0,0,0,0,0,0,0,233.70499999999998
2024-10-21T11:54:29.223936626Z,2024-10-21 11:54:29.223769812+00:00,10,2,38,A,B,0,233.67,2,130,166814,11405848,233.67,233.74,141,200,2,1,233.53,233.75,10,1,1,1,233.52,233.77,200,8,1,1,233.48,233.78,28,150,1,2,233.45,233.79,15,29,1,1,233.4,233.8,110,25,2,1,233.39,233.94,10,200,1,1,233.31,233.98,110,44,2,3,233.3,234.0,100,155,1,7,233.25,234.13,55,400,2,1,AAPL,2,2,0,0,0,0,0,0,0,0,0,233.70499999999998
2024-10-21T11:54:29.225196809Z,2024-10-21 11:54:29.225030400+00:00,10,2,38,A,B,0,233.67,3,130,166409,11405849,233.67,233.74,144,200,3,1,233.53,233.75,10,1,1,1,233.52,233.77,200,8,1,1,233.48,233.78,28,150,1,2,233.45,233.79,15,29,1,1,233.4,233.8,110,25,2,1,233.39,233.94,10,200,1,1,233.31,233.98,110,44,2,3,233.3,234.0,100,155,1,7,233.25,234.13,55,400,2,1,AAPL,3,3,0,0,0,0,0,0,0,0,0,233.70499999999998
2024-10-21T11:54:29.712600612Z,2024-10-21 11:54:29.712434212+00:00,10,2,38,A,B,2,233.52,200,130,166400,11406449,233.67,233.74,144,200,3,1,233.53,233.75,10,1,1,1,233.52,233.77,400,8,2,1,233.48,233.78,28,150,1,2,233.45,233.79,15,29,1,1,233.4,233.8,110,25,2,1,233.39,233.94,10,200,1,1,233.31,233.98,110,44,2,3,233.3,234.0,100,155,1,7,233.25,234.13,55,400,2,1,AAPL,0,0,0,200,0,0,0,0,0,0,0,233.70499999999998
2024-10-21T11:54:29.764839221Z,2024-10-21 11:54:29.764673165+00:00,10,2,38,C,B,2,233.52,200,130,166056,11406501,233.67,233.74,144,200,3,1,233.53,233.75,10,1,1,1,233.52,233.77,200,8,1,1,233.48,233.78,28,150,1,2,233.45,233.79,15,29,1,1,233.4,233.8,110,25,2,1,233.39,233.94,10,200,1,1,233.31,233.98,110,44,2,3,233.3,234.0,100,155,1,7,233.25,234.13,55,400,2,1,AAPL,0,0,0,-200,0,0,0,0,0,0,0,233.70499999999998
2024-10-21T11:54:29.764851707Z,2024-10-21 11:54:29.764685027+00:00,10,2,38,A,B,1,233.54,400,130,166680,11406502,233.67,233.74,144,200,3,1,233.54,233.75,400,1,1,1,233.53,233.77,10,8,1,1,233.48,233.78,28,150,1,2,233.45,233.79,15,29,1,1,233.4,233.8,110,25,2,1,233.39,233.94,10,200,1,1,233.31,233.98,110,44,2,3,233.3,234.0,100,155,1,7,233.25,234.13,55,400,2,1,AAPL,0,0,400,10,0,0,0,0,0,0,0,233.70499999999998
2024-10-21T11:54:36.289594629Z,2024-10-21 11:54:36.289427977+00:00,10,2,38,A,A,6,233.9,200,130,166652,11409388,233.67,233.74,144,200,3,1,233.54,233.75,400,1,1,1,233.53,233.77,10,8,1,1,233.48,233.78,28,150,1,2,233.45,233.79,15,29,1,1,233.4,233.8,110,25,2,1,233.39,233.9,10,200,1,1,233.31,233.94,110,200,2,1,233.3,233.98,100,44,1,3,233.25,234.0,55,155,2,7,AAPL,0,0,0,0,0,0,0,200,200,44,155,233.70499999999998
2024-10-21T11:54:37.990960617Z,2024-10-21 11:54:37.990793976+00:00,10,2,38,A,A,0,233.73,200,130,166641,11410372,233.67,233.73,144,200,3,1,233.54,233.75,400,1,1,1,233.53,233.77,10,8,1,1,233.48,233.78,28,150,1,2,233.45,233.79,15,29,1,1,233.4,233.8,110,25,2,1,233.39,233.9,10,200,1,1,233.31,233.94,110,200,2,1,233.3,233.98,100,44,1,3,233.25,234.0,55,155,2,7,AAPL,200,200,0,0,0,0,0,0,0,0,0,233.7
2024-10-21T11:54:39.124458000Z,2024-10-21 11:54:39.124291588+00:00,10,2,38,C,A,0,233.73,200,130,166412,11410864,233.67,233.75,144,1,3,1,233.54,233.77,400,8,1,1,233.53,233.78,10,150,1,2,233.48,233.79,28,29,1,1,233.45,233.8,15,25,1,1,233.4,233.9,110,200,2,1,233.39,233.94,10,200,1,1,233.31,233.98,110,44,2,3,233.3,234.0,100,155,1,7,233.25,234.13,55,400,2,1,AAPL,200,200,1,8,150,29,25,200,200,44,155,233.70999999999998
2024-10-21T11:54:39.134307134Z,2024-10-21 11:54:39.134140341+00:00,10,2,38,A,A,0,233.74,200,130,166793,11410873,233.67,233.74,144,200,3,1,233.54,233.75,400,1,1,1,233.53,233.77,10,8,1,1,233.48,233.78,28,150,1,2,233.45,233.79,15,29,1,1,233.4,233.8,110,25,2,1,233.39,233.9,10,200,1,1,233.31,233.94,110,200,2,1,233.3,233.98,100,44,1,3,233.25,234.0,55,155,2,7,AAPL,200,200,1,8,150,29,25,200,200,44,155,233.70499999999998
2024-10-21T11:54:41.233347439Z,2024-10-21 11:54:41.233181043+00:00,10,2,38,C,B,0,233.67,3,130,166396,11411787,233.67,233.74,141,200,2,1,233.54,233.75,400,1,1,1,233.53,233.77,10,8,1,1,233.48,233.78,28,150,1,2,233.45,233.79,15,29,1,1,233.4,233.8,110,25,2,1,233.39,233.9,10,200,1,1,233.31,233.94,110,200,2,1,233.3,233.98,100,44,1,3,233.25,234.0,55,155,2,7,AAPL,-3,-3,0,0,0,0,0,0,0,0,0,233.70499999999998
2024-10-21T11:54:41.234786818Z,2024-10-21 11:54:41.234620509+00:00,10,2,38,A,B,0,233.67,1,130,166309,11411790,233.67,233.74,142,200,3,1,233.54,233.75,400,1,1,1,233.53,233.77,10,8,1,1,233.48,233.78,28,150,1,2,233.45,233.79,15,29,1,1,233.4,233.8,110,25,2,1,233.39,233.9,10,200,1,1,233.31,233.94,110,200,2,1,233.3,233.98,100,44,1,3,233.25,234.0,55,155,2,7,AAPL,1,1,0,0,0,0,0,0,0,0,0,233.70499999999998
2024-10-21T11:54:41.236073416Z,2024-10-21 11:54:41.235907431+00:00,10,2,38,C,B,0,233.67,1,130,165985,11411831,233.67,233.74,141,200,2,1,233.54,233.75,400,1,1,1,233.53,233.77,10,8,1,1,233.48,233.78,28,150,1,2,233.45,233.79,15,29,1,1,233.4,233.8,110,25,2,1,233.39,233.9,10,200,1,1,233.31,233.94,110,200,2,1,233.3,233.98,100,44,1,3,233.25,234.0,55,155,2,7,AAPL,-1,-1,0,0,0,0,0,0,0,0,0,233.70499999999998
2024-10-21T11:54:41.236144516Z,2024-10-21 11:54:41.235977207+00:00,10,2,38,C,B,0,233.67,2,130,167309,11411832,233.67,233.74,139,200,1,1,233.54,233.75,400,1,1,1,233.53,233.77,10,8,1,1,233.48,233.78,28,150,1,2,233.45,233.79,15,29,1,1,233.4,233.8,110,25,2,1,233.39,233.9,10,200,1,1,233.31,233.94,110,200,2,1,233.3,233.98,100,44,1,3,233.25,234.0,55,155,2,7,AAPL,-2,-2,0,0,0,0,0,0,0,0,0,233.70499999999998
2024-10-21T11:54:41.238784694Z,2024-10-21 11:54:41.238618235+00:00,10,2,38,A,B,0,233.7,2,130,166459,11411834,233.7,233.74,2,200,1,1,233.67,233.75,139,1,1,1,233.54,233.77,400,8,1,1,233.53,233.78,10,150,1,2,233.48,233.79,28,29,1,1,233.45,233.8,15,25,1,1,233.4,233.9,110,200,2,1,233.39,233.94,10,200,1,1,233.31,233.98,110,44,2,3,233.3,234.0,100,155,1,7,AAPL,2,2,139,400,10,28,15,110,10,110,100,233.72
2024-10-21T11:54:41.239993456Z,2024-10-21 11:54:41.239827037+00:00,10,2,38,A,B,0,233.7,3,130,166419,11411835,233.7,233.74,5,200,2,1,233.67,233.75,139,1,1,1,233.54,233.77,400,8,1,1,233.53,233.78,10,150,1,2,233.48,233.79,28,29,1,1,233.45,233.8,15,25,1,1,233.4,233.9,110,200,2,1,233.39,233.94,10,200,1,1,233.31,233.98,110,44,2,3,233.3,234.0,100,155,1,7,AAPL,3,3,0,0,0,0,0,0,0,0,0,233.72
2024-10-21T11:54:50.970463583Z,2024-10-21 11:54:50.970297264+00:00,10,2,38,C,A,4,233.79,29,130,166319,11416279,233.7,233.74,5,200,2,1,233.67,233.75,139,1,1,1,233.54,233.77,400,8,1,1,233.53,233.78,10,150,1,2,233.48,233.8,28,25,1,1,233.45,233.9,15,200,1,1,233.4,233.94,110,200,2,1,233.39,233.98,10,44,1,3,233.31,234.0,110,155,2,7,233.3,234.13,100,400,1,1,AAPL,0,0,0,0,0,29,25,200,200,44,155,233.72
2024-10-21T11:54:50.970503601Z,2024-10-21 11:54:50.970336474+00:00,10,2,38,A,A,3,233.78,29,130,167127,11416280,233.7,233.74,5,200,2,1,233.67,233.75,139,1,1,1,233.54,233.77,400,8,1,1,233.53,233.78,10,179,1,3,233.48,233.8,28,25,1,1,233.45,233.9,15,200,1,1,233.4,233.94,110,200,2,1,233.39,233.98,10,44,1,3,233.31,234.0,110,155,2,7,233.3,234.13,100,400,1,1,AAPL,0,0,0,0,29,0,0,0,0,0,0,233.72
2024-10-21T11:54:53.247698803Z,2024-10-21 11:54:53.247532557+00:00,10,2,38,C,B,0,233.7,3,130,166246,11417889,233.7,233.74,2,200,1,1,233.67,233.75,139,1,1,1,233.54,233.77,400,8,1,1,233.53,233.78,10,179,1,3,233.48,233.8,28,25,1,1,233.45,233.9,15,200,1,1,233.4,233.94,110,200,2,1,233.39,233.98,10,44,1,3,233.31,234.0,110,155,2,7,233.3,234.13,100,400,1,1,AAPL,-3,-3,0,0,0,0,0,0,0,0,0,233.72
2024-10-21T11:54:53.249060172Z,2024-10-21 11:54:53.248893986+00:00,10,2,38,C,B,0,233.7,2,130,166186,11417890,233.67,233.74,139,200,1,1,233.54,233.75,400,1,1,1,233.53,233.77,10,8,1,1,233.48,233.78,28,179,1,3,233.45,233.8,15,25,1,1,233.4,233.9,110,200,2,1,233.39,233.94,10,200,1,1,233.31,233.98,110,44,2,3,233.3,234.0,100,155,1,7,233.25,234.13,55,400,2,1,AAPL,-2,-2,-139,-400,-10,-28,-15,-110,-10,-110,-100,233.70499999999998
2024-10-21T11:54:53.251488043Z,2024-10-21 11:54:53.251320969+00:00,10,2,38,A,B,0,233.67,3,130,167074,11417891,233.67,233.74,142,200,2,1,233.54,233.75,400,1,1,1,233.53,233.77,10,8,1,1,233.48,233.78,28,179,1,3,233.45,233.8,15,25,1,1,233.4,233.9,110,200,2,1,233.39,233.94,10,200,1,1,233.31,233.98,110,44,2,3,233.3,234.0,100,155,1,7,233.25,234.13,55,400,2,1,AAPL,3,3,0,0,0,0,0,0,0,0,0,233.70499999999998
2024-10-21T11:54:53.252712795Z,2024-10-21 11:54:53.252546517+00:00,10,2,38,A,B,0,233.67,2,130,166278,11417894,233.67,233.74,144,200,3,1,233.54,233.75,400,1,1,1,233.53,233.77,10,8,1,1,233.48,233.78,28,179,1,3,233.45,233.8,15,25,1,1,233.4,233.9,110,200,2,1,233.39,233.94,10,200,1,1,233.31,233.98,110,44,2,3,233.3,234.0,100,155,1,7,233.25,234.13,55,400,2,1,AAPL,2,2,0,0,0,0,0,0,0,0,0,233.70499999999998
2024-10-21T11:54:55.503664023Z,2024-10-21 11:54:55.503497741+00:00,10,2,38,C,B,3,233.48,28,130,166282,11418757,233.67,233.74,144,200,3,1,233.54,233.75,400,1,1,1,233.53,233.77,10,8,1,1,233.45,233.78,15,179,1,3,233.4,233.8,110,25,2,1,233.39,233.9,10,200,1,1,233.31,233.94,110,200,2,1,233.3,233.98,100,44,1,3,233.25,234.0,55,155,2,7,233.24,234.13,1,400,1,1,AAPL,0,0,0,0,-28,-15,-110,-10,-110,-100,-55,233.70499999999998
2024-10-21T11:54:55.503707349Z,2024-10-21 11:54:55.503541005+00:00,10,2,38,A,B,3,233.51,27,130,166344,11418758,233.67,233.74,144,200,3,1,233.54,233.75,400,1,1,1,233.53,233.77,10,8,1,1,233.51,233.78,27,179,1,3,233.45,233.8,15,25,1,1,233.4,233.9,110,200,2,1,233.39,233.94,10,200,1,1,233.31,233.98,110,44,2,3,233.3,234.0,100,155,1,7,233.25,234.13,55,400,2,1,AAPL,0,0,0,0,27,15,110,10,110,100,55,233.70499999999998
2024-10-21T11:54:55.551973702Z,2024-10-21 11:54:55.551806996+00:00,10,2,38,A,B,1,233.59,400,130,166706,11418795,233.67,233.74,144,200,3,1,233.59,233.75,400,1,1,1,233.53,233.77,10,8,1,1,233.51,233.78,27,179,1,3,233.45,233.8,15,25,1,1,233.4,233.9,110,200,2,1,233.39,233.94,10,200,1,1,233.31,233.98,110,44,2,3,233.3,234.0,100,155,1,7,233.25,234.13,55,400,2,1,AAPL,0,0,400,0,0,0,0,0,0,0,0,233.70499999999998
2024-10-21T11:54:58.133095032Z,2024-10-21 11:54:58.132928650+00:00,10,2,38,C,A,5,233.9,200,130,166382,11420067,233.67,233.74,144,200,3,1,233.59,233.75,400,1,1,1,233.53,233.77,10,8,1,1,233.51,233.78,27,179,1,3,233.45,233.8,15,25,1,1,233.4,233.94,110,200,2,1,233.39,233.98,10,44,1,3,233.31,234.0,110,155,2,7,233.3,234.13,100,400,1,1,233.25,234.17,55,1,2,1,AAPL,0,0,0,0,0,0,200,200,44,155,400,233.70499999999998
2024-10-21T11:54:58.134110732Z,2024-10-21 11:54:58.133944065+00:00,10,2,38,A,A,1,233.75,200,130,166667,11420068,233.67,233.74,144,200,3,1,233.59,233.75,400,201,1,2,233.53,233.77,10,8,1,1,233.51,233.78,27,179,1,3,233.45,233.8,15,25,1,1,233.4,233.94,110,200,2,1,233.39,233.98,10,44,1,3,233.31,234.0,110,155,2,7,233.3,234.13,100,400,1,1,233.25,234.17,55,1,2,1,AAPL,0,0,200,0,0,0,0,0,0,0,0,233.70499999999998
2024-10-21T11:55:09.125208612Z,2024-10-21 11:55:09.125042325+00:00,10,2,38,C,B,1,233.59,400,130,166287,11428279,233.67,233.74,144,200,3,1,233.53,233.75,10,201,1,2,233.51,233.77,27,8,1,1,233.45,233.78,15,179,1,3,233.4,233.8,110,25,2,1,233.39,233.94,10,200,1,1,233.31,233.98,110,44,2,3,233.3,234.0,100,155,1,7,233.25,234.13,55,400,2,1,233.24,234.17,1,1,1,1,AAPL,0,0,-400,-10,-27,-15,-110,-10,-110,-100,-55,233.70499999999998
2024-10-21T11:55:09.125222408Z,2024-10-21 11:55:09.125055670+00:00,10,2,38,A,B,1,233.57,400,130,166738,11428280,233.67,233.74,144,200,3,1,233.57,233.75,400,201,1,2,233.53,233.77,10,8,1,1,233.51,233.78,27,179,1,3,233.45,233.8,15,25,1,1,233.4,233.94,110,200,2,1,233.39,233.98,10,44,1,3,233.31,234.0,110,155,2,7,233.3,234.13,100,400,1,1,233.25,234.17,55,1,2,1,AAPL,0,0,400,10,27,15,110,10,110,100,55,233.70499999999998
2024-10-21T11:55:09.160176239Z,2024-10-21 11:55:09.160009889+00:00,10,2,38,C,A,3,233.78,29,130,166350,11428375,233.67,233.74,144,200,3,1,233.57,233.75,400,201,1,2,233.53,233.77,10,8,1,1,233.51,233.78,27,150,1,2,233.45,233.8,15,25,1,1,233.4,233.94,110,200,2,1,233.39,233.98,10,44,1,3,233.31,234.0,110,155,2,7,233.3,234.13,100,400,1,1,233.25,234.17,55,1,2,1,AAPL,0,0,0,0,-29,0,0,0,0,0,0,233.70499999999998
2024-10-21T11:55:09.160217682Z,2024-10-21 11:55:09.160051447+00:00,10,2,38,A,A,2,233.77,27,130,166235,11428376,233.67,233.74,144,200,3,1,233.57,233.75,400,201,1,2,233.53,233.77,10,35,1,2,233.51,233.78,27,150,1,2,233.45,233.8,15,25,1,1,233.4,233.94,110,200,2,1,233.39,233.98,10,44,1,3,233.31,234.0,110,155,2,7,233.3,234.13,100,400,1,1,233.25,234.17,55,1,2,1,AAPL,0,0,0,27,0,0,0,0,0,0,0,233.70499999999998
2024-10-21T11:55:13.899318666Z,2024-10-21 11:55:13.899151539+00:00,10,2,38,A,B,1,233.59,400,130,167127,11431712,233.67,233.74,144,200,3,1,233.59,233.75,400,201,1,2,233.53,233.77,10,35,1,2,233.51,233.78,27,150,1,2,233.45,233.8,15,25,1,1,233.4,233.94,110,200,2,1,233.39,233.98,10,44,1,3,233.31,234.0,110,155,2,7,233.3,234.13,100,400,1,1,233.25,234.17,55,1,2,1,AAPL,0,0,400,0,0,0,0,0,0,0,0,233.70499999999998
2024-10-21T11:55:22.016922342Z,2024-10-21 11:55:22.016715475+00:00,10,2,38,C,B,3,233.51,27,130,206867,11437208,233.67,233.74,144,200,3,1,233.59,233.75,400,201,1,2,233.53,233.77,10,35,1,2,233.45,233.78,15,150,1,2,233.4,233.8,110,25,2,1,233.39,233.94,10,200,1,1,233.31,233.98,110,44,2,3,233.3,234.0,100,155,1,7,233.25,234.13,55,400,2,1,233.24,234.17,1,1,1,1,AAPL,0,0,0,0,-27,-15,-110,-10,-110,-100,-55,233.70499999999998
2024-10-21T11:55:22.060339836Z,2024-10-21 11:55:22.060173668+00:00,10,2,38,A,B,3,233.52,27,130,166168,11437365,233.67,233.74,144,200,3,1,233.59,233.75,400,201,1,2,233.53,233.77,10,35,1,2,233.52,233.78,27,150,1,2,233.45,233.8,15,25,1,1,233.4,233.94,110,200,2,1,233.39,233.98,10,44,1,3,233.31,234.0,110,155,2,7,233.3,234.13,100,400,1,1,233.25,234.17,55,1,2,1,AAPL,0,0,0,0,27,15,110,10,110,100,55,233.70499999999998
2024-10-21T11:55:22.132944892Z,2024-10-21 11:55:22.132778490+00:00,10,2,38,A,B,1,233.6,400,130,166402,11437593,233.67,233.74,144,200,3,1,233.6,233.75,400,201,1,2,233.53,233.77,10,35,1,2,233.52,233.78,27,150,1,2,233.45,233.8,15,25,1,1,233.4,233.94,110,200,2,1,233.39,233.98,10,44,1,3,233.31,234.0,110,155,2,7,233.3,234.13,100,400,1,1,233.25,234.17,55,1,2,1,AAPL,0,0,400,0,0,0,0,0,0,0,0,233.70499999999998
2024-10-21T11:55:26.448145163Z,2024-10-21 11:55:26.447978801+00:00,10,2,38,A,A,0,233.73,200,130,166362,11440665,233.67,233.73,144,200,3,1,233.6,233.75,400,201,1,2,233.53,233.77,10,35,1,2,233.52,233.78,27,150,1,2,233.45,233.8,15,25,1,1,233.4,233.94,110,200,2,1,233.39,233.98,10,44,1,3,233.31,234.0,110,155,2,7,233.3,234.13,100,400,1,1,233.25,234.17,55,1,2,1,AAPL,200,200,0,0,0,0,0,0,0,0,0,233.7
2024-10-21T11:55:30.365451020Z,2024-10-21 11:55:30.365285173+00:00,10,2,38,C,B,1,233.6,400,130,165847,11442747,233.67,233.73,144,200,3,1,233.53,233.75,10,201,1,2,233.52,233.77,27,35,1,2,233.45,233.78,15,150,1,2,233.4,233.8,110,25,2,1,233.39,233.94,10,200,1,1,233.31,233.98,110,44,2,3,233.3,234.0,100,155,1,7,233.25,234.13,55,400,2,1,233.24,234.17,1,1,1,1,AAPL,0,0,-400,-10,-27,-15,-110,-10,-110,-100,-55,233.7
2024-10-21T11:55:30.365463941Z,2024-10-21 11:55:30.365297270+00:00,10,2,38,A,B,1,233.54,400,130,166671,11442749,233.67,233.73,144,200,3,1,233.54,233.75,400,201,1,2,233.53,233.77,10,35,1,2,233.52,233.78,27,150,1,2,233.45,233.8,15,25,1,1,233.4,233.94,110,200,2,1,233.39,233.98,10,44,1,3,233.31,234.0,110,155,2,7,233.3,234.13,100,400,1,1,233.25,234.17,55,1,2,1,AAPL,0,0,400,10,27,15,110,10,110,100,55,233.7
2024-10-21T11:55:30.377213560Z,2024-10-21 11:55:30.377046532+00:00,10,2,38,C,B,3,233.52,27,130,167028,11443045,233.67,233.73,144,200,3,1,233.54,233.75,400,201,1,2,233.53,233.77,10,35,1,2,233.45,233.78,15,150,1,2,233.4,233.8,110,25,2,1,233.39,233.94,10,200,1,1,233.31,233.98,110,44,2,3,233.3,234.0,100,155,1,7,233.25,234.13,55,400,2,1,233.24,234.17,1,1,1,1,AAPL,0,0,0,0,-27,-15,-110,-10,-110,-100,-55,233.7
2024-10-21T11:55:30.377277043Z,2024-10-21 11:55:30.377110788+00:00,10,2,38,A,B,2,233.53,30,130,166255,11443050,233.67,233.73,144,200,3,1,233.54,233.75,400,201,1,2,233.53,233.77,40,35,2,2,233.45,233.78,15,150,1,2,233.4,233.8,110,25,2,1,233.39,233.94,10,200,1,1,233.31,233.98,110,44,2,3,233.3,234.0,100,155,1,7,233.25,234.13,55,400,2,1,233.24,234.17,1,1,1,1,AAPL,0,0,0,30,0,0,0,0,0,0,0,233.7
2024-10-21T11:55:30.509581691Z,2024-10-21 11:55:30.509413271+00:00,10,2,38,C,A,2,233.77,27,130,168420,11443614,233.67,233.73,144,200,3,1,233.54,233.75,400,201,1,2,233.53,233.77,40,8,2,1,233.45,233.78,15,150,1,2,233.4,233.8,110,25,2,1,233.39,233.94,10,200,1,1,233.31,233.98,110,44,2,3,233.3,234.0,100,155,1,7,233.25,234.13,55,400,2,1,233.24,234.17,1,1,1,1,AAPL,0,0,0,-27,0,0,0,0,0,0,0,233.7
2024-10-21T11:55:30.509624409Z,2024-10-21 11:55:30.509458075+00:00,10,2,38,A,A,4,233.79,27,130,166334,11443615,233.67,233.73,144,200,3,1,233.54,233.75,400,201,1,2,233.53,233.77,40,8,2,1,233.45,233.78,15,150,1,2,233.4,233.79,110,27,2,1,233.39,233.8,10,25,1,1,233.31,233.94,110,200,2,1,233.3,233.98,100,44,1,3,233.25,234.0,55,155,2,7,233.24,234.13,1,400,1,1,AAPL,0,0,0,0,0,27,25,200,44,155,400,233.7
2024-10-21T11:55:30.560115755Z,2024-10-21 11:55:30.559949308+00:00,10,2,38,A,B,1,233.55,400,130,166447,11443807,233.67,233.73,144,200,3,1,233.55,233.75,400,201,1,2,233.53,233.77,40,8,2,1,233.45,233.78,15,150,1,2,233.4,233.79,110,27,2,1,233.39,233.8,10,25,1,1,233.31,233.94,110,200,2,1,233.3,233.98,100,44,1,3,233.25,234.0,55,155,2,7,233.24,234.13,1,400,1,1,AAPL,0,0,400,0,0,0,0,0,0,0,0,233.7
2024-10-21T11:55:31.195089596Z,2024-10-21 11:55:31.194923125+00:00,10,2,38,A,B,2,233.54,27,130,166471,11444867,233.67,233.73,144,200,3,1,233.55,233.75,400,201,1,2,233.54,233.77,27,8,1,1,233.53,233.78,40,150,2,2,233.45,233.79,15,27,1,1,233.4,233.8,110,25,2,1,233.39,233.94,10,200,1,1,233.31,233.98,110,44,2,3,233.3,234.0,100,155,1,7,233.25,234.13,55,400,2,1,AAPL,0,0,0,27,40,15,110,10,110,100,55,233.7
2024-10-21T11:55:31.195189780Z,2024-10-21 11:55:31.195023714+00:00,10,2,38,C,B,3,233.53,30,130,166066,11444870,233.67,233.73,144,200,3,1,233.55,233.75,400,201,1,2,233.54,233.77,27,8,1,1,233.53,233.78,10,150,1,2,233.45,233.79,15,27,1,1,233.4,233.8,110,25,2,1,233.39,233.94,10,200,1,1,233.31,233.98,110,44,2,3,233.3,234.0,100,155,1,7,233.25,234.13,55,400,2,1,AAPL,0,0,0,0,-30,0,0,0,0,0,0,233.7
2024-10-21T11:55:34.079427496Z,2024-10-21 11:55:34.079261198+00:00,10,2,38,C,B,0,233.67,139,130,166298,11447051,233.67,233.73,5,200,2,1,233.55,233.75,400,201,1,2,233.54,233.77,27,8,1,1,233.53,233.78,10,150,1,2,233.45,233.79,15,27,1,1,233.4,233.8,110,25,2,1,233.39,233.94,10,200,1,1,233.31,233.98,110,44,2,3,233.3,234.0,100,155,1,7,233.25,234.13,55,400,2,1,AAPL,-139,-139,0,0,0,0,0,0,0,0,0,233.7
2024-10-21T11:55:35.303088788Z,2024-10-21 11:55:35.302921978+00:00,10,2,38,C,B,0,233.67,2,130,166810,11448345,233.67,233.73,3,200,1,1,233.55,233.75,400,201,1,2,233.54,233.77,27,8,1,1,233.53,233.78,10,150,1,2,233.45,233.79,15,27,1,1,233.4,233.8,110,25,2,1,233.39,233.94,10,200,1,1,233.31,233.98,110,44,2,3,233.3,234.0,100,155,1,7,233.25,234.13,55,400,2,1,AAPL,-2,-2,0,0,0,0,0,0,0,0,0,233.7
2024-10-21T11:55:35.303234088Z,2024-10-21 11:55:35.303067914+00:00,10,2,38,C,B,0,233.67,3,130,166174,11448346,233.55,233.73,400,200,1,1,233.54,233.75,27,201,1,2,233.53,233.77,10,8,1,1,233.45,233.78,15,150,1,2,233.4,233.79,110,27,2,1,233.39,233.8,10,25,1,1,233.31,233.94,110,200,2,1,233.3,233.98,100,44,1,3,233.25,234.0,55,155,2,7,233.24,234.13,1,400,1,1,AAPL,-3,-3,-400,-27,-10,-15,-110,-10,-110,-100,-55,233.64
2024-10-21T11:55:35.304698115Z,2024-10-21 11:55:35.304531207+00:00,10,2,38,A,B,0,233.67,2,130,166908,11448347,233.67,233.73,2,200,1,1,233.55,233.75,400,201,1,2,233.54,233.77,27,8,1,1,233.53,233.78,10,150,1,2,233.45,233.79,15,27,1,1,233.4,233.8,110,25,2,1,233.39,233.94,10,200,1,1,233.31,233.98,110,44,2,3,233.3,234.0,100,155,1,7,233.25,234.13,55,400,2,1,AAPL,2,2,400,27,10,15,110,10,110,100,55,233.7
2024-10-21T11:55:35.305902949Z,2024-10-21 11:55:35.305736838+00:00,10,2,38,C,B,0,233.67,2,130,166111,11448348,233.55,233.73,400,200,1,1,233.54,233.75,27,201,1,2,233.53,233.77,10,8,1,1,233.45,233.78,15,150,1,2,233.4,233.79,110,27,2,1,233.39,233.8,10,25,1,1,233.31,233.94,110,200,2,1,233.3,233.98,100,44,1,3,233.25,234.0,55,155,2,7,233.24,234.13,1,400,1,1,AAPL,-2,-2,-400,-27,-10,-15,-110,-10,-110,-100,-55,233.64
2024-10-21T11:55:35.374378511Z,2024-10-21 11:55:35.374212373+00:00,10,2,38,C,B,0,233.55,400,130,166138,11448379,233.54,233.73,27,200,1,1,233.53,233.75,10,201,1,2,233.45,233.77,15,8,1,1,233.4,233.78,110,150,2,2,233.39,233.79,10,27,1,1,233.31,233.8,110,25,2,1,233.3,233.94,100,200,1,1,233.25,233.98,55,44,2,3,233.24,234.0,1,155,1,7,233.23,234.13,50,400,1,1,AAPL,-400,-400,-27,-10,-15,-110,-10,-110,-100,-55,-1,233.635
2024-10-21T11:55:35.374392676Z,2024-10-21 11:55:35.374226300+00:00,10,2,38,A,B,2,233.5,200,130,166376,11448380,233.54,233.73,27,200,1,1,233.53,233.75,10,201,1,2,233.5,233.77,200,8,1,1,233.45,233.78,15,150,1,2,233.4,233.79,110,27,2,1,233.39,233.8,10,25,1,1,233.31,233.94,110,200,2,1,233.3,233.98,100,44,1,3,233.25,234.0,55,155,2,7,233.24,234.13,1,400,1,1,AAPL,0,0,0,200,15,110,10,110,100,55,1,233.635
2024-10-21T11:55:38.243838236Z,2024-10-21 11:55:38.243671650+00:00,10,2,38,C,A,0,233.73,200,130,166586,11450385,233.54,233.75,27,201,1,2,233.53,233.77,10,8,1,1,233.5,233.78,200,150,1,2,233.45,233.79,15,27,1,1,233.4,233.8,110,25,2,1,233.39,233.94,10,200,1,1,233.31,233.98,110,44,2,3,233.3,234.0,100,155,1,7,233.25,234.13,55,400,2,1,233.24,234.17,1,1,1,1,AAPL,200,200,201,8,150,27,25,200,44,155,400,233.64499999999998
2024-10-21T11:55:38.243849825Z,2024-10-21 11:55:38.243683612+00:00,10,2,38,A,A,0,233.75,200,130,166213,11450386,233.54,233.75,27,401,1,3,233.53,233.77,10,8,1,1,233.5,233.78,200,150,1,2,233.45,233.79,15,27,1,1,233.4,233.8,110,25,2,1,233.39,233.94,10,200,1,1,233.31,233.98,110,44,2,3,233.3,234.0,100,155,1,7,233.25,234.13,55,400,2,1,233.24,234.17,1,1,1,1,AAPL,200,200,0,0,0,0,0,0,0,0,0,233.64499999999998
2024-10-21T11:55:38.298503075Z,2024-10-21 11:55:38.298336797+00:00,10,2,38,A,B,2,233.51,200,130,166278,11450436,233.54,233.75,27,401,1,3,233.53,233.77,10,8,1,1,233.51,233.78,200,150,1,2,233.45,233.79,15,27,1,1,233.4,233.8,110,25,2,1,233.39,233.94,10,200,1,1,233.31,233.98,110,44,2,3,233.3,234.0,100,155,1,7,233.25,234.13,55,400,2,1,233.24,234.17,1,1,1,1,AAPL,0,0,0,200,0,0,0,0,0,0,0,233.64499999999998
2024-10-21T11:55:38.572580545Z,2024-10-21 11:55:38.572413983+00:00,10,2,38,A,A,0,233.74,200,130,166562,11450747,233.54,233.74,27,200,1,1,233.53,233.75,10,201,1,2,233.51,233.77,200,8,1,1,233.45,233.78,15,150,1,2,233.4,233.79,110,27,2,1,233.39,233.8,10,25,1,1,233.31,233.94,110,200,2,1,233.3,233.98,100,44,1,3,233.25,234.0,55,155,2,7,233.24,234.13,1,400,1,1,AAPL,200,200,201,8,150,27,25,200,44,155,400,233.64
2024-10-21T11:55:44.733677601Z,2024-10-21 11:55:44.733510979+00:00,10,2,38,A,B,0,233.55,29,130,166622,11455418,233.55,233.74,29,200,1,1,233.54,233.75,27,201,1,2,233.53,233.77,10,8,1,1,233.51,233.78,200,150,1,2,233.45,233.79,15,27,1,1,233.4,233.8,110,25,2,1,233.39,233.94,10,200,1,1,233.31,233.98,110,44,2,3,233.3,234.0,100,155,1,7,233.25,234.13,55,400,2,1,AAPL,29,29,27,10,200,15,110,10,110,100,55,233.645
2024-10-21T11:55:44.792124247Z,2024-10-21 11:55:44.791957886+00:00,10,2,38,C,B,1,233.54,27,130,166361,11455485,233.55,233.74,29,200,1,1,233.53,233.75,10,201,1,2,233.51,233.77,200,8,1,1,233.45,233.78,15,150,1,2,233.4,233.79,110,27,2,1,233.39,233.8,10,25,1,1,233.31,233.94,110,200,2,1,233.3,233.98,100,44,1,3,233.25,234.0,55,155,2,7,233.24,234.13,1,400,1,1,AAPL,0,0,-27,-10,-200,-15,-110,-10,-110,-100,-55,233.645
2024-10-21T11:55:51.294115015Z,2024-10-21 11:55:51.293948230+00:00,10,2,38,A,A,0,233.73,100,130,166785,11459624,233.55,233.73,29,100,1,1,233.53,233.74,10,200,1,1,233.51,233.75,200,201,1,2,233.45,233.77,15,8,1,1,233.4,233.78,110,150,2,2,233.39,233.79,10,27,1,1,233.31,233.8,110,25,2,1,233.3,233.94,100,200,1,1,233.25,233.98,55,44,2,3,233.24,234.0,1,155,1,7,AAPL,100,100,200,201,8,150,27,25,200,44,155,233.64
2024-10-21T11:55:51.294383491Z,2024-10-21 11:55:51.294217665+00:00,10,2,38,C,A,0,233.73,100,130,165826,11459625,233.55,233.74,29,200,1,1,233.53,233.75,10,201,1,2,233.51,233.77,200,8,1,1,233.45,233.78,15,150,1,2,233.4,233.79,110,27,2,1,233.39,233.8,10,25,1,1,233.31,233.94,110,200,2,1,233.3,233.98,100,44,1,3,233.25,234.0,55,155,2,7,233.24,234.13,1,400,1,1,AAPL,100,100,200,201,8,150,27,25,200,44,155,233.645
2024-10-21T11:55:51.365354478Z,2024-10-21 11:55:51.365188500+00:00,10,2,38,C,B,2,233.51,200,130,165978,11459674,233.55,233.74,29,200,1,1,233.53,233.75,10,201,1,2,233.45,233.77,15,8,1,1,233.4,233.78,110,150,2,2,233.39,233.79,10,27,1,1,233.31,233.8,110,25,2,1,233.3,233.94,100,200,1,1,233.25,233.98,55,44,2,3,233.24,234.0,1,155,1,7,233.23,234.13,50,400,1,1,AAPL,0,0,0,-200,-15,-110,-10,-110,-100,-55,-1,233.645
2024-10-21T11:55:51.401763373Z,2024-10-21 11:55:51.401597368+00:00,10,2,38,A,B,2,233.47,200,130,166005,11459719,233.55,233.74,29,200,1,1,233.53,233.75,10,201,1,2,233.47,233.77,200,8,1,1,233.45,233.78,15,150,1,2,233.4,233.79,110,27,2,1,233.39,233.8,10,25,1,1,233.31,233.94,110,200,2,1,233.3,233.98,100,44,1,3,233.25,234.0,55,155,2,7,233.24,234.13,1,400,1,1,AAPL,0,0,0,200,15,110,10,110,100,55,1,233.645
2024-10-21T11:55:53.213495106Z,2024-10-21 11:55:53.213328704+00:00,10,2,38,A,A,6,233.81,26,130,166402,11460545,233.55,233.74,29,200,1,1,233.53,233.75,10,201,1,2,233.47,233.77,200,8,1,1,233.45,233.78,15,150,1,2,233.4,233.79,110,27,2,1,233.39,233.8,10,25,1,1,233.31,233.81,110,26,2,1,233.3,233.94,100,200,1,1,233.25,233.98,55,44,2,3,233.24,234.0,1,155,1,7,AAPL,0,0,0,0,0,0,0,26,200,44,155,233.645
2024-10-21T11:55:53.213531364Z,2024-10-21 11:55:53.213365167+00:00,10,2,38,C,A,4,233.79,27,130,166197,11460546,233.55,233.74,29,200,1,1,233.53,233.75,10,201,1,2,233.47,233.77,200,8,1,1,233.45,233.78,15,150,1,2,233.4,233.8,110,25,2,1,233.39,233.81,10,26,1,1,233.31,233.94,110,200,2,1,233.3,233.98,100,44,1,3,233.25,234.0,55,155,2,7,233.24,234.13,1,400,1,1,AAPL,0,0,0,0,0,27,25,26,200,44,155,233.645
2024-10-21T11:55:54.691552408Z,2024-10-21 11:55:54.691386316+00:00,10,2,38,A,B,2,233.47,200,130,166092,11461460,233.55,233.74,29,200,1,1,233.53,233.75,10,201,1,2,233.47,233.77,400,8,2,1,233.45,233.78,15,150,1,2,233.4,233.8,110,25,2,1,233.39,233.81,10,26,1,1,233.31,233.94,110,200,2,1,233.3,233.98,100,44,1,3,233.25,234.0,55,155,2,7,233.24,234.13,1,400,1,1,AAPL,0,0,0,200,0,0,0,0,0,0,0,233.645
2024-10-21T11:55:54.691564851Z,2024-10-21 11:55:54.691398035+00:00,10,2,38,C,A,0,233.74,200,130,166816,11461461,233.55,233.75,29,201,1,2,233.53,233.77,10,8,1,1,233.47,233.78,400,150,2,2,233.45,233.8,15,25,1,1,233.4,233.81,110,26,2,1,233.39,233.94,10,200,1,1,233.31,233.98,110,44,2,3,233.3,234.0,100,155,1,7,233.25,234.13,55,400,2,1,233.24,234.17,1,1,1,1,AAPL,200,200,201,8,150,25,26,200,44,155,400,233.65
2024-10-21T11:55:54.691573831Z,2024-10-21 11:55:54.691407713+00:00,10,2,38,A,A,1,233.76,200,130,166118,11461462,233.55,233.75,29,201,1,2,233.53,233.76,10,200,1,1,233.47,233.77,400,8,2,1,233.45,233.78,15,150,1,2,233.4,233.8,110,25,2,1,233.39,233.81,10,26,1,1,233.31,233.94,110,200,2,1,233.3,233.98,100,44,1,3,233.25,234.0,55,155,2,7,233.24,234.13,1,400,1,1,AAPL,0,0,200,8,150,25,26,200,44,155,400,233.65
2024-10-21T11:55:54.746022499Z,2024-10-21 11:55:54.745856609+00:00,10,2,38,C,B,2,233.47,200,130,165890,11461600,233.55,233.75,29,201,1,2,233.53,233.76,10,200,1,1,233.47,233.77,200,8,1,1,233.45,233.78,15,150,1,2,233.4,233.8,110,25,2,1,233.39,233.81,10,26,1,1,233.31,233.94,110,200,2,1,233.3,233.98,100,44,1,3,233.25,234.0,55,155,2,7,233.24,234.13,1,400,1,1,AAPL,0,0,0,-200,0,0,0,0,0,0,0,233.65
2024-10-21T11:55:54.746035106Z,2024-10-21 11:55:54.745868744+00:00,10,2,38,A,B,2,233.48,200,130,166362,11461601,233.55,233.75,29,201,1,2,233.53,233.76,10,200,1,1,233.48,233.77,200,8,1,1,233.45,233.78,15,150,1,2,233.4,233.8,110,25,2,1,233.39,233.81,10,26,1,1,233.31,233.94,110,200,2,1,233.3,233.98,100,44,1,3,233.25,234.0,55,155,2,7,233.24,234.13,1,400,1,1,AAPL,0,0,0,200,0,0,0,0,0,0,0,233.65
2024-10-21T11:55:54.762658342Z,2024-10-21 11:55:54.762492206+00:00,10,2,38,C,B,0,233.55,29,130,166136,11461707,233.53,233.75,10,201,1,2,233.48,233.76,200,200,1,1,233.45,233.77,15,8,1,1,233.4,233.78,110,150,2,2,233.39,233.8,10,25,1,1,233.31,233.81,110,26,2,1,233.3,233.94,100,200,1,1,233.25,233.98,55,44,2,3,233.24,234.0,1,155,1,7,233.23,234.13,50,400,1,1,AAPL,-29,-29,-10,-200,-15,-110,-10,-110,-100,-55,-1,233.64
2024-10-21T11:55:54.762696483Z,2024-10-21 11:55:54.762530320+00:00,10,2,38,A,B,0,233.56,28,130,166163,11461708,233.56,233.75,28,201,1,2,233.53,233.76,10,200,1,1,233.48,233.77,200,8,1,1,233.45,233.78,15,150,1,2,233.4,233.8,110,25,2,1,233.39,233.81,10,26,1,1,233.31,233.94,110,200,2,1,233.3,233.98,100,44,1,3,233.25,234.0,55,155,2,7,233.24,234.13,1,400,1,1,AAPL,28,28,10,200,15,110,10,110,100,55,1,233.655
2024-10-21T11:55:55.306858576Z,2024-10-21 11:55:55.306692496+00:00,10,2,38,C,B,2,233.48,200,130,166080,11462057,233.56,233.75,28,201,1,2,233.53,233.76,10,200,1,1,233.45,233.77,15,8,1,1,233.4,233.78,110,150,2,2,233.39,233.8,10,25,1,1,233.31,233.81,110,26,2,1,233.3,233.94,100,200,1,1,233.25,233.98,55,44,2,3,233.24,234.0,1,155,1,7,233.23,234.13,50,400,1,1,AAPL,0,0,0,-200,-15,-110,-10,-110,-100,-55,-1,233.655
2024-10-21T11:55:55.306871673Z,2024-10-21 11:55:55.306705027+00:00,10,2,38,A,B,2,233.46,400,130,166646,11462058,233.56,233.75,28,201,1,2,233.53,233.76,10,200,1,1,233.46,233.77,400,8,1,1,233.45,233.78,15,150,1,2,233.4,233.8,110,25,2,1,233.39,233.81,10,26,1,1,233.31,233.94,110,200,2,1,233.3,233.98,100,44,1,3,233.25,234.0,55,155,2,7,233.24,234.13,1,400,1,1,AAPL,0,0,0,400,15,110,10,110,100,55,1,233.655
2024-10-21T11:55:55.361248847Z,2024-10-21 11:55:55.361082355+00:00,10,2,38,A,A,0,233.75,200,130,166492,11462096,233.56,233.75,28,401,1,3,233.53,233.77,10,8,1,1,233.46,233.78,400,150,1,2,233.45,233.8,15,25,1,1,233.4,233.81,110,26,2,1,233.39,233.94,10,200,1,1,233.31,233.98,110,44,2,3,233.3,234.0,100,155,1,7,233.25,234.13,55,400,2,1,233.24,234.17,1,1,1,1,AAPL,200,200,200,8,150,25,26,200,44,155,400,233.655
2024-10-21T11:55:55.706272013Z,2024-10-21 11:55:55.706105479+00:00,10,2,38,A,B,2,233.47,200,130,166534,11462281,233.56,233.75,28,401,1,3,233.53,233.77,10,8,1,1,233.47,233.78,200,150,1,2,233.45,233.8,15,25,1,1,233.4,233.81,110,26,2,1,233.39,233.94,10,200,1,1,233.31,233.98,110,44,2,3,233.3,234.0,100,155,1,7,233.25,234.13,55,400,2,1,233.24,234.17,1,1,1,1,AAPL,0,0,0,200,0,0,0,0,0,0,0,233.655
2024-10-21T11:55:58.151746575Z,2024-10-21 11:55:58.151580102+00:00,10,2,38,A,B,2,233.47,200,130,166473,11463546,233.56,233.75,28,401,1,3,233.53,233.77,10,8,1,1,233.47,233.78,400,150,2,2,233.45,233.8,15,25,1,1,233.4,233.81,110,26,2,1,233.39,233.94,10,200,1,1,233.31,233.98,110,44,2,3,233.3,234.0,100,155,1,7,233.25,234.13,55,400,2,1,233.24,234.17,1,1,1,1,AAPL,0,0,0,200,0,0,0,0,0,0,0,233.655
2024-10-21T11:56:07.493822226Z,2024-10-21 11:56:07.493655598+00:00,10,2,38,C,A,7,234.0,2,130,166628,11471731,233.56,233.75,28,401,1,3,233.53,233.77,10,8,1,1,233.47,233.78,400,150,2,2,233.45,233.8,15,25,1,1,233.4,233.81,110,26,2,1,233.39,233.94,10,200,1,1,233.31,233.98,110,44,2,3,233.3,234.0,100,153,1,6,233.25,234.13,55,400,2,1,233.24,234.17,1,1,1,1,AAPL,0,0,0,0,0,0,0,0,-2,0,0,233.655
2024-10-21T11:56:10.953659035Z,2024-10-21 11:56:10.953492365+00:00,10,2,38,C,A,0,233.75,200,130,166670,11474926,233.56,233.75,28,201,1,2,233.53,233.77,10,8,1,1,233.47,233.78,400,150,2,2,233.45,233.8,15,25,1,1,233.4,233.81,110,26,2,1,233.39,233.94,10,200,1,1,233.31,233.98,110,44,2,3,233.3,234.0,100,153,1,6,233.25,234.13,55,400,2,1,233.24,234.17,1,1,1,1,AAPL,-200,-200,0,0,0,0,0,0,0,0,0,233.655
2024-10-21T11:56:10.953670665Z,2024-10-21 11:56:10.953504236+00:00,10,2,38,A,A,1,233.77,200,130,166429,11474927,233.56,233.75,28,201,1,2,233.53,233.77,10,208,1,2,233.47,233.78,400,150,2,2,233.45,233.8,15,25,1,1,233.4,233.81,110,26,2,1,233.39,233.94,10,200,1,1,233.31,233.98,110,44,2,3,233.3,234.0,100,153,1,6,233.25,234.13,55,400,2,1,233.24,234.17,1,1,1,1,AAPL,0,0,200,0,0,0,0,0,0,0,0,233.655
2024-10-21T11:56:11.008321762Z,2024-10-21 11:56:11.008155483+00:00,10,2,38,C,B,2,233.47,200,130,166279,11475150,233.56,233.75,28,201,1,2,233.53,233.77,10,208,1,2,233.47,233.78,200,150,1,2,233.45,233.8,15,25,1,1,233.4,233.81,110,26,2,1,233.39,233.94,10,200,1,1,233.31,233.98,110,44,2,3,233.3,234.0,100,153,1,6,233.25,234.13,55,400,2,1,233.24,234.17,1,1,1,1,AAPL,0,0,0,-200,0,0,0,0,0,0,0,233.655
2024-10-21T11:56:11.008333820Z,2024-10-21 11:56:11.008167451+00:00,10,2,38,A,B,2,233.48,400,130,166369,11475151,233.56,233.75,28,201,1,2,233.53,233.77,10,208,1,2,233.48,233.78,400,150,1,2,233.45,233.8,15,25,1,1,233.4,233.81,110,26,2,1,233.39,233.94,10,200,1,1,233.31,233.98,110,44,2,3,233.3,234.0,100,153,1,6,233.25,234.13,55,400,2,1,233.24,234.17,1,1,1,1,AAPL,0,0,0,400,0,0,0,0,0,0,0,233.655
2024-10-21T11:56:11.038918460Z,2024-10-21 11:56:11.038752302+00:00,10,2,38,C,B,0,233.56,28,130,166158,11475414,233.53,233.75,10,201,1,2,233.48,233.77,400,208,1,2,233.45,233.78,15,150,1,2,233.4,233.8,110,25,2,1,233.39,233.81,10,26,1,1,233.31,233.94,110,200,2,1,233.3,233.98,100,44,1,3,233.25,234.0,55,153,2,6,233.24,234.13,1,400,1,1,233.23,234.17,50,1,1,1,AAPL,-28,-28,-10,-400,-15,-110,-10,-110,-100,-55,-1,233.64
2024-10-21T11:56:11.038969093Z,2024-10-21 11:56:11.038803026+00:00,10,2,38,A,B,0,233.57,26,130,166067,11475415,233.57,233.75,26,201,1,2,233.53,233.77,10,208,1,2,233.48,233.78,400,150,1,2,233.45,233.8,15,25,1,1,233.4,233.81,110,26,2,1,233.39,233.94,10,200,1,1,233.31,233.98,110,44,2,3,233.3,234.0,100,153,1,6,233.25,234.13,55,400,2,1,233.24,234.17,1,1,1,1,AAPL,26,26,10,400,15,110,10,110,100,55,1,233.66
2024-10-21T11:56:14.983045514Z,2024-10-21 11:56:14.982879375+00:00,10,2,38,C,A,1,233.77,200,130,166139,11478870,233.57,233.75,26,201,1,2,233.53,233.77,10,8,1,1,233.48,233.78,400,150,1,2,233.45,233.8,15,25,1,1,233.4,233.81,110,26,2,1,233.39,233.94,10,200,1,1,233.31,233.98,110,44,2,3,233.3,234.0,100,153,1,6,233.25,234.13,55,400,2,1,233.24,234.17,1,1,1,1,AAPL,0,0,-200,0,0,0,0,0,0,0,0,233.66
2024-10-21T11:56:14.983058049Z,2024-10-21 11:56:14.982891924+00:00,10,2,38,A,A,2,233.78,200,130,166125,11478871,233.57,233.75,26,201,1,2,233.53,233.77,10,8,1,1,233.48,233.78,400,350,1,3,233.45,233.8,15,25,1,1,233.4,233.81,110,26,2,1,233.39,233.94,10,200,1,1,233.31,233.98,110,44,2,3,233.3,234.0,100,153,1,6,233.25,234.13,55,400,2,1,233.24,234.17,1,1,1,1,AAPL,0,0,0,200,0,0,0,0,0,0,0,233.66
2024-10-21T11:56:15.037129152Z,2024-10-21 11:56:15.036962807+00:00,10,2,38,A,A,1,233.77,200,130,166345,11478943,233.57,233.75,26,201,1,2,233.53,233.77,10,208,1,2,233.48,233.78,400,150,1,2,233.45,233.8,15,25,1,1,233.4,233.81,110,26,2,1,233.39,233.94,10,200,1,1,233.31,233.98,110,44,2,3,233.3,234.0,100,153,1,6,233.25,234.13,55,400,2,1,233.24,234.17,1,1,1,1,AAPL,0,0,200,-200,0,0,0,0,0,0,0,233.66
2024-10-21T11:56:15.039252622Z,2024-10-21 11:56:15.039085832+00:00,10,2,38,C,A,4,233.81,26,130,166790,11478955,233.57,233.75,26,201,1,2,233.53,233.77,10,208,1,2,233.48,233.78,400,150,1,2,233.45,233.8,15,25,1,1,233.4,233.94,110,200,2,1,233.39,233.98,10,44,1,3,233.31,234.0,110,153,2,6,233.3,234.13,100,400,1,1,233.25,234.17,55,1,2,1,233.24,234.41,1,600,1,2,AAPL,0,0,0,0,0,26,200,44,153,400,1,233.66
2024-10-21T11:56:15.039369586Z,2024-10-21 11:56:15.039203352+00:00,10,2,38,A,A,4,233.84,28,130,166234,11478956,233.57,233.75,26,201,1,2,233.53,233.77,10,208,1,2,233.48,233.78,400,150,1,2,233.45,233.8,15,25,1,1,233.4,233.84,110,28,2,1,233.39,233.94,10,200,1,1,233.31,233.98,110,44,2,3,233.3,234.0,100,153,1,6,233.25,234.13,55,400,2,1,233.24,234.17,1,1,1,1,AAPL,0,0,0,0,0,28,200,44,153,400,1,233.66
2024-10-21T11:56:17.923045221Z,2024-10-21 11:56:17.922879284+00:00,10,2,38,C,A,4,233.84,28,130,165937,11481519,233.57,233.75,26,201,1,2,233.53,233.77,10,208,1,2,233.48,233.78,400,150,1,2,233.45,233.8,15,25,1,1,233.4,233.94,110,200,2,1,233.39,233.98,10,44,1,3,233.31,234.0,110,153,2,6,233.3,234.13,100,400,1,1,233.25,234.17,55,1,2,1,233.24,234.41,1,600,1,2,AAPL,0,0,0,0,0,28,200,44,153,400,1,233.66
2024-10-21T11:56:17.923122278Z,2024-10-21 11:56:17.922956219+00:00,10,2,38,A,A,4,233.83,30,130,166059,11481520,233.57,233.75,26,201,1,2,233.53,233.77,10,208,1,2,233.48,233.78,400,150,1,2,233.45,233.8,15,25,1,1,233.4,233.83,110,30,2,1,233.39,233.94,10,200,1,1,233.31,233.98,110,44,2,3,233.3,234.0,100,153,1,6,233.25,234.13,55,400,2,1,233.24,234.17,1,1,1,1,AAPL,0,0,0,0,0,30,200,44,153,400,1,233.66
2024-10-21T11:56:23.203528631Z,2024-10-21 11:56:23.203362495+00:00,10,2,38,C,A,1,233.77,200,130,166136,11484712,233.57,233.75,26,201,1,2,233.53,233.77,10,8,1,1,233.48,233.78,400,150,1,2,233.45,233.8,15,25,1,1,233.4,233.83,110,30,2,1,233.39,233.94,10,200,1,1,233.31,233.98,110,44,2,3,233.3,234.0,100,153,1,6,233.25,234.13,55,400,2,1,233.24,234.17,1,1,1,1,AAPL,0,0,-200,0,0,0,0,0,0,0,0,233.66
2024-10-21T11:56:23.203540531Z,2024-10-21 11:56:23.203374367+00:00,10,2,38,A,A,2,233.78,200,130,166164,11484713,233.57,233.75,26,201,1,2,233.53,233.77,10,8,1,1,233.48,233.78,400,350,1,3,233.45,233.8,15,25,1,1,233.4,233.83,110,30,2,1,233.39,233.94,10,200,1,1,233.31,233.98,110,44,2,3,233.3,234.0,100,153,1,6,233.25,234.13,55,400,2,1,233.24,234.17,1,1,1,1,AAPL,0,0,0,200,0,0,0,0,0,0,0,233.66
2024-10-21T11:56:23.231147559Z,2024-10-21 11:56:23.230980890+00:00,10,2,38,A,B,2,233.49,400,130,166669,11484750,233.57,233.75,26,201,1,2,233.53,233.77,10,8,1,1,233.49,233.78,400,350,1,3,233.45,233.8,15,25,1,1,233.4,233.83,110,30,2,1,233.39,233.94,10,200,1,1,233.31,233.98,110,44,2,3,233.3,234.0,100,153,1,6,233.25,234.13,55,400,2,1,233.24,234.17,1,1,1,1,AAPL,0,0,0,400,0,0,0,0,0,0,0,233.66
2024-10-21T11:56:23.259172222Z,2024-10-21 11:56:23.259005865+00:00,10,2,38,A,B,2,233.5,200,130,166357,11484879,233.57,233.75,26,201,1,2,233.53,233.77,10,8,1,1,233.5,233.78,200,350,1,3,233.45,233.8,15,25,1,1,233.4,233.83,110,30,2,1,233.39,233.94,10,200,1,1,233.31,233.98,110,44,2,3,233.3,234.0,100,153,1,6,233.25,234.13,55,400,2,1,233.24,234.17,1,1,1,1,AAPL,0,0,0,200,0,0,0,0,0,0,0,233.66
2024-10-21T11:56:23.260590051Z,2024-10-21 11:56:23.260424017+00:00,10,2,38,C,B,0,233.57,26,130,166034,11484896,233.53,233.75,10,201,1,2,233.5,233.77,200,8,1,1,233.45,233.78,15,350,1,3,233.4,233.8,110,25,2,1,233.39,233.83,10,30,1,1,233.31,233.94,110,200,2,1,233.3,233.98,100,44,1,3,233.25,234.0,55,153,2,6,233.24,234.13,1,400,1,1,233.23,234.17,50,1,1,1,AAPL,-26,-26,-10,-200,-15,-110,-10,-110,-100,-55,-1,233.64
2024-10-21T11:56:23.260686828Z,2024-10-21 11:56:23.260520532+00:00,10,2,38,A,B,0,233.58,27,130,166296,11484897,233.58,233.75,27,201,1,2,233.53,233.77,10,8,1,1,233.5,233.78,200,350,1,3,233.45,233.8,15,25,1,1,233.4,233.83,110,30,2,1,233.39,233.94,10,200,1,1,233.31,233.98,110,44,2,3,233.3,234.0,100,153,1,6,233.25,234.13,55,400,2,1,233.24,234.17,1,1,1,1,AAPL,27,27,10,200,15,110,10,110,100,55,1,233.66500000000002
2024-10-21T11:56:24.985463111Z,2024-10-21 11:56:24.985297090+00:00,10,2,38,C,B,2,233.5,200,130,166021,11486304,233.58,233.75,27,201,1,2,233.53,233.77,10,8,1,1,233.45,233.78,15,350,1,3,233.4,233.8,110,25,2,1,233.39,233.83,10,30,1,1,233.31,233.94,110,200,2,1,233.3,233.98,100,44,1,3,233.25,234.0,55,153,2,6,233.24,234.13,1,400,1,1,233.23,234.17,50,1,1,1,AAPL,0,0,0,-200,-15,-110,-10,-110,-100,-55,-1,233.66500000000002
2024-10-21T11:56:24.985475867Z,2024-10-21 11:56:24.985309618+00:00,10,2,38,A,B,2,233.48,400,130,166249,11486305,233.58,233.75,27,201,1,2,233.53,233.77,10,8,1,1,233.48,233.78,400,350,1,3,233.45,233.8,15,25,1,1,233.4,233.83,110,30,2,1,233.39,233.94,10,200,1,1,233.31,233.98,110,44,2,3,233.3,234.0,100,153,1,6,233.25,234.13,55,400,2,1,233.24,234.17,1,1,1,1,AAPL,0,0,0,400,15,110,10,110,100,55,1,233.66500000000002
2024-10-21T11:56:25.053368268Z,2024-10-21 11:56:25.053201827+00:00,10,2,38,A,A,1,233.77,200,130,166441,11486393,233.58,233.75,27,201,1,2,233.53,233.77,10,208,1,2,233.48,233.78,400,150,1,2,233.45,233.8,15,25,1,1,233.4,233.83,110,30,2,1,233.39,233.94,10,200,1,1,233.31,233.98,110,44,2,3,233.3,234.0,100,153,1,6,233.25,234.13,55,400,2,1,233.24,234.17,1,1,1,1,AAPL,0,0,200,-200,0,0,0,0,0,0,0,233.66500000000002
2024-10-21T11:56:29.970777659Z,2024-10-21 11:56:29.970611371+00:00,10,2,38,A,A,7,234.0,1,130,166288,11488797,233.58,233.75,27,201,1,2,233.53,233.77,10,208,1,2,233.48,233.78,400,150,1,2,233.45,233.8,15,25,1,1,233.4,233.83,110,30,2,1,233.39,233.94,10,200,1,1,233.31,233.98,110,44,2,3,233.3,234.0,100,154,1,7,233.25,234.13,55,400,2,1,233.24,234.17,1,1,1,1,AAPL,0,0,0,0,0,0,0,0,1,0,0,233.66500000000002
2024-10-21T11:56:34.567962213Z,2024-10-21 11:56:34.567796323+00:00,10,2,38,C,A,1,233.77,200,130,165890,11492628,233.58,233.75,27,201,1,2,233.53,233.77,10,8,1,1,233.48,233.78,400,150,1,2,233.45,233.8,15,25,1,1,233.4,233.83,110,30,2,1,233.39,233.94,10,200,1,1,233.31,233.98,110,44,2,3,233.3,234.0,100,154,1,7,233.25,234.13,55,400,2,1,233.24,234.17,1,1,1,1,AAPL,0,0,-200,0,0,0,0,0,0,0,0,233.66500000000002
2024-10-21T11:56:34.567975518Z,2024-10-21 11:56:34.567809267+00:00,10,2,38,A,A,2,233.78,200,130,166251,11492629,233.58,233.75,27,201,1,2,233.53,233.77,10,8,1,1,233.48,233.78,400,350,1,3,233.45,233.8,15,25,1,1,233.4,233.83,110,30,2,1,233.39,233.94,10,200,1,1,233.31,233.98,110,44,2,3,233.3,234.0,100,154,1,7,233.25,234.13,55,400,2,1,233.24,234.17,1,1,1,1,AAPL,0,0,0,200,0,0,0,0,0,0,0,233.66500000000002
2024-10-21T11:56:34.623579638Z,2024-10-21 11:56:34.623413180+00:00,10,2,38,A,A,1,233.77,200,130,166458,11492694,233.58,233.75,27,201,1,2,233.53,233.77,10,208,1,2,233.48,233.78,400,150,1,2,233.45,233.8,15,25,1,1,233.4,233.83,110,30,2,1,233.39,233.94,10,200,1,1,233.31,233.98,110,44,2,3,233.3,234.0,100,154,1,7,233.25,234.13,55,400,2,1,233.24,234.17,1,1,1,1,AAPL,0,0,200,-200,0,0,0,0,0,0,0,233.66500000000002
2024-10-21T11:56:42.272792276Z,2024-10-21 11:56:42.272625996+00:00,10,2,38,A,B,2,233.49,200,130,166280,11497144,233.58,233.75,27,201,1,2,233.53,233.77,10,208,1,2,233.49,233.78,200,150,1,2,233.45,233.8,15,25,1,1,233.4,233.83,110,30,2,1,233.39,233.94,10,200,1,1,233.31,233.98,110,44,2,3,233.3,234.0,100,154,1,7,233.25,234.13,55,400,2,1,233.24,234.17,1,1,1,1,AAPL,0,0,0,200,0,0,0,0,0,0,0,233.66500000000002
2024-10-21T11:56:43.878875408Z,2024-10-21 11:56:43.878708550+00:00,10,2,38,A,A,0,233.72,100,130,166858,11498282,233.58,233.72,27,100,1,1,233.53,233.75,10,201,1,2,233.49,233.77,200,208,1,2,233.45,233.78,15,150,1,2,233.4,233.8,110,25,2,1,233.39,233.83,10,30,1,1,233.31,233.94,110,200,2,1,233.3,233.98,100,44,1,3,233.25,234.0,55,154,2,7,233.24,234.13,1,400,1,1,AAPL,100,100,201,208,150,25,30,200,44,154,400,233.65
2024-10-21T11:56:43.879158080Z,2024-10-21 11:56:43.878991240+00:00,10,2,38,C,A,0,233.72,100,130,166840,11498283,233.58,233.75,27,201,1,2,233.53,233.77,10,208,1,2,233.49,233.78,200,150,1,2,233.45,233.8,15,25,1,1,233.4,233.83,110,30,2,1,233.39,233.94,10,200,1,1,233.31,233.98,110,44,2,3,233.3,234.0,100,154,1,7,233.25,234.13,55,400,2,1,233.24,234.17,1,1,1,1,AAPL,100,100,201,208,150,25,30,200,44,154,400,233.66500000000002
2024-10-21T11:56:47.448863756Z,2024-10-21 11:56:47.448697059+00:00,10,2,38,C,A,1,233.77,200,130,166697,11501263,233.58,233.75,27,201,1,2,233.53,233.77,10,8,1,1,233.49,233.78,200,150,1,2,233.45,233.8,15,25,1,1,233.4,233.83,110,30,2,1,233.39,233.94,10,200,1,1,233.31,233.98,110,44,2,3,233.3,234.0,100,154,1,7,233.25,234.13,55,400,2,1,233.24,234.17,1,1,1,1,AAPL,0,0,-200,0,0,0,0,0,0,0,0,233.66500000000002
2024-10-21T11:56:47.557849873Z,2024-10-21 11:56:47.557683879+00:00,10,2,38,A,A,1,233.77,200,130,165994,11501298,233.58,233.75,27,201,1,2,233.53,233.77,10,208,1,2,233.49,233.78,200,150,1,2,233.45,233.8,15,25,1,1,233.4,233.83,110,30,2,1,233.39,233.94,10,200,1,1,233.31,233.98,110,44,2,3,233.3,234.0,100,154,1,7,233.25,234.13,55,400,2,1,233.24,234.17,1,1,1,1,AAPL,0,0,200,0,0,0,0,0,0,0,0,233.66500000000002
2024-10-21T11:56:51.014820854Z,2024-10-21 11:56:51.014654312+00:00,10,2,38,A,B,2,233.49,200,130,166542,11503024,233.58,233.75,27,201,1,2,233.53,233.77,10,208,1,2,233.49,233.78,400,150,2,2,233.45,233.8,15,25,1,1,233.4,233.83,110,30,2,1,233.39,233.94,10,200,1,1,233.31,233.98,110,44,2,3,233.3,234.0,100,154,1,7,233.25,234.13,55,400,2,1,233.24,234.17,1,1,1,1,AAPL,0,0,0,200,0,0,0,0,0,0,0,233.66500000000002
2024-10-21T11:56:51.014832334Z,2024-10-21 11:56:51.014666179+00:00,10,2,38,C,A,1,233.77,200,130,166155,11503025,233.58,233.75,27,201,1,2,233.53,233.77,10,8,1,1,233.49,233.78,400,150,2,2,233.45,233.8,15,25,1,1,233.4,233.83,110,30,2,1,233.39,233.94,10,200,1,1,233.31,233.98,110,44,2,3,233.3,234.0,100,154,1,7,233.25,234.13,55,400,2,1,233.24,234.17,1,1,1,1,AAPL,0,0,-200,0,0,0,0,0,0,0,0,233.66500000000002
2024-10-21T11:56:51.014842838Z,2024-10-21 11:56:51.014676787+00:00,10,2,38,A,A,3,233.79,200,130,166051,11503026,233.58,233.75,27,201,1,2,233.53,233.77,10,8,1,1,233.49,233.78,400,150,2,2,233.45,233.79,15,200,1,1,233.4,233.8,110,25,2,1,233.39,233.83,10,30,1,1,233.31,233.94,110,200,2,1,233.3,233.98,100,44,1,3,233.25,234.0,55,154,2,7,233.24,234.13,1,400,1,1,AAPL,0,0,0,0,200,25,30,200,44,154,400,233.66500000000002
2024-10-21T11:56:55.866202310Z,2024-10-21 11:56:55.866035650+00:00,10,2,38,A,A,2,233.78,200,130,166660,11506229,233.58,233.75,27,201,1,2,233.53,233.77,10,8,1,1,233.49,233.78,400,350,2,3,233.45,233.8,15,25,1,1,233.4,233.83,110,30,2,1,233.39,233.94,10,200,1,1,233.31,233.98,110,44,2,3,233.3,234.0,100,154,1,7,233.25,234.13,55,400,2,1,233.24,234.17,1,1,1,1,AAPL,0,0,0,200,200,25,30,200,44,154,400,233.66500000000002
2024-10-21T11:57:04.890567315Z,2024-10-21 11:57:04.890399029+00:00,10,2,38,A,A,0,233.72,100,130,168286,11513463,233.58,233.72,27,100,1,1,233.53,233.75,10,201,1,2,233.49,233.77,400,8,2,1,233.45,233.78,15,350,1,3,233.4,233.8,110,25,2,1,233.39,233.83,10,30,1,1,233.31,233.94,110,200,2,1,233.3,233.98,100,44,1,3,233.25,234.0,55,154,2,7,233.24,234.13,1,400,1,1,AAPL,100,100,201,8,350,25,30,200,44,154,400,233.65
2024-10-21T11:57:04.890891078Z,2024-10-21 11:57:04.890725062+00:00,10,2,38,C,A,0,233.72,100,130,166016,11513464,233.58,233.75,27,201,1,2,233.53,233.77,10,8,1,1,233.49,233.78,400,350,2,3,233.45,233.8,15,25,1,1,233.4,233.83,110,30,2,1,233.39,233.94,10,200,1,1,233.31,233.98,110,44,2,3,233.3,234.0,100,154,1,7,233.25,234.13,55,400,2,1,233.24,234.17,1,1,1,1,AAPL,100,100,201,8,350,25,30,200,44,154,400,233.66500000000002
2024-10-21T11:57:06.459110448Z,2024-10-21 11:57:06.458943234+00:00,10,2,38,A,B,0,233.67,1,130,167214,11514372,233.67,233.75,1,201,1,2,233.58,233.77,27,8,1,1,233.53,233.78,10,350,1,3,233.49,233.8,400,25,2,1,233.45,233.83,15,30,1,1,233.4,233.94,110,200,2,1,233.39,233.98,10,44,1,3,233.31,234.0,110,154,2,7,233.3,234.13,100,400,1,1,233.25,234.17,55,1,2,1,AAPL,1,1,27,10,400,15,110,10,110,100,55,233.70999999999998
2024-10-21T11:57:06.459453253Z,2024-10-21 11:57:06.459285665+00:00,10,2,38,T,N,0,233.68,1,130,167588,11514373,233.67,233.75,1,201,1,2,233.58,233.77,27,8,1,1,233.53,233.78,10,350,1,3,233.49,233.8,400,25,2,1,233.45,233.83,15,30,1,1,233.4,233.94,110,200,2,1,233.39,233.98,10,44,1,3,233.31,234.0,110,154,2,7,233.3,234.13,100,400,1,1,233.25,234.17,55,1,2,1,AAPL,0,0,0,0,0,0,0,0,0,0,0,233.70999999999998
2024-10-21T11:57:07.554309980Z,2024-10-21 11:57:07.554141976+00:00,10,2,38,T,N,0,233.68,1,130,168004,11515087,233.67,233.75,1,201,1,2,233.58,233.77,27,8,1,1,233.53,233.78,10,350,1,3,233.49,233.8,400,25,2,1,233.45,233.83,15,30,1,1,233.4,233.94,110,200,2,1,233.39,233.98,10,44,1,3,233.31,234.0,110,154,2,7,233.3,234.13,100,400,1,1,233.25,234.17,55,1,2,1,AAPL,0,0,0,0,0,0,0,0,0,0,0,233.70999999999998
2024-10-21T11:57:08.621300353Z,2024-10-21 11:57:08.621131954+00:00,10,2,38,T,N,0,233.68,1,130,168399,11515684,233.67,233.75,1,201,1,2,233.58,233.77,27,8,1,1,233.53,233.78,10,350,1,3,233.49,233.8,400,25,2,1,233.45,233.83,15,30,1,1,233.4,233.94,110,200,2,1,233.39,233.98,10,44,1,3,233.31,234.0,110,154,2,7,233.3,234.13,100,400,1,1,233.25,234.17,55,1,2,1,AAPL,0,0,0,0,0,0,0,0,0,0,0,233.70999999999998
2024-10-21T11:57:10.160255594Z,2024-10-21 11:57:10.160087903+00:00,10,2,38,T,N,0,233.68,1,130,167691,11516600,233.67,233.75,1,201,1,2,233.58,233.77,27,8,1,1,233.53,233.78,10,350,1,3,233.49,233.8,400,25,2,1,233.45,233.83,15,30,1,1,233.4,233.94,110,200,2,1,233.39,233.98,10,44,1,3,233.31,234.0,110,154,2,7,233.3,234.13,100,400,1,1,233.25,234.17,55,1,2,1,AAPL,0,0,0,0,0,0,0,0,0,0,0,233.70999999999998
2024-10-21T11:57:14.111053066Z,2024-10-21 11:57:14.110885099+00:00,10,2,38,T,N,0,233.68,1,130,167967,11518245,233.67,233.75,1,201,1,2,233.58,233.77,27,8,1,1,233.53,233.78,10,350,1,3,233.49,233.8,400,25,2,1,233.45,233.83,15,30,1,1,233.4,233.94,110,200,2,1,233.39,233.98,10,44,1,3,233.31,234.0,110,154,2,7,233.3,234.13,100,400,1,1,233.25,234.17,55,1,2,1,AAPL,0,0,0,0,0,0,0,0,0,0,0,233.70999999999998
2024-10-21T11:57:14.837835451Z,2024-10-21 11:57:14.837669309+00:00,10,2,38,C,B,1,233.58,27,130,166142,11518715,233.67,233.75,1,201,1,2,233.53,233.77,10,8,1,1,233.49,233.78,400,350,2,3,233.45,233.8,15,25,1,1,233.4,233.83,110,30,2,1,233.39,233.94,10,200,1,1,233.31,233.98,110,44,2,3,233.3,234.0,100,154,1,7,233.25,234.13,55,400,2,1,233.24,234.17,1,1,1,1,AAPL,0,0,-27,-10,-400,-15,-110,-10,-110,-100,-55,233.70999999999998
2024-10-21T11:57:14.894688317Z,2024-10-21 11:57:14.894521785+00:00,10,2,38,A,B,1,233.59,29,130,166532,11518781,233.67,233.75,1,201,1,2,233.59,233.77,29,8,1,1,233.53,233.78,10,350,1,3,233.49,233.8,400,25,2,1,233.45,233.83,15,30,1,1,233.4,233.94,110,200,2,1,233.39,233.98,10,44,1,3,233.31,234.0,110,154,2,7,233.3,234.13,100,400,1,1,233.25,234.17,55,1,2,1,AAPL,0,0,29,10,400,15,110,10,110,100,55,233.70999999999998
2024-10-21T11:57:15.098931948Z,2024-10-21 11:57:15.098765695+00:00,10,2,38,C,A,2,233.78,200,130,166253,11518952,233.67,233.75,1,201,1,2,233.59,233.77,29,8,1,1,233.53,233.78,10,150,1,2,233.49,233.8,400,25,2,1,233.45,233.83,15,30,1,1,233.4,233.94,110,200,2,1,233.39,233.98,10,44,1,3,233.31,234.0,110,154,2,7,233.3,234.13,100,400,1,1,233.25,234.17,55,1,2,1,AAPL,0,0,0,-200,0,0,0,0,0,0,0,233.70999999999998
2024-10-21T11:57:15.098943891Z,2024-10-21 11:57:15.098777532+00:00,10,2,38,A,A,3,233.8,200,130,166359,11518953,233.67,233.75,1,201,1,2,233.59,233.77,29,8,1,1,233.53,233.78,10,150,1,2,233.49,233.8,400,225,2,2,233.45,233.83,15,30,1,1,233.4,233.94,110,200,2,1,233.39,233.98,10,44,1,3,233.31,234.0,110,154,2,7,233.3,234.13,100,400,1,1,233.25,234.17,55,1,2,1,AAPL,0,0,0,0,200,0,0,0,0,0,0,233.70999999999998
2024-10-21T11:57:15.158304832Z,2024-10-21 11:57:15.158138746+00:00,10,2,38,C,B,3,233.49,200,130,166086,11519035,233.67,233.75,1,201,1,2,233.59,233.77,29,8,1,1,233.53,233.78,10,150,1,2,233.49,233.8,200,225,1,2,233.45,233.83,15,30,1,1,233.4,233.94,110,200,2,1,233.39,233.98,10,44,1,3,233.31,234.0,110,154,2,7,233.3,234.13,100,400,1,1,233.25,234.17,55,1,2,1,AAPL,0,0,0,0,-200,0,0,0,0,0,0,233.70999999999998
2024-10-21T11:57:15.158317508Z,2024-10-21 11:57:15.158151037+00:00,10,2,38,A,B,3,233.5,400,130,166471,11519036,233.67,233.75,1,201,1,2,233.59,233.77,29,8,1,1,233.53,233.78,10,150,1,2,233.5,233.8,400,225,1,2,233.45,233.83,15,30,1,1,233.4,233.94,110,200,2,1,233.39,233.98,10,44,1,3,233.31,234.0,110,154,2,7,233.3,234.13,100,400,1,1,233.25,234.17,55,1,2,1,AAPL,0,0,0,0,400,0,0,0,0,0,0,233.70999999999998
2024-10-21T11:57:15.238726868Z,2024-10-21 11:57:15.238560230+00:00,10,2,38,A,A,3,233.79,200,130,166638,11519174,233.67,233.75,1,201,1,2,233.59,233.77,29,8,1,1,233.53,233.78,10,150,1,2,233.5,233.79,400,200,1,1,233.45,233.8,15,25,1,1,233.4,233.83,110,30,2,1,233.39,233.94,10,200,1,1,233.31,233.98,110,44,2,3,233.3,234.0,100,154,1,7,233.25,234.13,55,400,2,1,AAPL,0,0,0,0,200,25,30,200,44,154,400,233.70999999999998
2024-10-21T11:57:15.426846547Z,2024-10-21 11:57:15.426680348+00:00,10,2,38,A,A,2,233.78,200,130,166199,11519431,233.67,233.75,1,201,1,2,233.59,233.77,29,8,1,1,233.53,233.78,10,350,1,3,233.5,233.8,400,25,1,1,233.45,233.83,15,30,1,1,233.4,233.94,110,200,2,1,233.39,233.98,10,44,1,3,233.31,234.0,110,154,2,7,233.3,234.13,100,400,1,1,233.25,234.17,55,1,2,1,AAPL,0,0,0,200,200,25,30,200,44,154,400,233.70999999999998
2024-10-21T11:57:15.993417928Z,2024-10-21 11:57:15.993250474+00:00,10,2,38,T,N,0,233.68,1,130,167454,11519726,233.67,233.75,1,201,1,2,233.59,233.77,29,8,1,1,233.53,233.78,10,350,1,3,233.5,233.8,400,25,1,1,233.45,233.83,15,30,1,1,233.4,233.94,110,200,2,1,233.39,233.98,10,44,1,3,233.31,234.0,110,154,2,7,233.3,234.13,100,400,1,1,233.25,234.17,55,1,2,1,AAPL,0,0,0,0,0,0,0,0,0,0,0,233.70999999999998
2024-10-21T11:57:17.249309759Z,2024-10-21 11:57:17.249143876+00:00,10,2,38,C,A,2,233.78,200,130,165883,11520279,233.67,233.75,1,201,1,2,233.59,233.77,29,8,1,1,233.53,233.78,10,150,1,2,233.5,233.8,400,25,1,1,233.45,233.83,15,30,1,1,233.4,233.94,110,200,2,1,233.39,233.98,10,44,1,3,233.31,234.0,110,154,2,7,233.3,234.13,100,400,1,1,233.25,234.17,55,1,2,1,AAPL,0,0,0,-200,0,0,0,0,0,0,0,233.70999999999998
2024-10-21T11:57:17.249321783Z,2024-10-21 11:57:17.249155657+00:00,10,2,38,A,A,3,233.8,200,130,166126,11520280,233.67,233.75,1,201,1,2,233.59,233.77,29,8,1,1,233.53,233.78,10,150,1,2,233.5,233.8,400,225,1,2,233.45,233.83,15,30,1,1,233.4,233.94,110,200,2,1,233.39,233.98,10,44,1,3,233.31,234.0,110,154,2,7,233.3,234.13,100,400,1,1,233.25,234.17,55,1,2,1,AAPL,0,0,0,0,200,0,0,0,0,0,0,233.70999999999998
2024-10-21T11:57:17.305025226Z,2024-10-21 11:57:17.304858834+00:00,10,2,38,A,A,2,233.78,200,130,166392,11520350,233.67,233.75,1,201,1,2,233.59,233.77,29,8,1,1,233.53,233.78,10,350,1,3,233.5,233.8,400,25,1,1,233.45,233.83,15,30,1,1,233.4,233.94,110,200,2,1,233.39,233.98,10,44,1,3,233.31,234.0,110,154,2,7,233.3,234.13,100,400,1,1,233.25,234.17,55,1,2,1,AAPL,0,0,0,200,-200,0,0,0,0,0,0,233.70999999999998
2024-10-21T11:57:17.495322650Z,2024-10-21 11:57:17.495155713+00:00,10,2,38,T,N,0,233.68,1,130,166937,11520659,233.67,233.75,1,201,1,2,233.59,233.77,29,8,1,1,233.53,233.78,10,350,1,3,233.5,233.8,400,25,1,1,233.45,233.83,15,30,1,1,233.4,233.94,110,200,2,1,233.39,233.98,10,44,1,3,233.31,234.0,110,154,2,7,233.3,234.13,100,400,1,1,233.25,234.17,55,1,2,1,AAPL,0,0,0,0,0,0,0,0,0,0,0,233.70999999999998
2024-10-21T11:57:20.112278421Z,2024-10-21 11:57:20.112111433+00:00,10,2,38,A,A,0,233.72,20,130,166988,11522305,233.67,233.72,1,20,1,1,233.59,233.75,29,201,1,2,233.53,233.77,10,8,1,1,233.5,233.78,400,350,1,3,233.45,233.8,15,25,1,1,233.4,233.83,110,30,2,1,233.39,233.94,10,200,1,1,233.31,233.98,110,44,2,3,233.3,234.0,100,154,1,7,233.25,234.13,55,400,2,1,AAPL,20,20,201,8,350,25,30,200,44,154,400,233.695
2024-10-21T11:57:22.737375024Z,2024-10-21 11:57:22.737207625+00:00,10,2,38,T,N,0,233.68,1,130,167399,11523551,233.67,233.72,1,20,1,1,233.59,233.75,29,201,1,2,233.53,233.77,10,8,1,1,233.5,233.78,400,350,1,3,233.45,233.8,15,25,1,1,233.4,233.83,110,30,2,1,233.39,233.94,10,200,1,1,233.31,233.98,110,44,2,3,233.3,234.0,100,154,1,7,233.25,234.13,55,400,2,1,AAPL,0,0,0,0,0,0,0,0,0,0,0,233.695
2024-10-21T11:57:23.434601515Z,2024-10-21 11:57:23.434433631+00:00,10,2,38,T,N,0,233.68,3,130,167884,11524035,233.67,233.72,1,20,1,1,233.59,233.75,29,201,1,2,233.53,233.77,10,8,1,1,233.5,233.78,400,350,1,3,233.45,233.8,15,25,1,1,233.4,233.83,110,30,2,1,233.39,233.94,10,200,1,1,233.31,233.98,110,44,2,3,233.3,234.0,100,154,1,7,233.25,234.13,55,400,2,1,AAPL,0,0,0,0,0,0,0,0,0,0,0,233.695
2024-10-21T11:57:23.522346730Z,2024-10-21 11:57:23.522180556+00:00,10,2,38,C,B,1,233.59,29,130,166174,11524292,233.67,233.72,1,20,1,1,233.53,233.75,10,201,1,2,233.5,233.77,400,8,1,1,233.45,233.78,15,350,1,3,233.4,233.8,110,25,2,1,233.39,233.83,10,30,1,1,233.31,233.94,110,200,2,1,233.3,233.98,100,44,1,3,233.25,234.0,55,154,2,7,233.24,234.13,1,400,1,1,AAPL,0,0,-29,-10,-400,-15,-110,-10,-110,-100,-55,233.695
2024-10-21T11:57:23.522487271Z,2024-10-21 11:57:23.522320812+00:00,10,2,38,A,B,3,233.47,27,130,166459,11524293,233.67,233.72,1,20,1,1,233.53,233.75,10,201,1,2,233.5,233.77,400,8,1,1,233.47,233.78,27,350,1,3,233.45,233.8,15,25,1,1,233.4,233.83,110,30,2,1,233.39,233.94,10,200,1,1,233.31,233.98,110,44,2,3,233.3,234.0,100,154,1,7,233.25,234.13,55,400,2,1,AAPL,0,0,0,0,27,15,110,10,110,100,55,233.695
2024-10-21T11:57:23.576153028Z,2024-10-21 11:57:23.575986228+00:00,10,2,38,A,A,2,233.77,200,130,166800,11524341,233.67,233.72,1,20,1,1,233.53,233.75,10,201,1,2,233.5,233.77,400,208,1,2,233.47,233.78,27,150,1,2,233.45,233.8,15,25,1,1,233.4,233.83,110,30,2,1,233.39,233.94,10,200,1,1,233.31,233.98,110,44,2,3,233.3,234.0,100,154,1,7,233.25,234.13,55,400,2,1,AAPL,0,0,0,200,-200,0,0,0,0,0,0,233.695
2024-10-21T11:57:23.893319325Z,2024-10-21 11:57:23.893151634+00:00,10,2,38,T,A,0,233.67,1,130,167691,11524531,233.67,233.72,1,20,1,1,233.53,233.75,10,201,1,2,233.5,233.77,400,208,1,2,233.47,233.78,27,150,1,2,233.45,233.8,15,25,1,1,233.4,233.83,110,30,2,1,233.39,233.94,10,200,1,1,233.31,233.98,110,44,2,3,233.3,234.0,100,154,1,7,233.25,234.13,55,400,2,1,AAPL,0,0,0,0,0,0,0,0,0,0,0,233.695
2024-10-21T11:57:23.893319325Z,2024-10-21 11:57:23.893151634+00:00,10,2,38,C,B,0,233.67,1,130,167691,11524531,233.53,233.72,10,20,1,1,233.5,233.75,400,201,1,2,233.47,233.77,27,208,1,2,233.45,233.78,15,150,1,2,233.4,233.8,110,25,2,1,233.39,233.83,10,30,1,1,233.31,233.94,110,200,2,1,233.3,233.98,100,44,1,3,233.25,234.0,55,154,2,7,233.24,234.13,1,400,1,1,AAPL,-1,-1,-10,-400,-27,-15,-110,-10,-110,-100,-55,233.625
2024-10-21T11:57:23.893366480Z,2024-10-21 11:57:23.893200066+00:00,10,2,38,A,A,0,233.71,23,130,166414,11524532,233.53,233.71,10,23,1,1,233.5,233.72,400,20,1,1,233.47,233.75,27,201,1,2,233.45,233.77,15,208,1,2,233.4,233.78,110,150,2,2,233.39,233.8,10,25,1,1,233.31,233.83,110,30,2,1,233.3,233.94,100,200,1,1,233.25,233.98,55,44,2,3,233.24,234.0,1,154,1,7,AAPL,23,23,20,201,208,150,25,30,200,44,154,233.62
2024-10-21T11:57:23.964455827Z,2024-10-21 11:57:23.964289822+00:00,10,2,38,C,B,1,233.5,400,130,166005,11524643,233.53,233.71,10,23,1,1,233.47,233.72,27,20,1,1,233.45,233.75,15,201,1,2,233.4,233.77,110,208,2,2,233.39,233.78,10,150,1,2,233.31,233.8,110,25,2,1,233.3,233.83,100,30,1,1,233.25,233.94,55,200,2,1,233.24,233.98,1,44,1,3,233.23,234.0,50,154,1,7,AAPL,0,0,-400,-27,-15,-110,-10,-110,-100,-55,-1,233.62
2024-10-21T11:57:23.964468660Z,2024-10-21 11:57:23.964302478+00:00,10,2,38,A,B,1,233.49,200,130,166182,11524644,233.53,233.71,10,23,1,1,233.49,233.72,200,20,1,1,233.47,233.75,27,201,1,2,233.45,233.77,15,208,1,2,233.4,233.78,110,150,2,2,233.39,233.8,10,25,1,1,233.31,233.83,110,30,2,1,233.3,233.94,100,200,1,1,233.25,233.98,55,44,2,3,233.24,234.0,1,154,1,7,AAPL,0,0,200,27,15,110,10,110,100,55,1,233.62
2024-10-21T11:57:23.993929216Z,2024-10-21 11:57:23.993763323+00:00,10,2,38,C,A,0,233.71,23,130,165893,11524653,233.53,233.72,10,20,1,1,233.49,233.75,200,201,1,2,233.47,233.77,27,208,1,2,233.45,233.78,15,150,1,2,233.4,233.8,110,25,2,1,233.39,233.83,10,30,1,1,233.31,233.94,110,200,2,1,233.3,233.98,100,44,1,3,233.25,234.0,55,154,2,7,233.24,234.13,1,400,1,1,AAPL,23,23,20,201,208,150,25,30,200,44,154,233.625
2024-10-21T11:57:25.745730581Z,2024-10-21 11:57:25.745564633+00:00,10,2,38,C,B,1,233.49,200,130,165948,11525365,233.53,233.72,10,20,1,1,233.47,233.75,27,201,1,2,233.45,233.77,15,208,1,2,233.4,233.78,110,150,2,2,233.39,233.8,10,25,1,1,233.31,233.83,110,30,2,1,233.3,233.94,100,200,1,1,233.25,233.98,55,44,2,3,233.24,234.0,1,154,1,7,233.23,234.13,50,400,1,1,AAPL,0,0,-200,-27,-15,-110,-10,-110,-100,-55,-1,233.625
2024-10-21T11:57:25.813958448Z,2024-10-21 11:57:25.813792371+00:00,10,2,38,C,A,2,233.77,200,130,166077,11525510,233.53,233.72,10,20,1,1,233.47,233.75,27,201,1,2,233.45,233.77,15,8,1,1,233.4,233.78,110,150,2,2,233.39,233.8,10,25,1,1,233.31,233.83,110,30,2,1,233.3,233.94,100,200,1,1,233.25,233.98,55,44,2,3,233.24,234.0,1,154,1,7,233.23,234.13,50,400,1,1,AAPL,0,0,0,-200,0,0,0,0,0,0,0,233.625
2024-10-21T11:57:25.853139618Z,2024-10-21 11:57:25.852973172+00:00,10,2,38,A,A,3,233.78,200,130,166446,11525536,233.53,233.72,10,20,1,1,233.47,233.75,27,201,1,2,233.45,233.77,15,8,1,1,233.4,233.78,110,350,2,3,233.39,233.8,10,25,1,1,233.31,233.83,110,30,2,1,233.3,233.94,100,200,1,1,233.25,233.98,55,44,2,3,233.24,234.0,1,154,1,7,233.23,234.13,50,400,1,1,AAPL,0,0,0,0,200,0,0,0,0,0,0,233.625
2024-10-21T11:57:25.863140339Z,2024-10-21 11:57:25.862973670+00:00,10,2,38,A,B,1,233.49,400,130,166669,11525541,233.53,233.72,10,20,1,1,233.49,233.75,400,201,1,2,233.47,233.77,27,8,1,1,233.45,233.78,15,350,1,3,233.4,233.8,110,25,2,1,233.39,233.83,10,30,1,1,233.31,233.94,110,200,2,1,233.3,233.98,100,44,1,3,233.25,234.0,55,154,2,7,233.24,234.13,1,400,1,1,AAPL,0,0,400,27,15,110,10,110,100,55,1,233.625
2024-10-21T11:57:25.868840178Z,2024-10-21 11:57:25.868673528+00:00,10,2,38,A,B,0,233.54,200,130,166650,11525550,233.54,233.72,200,20,1,1,233.53,233.75,10,201,1,2,233.47,233.77,27,8,1,1,233.45,233.78,15,350,1,3,233.4,233.8,110,25,2,1,233.39,233.83,10,30,1,1,233.31,233.94,110,200,2,1,233.3,233.98,100,44,1,3,233.25,234.0,55,154,2,7,233.24,234.13,1,400,1,1,AAPL,200,200,10,0,0,0,0,0,0,0,0,233.63
2024-10-21T11:57:26.000516279Z,2024-10-21 11:57:26.000349886+00:00,10,2,38,A,B,0,233.54,200,130,166393,11525708,233.54,233.72,400,20,2,1,233.53,233.75,10,201,1,2,233.47,233.77,27,8,1,1,233.45,233.78,15,350,1,3,233.4,233.8,110,25,2,1,233.39,233.83,10,30,1,1,233.31,233.94,110,200,2,1,233.3,233.98,100,44,1,3,233.25,234.0,55,154,2,7,233.24,234.13,1,400,1,1,AAPL,200,200,0,0,0,0,0,0,0,0,0,233.63
2024-10-21T11:57:28.039458831Z,2024-10-21 11:57:28.039292565+00:00,10,2,38,C,B,0,233.54,200,130,166266,11526531,233.54,233.72,200,20,1,1,233.53,233.75,10,201,1,2,233.47,233.77,27,8,1,1,233.45,233.78,15,350,1,3,233.4,233.8,110,25,2,1,233.39,233.83,10,30,1,1,233.31,233.94,110,200,2,1,233.3,233.98,100,44,1,3,233.25,234.0,55,154,2,7,233.24,234.13,1,400,1,1,AAPL,-200,-200,0,0,0,0,0,0,0,0,0,233.63
2024-10-21T11:57:28.039469716Z,2024-10-21 11:57:28.039302990+00:00,10,2,38,C,B,0,233.54,200,130,166726,11526532,233.53,233.72,10,20,1,1,233.47,233.75,27,201,1,2,233.45,233.77,15,8,1,1,233.4,233.78,110,350,2,3,233.39,233.8,10,25,1,1,233.31,233.83,110,30,2,1,233.3,233.94,100,200,1,1,233.25,233.98,55,44,2,3,233.24,234.0,1,154,1,7,233.23,234.13,50,400,1,1,AAPL,-200,-200,-10,-27,-15,-110,-10,-110,-100,-55,-1,233.625
2024-10-21T11:57:28.039515596Z,2024-10-21 11:57:28.039347712+00:00,10,2,38,T,N,0,233.68,50,130,167884,11526533,233.53,233.72,10,20,1,1,233.47,233.75,27,201,1,2,233.45,233.77,15,8,1,1,233.4,233.78,110,350,2,3,233.39,233.8,10,25,1,1,233.31,233.83,110,30,2,1,233.3,233.94,100,200,1,1,233.25,233.98,55,44,2,3,233.24,234.0,1,154,1,7,233.23,234.13,50,400,1,1,AAPL,0,0,0,0,0,0,0,0,0,0,0,233.625
2024-10-21T11:57:28.153873361Z,2024-10-21 11:57:28.153707091+00:00,10,2,38,A,B,1,233.48,400,130,166270,11526618,233.53,233.72,10,20,1,1,233.48,233.75,400,201,1,2,233.47,233.77,27,8,1,1,233.45,233.78,15,350,1,3,233.4,233.8,110,25,2,1,233.39,233.83,10,30,1,1,233.31,233.94,110,200,2,1,233.3,233.98,100,44,1,3,233.25,234.0,55,154,2,7,233.24,234.13,1,400,1,1,AAPL,0,0,400,27,15,110,10,110,100,55,1,233.625
2024-10-21T11:57:28.163878325Z,2024-10-21 11:57:28.163711748+00:00,10,2,38,A,B,0,233.54,200,130,166577,11526622,233.54,233.72,200,20,1,1,233.53,233.75,10,201,1,2,233.47,233.77,27,8,1,1,233.45,233.78,15,350,1,3,233.4,233.8,110,25,2,1,233.39,233.83,10,30,1,1,233.31,233.94,110,200,2,1,233.3,233.98,100,44,1,3,233.25,234.0,55,154,2,7,233.24,234.13,1,400,1,1,AAPL,200,200,10,0,0,0,0,0,0,0,0,233.63
2024-10-21T11:57:28.163892251Z,2024-10-21 11:57:28.163725884+00:00,10,2,38,A,A,2,233.77,200,130,166367,11526623,233.54,233.72,200,20,1,1,233.53,233.75,10,201,1,2,233.47,233.77,27,208,1,2,233.45,233.78,15,150,1,2,233.4,233.8,110,25,2,1,233.39,233.83,10,30,1,1,233.31,233.94,110,200,2,1,233.3,233.98,100,44,1,3,233.25,234.0,55,154,2,7,233.24,234.13,1,400,1,1,AAPL,0,0,0,200,-200,0,0,0,0,0,0,233.63
2024-10-21T11:57:29.332119420Z,2024-10-21 11:57:29.331953680+00:00,10,2,38,C,A,2,233.77,200,130,165740,11527067,233.54,233.72,200,20,1,1,233.53,233.75,10,201,1,2,233.47,233.77,27,8,1,1,233.45,233.78,15,150,1,2,233.4,233.8,110,25,2,1,233.39,233.83,10,30,1,1,233.31,233.94,110,200,2,1,233.3,233.98,100,44,1,3,233.25,234.0,55,154,2,7,233.24,234.13,1,400,1,1,AAPL,0,0,0,-200,0,0,0,0,0,0,0,233.63
2024-10-21T11:57:29.332132648Z,2024-10-21 11:57:29.331966683+00:00,10,2,38,A,A,3,233.78,200,130,165965,11527068,233.54,233.72,200,20,1,1,233.53,233.75,10,201,1,2,233.47,233.77,27,8,1,1,233.45,233.78,15,350,1,3,233.4,233.8,110,25,2,1,233.39,233.83,10,30,1,1,233.31,233.94,110,200,2,1,233.3,233.98,100,44,1,3,233.25,234.0,55,154,2,7,233.24,234.13,1,400,1,1,AAPL,0,0,0,0,200,0,0,0,0,0,0,233.63
2024-10-21T11:57:30.995359196Z,2024-10-21 11:57:30.995192991+00:00,10,2,38,A,B,0,233.54,200,130,166205,11528694,233.54,233.72,400,20,2,1,233.53,233.75,10,201,1,2,233.47,233.77,27,8,1,1,233.45,233.78,15,350,1,3,233.4,233.8,110,25,2,1,233.39,233.83,10,30,1,1,233.31,233.94,110,200,2,1,233.3,233.98,100,44,1,3,233.25,234.0,55,154,2,7,233.24,234.13,1,400,1,1,AAPL,200,200,0,0,0,0,0,0,0,0,0,233.63
2024-10-21T11:57:31.496401280Z,2024-10-21 11:57:31.496234971+00:00,10,2,38,A,A,1,233.74,500,130,166309,11528948,233.54,233.72,400,20,2,1,233.53,233.74,10,500,1,1,233.47,233.75,27,201,1,2,233.45,233.77,15,8,1,1,233.4,233.78,110,350,2,3,233.39,233.8,10,25,1,1,233.31,233.83,110,30,2,1,233.3,233.94,100,200,1,1,233.25,233.98,55,44,2,3,233.24,234.0,1,154,1,7,AAPL,0,0,500,201,8,350,25,30,200,44,154,233.63
2024-10-21T11:57:36.264708785Z,2024-10-21 11:57:36.264542456+00:00,10,2,38,C,A,0,233.72,20,130,166329,11532750,233.54,233.74,400,500,2,1,233.53,233.75,10,201,1,2,233.47,233.77,27,8,1,1,233.45,233.78,15,350,1,3,233.4,233.8,110,25,2,1,233.39,233.83,10,30,1,1,233.31,233.94,110,200,2,1,233.3,233.98,100,44,1,3,233.25,234.0,55,154,2,7,233.24,234.13,1,400,1,1,AAPL,20,20,500,201,8,350,25,30,200,44,154,233.64
2024-10-21T11:57:36.268101167Z,2024-10-21 11:57:36.267934826+00:00,10,2,38,C,B,0,233.54,200,130,166341,11532755,233.54,233.74,200,500,1,1,233.53,233.75,10,201,1,2,233.47,233.77,27,8,1,1,233.45,233.78,15,350,1,3,233.4,233.8,110,25,2,1,233.39,233.83,10,30,1,1,233.31,233.94,110,200,2,1,233.3,233.98,100,44,1,3,233.25,234.0,55,154,2,7,233.24,234.13,1,400,1,1,AAPL,-200,-200,0,0,0,0,0,0,0,0,0,233.64
2024-10-21T11:57:37.888147782Z,2024-10-21 11:57:37.887981490+00:00,10,2,38,A,B,0,233.65,1,130,166292,11533577,233.65,233.74,1,500,1,1,233.54,233.75,200,201,1,2,233.53,233.77,10,8,1,1,233.47,233.78,27,350,1,3,233.45,233.8,15,25,1,1,233.4,233.83,110,30,2,1,233.39,233.94,10,200,1,1,233.31,233.98,110,44,2,3,233.3,234.0,100,154,1,7,233.25,234.13,55,400,2,1,AAPL,1,1,200,10,27,15,110,10,110,100,55,233.695
2024-10-21T11:57:38.017129745Z,2024-10-21 11:57:38.016963535+00:00,10,2,38,A,B,1,233.54,200,130,166210,11533703,233.65,233.74,1,500,1,1,233.54,233.75,400,201,2,2,233.53,233.77,10,8,1,1,233.47,233.78,27,350,1,3,233.45,233.8,15,25,1,1,233.4,233.83,110,30,2,1,233.39,233.94,10,200,1,1,233.31,233.98,110,44,2,3,233.3,234.0,100,154,1,7,233.25,234.13,55,400,2,1,AAPL,0,0,200,0,0,0,0,0,0,0,0,233.695
2024-10-21T11:57:40.885606594Z,2024-10-21 11:57:40.885440558+00:00,10,2,38,C,B,3,233.47,27,130,166036,11535145,233.65,233.74,1,500,1,1,233.54,233.75,400,201,2,2,233.53,233.77,10,8,1,1,233.45,233.78,15,350,1,3,233.4,233.8,110,25,2,1,233.39,233.83,10,30,1,1,233.31,233.94,110,200,2,1,233.3,233.98,100,44,1,3,233.25,234.0,55,154,2,7,233.24,234.13,1,400,1,1,AAPL,0,0,0,0,-27,-15,-110,-10,-110,-100,-55,233.695
2024-10-21T11:57:40.885648201Z,2024-10-21 11:57:40.885481569+00:00,10,2,38,A,B,3,233.48,26,130,166632,11535146,233.65,233.74,1,500,1,1,233.54,233.75,400,201,2,2,233.53,233.77,10,8,1,1,233.48,233.78,26,350,1,3,233.45,233.8,15,25,1,1,233.4,233.83,110,30,2,1,233.39,233.94,10,200,1,1,233.31,233.98,110,44,2,3,233.3,234.0,100,154,1,7,233.25,234.13,55,400,2,1,AAPL,0,0,0,0,26,15,110,10,110,100,55,233.695
2024-10-21T11:57:41.319317780Z,2024-10-21 11:57:41.319151873+00:00,10,2,38,C,A,3,233.78,200,130,165907,11535430,233.65,233.74,1,500,1,1,233.54,233.75,400,201,2,2,233.53,233.77,10,8,1,1,233.48,233.78,26,150,1,2,233.45,233.8,15,25,1,1,233.4,233.83,110,30,2,1,233.39,233.94,10,200,1,1,233.31,233.98,110,44,2,3,233.3,234.0,100,154,1,7,233.25,234.13,55,400,2,1,AAPL,0,0,0,0,-200,0,0,0,0,0,0,233.695
2024-10-21T11:57:41.319329838Z,2024-10-21 11:57:41.319163898+00:00,10,2,38,A,A,4,233.79,200,130,165940,11535431,233.65,233.74,1,500,1,1,233.54,233.75,400,201,2,2,233.53,233.77,10,8,1,1,233.48,233.78,26,150,1,2,233.45,233.79,15,200,1,1,233.4,233.8,110,25,2,1,233.39,233.83,10,30,1,1,233.31,233.94,110,200,2,1,233.3,233.98,100,44,1,3,233.25,234.0,55,154,2,7,AAPL,0,0,0,0,0,200,25,30,200,44,154,233.695
2024-10-21T11:57:41.375862954Z,2024-10-21 11:57:41.375697228+00:00,10,2,38,C,B,1,233.54,200,130,165726,11535542,233.65,233.74,1,500,1,1,233.54,233.75,200,201,1,2,233.53,233.77,10,8,1,1,233.48,233.78,26,150,1,2,233.45,233.79,15,200,1,1,233.4,233.8,110,25,2,1,233.39,233.83,10,30,1,1,233.31,233.94,110,200,2,1,233.3,233.98,100,44,1,3,233.25,234.0,55,154,2,7,AAPL,0,0,-200,0,0,0,0,0,0,0,0,233.695
2024-10-21T11:57:41.375875655Z,2024-10-21 11:57:41.375709324+00:00,10,2,38,A,B,1,233.55,400,130,166331,11535543,233.65,233.74,1,500,1,1,233.55,233.75,400,201,1,2,233.53,233.77,10,8,1,1,233.48,233.78,26,150,1,2,233.45,233.79,15,200,1,1,233.4,233.8,110,25,2,1,233.39,233.83,10,30,1,1,233.31,233.94,110,200,2,1,233.3,233.98,100,44,1,3,233.25,234.0,55,154,2,7,AAPL,0,0,400,0,0,0,0,0,0,0,0,233.695
2024-10-21T11:57:41.965826689Z,2024-10-21 11:57:41.965660865+00:00,10,2,38,C,B,1,233.55,400,130,165824,11536042,233.65,233.74,1,500,1,1,233.53,233.75,10,201,1,2,233.48,233.77,26,8,1,1,233.45,233.78,15,150,1,2,233.4,233.79,110,200,2,1,233.39,233.8,10,25,1,1,233.31,233.83,110,30,2,1,233.3,233.94,100,200,1,1,233.25,233.98,55,44,2,3,233.24,234.0,1,154,1,7,AAPL,0,0,-400,-10,-26,-15,-110,-10,-110,-100,-55,233.695
2024-10-21T11:57:42.074339748Z,2024-10-21 11:57:42.074173420+00:00,10,2,38,A,B,2,233.49,200,130,166328,11536099,233.65,233.74,1,500,1,1,233.53,233.75,10,201,1,2,233.49,233.77,200,8,1,1,233.48,233.78,26,150,1,2,233.45,233.79,15,200,1,1,233.4,233.8,110,25,2,1,233.39,233.83,10,30,1,1,233.31,233.94,110,200,2,1,233.3,233.98,100,44,1,3,233.25,234.0,55,154,2,7,AAPL,0,0,0,200,26,15,110,10,110,100,55,233.695
2024-10-21T11:57:42.169388484Z,2024-10-21 11:57:42.169221771+00:00,10,2,38,A,B,2,233.5,200,130,166713,11536143,233.65,233.74,1,500,1,1,233.53,233.75,10,201,1,2,233.5,233.77,200,8,1,1,233.48,233.78,26,150,1,2,233.45,233.79,15,200,1,1,233.4,233.8,110,25,2,1,233.39,233.83,10,30,1,1,233.31,233.94,110,200,2,1,233.3,233.98,100,44,1,3,233.25,234.0,55,154,2,7,AAPL,0,0,0,200,0,0,0,0,0,0,0,233.695
2024-10-21T11:57:42.208045550Z,2024-10-21 11:57:42.207878969+00:00,10,2,38,C,B,2,233.5,200,130,166581,11536169,233.65,233.74,1,500,1,1,233.53,233.75,10,201,1,2,233.48,233.77,26,8,1,1,233.45,233.78,15,150,1,2,233.4,233.79,110,200,2,1,233.39,233.8,10,25,1,1,233.31,233.83,110,30,2,1,233.3,233.94,100,200,1,1,233.25,233.98,55,44,2,3,233.24,234.0,1,154,1,7,AAPL,0,0,0,-200,-26,-15,-110,-10,-110,-100,-55,233.695
2024-10-21T11:57:42.313426957Z,2024-10-21 11:57:42.313260974+00:00,10,2,38,A,B,2,233.49,200,130,165983,11536217,233.65,233.74,1,500,1,1,233.53,233.75,10,201,1,2,233.49,233.77,200,8,1,1,233.48,233.78,26,150,1,2,233.45,233.79,15,200,1,1,233.4,233.8,110,25,2,1,233.39,233.83,10,30,1,1,233.31,233.94,110,200,2,1,233.3,233.98,100,44,1,3,233.25,234.0,55,154,2,7,AAPL,0,0,0,200,26,15,110,10,110,100,55,233.695
2024-10-21T11:57:42.380325383Z,2024-10-21 11:57:42.380159117+00:00,10,2,38,A,B,2,233.49,200,130,166266,11536247,233.65,233.74,1,500,1,1,233.53,233.75,10,201,1,2,233.49,233.77,400,8,2,1,233.48,233.78,26,150,1,2,233.45,233.79,15,200,1,1,233.4,233.8,110,25,2,1,233.39,233.83,10,30,1,1,233.31,233.94,110,200,2,1,233.3,233.98,100,44,1,3,233.25,234.0,55,154,2,7,AAPL,0,0,0,200,0,0,0,0,0,0,0,233.695
2024-10-21T11:57:42.412490406Z,2024-10-21 11:57:42.412324426+00:00,10,2,38,C,B,2,233.49,200,130,165980,11536276,233.65,233.74,1,500,1,1,233.53,233.75,10,201,1,2,233.49,233.77,200,8,1,1,233.48,233.78,26,150,1,2,233.45,233.79,15,200,1,1,233.4,233.8,110,25,2,1,233.39,233.83,10,30,1,1,233.31,233.94,110,200,2,1,233.3,233.98,100,44,1,3,233.25,234.0,55,154,2,7,AAPL,0,0,0,-200,0,0,0,0,0,0,0,233.695
2024-10-21T11:57:42.412502842Z,2024-10-21 11:57:42.412336614+00:00,10,2,38,A,B,2,233.5,200,130,166228,11536277,233.65,233.74,1,500,1,1,233.53,233.75,10,201,1,2,233.5,233.77,200,8,1,1,233.48,233.78,26,150,1,2,233.45,233.79,15,200,1,1,233.4,233.8,110,25,2,1,233.39,233.83,10,30,1,1,233.31,233.94,110,200,2,1,233.3,233.98,100,44,1,3,233.25,234.0,55,154,2,7,AAPL,0,0,0,200,0,0,0,0,0,0,0,233.695
2024-10-21T11:57:48.073129275Z,2024-10-21 11:57:48.072962640+00:00,10,2,38,A,B,2,233.5,200,130,166635,11540432,233.65,233.74,1,500,1,1,233.53,233.75,10,201,1,2,233.5,233.77,400,8,2,1,233.48,233.78,26,150,1,2,233.45,233.79,15,200,1,1,233.4,233.8,110,25,2,1,233.39,233.83,10,30,1,1,233.31,233.94,110,200,2,1,233.3,233.98,100,44,1,3,233.25,234.0,55,154,2,7,AAPL,0,0,0,200,0,0,0,0,0,0,0,233.695
2024-10-21T11:57:48.073140030Z,2024-10-21 11:57:48.072974095+00:00,10,2,38,C,A,4,233.79,200,130,165935,11540433,233.65,233.74,1,500,1,1,233.53,233.75,10,201,1,2,233.5,233.77,400,8,2,1,233.48,233.78,26,150,1,2,233.45,233.8,15,25,1,1,233.4,233.83,110,30,2,1,233.39,233.94,10,200,1,1,233.31,233.98,110,44,2,3,233.3,234.0,100,154,1,7,233.25,234.13,55,400,2,1,AAPL,0,0,0,0,0,200,25,30,200,44,154,233.695
2024-10-21T11:57:48.073150753Z,2024-10-21 11:57:48.072984615+00:00,10,2,38,A,A,4,233.8,200,130,166138,11540434,233.65,233.74,1,500,1,1,233.53,233.75,10,201,1,2,233.5,233.77,400,8,2,1,233.48,233.78,26,150,1,2,233.45,233.8,15,225,1,2,233.4,233.83,110,30,2,1,233.39,233.94,10,200,1,1,233.31,233.98,110,44,2,3,233.3,234.0,100,154,1,7,233.25,234.13,55,400,2,1,AAPL,0,0,0,0,0,200,0,0,0,0,0,233.695
2024-10-21T11:57:48.076825301Z,2024-10-21 11:57:48.076659157+00:00,10,2,38,C,A,5,233.83,30,130,166144,11540485,233.65,233.74,1,500,1,1,233.53,233.75,10,201,1,2,233.5,233.77,400,8,2,1,233.48,233.78,26,150,1,2,233.45,233.8,15,225,1,2,233.4,233.94,110,200,2,1,233.39,233.98,10,44,1,3,233.31,234.0,110,154,2,7,233.3,234.13,100,400,1,1,233.25,234.17,55,1,2,1,AAPL,0,0,0,0,0,0,30,200,44,154,400,233.695
2024-10-21T11:57:48.076908946Z,2024-10-21 11:57:48.076742621+00:00,10,2,38,A,A,5,233.86,28,130,166325,11540488,233.65,233.74,1,500,1,1,233.53,233.75,10,201,1,2,233.5,233.77,400,8,2,1,233.48,233.78,26,150,1,2,233.45,233.8,15,225,1,2,233.4,233.86,110,28,2,1,233.39,233.94,10,200,1,1,233.31,233.98,110,44,2,3,233.3,234.0,100,154,1,7,233.25,234.13,55,400,2,1,AAPL,0,0,0,0,0,0,28,200,44,154,400,233.695
2024-10-21T11:57:48.136642704Z,2024-10-21 11:57:48.136477014+00:00,10,2,38,C,B,2,233.5,200,130,165690,11540727,233.65,233.74,1,500,1,1,233.53,233.75,10,201,1,2,233.5,233.77,200,8,1,1,233.48,233.78,26,150,1,2,233.45,233.8,15,225,1,2,233.4,233.86,110,28,2,1,233.39,233.94,10,200,1,1,233.31,233.98,110,44,2,3,233.3,234.0,100,154,1,7,233.25,234.13,55,400,2,1,AAPL,0,0,0,-200,0,0,0,0,0,0,0,233.695
2024-10-21T11:57:48.136655500Z,2024-10-21 11:57:48.136488492+00:00,10,2,38,A,B,2,233.51,200,130,167008,11540728,233.65,233.74,1,500,1,1,233.53,233.75,10,201,1,2,233.51,233.77,200,8,1,1,233.48,233.78,26,150,1,2,233.45,233.8,15,225,1,2,233.4,233.86,110,28,2,1,233.39,233.94,10,200,1,1,233.31,233.98,110,44,2,3,233.3,234.0,100,154,1,7,233.25,234.13,55,400,2,1,AAPL,0,0,0,200,0,0,0,0,0,0,0,233.695
2024-10-21T11:57:48.194778031Z,2024-10-21 11:57:48.194611663+00:00,10,2,38,C,B,3,233.48,26,130,166368,11540865,233.65,233.74,1,500,1,1,233.53,233.75,10,201,1,2,233.51,233.77,200,8,1,1,233.45,233.78,15,150,1,2,233.4,233.8,110,225,2,2,233.39,233.86,10,28,1,1,233.31,233.94,110,200,2,1,233.3,233.98,100,44,1,3,233.25,234.0,55,154,2,7,233.24,234.13,1,400,1,1,AAPL,0,0,0,0,-26,-15,-110,-10,-110,-100,-55,233.695
2024-10-21T11:57:48.194826771Z,2024-10-21 11:57:48.194659897+00:00,10,2,38,A,B,3,233.49,29,130,166874,11540868,233.65,233.74,1,500,1,1,233.53,233.75,10,201,1,2,233.51,233.77,200,8,1,1,233.49,233.78,29,150,1,2,233.45,233.8,15,225,1,2,233.4,233.86,110,28,2,1,233.39,233.94,10,200,1,1,233.31,233.98,110,44,2,3,233.3,234.0,100,154,1,7,233.25,234.13,55,400,2,1,AAPL,0,0,0,0,29,15,110,10,110,100,55,233.695
2024-10-21T11:57:51.070775104Z,2024-10-21 11:57:51.070607242+00:00,10,2,38,T,N,0,233.71,50,130,167862,11543012,233.65,233.74,1,500,1,1,233.53,233.75,10,201,1,2,233.51,233.77,200,8,1,1,233.49,233.78,29,150,1,2,233.45,233.8,15,225,1,2,233.4,233.86,110,28,2,1,233.39,233.94,10,200,1,1,233.31,233.98,110,44,2,3,233.3,234.0,100,154,1,7,233.25,234.13,55,400,2,1,AAPL,0,0,0,0,0,0,0,0,0,0,0,233.695
2024-10-21T11:57:51.271362157Z,2024-10-21 11:57:51.271195500+00:00,10,2,38,A,A,4,233.79,200,130,166657,11543518,233.65,233.74,1,500,1,1,233.53,233.75,10,201,1,2,233.51,233.77,200,8,1,1,233.49,233.78,29,150,1,2,233.45,233.79,15,200,1,1,233.4,233.8,110,25,2,1,233.39,233.86,10,28,1,1,233.31,233.94,110,200,2,1,233.3,233.98,100,44,1,3,233.25,234.0,55,154,2,7,AAPL,0,0,0,0,0,200,25,28,200,44,154,233.695
2024-10-21T11:57:51.287274496Z,2024-10-21 11:57:51.287108312+00:00,10,2,38,C,A,6,233.86,28,130,166184,11543617,233.65,233.74,1,500,1,1,233.53,233.75,10,201,1,2,233.51,233.77,200,8,1,1,233.49,233.78,29,150,1,2,233.45,233.79,15,200,1,1,233.4,233.8,110,25,2,1,233.39,233.94,10,200,1,1,233.31,233.98,110,44,2,3,233.3,234.0,100,154,1,7,233.25,234.13,55,400,2,1,AAPL,0,0,0,0,0,0,0,28,200,44,154,233.695
2024-10-21T11:57:51.287324161Z,2024-10-21 11:57:51.287157718+00:00,10,2,38,A,A,6,233.85,29,130,166443,11543618,233.65,233.74,1,500,1,1,233.53,233.75,10,201,1,2,233.51,233.77,200,8,1,1,233.49,233.78,29,150,1,2,233.45,233.79,15,200,1,1,233.4,233.8,110,25,2,1,233.39,233.85,10,29,1,1,233.31,233.94,110,200,2,1,233.3,233.98,100,44,1,3,233.25,234.0,55,154,2,7,AAPL,0,0,0,0,0,0,0,29,200,44,154,233.695
2024-10-21T11:57:51.322868054Z,2024-10-21 11:57:51.322699915+00:00,10,2,38,T,N,0,233.71,7,130,168139,11543733,233.65,233.74,1,500,1,1,233.53,233.75,10,201,1,2,233.51,233.77,200,8,1,1,233.49,233.78,29,150,1,2,233.45,233.79,15,200,1,1,233.4,233.8,110,25,2,1,233.39,233.85,10,29,1,1,233.31,233.94,110,200,2,1,233.3,233.98,100,44,1,3,233.25,234.0,55,154,2,7,AAPL,0,0,0,0,0,0,0,0,0,0,0,233.695
2024-10-21T11:57:52.318095141Z,2024-10-21 11:57:52.317929239+00:00,10,2,38,C,A,4,233.79,200,130,165902,11544404,233.65,233.74,1,500,1,1,233.53,233.75,10,201,1,2,233.51,233.77,200,8,1,1,233.49,233.78,29,150,1,2,233.45,233.8,15,25,1,1,233.4,233.85,110,29,2,1,233.39,233.94,10,200,1,1,233.31,233.98,110,44,2,3,233.3,234.0,100,154,1,7,233.25,234.13,55,400,2,1,AAPL,0,0,0,0,0,200,25,29,200,44,154,233.695
2024-10-21T11:57:52.318108707Z,2024-10-21 11:57:52.317942384+00:00,10,2,38,A,A,4,233.8,200,130,166323,11544405,233.65,233.74,1,500,1,1,233.53,233.75,10,201,1,2,233.51,233.77,200,8,1,1,233.49,233.78,29,150,1,2,233.45,233.8,15,225,1,2,233.4,233.85,110,29,2,1,233.39,233.94,10,200,1,1,233.31,233.98,110,44,2,3,233.3,234.0,100,154,1,7,233.25,234.13,55,400,2,1,AAPL,0,0,0,0,0,200,0,0,0,0,0,233.695
2024-10-21T11:57:58.266750822Z,2024-10-21 11:57:58.266584280+00:00,10,2,38,A,A,4,233.79,200,130,166542,11548474,233.65,233.74,1,500,1,1,233.53,233.75,10,201,1,2,233.51,233.77,200,8,1,1,233.49,233.78,29,150,1,2,233.45,233.79,15,200,1,1,233.4,233.8,110,25,2,1,233.39,233.85,10,29,1,1,233.31,233.94,110,200,2,1,233.3,233.98,100,44,1,3,233.25,234.0,55,154,2,7,AAPL,0,0,0,0,0,200,25,29,200,44,154,233.695
2024-10-21T11:58:06.284887079Z,2024-10-21 11:58:06.284720780+00:00,10,2,38,C,B,2,233.51,200,130,166299,11554578,233.65,233.74,1,500,1,1,233.53,233.75,10,201,1,2,233.49,233.77,29,8,1,1,233.45,233.78,15,150,1,2,233.4,233.79,110,200,2,1,233.39,233.8,10,25,1,1,233.31,233.85,110,29,2,1,233.3,233.94,100,200,1,1,233.25,233.98,55,44,2,3,233.24,234.0,1,154,1,7,AAPL,0,0,0,-200,-29,-15,-110,-10,-110,-100,-55,233.695
2024-10-21T11:58:06.284899850Z,2024-10-21 11:58:06.284733562+00:00,10,2,38,A,B,2,233.49,200,130,166288,11554579,233.65,233.74,1,500,1,1,233.53,233.75,10,201,1,2,233.49,233.77,229,8,2,1,233.45,233.78,15,150,1,2,233.4,233.79,110,200,2,1,233.39,233.8,10,25,1,1,233.31,233.85,110,29,2,1,233.3,233.94,100,200,1,1,233.25,233.98,55,44,2,3,233.24,234.0,1,154,1,7,AAPL,0,0,0,200,0,0,0,0,0,0,0,233.695
2024-10-21T11:58:06.339737678Z,2024-10-21 11:58:06.339571308+00:00,10,2,38,A,A,3,233.78,200,130,166370,11554687,233.65,233.74,1,500,1,1,233.53,233.75,10,201,1,2,233.49,233.77,229,8,2,1,233.45,233.78,15,350,1,3,233.4,233.8,110,25,2,1,233.39,233.85,10,29,1,1,233.31,233.94,110,200,2,1,233.3,233.98,100,44,1,3,233.25,234.0,55,154,2,7,233.24,234.13,1,400,1,1,AAPL,0,0,0,0,200,200,25,29,200,44,154,233.695
2024-10-21T11:58:06.359996032Z,2024-10-21 11:58:06.359829740+00:00,10,2,38,A,B,2,233.49,200,130,166292,11554809,233.65,233.74,1,500,1,1,233.53,233.75,10,201,1,2,233.49,233.77,429,8,3,1,233.45,233.78,15,350,1,3,233.4,233.8,110,25,2,1,233.39,233.85,10,29,1,1,233.31,233.94,110,200,2,1,233.3,233.98,100,44,1,3,233.25,234.0,55,154,2,7,233.24,234.13,1,400,1,1,AAPL,0,0,0,200,0,0,0,0,0,0,0,233.695
2024-10-21T11:58:06.360372874Z,2024-10-21 11:58:06.360206541+00:00,10,2,38,A,A,5,233.84,29,130,166333,11554810,233.65,233.74,1,500,1,1,233.53,233.75,10,201,1,2,233.49,233.77,429,8,3,1,233.45,233.78,15,350,1,3,233.4,233.8,110,25,2,1,233.39,233.84,10,29,1,1,233.31,233.85,110,29,2,1,233.3,233.94,100,200,1,1,233.25,233.98,55,44,2,3,233.24,234.0,1,154,1,7,AAPL,0,0,0,0,0,0,29,29,200,44,154,233.695
2024-10-21T11:58:06.360409628Z,2024-10-21 11:58:06.360243785+00:00,10,2,38,C,A,6,233.85,29,130,165843,11554811,233.65,233.74,1,500,1,1,233.53,233.75,10,201,1,2,233.49,233.77,429,8,3,1,233.45,233.78,15,350,1,3,233.4,233.8,110,25,2,1,233.39,233.84,10,29,1,1,233.31,233.94,110,200,2,1,233.3,233.98,100,44,1,3,233.25,234.0,55,154,2,7,233.24,234.13,1,400,1,1,AAPL,0,0,0,0,0,0,0,29,200,44,154,233.695
2024-10-21T11:58:06.414826565Z,2024-10-21 11:58:06.414660818+00:00,10,2,38,C,B,2,233.49,200,130,165747,11554881,233.65,233.74,1,500,1,1,233.53,233.75,10,201,1,2,233.49,233.77,229,8,2,1,233.45,233.78,15,350,1,3,233.4,233.8,110,25,2,1,233.39,233.84,10,29,1,1,233.31,233.94,110,200,2,1,233.3,233.98,100,44,1,3,233.25,234.0,55,154,2,7,233.24,234.13,1,400,1,1,AAPL,0,0,0,-200,0,0,0,0,0,0,0,233.695
2024-10-21T11:58:06.414839107Z,2024-10-21 11:58:06.414672832+00:00,10,2,38,A,B,2,233.51,200,130,166275,11554882,233.65,233.74,1,500,1,1,233.53,233.75,10,201,1,2,233.51,233.77,200,8,1,1,233.49,233.78,29,350,1,3,233.45,233.8,15,25,1,1,233.4,233.84,110,29,2,1,233.39,233.94,10,200,1,1,233.31,233.98,110,44,2,3,233.3,234.0,100,154,1,7,233.25,234.13,55,400,2,1,AAPL,0,0,0,200,29,15,110,10,110,100,55,233.695
2024-10-21T11:58:14.036518564Z,2024-10-21 11:58:14.036350634+00:00,10,2,38,T,N,0,233.73,87,130,167930,11561326,233.65,233.74,1,500,1,1,233.53,233.75,10,201,1,2,233.51,233.77,200,8,1,1,233.49,233.78,29,350,1,3,233.45,233.8,15,25,1,1,233.4,233.84,110,29,2,1,233.39,233.94,10,200,1,1,233.31,233.98,110,44,2,3,233.3,234.0,100,154,1,7,233.25,234.13,55,400,2,1,AAPL,0,0,0,0,0,0,0,0,0,0,0,233.695
2024-10-21T11:58:14.036543021Z,2024-10-21 11:58:14.036377136+00:00,10,2,38,C,A,3,233.78,200,130,165885,11561327,233.65,233.74,1,500,1,1,233.53,233.75,10,201,1,2,233.51,233.77,200,8,1,1,233.49,233.78,29,150,1,2,233.45,233.8,15,25,1,1,233.4,233.84,110,29,2,1,233.39,233.94,10,200,1,1,233.31,233.98,110,44,2,3,233.3,234.0,100,154,1,7,233.25,234.13,55,400,2,1,AAPL,0,0,0,0,-200,0,0,0,0,0,0,233.695
2024-10-21T11:58:14.144875530Z,2024-10-21 11:58:14.144708873+00:00,10,2,38,A,A,3,233.78,200,130,166657,11561371,233.65,233.74,1,500,1,1,233.53,233.75,10,201,1,2,233.51,233.77,200,8,1,1,233.49,233.78,29,350,1,3,233.45,233.8,15,25,1,1,233.4,233.84,110,29,2,1,233.39,233.94,10,200,1,1,233.31,233.98,110,44,2,3,233.3,234.0,100,154,1,7,233.25,234.13,55,400,2,1,AAPL,0,0,0,0,200,0,0,0,0,0,0,233.695
2024-10-21T11:58:18.578872390Z,2024-10-21 11:58:18.578706483+00:00,10,2,38,C,A,3,233.78,200,130,165907,11564710,233.65,233.74,1,500,1,1,233.53,233.75,10,201,1,2,233.51,233.77,200,8,1,1,233.49,233.78,29,150,1,2,233.45,233.8,15,25,1,1,233.4,233.84,110,29,2,1,233.39,233.94,10,200,1,1,233.31,233.98,110,44,2,3,233.3,234.0,100,154,1,7,233.25,234.13,55,400,2,1,AAPL,0,0,0,0,-200,0,0,0,0,0,0,233.695
2024-10-21T11:58:18.578884023Z,2024-10-21 11:58:18.578717695+00:00,10,2,38,A,A,4,233.79,200,130,166328,11564711,233.65,233.74,1,500,1,1,233.53,233.75,10,201,1,2,233.51,233.77,200,8,1,1,233.49,233.78,29,150,1,2,233.45,233.79,15,200,1,1,233.4,233.8,110,25,2,1,233.39,233.84,10,29,1,1,233.31,233.94,110,200,2,1,233.3,233.98,100,44,1,3,233.25,234.0,55,154,2,7,AAPL,0,0,0,0,0,200,25,29,200,44,154,233.695
2024-10-21T11:58:18.649746443Z,2024-10-21 11:58:18.649580622+00:00,10,2,38,C,A,4,233.79,200,130,165821,11564816,233.65,233.74,1,500,1,1,233.53,233.75,10,201,1,2,233.51,233.77,200,8,1,1,233.49,233.78,29,150,1,2,233.45,233.8,15,25,1,1,233.4,233.84,110,29,2,1,233.39,233.94,10,200,1,1,233.31,233.98,110,44,2,3,233.3,234.0,100,154,1,7,233.25,234.13,55,400,2,1,AAPL,0,0,0,0,0,200,25,29,200,44,154,233.695
2024-10-21T11:58:18.666361221Z,2024-10-21 11:58:18.666193529+00:00,10,2,38,T,B,0,233.74,65,130,167692,11564831,233.65,233.74,1,500,1,1,233.53,233.75,10,201,1,2,233.51,233.77,200,8,1,1,233.49,233.78,29,150,1,2,233.45,233.8,15,25,1,1,233.4,233.84,110,29,2,1,233.39,233.94,10,200,1,1,233.31,233.98,110,44,2,3,233.3,234.0,100,154,1,7,233.25,234.13,55,400,2,1,AAPL,0,0,0,0,0,0,0,0,0,0,0,233.695
2024-10-21T11:58:18.666361221Z,2024-10-21 11:58:18.666193529+00:00,10,2,38,C,A,0,233.74,65,130,167692,11564831,233.65,233.74,1,435,1,1,233.53,233.75,10,201,1,2,233.51,233.77,200,8,1,1,233.49,233.78,29,150,1,2,233.45,233.8,15,25,1,1,233.4,233.84,110,29,2,1,233.39,233.94,10,200,1,1,233.31,233.98,110,44,2,3,233.3,234.0,100,154,1,7,233.25,234.13,55,400,2,1,AAPL,-65,-65,0,0,0,0,0,0,0,0,0,233.695
2024-10-21T11:58:18.722126458Z,2024-10-21 11:58:18.721960191+00:00,10,2,38,A,A,5,233.83,400,130,166267,11565202,233.65,233.74,1,435,1,1,233.53,233.75,10,201,1,2,233.51,233.77,200,8,1,1,233.49,233.78,29,150,1,2,233.45,233.8,15,25,1,1,233.4,233.83,110,400,2,1,233.39,233.84,10,29,1,1,233.31,233.94,110,200,2,1,233.3,233.98,100,44,1,3,233.25,234.0,55,154,2,7,AAPL,0,0,0,0,0,0,400,29,200,44,154,233.695
2024-10-21T11:58:18.722718534Z,2024-10-21 11:58:18.722551669+00:00,10,2,38,A,A,7,233.9,27,130,166865,11565205,233.65,233.74,1,435,1,1,233.53,233.75,10,201,1,2,233.51,233.77,200,8,1,1,233.49,233.78,29,150,1,2,233.45,233.8,15,25,1,1,233.4,233.83,110,400,2,1,233.39,233.84,10,29,1,1,233.31,233.9,110,27,2,1,233.3,233.94,100,200,1,1,233.25,233.98,55,44,2,3,AAPL,0,0,0,0,0,0,0,0,27,200,44,233.695
2024-10-21T11:58:18.722745911Z,2024-10-21 11:58:18.722579315+00:00,10,2,38,C,A,6,233.84,29,130,166596,11565206,233.65,233.74,1,435,1,1,233.53,233.75,10,201,1,2,233.51,233.77,200,8,1,1,233.49,233.78,29,150,1,2,233.45,233.8,15,25,1,1,233.4,233.83,110,400,2,1,233.39,233.9,10,27,1,1,233.31,233.94,110,200,2,1,233.3,233.98,100,44,1,3,233.25,234.0,55,154,2,7,AAPL,0,0,0,0,0,0,0,29,27,200,44,233.695
2024-10-21T11:58:18.734002535Z,2024-10-21 11:58:18.733836431+00:00,10,2,38,C,A,5,233.83,400,130,166104,11565231,233.65,233.74,1,435,1,1,233.53,233.75,10,201,1,2,233.51,233.77,200,8,1,1,233.49,233.78,29,150,1,2,233.45,233.8,15,25,1,1,233.4,233.9,110,27,2,1,233.39,233.94,10,200,1,1,233.31,233.98,110,44,2,3,233.3,234.0,100,154,1,7,233.25,234.13,55,400,2,1,AAPL,0,0,0,0,0,0,400,27,200,44,154,233.695
2024-10-21T11:58:18.771912264Z,2024-10-21 11:58:18.771745684+00:00,10,2,38,A,A,5,233.83,200,130,166580,11565306,233.65,233.74,1,435,1,1,233.53,233.75,10,201,1,2,233.51,233.77,200,8,1,1,233.49,233.78,29,150,1,2,233.45,233.8,15,25,1,1,233.4,233.83,110,200,2,1,233.39,233.9,10,27,1,1,233.31,233.94,110,200,2,1,233.3,233.98,100,44,1,3,233.25,234.0,55,154,2,7,AAPL,0,0,0,0,0,0,200,27,200,44,154,233.695
2024-10-21T11:58:19.575062840Z,2024-10-21 11:58:19.574896952+00:00,10,2,38,C,A,5,233.83,200,130,165888,11566008,233.65,233.74,1,435,1,1,233.53,233.75,10,201,1,2,233.51,233.77,200,8,1,1,233.49,233.78,29,150,1,2,233.45,233.8,15,25,1,1,233.4,233.9,110,27,2,1,233.39,233.94,10,200,1,1,233.31,233.98,110,44,2,3,233.3,234.0,100,154,1,7,233.25,234.13,55,400,2,1,AAPL,0,0,0,0,0,0,200,27,200,44,154,233.695
2024-10-21T11:58:19.575074157Z,2024-10-21 11:58:19.574907103+00:00,10,2,38,A,A,5,233.85,200,130,167054,11566009,233.65,233.74,1,435,1,1,233.53,233.75,10,201,1,2,233.51,233.77,200,8,1,1,233.49,233.78,29,150,1,2,233.45,233.8,15,25,1,1,233.4,233.85,110,200,2,1,233.39,233.9,10,27,1,1,233.31,233.94,110,200,2,1,233.3,233.98,100,44,1,3,233.25,234.0,55,154,2,7,AAPL,0,0,0,0,0,0,200,27,200,44,154,233.695
2024-10-21T11:58:19.604637959Z,2024-10-21 11:58:19.604471701+00:00,10,2,38,A,B,2,233.52,200,130,166258,11566140,233.65,233.74,1,435,1,1,233.53,233.75,10,201,1,2,233.52,233.77,200,8,1,1,233.49,233.78,29,150,1,2,233.45,233.8,15,25,1,1,233.4,233.85,110,200,2,1,233.39,233.9,10,27,1,1,233.31,233.94,110,200,2,1,233.3,233.98,100,44,1,3,233.25,234.0,55,154,2,7,AAPL,0,0,0,200,0,0,0,0,0,0,0,233.695
2024-10-21T11:58:19.632669907Z,2024-10-21 11:58:19.632503658+00:00,10,2,38,A,A,5,233.84,200,130,166249,11566182,233.65,233.74,1,435,1,1,233.53,233.75,10,201,1,2,233.52,233.77,200,8,1,1,233.49,233.78,29,150,1,2,233.45,233.8,15,25,1,1,233.4,233.84,110,200,2,1,233.39,233.9,10,27,1,1,233.31,233.94,110,200,2,1,233.3,233.98,100,44,1,3,233.25,234.0,55,154,2,7,AAPL,0,0,0,0,0,0,200,0,0,0,0,233.695
2024-10-21T11:58:21.722523136Z,2024-10-21 11:58:21.722356897+00:00,10,2,38,A,A,5,233.84,200,130,166239,11567782,233.65,233.74,1,435,1,1,233.53,233.75,10,201,1,2,233.52,233.77,200,8,1,1,233.49,233.78,29,150,1,2,233.45,233.8,15,25,1,1,233.4,233.84,110,400,2,2,233.39,233.9,10,27,1,1,233.31,233.94,110,200,2,1,233.3,233.98,100,44,1,3,233.25,234.0,55,154,2,7,AAPL,0,0,0,0,0,0,200,0,0,0,0,233.695
2024-10-21T11:58:21.794830742Z,2024-10-21 11:58:21.794663862+00:00,10,2,38,A,B,1,233.55,200,130,166880,11567840,233.65,233.74,1,435,1,1,233.55,233.75,200,201,1,2,233.53,233.77,10,8,1,1,233.49,233.78,29,150,1,2,233.45,233.8,15,25,1,1,233.4,233.84,110,400,2,2,233.39,233.9,10,27,1,1,233.31,233.94,110,200,2,1,233.3,233.98,100,44,1,3,233.25,234.0,55,154,2,7,AAPL,0,0,200,10,0,0,0,0,0,0,0,233.695
2024-10-21T11:58:32.993512492Z,2024-10-21 11:58:32.993346096+00:00,10,2,38,A,B,1,233.56,200,130,166396,11577193,233.65,233.74,1,435,1,1,233.56,233.75,200,201,1,2,233.53,233.77,10,8,1,1,233.49,233.78,29,150,1,2,233.45,233.8,15,25,1,1,233.4,233.84,110,400,2,2,233.39,233.9,10,27,1,1,233.31,233.94,110,200,2,1,233.3,233.98,100,44,1,3,233.25,234.0,55,154,2,7,AAPL,0,0,200,0,0,0,0,0,0,0,0,233.695
2024-10-21T11:58:37.947719334Z,2024-10-21 11:58:37.947553299+00:00,10,2,38,C,A,5,233.84,200,130,166035,11580485,233.65,233.74,1,435,1,1,233.56,233.75,200,201,1,2,233.53,233.77,10,8,1,1,233.49,233.78,29,150,1,2,233.45,233.8,15,25,1,1,233.4,233.84,110,200,2,1,233.39,233.9,10,27,1,1,233.31,233.94,110,200,2,1,233.3,233.98,100,44,1,3,233.25,234.0,55,154,2,7,AAPL,0,0,0,0,0,0,-200,0,0,0,0,233.695
2024-10-21T11:58:37.947728963Z,2024-10-21 11:58:37.947562931+00:00,10,2,38,C,A,5,233.84,200,130,166032,11580486,233.65,233.74,1,435,1,1,233.56,233.75,200,201,1,2,233.53,233.77,10,8,1,1,233.49,233.78,29,150,1,2,233.45,233.8,15,25,1,1,233.4,233.9,110,27,2,1,233.39,233.94,10,200,1,1,233.31,233.98,110,44,2,3,233.3,234.0,100,154,1,7,233.25,234.13,55,400,2,1,AAPL,0,0,0,0,0,0,200,27,200,44,154,233.695
2024-10-21T11:58:37.947740754Z,2024-10-21 11:58:37.947573917+00:00,10,2,38,A,A,5,233.85,400,130,166837,11580487,233.65,233.74,1,435,1,1,233.56,233.75,200,201,1,2,233.53,233.77,10,8,1,1,233.49,233.78,29,150,1,2,233.45,233.8,15,25,1,1,233.4,233.85,110,400,2,1,233.39,233.9,10,27,1,1,233.31,233.94,110,200,2,1,233.3,233.98,100,44,1,3,233.25,234.0,55,154,2,7,AAPL,0,0,0,0,0,0,400,27,200,44,154,233.695
2024-10-21T11:58:40.491589839Z,2024-10-21 11:58:40.491423845+00:00,10,2,38,C,B,3,233.49,29,130,165994,11582081,233.65,233.74,1,435,1,1,233.56,233.75,200,201,1,2,233.53,233.77,10,8,1,1,233.45,233.78,15,150,1,2,233.4,233.8,110,25,2,1,233.39,233.85,10,400,1,1,233.31,233.9,110,27,2,1,233.3,233.94,100,200,1,1,233.25,233.98,55,44,2,3,233.24,234.0,1,154,1,7,AAPL,0,0,0,0,-29,-15,-110,-10,-110,-100,-55,233.695
2024-10-21T11:58:40.491633125Z,2024-10-21 11:58:40.491466764+00:00,10,2,38,A,B,3,233.5,26,130,166361,11582082,233.65,233.74,1,435,1,1,233.56,233.75,200,201,1,2,233.53,233.77,10,8,1,1,233.5,233.78,26,150,1,2,233.45,233.8,15,25,1,1,233.4,233.85,110,400,2,1,233.39,233.9,10,27,1,1,233.31,233.94,110,200,2,1,233.3,233.98,100,44,1,3,233.25,234.0,55,154,2,7,AAPL,0,0,0,0,26,15,110,10,110,100,55,233.695
2024-10-21T11:58:50.556894132Z,2024-10-21 11:58:50.556727313+00:00,10,2,38,A,A,5,233.84,400,130,166819,11587782,233.65,233.74,1,435,1,1,233.56,233.75,200,201,1,2,233.53,233.77,10,8,1,1,233.5,233.78,26,150,1,2,233.45,233.8,15,25,1,1,233.4,233.84,110,400,2,1,233.39,233.9,10,27,1,1,233.31,233.94,110,200,2,1,233.3,233.98,100,44,1,3,233.25,234.0,55,154,2,7,AAPL,0,0,0,0,0,0,400,0,0,0,0,233.695
2024-10-21T11:58:53.131507522Z,2024-10-21 11:58:53.131341094+00:00,10,2,38,A,B,1,233.56,200,130,166428,11589174,233.65,233.74,1,435,1,1,233.56,233.75,400,201,2,2,233.53,233.77,10,8,1,1,233.5,233.78,26,150,1,2,233.45,233.8,15,25,1,1,233.4,233.84,110,400,2,1,233.39,233.9,10,27,1,1,233.31,233.94,110,200,2,1,233.3,233.98,100,44,1,3,233.25,234.0,55,154,2,7,AAPL,0,0,200,0,0,0,0,0,0,0,0,233.695
2024-10-21T11:58:53.954474192Z,2024-10-21 11:58:53.954307531+00:00,10,2,38,T,B,0,233.74,40,130,166661,11589595,233.65,233.74,1,435,1,1,233.56,233.75,400,201,2,2,233.53,233.77,10,8,1,1,233.5,233.78,26,150,1,2,233.45,233.8,15,25,1,1,233.4,233.84,110,400,2,1,233.39,233.9,10,27,1,1,233.31,233.94,110,200,2,1,233.3,233.98,100,44,1,3,233.25,234.0,55,154,2,7,AAPL,0,0,0,0,0,0,0,0,0,0,0,233.695
2024-10-21T11:58:53.954474192Z,2024-10-21 11:58:53.954307531+00:00,10,2,38,C,A,0,233.74,40,130,166661,11589595,233.65,233.74,1,395,1,1,233.56,233.75,400,201,2,2,233.53,233.77,10,8,1,1,233.5,233.78,26,150,1,2,233.45,233.8,15,25,1,1,233.4,233.84,110,400,2,1,233.39,233.9,10,27,1,1,233.31,233.94,110,200,2,1,233.3,233.98,100,44,1,3,233.25,234.0,55,154,2,7,AAPL,-40,-40,0,0,0,0,0,0,0,0,0,233.695
2024-10-21T11:58:53.954484330Z,2024-10-21 11:58:53.954317948+00:00,10,2,38,A,B,0,233.66,100,130,166382,11589596,233.66,233.74,100,395,1,1,233.65,233.75,1,201,1,2,233.56,233.77,400,8,2,1,233.53,233.78,10,150,1,2,233.5,233.8,26,25,1,1,233.45,233.84,15,400,1,1,233.4,233.9,110,27,2,1,233.39,233.94,10,200,1,1,233.31,233.98,110,44,2,3,233.3,234.0,100,154,1,7,AAPL,100,100,1,400,10,26,15,110,10,110,100,233.7
2024-10-21T11:58:53.954646013Z,2024-10-21 11:58:53.954477659+00:00,10,2,38,T,B,0,233.74,395,0,168354,11589601,233.66,233.74,100,395,1,1,233.65,233.75,1,201,1,2,233.56,233.77,400,8,2,1,233.53,233.78,10,150,1,2,233.5,233.8,26,25,1,1,233.45,233.84,15,400,1,1,233.4,233.9,110,27,2,1,233.39,233.94,10,200,1,1,233.31,233.98,110,44,2,3,233.3,234.0,100,154,1,7,AAPL,0,0,0,0,0,0,0,0,0,0,0,233.7
2024-10-21T11:58:53.954646013Z,2024-10-21 11:58:53.954477659+00:00,10,2,38,T,N,0,233.74,40,130,168354,11589602,233.66,233.75,100,201,1,2,233.65,233.77,1,8,1,1,233.56,233.78,400,150,2,2,233.53,233.8,10,25,1,1,233.5,233.84,26,400,1,1,233.45,233.9,15,27,1,1,233.4,233.94,110,200,2,1,233.39,233.98,10,44,1,3,233.31,234.0,110,154,2,7,233.3,234.13,100,400,1,1,AAPL,395,395,201,8,150,25,400,27,200,44,154,233.70499999999998
2024-10-21T11:58:53.954667578Z,2024-10-21 11:58:53.954501480+00:00,10,2,38,A,B,0,233.7,100,130,166098,11589603,233.7,233.75,100,201,1,2,233.66,233.77,100,8,1,1,233.65,233.78,1,150,1,2,233.56,233.8,400,25,2,1,233.53,233.84,10,400,1,1,233.5,233.9,26,27,1,1,233.45,233.94,15,200,1,1,233.4,233.98,110,44,2,3,233.39,234.0,10,154,1,7,233.31,234.13,110,400,2,1,AAPL,100,100,100,1,400,10,26,15,110,10,110,233.725
2024-10-21T11:58:53.954668924Z,2024-10-21 11:58:53.954502815+00:00,10,2,38,A,B,1,233.68,100,130,166109,11589604,233.7,233.75,100,201,1,2,233.68,233.77,100,8,1,1,233.66,233.78,100,150,1,2,233.65,233.8,1,25,1,1,233.56,233.84,400,400,2,1,233.53,233.9,10,27,1,1,233.5,233.94,26,200,1,1,233.45,233.98,15,44,1,3,233.4,234.0,110,154,2,7,233.39,234.13,10,400,1,1,AAPL,0,0,100,100,1,400,10,26,15,110,10,233.725
2024-10-21T11:58:53.954674047Z,2024-10-21 11:58:53.954507571+00:00,10,2,38,A,B,1,233.68,100,130,166476,11589605,233.7,233.75,100,201,1,2,233.68,233.77,200,8,2,1,233.66,233.78,100,150,1,2,233.65,233.8,1,25,1,1,233.56,233.84,400,400,2,1,233.53,233.9,10,27,1,1,233.5,233.94,26,200,1,1,233.45,233.98,15,44,1,3,233.4,234.0,110,154,2,7,233.39,234.13,10,400,1,1,AAPL,0,0,100,0,0,0,0,0,0,0,0,233.725
2024-10-21T11:58:53.954681864Z,2024-10-21 11:58:53.954515456+00:00,10,2,38,A,B,1,233.68,100,130,166408,11589606,233.7,233.75,100,201,1,2,233.68,233.77,300,8,3,1,233.66,233.78,100,150,1,2,233.65,233.8,1,25,1,1,233.56,233.84,400,400,2,1,233.53,233.9,10,27,1,1,233.5,233.94,26,200,1,1,233.45,233.98,15,44,1,3,233.4,234.0,110,154,2,7,233.39,234.13,10,400,1,1,AAPL,0,0,100,0,0,0,0,0,0,0,0,233.725
2024-10-21T11:58:53.954686890Z,2024-10-21 11:58:53.954518683+00:00,10,2,38,A,B,1,233.68,100,130,168207,11589607,233.7,233.75,100,201,1,2,233.68,233.77,400,8,4,1,233.66,233.78,100,150,1,2,233.65,233.8,1,25,1,1,233.56,233.84,400,400,2,1,233.53,233.9,10,27,1,1,233.5,233.94,26,200,1,1,233.45,233.98,15,44,1,3,233.4,234.0,110,154,2,7,233.39,234.13,10,400,1,1,AAPL,0,0,100,0,0,0,0,0,0,0,0,233.725
2024-10-21T11:58:53.954688296Z,2024-10-21 11:58:53.954521070+00:00,10,2,38,A,B,0,233.7,40,130,167226,11589608,233.7,233.75,140,201,2,2,233.68,233.77,400,8,4,1,233.66,233.78,100,150,1,2,233.65,233.8,1,25,1,1,233.56,233.84,400,400,2,1,233.53,233.9,10,27,1,1,233.5,233.94,26,200,1,1,233.45,233.98,15,44,1,3,233.4,234.0,110,154,2,7,233.39,234.13,10,400,1,1,AAPL,40,40,0,0,0,0,0,0,0,0,0,233.725
2024-10-21T11:58:53.954700521Z,2024-10-21 11:58:53.954534910+00:00,10,2,38,C,A,4,233.84,400,130,165611,11589609,233.7,233.75,140,201,2,2,233.68,233.77,400,8,4,1,233.66,233.78,100,150,1,2,233.65,233.8,1,25,1,1,233.56,233.9,400,27,2,1,233.53,233.94,10,200,1,1,233.5,233.98,26,44,1,3,233.45,234.0,15,154,1,7,233.4,234.13,110,400,2,1,233.39,234.17,10,1,1,1,AAPL,0,0,0,0,0,400,27,200,44,154,400,233.725
2024-10-21T11:58:53.954701970Z,2024-10-21 11:58:53.954535707+00:00,10,2,38,A,B,2,233.67,40,130,166263,11589610,233.7,233.75,140,201,2,2,233.68,233.77,400,8,4,1,233.67,233.78,40,150,1,2,233.66,233.8,100,25,1,1,233.65,233.9,1,27,1,1,233.56,233.94,400,200,2,1,233.53,233.98,10,44,1,3,233.5,234.0,26,154,1,7,233.45,234.13,15,400,1,1,233.4,234.17,110,1,2,1,AAPL,0,0,0,40,100,1,400,10,26,15,110,233.725
2024-10-21T11:58:53.954713634Z,2024-10-21 11:58:53.954546864+00:00,10,2,38,C,B,1,233.68,100,130,166770,11589611,233.7,233.75,140,201,2,2,233.68,233.77,300,8,3,1,233.67,233.78,40,150,1,2,233.66,233.8,100,25,1,1,233.65,233.9,1,27,1,1,233.56,233.94,400,200,2,1,233.53,233.98,10,44,1,3,233.5,234.0,26,154,1,7,233.45,234.13,15,400,1,1,233.4,234.17,110,1,2,1,AAPL,0,0,-100,0,0,0,0,0,0,0,0,233.725
2024-10-21T11:58:53.954714820Z,2024-10-21 11:58:53.954549208+00:00,10,2,38,C,B,0,233.7,100,130,165612,11589612,233.7,233.75,40,201,1,2,233.68,233.77,300,8,3,1,233.67,233.78,40,150,1,2,233.66,233.8,100,25,1,1,233.65,233.9,1,27,1,1,233.56,233.94,400,200,2,1,233.53,233.98,10,44,1,3,233.5,234.0,26,154,1,7,233.45,234.13,15,400,1,1,233.4,234.17,110,1,2,1,AAPL,-100,-100,0,0,0,0,0,0,0,0,0,233.725
2024-10-21T11:58:53.954724743Z,2024-10-21 11:58:53.954555754+00:00,10,2,38,T,N,0,233.74,110,130,168989,11589613,233.7,233.75,40,201,1,2,233.68,233.77,300,8,3,1,233.67,233.78,40,150,1,2,233.66,233.8,100,25,1,1,233.65,233.9,1,27,1,1,233.56,233.94,400,200,2,1,233.53,233.98,10,44,1,3,233.5,234.0,26,154,1,7,233.45,234.13,15,400,1,1,233.4,234.17,110,1,2,1,AAPL,0,0,0,0,0,0,0,0,0,0,0,233.725
2024-10-21T11:58:53.954731951Z,2024-10-21 11:58:53.954564591+00:00,10,2,38,C,B,1,233.68,100,130,167360,11589614,233.7,233.75,40,201,1,2,233.68,233.77,200,8,2,1,233.67,233.78,40,150,1,2,233.66,233.8,100,25,1,1,233.65,233.9,1,27,1,1,233.56,233.94,400,200,2,1,233.53,233.98,10,44,1,3,233.5,234.0,26,154,1,7,233.45,234.13,15,400,1,1,233.4,234.17,110,1,2,1,AAPL,0,0,-100,0,0,0,0,0,0,0,0,233.725
2024-10-21T11:58:53.954737728Z,2024-10-21 11:58:53.954570870+00:00,10,2,38,C,B,1,233.68,100,130,166858,11589615,233.7,233.75,40,201,1,2,233.68,233.77,100,8,1,1,233.67,233.78,40,150,1,2,233.66,233.8,100,25,1,1,233.65,233.9,1,27,1,1,233.56,233.94,400,200,2,1,233.53,233.98,10,44,1,3,233.5,234.0,26,154,1,7,233.45,234.13,15,400,1,1,233.4,234.17,110,1,2,1,AAPL,0,0,-100,0,0,0,0,0,0,0,0,233.725
2024-10-21T11:58:53.954832820Z,2024-10-21 11:58:53.954666995+00:00,10,2,38,C,B,3,233.66,100,130,165825,11589616,233.7,233.75,40,201,1,2,233.68,233.77,100,8,1,1,233.67,233.78,40,150,1,2,233.65,233.8,1,25,1,1,233.56,233.9,400,27,2,1,233.53,233.94,10,200,1,1,233.5,233.98,26,44,1,3,233.45,234.0,15,154,1,7,233.4,234.13,110,400,2,1,233.39,234.17,10,1,1,1,AAPL,0,0,0,0,-100,-1,-400,-10,-26,-15,-110,233.725
2024-10-21T11:58:53.955116146Z,2024-10-21 11:58:53.954950395+00:00,10,2,38,C,B,1,233.68,100,130,165751,11589618,233.7,233.75,40,201,1,2,233.67,233.77,40,8,1,1,233.65,233.78,1,150,1,2,233.56,233.8,400,25,2,1,233.53,233.9,10,27,1,1,233.5,233.94,26,200,1,1,233.45,233.98,15,44,1,3,233.4,234.0,110,154,2,7,233.39,234.13,10,400,1,1,233.31,234.17,110,1,2,1,AAPL,0,0,-100,-40,-1,-400,-10,-26,-15,-110,-10,233.725
2024-10-21T11:58:54.013732422Z,2024-10-21 11:58:54.013566047+00:00,10,2,38,A,A,4,233.84,200,130,166375,11590027,233.7,233.75,40,201,1,2,233.67,233.77,40,8,1,1,233.65,233.78,1,150,1,2,233.56,233.8,400,25,2,1,233.53,233.84,10,200,1,1,233.5,233.9,26,27,1,1,233.45,233.94,15,200,1,1,233.4,233.98,110,44,2,3,233.39,234.0,10,154,1,7,233.31,234.13,110,400,2,1,AAPL,0,0,0,0,0,200,27,200,44,154,400,233.725
2024-10-21T11:58:54.013755259Z,2024-10-21 11:58:54.013589130+00:00,10,2,38,C,A,4,233.84,200,130,166129,11590028,233.7,233.75,40,201,1,2,233.67,233.77,40,8,1,1,233.65,233.78,1,150,1,2,233.56,233.8,400,25,2,1,233.53,233.9,10,27,1,1,233.5,233.94,26,200,1,1,233.45,233.98,15,44,1,3,233.4,234.0,110,154,2,7,233.39,234.13,10,400,1,1,233.31,234.17,110,1,2,1,AAPL,0,0,0,0,0,200,27,200,44,154,400,233.725
2024-10-21T11:58:54.021610376Z,2024-10-21 11:58:54.021444014+00:00,10,2,38,A,A,4,233.84,200,130,166362,11590029,233.7,233.75,40,201,1,2,233.67,233.77,40,8,1,1,233.65,233.78,1,150,1,2,233.56,233.8,400,25,2,1,233.53,233.84,10,200,1,1,233.5,233.9,26,27,1,1,233.45,233.94,15,200,1,1,233.4,233.98,110,44,2,3,233.39,234.0,10,154,1,7,233.31,234.13,110,400,2,1,AAPL,0,0,0,0,0,200,27,200,44,154,400,233.725
2024-10-21T11:58:54.043514811Z,2024-10-21 11:58:54.043347922+00:00,10,2,38,A,A,4,233.84,200,130,166889,11590054,233.7,233.75,40,201,1,2,233.67,233.77,40,8,1,1,233.65,233.78,1,150,1,2,233.56,233.8,400,25,2,1,233.53,233.84,10,400,1,2,233.5,233.9,26,27,1,1,233.45,233.94,15,200,1,1,233.4,233.98,110,44,2,3,233.39,234.0,10,154,1,7,233.31,234.13,110,400,2,1,AAPL,0,0,0,0,0,200,0,0,0,0,0,233.725
2024-10-21T11:58:54.063932439Z,2024-10-21 11:58:54.063766628+00:00,10,2,38,C,B,1,233.67,40,130,165811,11590066,233.7,233.75,40,201,1,2,233.65,233.77,1,8,1,1,233.56,233.78,400,150,2,2,233.53,233.8,10,25,1,1,233.5,233.84,26,400,1,2,233.45,233.9,15,27,1,1,233.4,233.94,110,200,2,1,233.39,233.98,10,44,1,3,233.31,234.0,110,154,2,7,233.3,234.13,100,400,1,1,AAPL,0,0,-40,-1,-400,-10,-26,-15,-110,-10,-110,233.725
2024-10-21T11:58:54.213932055Z,2024-10-21 11:58:54.213766156+00:00,10,2,38,C,B,0,233.7,40,130,165899,11590218,233.65,233.75,1,201,1,2,233.56,233.77,400,8,2,1,233.53,233.78,10,150,1,2,233.5,233.8,26,25,1,1,233.45,233.84,15,400,1,2,233.4,233.9,110,27,2,1,233.39,233.94,10,200,1,1,233.31,233.98,110,44,2,3,233.3,234.0,100,154,1,7,233.25,234.13,55,400,2,1,AAPL,-40,-40,-1,-400,-10,-26,-15,-110,-10,-110,-100,233.7
2024-10-21T11:58:58.704824203Z,2024-10-21 11:58:58.704657287+00:00,10,2,38,A,B,2,233.54,26,130,166916,11592894,233.65,233.75,1,201,1,2,233.56,233.77,400,8,2,1,233.54,233.78,26,150,1,2,233.53,233.8,10,25,1,1,233.5,233.84,26,400,1,2,233.45,233.9,15,27,1,1,233.4,233.94,110,200,2,1,233.39,233.98,10,44,1,3,233.31,234.0,110,154,2,7,233.3,234.13,100,400,1,1,AAPL,0,0,0,26,10,26,15,110,10,110,100,233.7
2024-10-21T11:58:58.704911600Z,2024-10-21 11:58:58.704745556+00:00,10,2,38,C,B,4,233.5,26,130,166044,11592895,233.65,233.75,1,201,1,2,233.56,233.77,400,8,2,1,233.54,233.78,26,150,1,2,233.53,233.8,10,25,1,1,233.45,233.84,15,400,1,2,233.4,233.9,110,27,2,1,233.39,233.94,10,200,1,1,233.31,233.98,110,44,2,3,233.3,234.0,100,154,1,7,233.25,234.13,55,400,2,1,AAPL,0,0,0,0,0,-26,-15,-110,-10,-110,-100,233.7
2024-10-21T11:58:58.758575390Z,2024-10-21 11:58:58.758409305+00:00,10,2,38,C,B,1,233.56,200,130,166085,11592914,233.65,233.75,1,201,1,2,233.56,233.77,200,8,1,1,233.54,233.78,26,150,1,2,233.53,233.8,10,25,1,1,233.45,233.84,15,400,1,2,233.4,233.9,110,27,2,1,233.39,233.94,10,200,1,1,233.31,233.98,110,44,2,3,233.3,234.0,100,154,1,7,233.25,234.13,55,400,2,1,AAPL,0,0,-200,0,0,0,0,0,0,0,0,233.7
2024-10-21T11:58:58.758589359Z,2024-10-21 11:58:58.758422757+00:00,10,2,38,A,B,1,233.61,200,130,166602,11592915,233.65,233.75,1,201,1,2,233.61,233.77,200,8,1,1,233.54,233.78,26,150,1,2,233.53,233.8,10,25,1,1,233.45,233.84,15,400,1,2,233.4,233.9,110,27,2,1,233.39,233.94,10,200,1,1,233.31,233.98,110,44,2,3,233.3,234.0,100,154,1,7,233.25,234.13,55,400,2,1,AAPL,0,0,200,0,0,0,0,0,0,0,0,233.7
2024-10-21T11:58:58.912542023Z,2024-10-21 11:58:58.912375357+00:00,10,2,38,A,B,0,233.66,100,130,166666,11592972,233.66,233.75,100,201,1,2,233.65,233.77,1,8,1,1,233.61,233.78,200,150,1,2,233.54,233.8,26,25,1,1,233.53,233.84,10,400,1,2,233.45,233.9,15,27,1,1,233.4,233.94,110,200,2,1,233.39,233.98,10,44,1,3,233.31,234.0,110,154,2,7,233.3,234.13,100,400,1,1,AAPL,100,100,1,200,26,10,15,110,10,110,100,233.70499999999998
2024-10-21T11:58:58.912719366Z,2024-10-21 11:58:58.912551174+00:00,10,2,38,T,B,0,233.75,1,0,168192,11592975,233.66,233.75,100,201,1,2,233.65,233.77,1,8,1,1,233.61,233.78,200,150,1,2,233.54,233.8,26,25,1,1,233.53,233.84,10,400,1,2,233.45,233.9,15,27,1,1,233.4,233.94,110,200,2,1,233.39,233.98,10,44,1,3,233.31,234.0,110,154,2,7,233.3,234.13,100,400,1,1,AAPL,0,0,0,0,0,0,0,0,0,0,0,233.70499999999998
2024-10-21T11:58:58.912719366Z,2024-10-21 11:58:58.912551174+00:00,10,2,38,T,B,0,233.75,200,130,168192,11592976,233.66,233.75,100,200,1,1,233.65,233.77,1,8,1,1,233.61,233.78,200,150,1,2,233.54,233.8,26,25,1,1,233.53,233.84,10,400,1,2,233.45,233.9,15,27,1,1,233.4,233.94,110,200,2,1,233.39,233.98,10,44,1,3,233.31,234.0,110,154,2,7,233.3,234.13,100,400,1,1,AAPL,-1,-1,0,0,0,0,0,0,0,0,0,233.70499999999998
2024-10-21T11:58:58.912719366Z,2024-10-21 11:58:58.912551174+00:00,10,2,38,C,A,0,233.75,200,130,168192,11592976,233.66,233.77,100,8,1,1,233.65,233.78,1,150,1,2,233.61,233.8,200,25,1,1,233.54,233.84,26,400,1,2,233.53,233.9,10,27,1,1,233.45,233.94,15,200,1,1,233.4,233.98,110,44,2,3,233.39,234.0,10,154,1,7,233.31,234.13,110,400,2,1,233.3,234.17,100,1,1,1,AAPL,200,200,8,150,25,400,27,200,44,154,400,233.715
2024-10-21T11:58:58.912744804Z,2024-10-21 11:58:58.912577219+00:00,10,2,38,A,B,0,233.68,100,130,167585,11592979,233.71,233.77,100,8,1,1,233.68,233.78,200,150,2,2,233.66,233.8,100,25,1,1,233.65,233.84,1,400,1,2,233.61,233.9,200,27,1,1,233.54,233.94,26,200,1,1,233.53,233.98,10,44,1,3,233.45,234.0,15,154,1,7,233.4,234.13,110,400,2,1,233.39,234.17,10,1,1,1,AAPL,100,100,200,100,1,200,26,10,15,110,10,233.74
2024-10-21T11:58:58.912755099Z,2024-10-21 11:58:58.912588388+00:00,10,2,38,A,B,1,233.68,100,130,166711,11592981,233.71,233.77,100,8,1,1,233.68,233.78,400,150,4,2,233.66,233.8,100,25,1,1,233.65,233.84,1,400,1,2,233.61,233.9,200,27,1,1,233.54,233.94,26,200,1,1,233.53,233.98,10,44,1,3,233.45,234.0,15,154,1,7,233.4,234.13,110,400,2,1,233.39,234.17,10,1,1,1,AAPL,0,0,200,0,0,0,0,0,0,0,0,233.74
2024-10-21T11:58:58.912761550Z,2024-10-21 11:58:58.912594900+00:00,10,2,38,A,B,1,233.7,38,130,166650,11592982,233.71,233.77,100,8,1,1,233.7,233.78,38,150,1,2,233.68,233.8,400,25,4,1,233.66,233.84,100,400,1,2,233.65,233.9,1,27,1,1,233.61,233.94,200,200,1,1,233.54,233.98,26,44,1,3,233.53,234.0,10,154,1,7,233.45,234.13,15,400,1,1,233.4,234.17,110,1,2,1,AAPL,0,0,38,400,100,1,200,26,10,15,110,233.74
2024-10-21T11:58:58.912776419Z,2024-10-21 11:58:58.912609151+00:00,10,2,38,A,B,3,233.67,38,130,167268,11592984,233.71,233.77,100,8,1,1,233.7,233.78,38,150,1,2,233.68,233.8,400,25,4,1,233.67,233.84,38,400,1,2,233.66,233.9,100,27,1,1,233.65,233.94,1,200,1,1,233.61,233.98,200,44,1,3,233.54,234.0,26,154,1,7,233.53,234.13,10,400,1,1,233.45,234.17,15,1,1,1,AAPL,0,0,0,0,38,100,1,200,26,10,15,233.74
2024-10-21T11:58:58.912779652Z,2024-10-21 11:58:58.912613899+00:00,10,2,38,C,B,2,233.68,100,130,165753,11592985,233.71,233.77,100,8,1,1,233.7,233.78,38,150,1,2,233.68,233.8,300,25,3,1,233.67,233.84,38,400,1,2,233.66,233.9,100,27,1,1,233.65,233.94,1,200,1,1,233.61,233.98,200,44,1,3,233.54,234.0,26,154,1,7,233.53,234.13,10,400,1,1,233.45,234.17,15,1,1,1,AAPL,0,0,0,-100,0,0,0,0,0,0,0,233.74
2024-10-21T11:58:58.912783553Z,2024-10-21 11:58:58.912617614+00:00,10,2,38,C,A,3,233.84,200,130,165939,11592986,233.71,233.77,100,8,1,1,233.7,233.78,38,150,1,2,233.68,233.8,300,25,3,1,233.67,233.84,38,200,1,1,233.66,233.9,100,27,1,1,233.65,233.94,1,200,1,1,233.61,233.98,200,44,1,3,233.54,234.0,26,154,1,7,233.53,234.13,10,400,1,1,233.45,234.17,15,1,1,1,AAPL,0,0,0,0,-200,0,0,0,0,0,0,233.74
2024-10-21T11:58:58.912786801Z,2024-10-21 11:58:58.912620981+00:00,10,2,38,C,B,0,233.71,100,130,165820,11592987,233.7,233.77,38,8,1,1,233.68,233.78,300,150,3,2,233.67,233.8,38,25,1,1,233.66,233.84,100,200,1,1,233.65,233.9,1,27,1,1,233.61,233.94,200,200,1,1,233.54,233.98,26,44,1,3,233.53,234.0,10,154,1,7,233.45,234.13,15,400,1,1,233.4,234.17,110,1,2,1,AAPL,-100,-100,-38,-300,-38,-100,-1,-200,-26,-10,-15,233.735
2024-10-21T11:58:58.912794208Z,2024-10-21 11:58:58.912628049+00:00,10,2,38,C,A,3,233.84,200,130,166159,11592988,233.7,233.77,38,8,1,1,233.68,233.78,300,150,3,2,233.67,233.8,38,25,1,1,233.66,233.9,100,27,1,1,233.65,233.94,1,200,1,1,233.61,233.98,200,44,1,3,233.54,234.0,26,154,1,7,233.53,234.13,10,400,1,1,233.45,234.17,15,1,1,1,233.4,234.41,110,600,2,2,AAPL,0,0,0,0,200,27,200,44,154,400,1,233.735
2024-10-21T11:58:58.912804792Z,2024-10-21 11:58:58.912639087+00:00,10,2,38,C,B,1,233.68,100,130,165705,11592990,233.7,233.77,38,8,1,1,233.68,233.78,200,150,2,2,233.67,233.8,38,25,1,1,233.66,233.9,100,27,1,1,233.65,233.94,1,200,1,1,233.61,233.98,200,44,1,3,233.54,234.0,26,154,1,7,233.53,234.13,10,400,1,1,233.45,234.17,15,1,1,1,233.4,234.41,110,600,2,2,AAPL,0,0,-100,0,0,0,0,0,0,0,0,233.735
2024-10-21T11:58:58.912808391Z,2024-10-21 11:58:58.912642543+00:00,10,2,38,C,B,1,233.68,100,130,165848,11592991,233.7,233.77,38,8,1,1,233.68,233.78,100,150,1,2,233.67,233.8,38,25,1,1,233.66,233.9,100,27,1,1,233.65,233.94,1,200,1,1,233.61,233.98,200,44,1,3,233.54,234.0,26,154,1,7,233.53,234.13,10,400,1,1,233.45,234.17,15,1,1,1,233.4,234.41,110,600,2,2,AAPL,0,0,-100,0,0,0,0,0,0,0,0,233.735
2024-10-21T11:58:58.912849846Z,2024-10-21 11:58:58.912684059+00:00,10,2,38,C,B,3,233.66,100,130,165787,11592992,233.7,233.77,38,8,1,1,233.68,233.78,100,150,1,2,233.67,233.8,38,25,1,1,233.65,233.9,1,27,1,1,233.61,233.94,200,200,1,1,233.54,233.98,26,44,1,3,233.53,234.0,10,154,1,7,233.45,234.13,15,400,1,1,233.4,234.17,110,1,2,1,233.39,234.41,10,600,1,2,AAPL,0,0,0,0,-100,-1,-200,-26,-10,-15,-110,233.735
2024-10-21T11:58:58.913120559Z,2024-10-21 11:58:58.912954809+00:00,10,2,38,C,B,1,235.0,1000,130,165750,11592994,233.7,233.77,38,8,1,1,233.67,233.78,38,150,1,2,233.65,233.8,1,25,1,1,233.61,233.9,200,27,1,1,233.54,233.94,26,200,1,1,233.53,233.98,10,44,1,3,233.45,234.0,15,154,1,7,233.4,234.13,110,400,2,1,233.39,234.17,10,1,1,1,233.31,234.41,110,600,2,2,AAPL,0,0,-100,-38,-1,-200,-26,-10,-15,-110,-10,233.735
2024-10-21T11:58:58.926633058Z,2024-10-21 11:58:58.926466671+00:00,10,2,38,A,A,3,233.85,200,130,166387,11593007,233.7,233.77,38,8,1,1,233.67,233.78,38,150,1,2,233.65,233.8,1,25,1,1,233.61,233.85,200,200,1,1,233.54,233.9,26,27,1,1,233.53,233.94,10,200,1,1,233.45,233.98,15,44,1,3,233.4,234.0,110,154,2,7,233.39,234.13,10,400,1,1,233.31,234.17,110,1,2,1,AAPL,0,0,0,0,200,27,200,44,154,400,1,233.735
2024-10-21T11:58:58.945632815Z,2024-10-21 11:58:58.945466491+00:00,10,2,38,A,A,3,233.85,200,130,166324,11593017,233.7,233.77,38,8,1,1,233.67,233.78,38,150,1,2,233.65,233.8,1,25,1,1,233.61,233.85,200,400,1,2,233.54,233.9,26,27,1,1,233.53,233.94,10,200,1,1,233.45,233.98,15,44,1,3,233.4,234.0,110,154,2,7,233.39,234.13,10,400,1,1,233.31,234.17,110,1,2,1,AAPL,0,0,0,0,200,0,0,0,0,0,0,233.735
2024-10-21T11:58:58.980361981Z,2024-10-21 11:58:58.980196081+00:00,10,2,38,C,A,3,233.85,200,130,165900,11593035,233.7,233.77,38,8,1,1,233.67,233.78,38,150,1,2,233.65,233.8,1,25,1,1,233.61,233.85,200,200,1,1,233.54,233.9,26,27,1,1,233.53,233.94,10,200,1,1,233.45,233.98,15,44,1,3,233.4,234.0,110,154,2,7,233.39,234.13,10,400,1,1,233.31,234.17,110,1,2,1,AAPL,0,0,0,0,-200,0,0,0,0,0,0,233.735
2024-10-21T11:58:58.980371284Z,2024-10-21 11:58:58.980205607+00:00,10,2,38,C,A,3,233.85,200,130,165677,11593036,233.7,233.77,38,8,1,1,233.67,233.78,38,150,1,2,233.65,233.8,1,25,1,1,233.61,233.9,200,27,1,1,233.54,233.94,26,200,1,1,233.53,233.98,10,44,1,3,233.45,234.0,15,154,1,7,233.4,234.13,110,400,2,1,233.39,234.17,10,1,1,1,233.31,234.41,110,600,2,2,AAPL,0,0,0,0,200,27,200,44,154,400,1,233.735
2024-10-21T11:58:58.983554818Z,2024-10-21 11:58:58.983388525+00:00,10,2,38,C,B,3,233.61,200,130,166293,11593038,233.7,233.77,38,8,1,1,233.67,233.78,38,150,1,2,233.65,233.8,1,25,1,1,233.54,233.9,26,27,1,1,233.53,233.94,10,200,1,1,233.45,233.98,15,44,1,3,233.4,234.0,110,154,2,7,233.39,234.13,10,400,1,1,233.31,234.17,110,1,2,1,233.3,234.41,100,600,1,2,AAPL,0,0,0,0,-200,-26,-10,-15,-110,-10,-110,233.735
2024-10-21T11:58:58.983567276Z,2024-10-21 11:58:58.983400771+00:00,10,2,38,A,B,3,233.56,400,130,166505,11593039,233.7,233.77,38,8,1,1,233.67,233.78,38,150,1,2,233.65,233.8,1,25,1,1,233.56,233.9,400,27,1,1,233.54,233.94,26,200,1,1,233.53,233.98,10,44,1,3,233.45,234.0,15,154,1,7,233.4,234.13,110,400,2,1,233.39,234.17,10,1,1,1,233.31,234.41,110,600,2,2,AAPL,0,0,0,0,400,26,10,15,110,10,110,233.735
2024-10-21T11:58:59.013929420Z,2024-10-21 11:58:59.013763041+00:00,10,2,38,C,B,1,233.67,38,130,166379,11593062,233.7,233.77,38,8,1,1,233.65,233.78,1,150,1,2,233.56,233.8,400,25,1,1,233.54,233.9,26,27,1,1,233.53,233.94,10,200,1,1,233.45,233.98,15,44,1,3,233.4,234.0,110,154,2,7,233.39,234.13,10,400,1,1,233.31,234.17,110,1,2,1,233.3,234.41,100,600,1,2,AAPL,0,0,-38,-1,-400,-26,-10,-15,-110,-10,-110,233.735
2024-10-21T11:58:59.013989405Z,2024-10-21 11:58:59.013823110+00:00,10,2,38,A,A,3,233.85,200,130,166295,11593063,233.7,233.77,38,8,1,1,233.65,233.78,1,150,1,2,233.56,233.8,400,25,1,1,233.54,233.85,26,200,1,1,233.53,233.9,10,27,1,1,233.45,233.94,15,200,1,1,233.4,233.98,110,44,2,3,233.39,234.0,10,154,1,7,233.31,234.13,110,400,2,1,233.3,234.17,100,1,1,1,AAPL,0,0,0,0,200,27,200,44,154,400,1,233.735
2024-10-21T11:58:59.163929286Z,2024-10-21 11:58:59.163763153+00:00,10,2,38,C,B,0,233.7,38,130,166133,11593111,233.65,233.77,1,8,1,1,233.56,233.78,400,150,1,2,233.54,233.8,26,25,1,1,233.53,233.85,10,200,1,1,233.45,233.9,15,27,1,1,233.4,233.94,110,200,2,1,233.39,233.98,10,44,1,3,233.31,234.0,110,154,2,7,233.3,234.13,100,400,1,1,233.25,234.17,55,1,2,1,AAPL,-38,-38,-1,-400,-26,-10,-15,-110,-10,-110,-100,233.71
2024-10-21T11:59:00.168394703Z,2024-10-21 11:59:00.168228588+00:00,10,2,38,C,B,2,233.54,26,130,166115,11594290,233.65,233.77,1,8,1,1,233.56,233.78,400,150,1,2,233.53,233.8,10,25,1,1,233.45,233.85,15,200,1,1,233.4,233.9,110,27,2,1,233.39,233.94,10,200,1,1,233.31,233.98,110,44,2,3,233.3,234.0,100,154,1,7,233.25,234.13,55,400,2,1,233.24,234.17,1,1,1,1,AAPL,0,0,0,-26,-10,-15,-110,-10,-110,-100,-55,233.71
2024-10-21T11:59:00.168436220Z,2024-10-21 11:59:00.168269867+00:00,10,2,38,A,B,2,233.55,30,130,166353,11594291,233.65,233.77,1,8,1,1,233.56,233.78,400,150,1,2,233.55,233.8,30,25,1,1,233.53,233.85,10,200,1,1,233.45,233.9,15,27,1,1,233.4,233.94,110,200,2,1,233.39,233.98,10,44,1,3,233.31,234.0,110,154,2,7,233.3,234.13,100,400,1,1,233.25,234.17,55,1,2,1,AAPL,0,0,0,30,10,15,110,10,110,100,55,233.71
2024-10-21T11:59:00.853997755Z,2024-10-21 11:59:00.853830846+00:00,10,2,38,A,A,3,233.84,200,130,166909,11595138,233.65,233.77,1,8,1,1,233.56,233.78,400,150,1,2,233.55,233.8,30,25,1,1,233.53,233.84,10,200,1,1,233.45,233.9,15,27,1,1,233.4,233.94,110,200,2,1,233.39,233.98,10,44,1,3,233.31,234.0,110,154,2,7,233.3,234.13,100,400,1,1,233.25,234.17,55,1,2,1,AAPL,0,0,0,0,200,0,0,0,0,0,0,233.71
2024-10-21T11:59:01.071691307Z,2024-10-21 11:59:01.071525039+00:00,10,2,38,C,B,1,233.56,400,130,166268,11595523,233.65,233.77,1,8,1,1,233.55,233.78,30,150,1,2,233.53,233.8,10,25,1,1,233.45,233.84,15,200,1,1,233.4,233.9,110,27,2,1,233.39,233.94,10,200,1,1,233.31,233.98,110,44,2,3,233.3,234.0,100,154,1,7,233.25,234.13,55,400,2,1,233.24,234.17,1,1,1,1,AAPL,0,0,-400,-30,-10,-15,-110,-10,-110,-100,-55,233.71
2024-10-21T11:59:01.071703415Z,2024-10-21 11:59:01.071537379+00:00,10,2,38,A,B,2,233.54,400,130,166036,11595524,233.65,233.77,1,8,1,1,233.55,233.78,30,150,1,2,233.54,233.8,400,25,1,1,233.53,233.84,10,200,1,1,233.45,233.9,15,27,1,1,233.4,233.94,110,200,2,1,233.39,233.98,10,44,1,3,233.31,234.0,110,154,2,7,233.3,234.13,100,400,1,1,233.25,234.17,55,1,2,1,AAPL,0,0,0,400,10,15,110,10,110,100,55,233.71
2024-10-21T11:59:01.127500003Z,2024-10-21 11:59:01.127333717+00:00,10,2,38,A,A,3,233.83,200,130,166286,11595689,233.65,233.77,1,8,1,1,233.55,233.78,30,150,1,2,233.54,233.8,400,25,1,1,233.53,233.83,10,200,1,1,233.45,233.9,15,27,1,1,233.4,233.94,110,200,2,1,233.39,233.98,10,44,1,3,233.31,234.0,110,154,2,7,233.3,234.13,100,400,1,1,233.25,234.17,55,1,2,1,AAPL,0,0,0,0,200,0,0,0,0,0,0,233.71
2024-10-21T11:59:01.142037998Z,2024-10-21 11:59:01.141872098+00:00,10,2,38,C,A,3,233.83,200,130,165900,11595742,233.65,233.77,1,8,1,1,233.55,233.78,30,150,1,2,233.54,233.8,400,25,1,1,233.53,233.9,10,27,1,1,233.45,233.94,15,200,1,1,233.4,233.98,110,44,2,3,233.39,234.0,10,154,1,7,233.31,234.13,110,400,2,1,233.3,234.17,100,1,1,1,233.25,234.41,55,600,2,2,AAPL,0,0,0,0,200,27,200,44,154,400,1,233.71
2024-10-21T11:59:01.142051431Z,2024-10-21 11:59:01.141884696+00:00,10,2,38,A,A,3,233.89,400,130,166735,11595743,233.65,233.77,1,8,1,1,233.55,233.78,30,150,1,2,233.54,233.8,400,25,1,1,233.53,233.89,10,400,1,1,233.45,233.9,15,27,1,1,233.4,233.94,110,200,2,1,233.39,233.98,10,44,1,3,233.31,234.0,110,154,2,7,233.3,234.13,100,400,1,1,233.25,234.17,55,1,2,1,AAPL,0,0,0,0,400,27,200,44,154,400,1,233.71
2024-10-21T11:59:01.197168571Z,2024-10-21 11:59:01.197001468+00:00,10,2,38,A,B,1,233.55,400,130,167103,11595894,233.65,233.77,1,8,1,1,233.55,233.78,430,150,2,2,233.53,233.8,10,25,1,1,233.45,233.89,15,400,1,1,233.4,233.9,110,27,2,1,233.39,233.94,10,200,1,1,233.31,233.98,110,44,2,3,233.3,234.0,100,154,1,7,233.25,234.13,55,400,2,1,233.24,234.17,1,1,1,1,AAPL,0,0,400,-400,-10,-15,-110,-10,-110,-100,-55,233.71
2024-10-21T11:59:01.197180089Z,2024-10-21 11:59:01.197013688+00:00,10,2,38,A,A,3,233.84,200,130,166401,11595895,233.65,233.77,1,8,1,1,233.55,233.78,430,150,2,2,233.53,233.8,10,25,1,1,233.45,233.84,15,200,1,1,233.4,233.9,110,27,2,1,233.39,233.94,10,200,1,1,233.31,233.98,110,44,2,3,233.3,234.0,100,154,1,7,233.25,234.13,55,400,2,1,233.24,234.17,1,1,1,1,AAPL,0,0,0,0,200,0,0,0,0,0,0,233.71
2024-10-21T11:59:01.308774903Z,2024-10-21 11:59:01.308608556+00:00,10,2,38,A,A,3,233.83,200,130,166347,11596082,233.65,233.77,1,8,1,1,233.55,233.78,430,150,2,2,233.53,233.8,10,25,1,1,233.45,233.83,15,200,1,1,233.4,233.9,110,27,2,1,233.39,233.94,10,200,1,1,233.31,233.98,110,44,2,3,233.3,234.0,100,154,1,7,233.25,234.13,55,400,2,1,233.24,234.17,1,1,1,1,AAPL,0,0,0,0,200,0,0,0,0,0,0,233.71
2024-10-21T11:59:01.341868800Z,2024-10-21 11:59:01.341702894+00:00,10,2,38,C,B,1,233.55,30,130,165906,11596156,233.65,233.77,1,8,1,1,233.55,233.78,400,150,1,2,233.53,233.8,10,25,1,1,233.45,233.83,15,200,1,1,233.4,233.9,110,27,2,1,233.39,233.94,10,200,1,1,233.31,233.98,110,44,2,3,233.3,234.0,100,154,1,7,233.25,234.13,55,400,2,1,233.24,234.17,1,1,1,1,AAPL,0,0,-30,0,0,0,0,0,0,0,0,233.71
2024-10-21T11:59:01.341924075Z,2024-10-21 11:59:01.341757997+00:00,10,2,38,A,B,2,233.53,27,130,166078,11596157,233.65,233.77,1,8,1,1,233.55,233.78,400,150,1,2,233.53,233.8,37,25,2,1,233.45,233.83,15,200,1,1,233.4,233.9,110,27,2,1,233.39,233.94,10,200,1,1,233.31,233.98,110,44,2,3,233.3,234.0,100,154,1,7,233.25,234.13,55,400,2,1,233.24,234.17,1,1,1,1,AAPL,0,0,0,27,0,0,0,0,0,0,0,233.71
2024-10-21T11:59:01.498895489Z,2024-10-21 11:59:01.498729008+00:00,10,2,38,A,B,1,233.59,200,130,166481,11596259,233.65,233.77,1,8,1,1,233.59,233.78,200,150,1,2,233.53,233.8,37,25,2,1,233.45,233.83,15,200,1,1,233.4,233.9,110,27,2,1,233.39,233.94,10,200,1,1,233.31,233.98,110,44,2,3,233.3,234.0,100,154,1,7,233.25,234.13,55,400,2,1,233.24,234.17,1,1,1,1,AAPL,0,0,200,0,0,0,0,0,0,0,0,233.71
2024-10-21T11:59:01.983861981Z,2024-10-21 11:59:01.983695936+00:00,10,2,38,A,B,1,233.59,200,130,166045,11596500,233.65,233.77,1,8,1,1,233.59,233.78,400,150,2,2,233.53,233.8,37,25,2,1,233.45,233.83,15,200,1,1,233.4,233.9,110,27,2,1,233.39,233.94,10,200,1,1,233.31,233.98,110,44,2,3,233.3,234.0,100,154,1,7,233.25,234.13,55,400,2,1,233.24,234.17,1,1,1,1,AAPL,0,0,200,0,0,0,0,0,0,0,0,233.71
2024-10-21T11:59:02.037559250Z,2024-10-21 11:59:02.037392833+00:00,10,2,38,C,B,1,233.59,200,130,166417,11596603,233.65,233.77,1,8,1,1,233.59,233.78,200,150,1,2,233.53,233.8,37,25,2,1,233.45,233.83,15,200,1,1,233.4,233.9,110,27,2,1,233.39,233.94,10,200,1,1,233.31,233.98,110,44,2,3,233.3,234.0,100,154,1,7,233.25,234.13,55,400,2,1,233.24,234.17,1,1,1,1,AAPL,0,0,-200,0,0,0,0,0,0,0,0,233.71
2024-10-21T11:59:02.037571727Z,2024-10-21 11:59:02.037405330+00:00,10,2,38,A,B,1,233.6,200,130,166397,11596604,233.65,233.77,1,8,1,1,233.6,233.78,200,150,1,2,233.53,233.8,37,25,2,1,233.45,233.83,15,200,1,1,233.4,233.9,110,27,2,1,233.39,233.94,10,200,1,1,233.31,233.98,110,44,2,3,233.3,234.0,100,154,1,7,233.25,234.13,55,400,2,1,233.24,234.17,1,1,1,1,AAPL,0,0,200,0,0,0,0,0,0,0,0,233.71
2024-10-21T11:59:02.587441184Z,2024-10-21 11:59:02.587275146+00:00,10,2,38,A,B,1,233.61,200,130,166038,11596977,233.65,233.77,1,8,1,1,233.61,233.78,200,150,1,2,233.53,233.8,37,25,2,1,233.45,233.83,15,200,1,1,233.4,233.9,110,27,2,1,233.39,233.94,10,200,1,1,233.31,233.98,110,44,2,3,233.3,234.0,100,154,1,7,233.25,234.13,55,400,2,1,233.24,234.17,1,1,1,1,AAPL,0,0,200,0,0,0,0,0,0,0,0,233.71
2024-10-21T11:59:05.075802504Z,2024-10-21 11:59:05.075636621+00:00,10,2,38,C,A,3,233.83,200,130,165883,11598871,233.65,233.77,1,8,1,1,233.61,233.78,200,150,1,2,233.53,233.8,37,25,2,1,233.45,233.9,15,27,1,1,233.4,233.94,110,200,2,1,233.39,233.98,10,44,1,3,233.31,234.0,110,154,2,7,233.3,234.13,100,400,1,1,233.25,234.17,55,1,2,1,233.24,234.41,1,600,1,2,AAPL,0,0,0,0,200,27,200,44,154,400,1,233.71
2024-10-21T11:59:05.075814633Z,2024-10-21 11:59:05.075648273+00:00,10,2,38,A,A,3,233.85,200,130,166360,11598872,233.65,233.77,1,8,1,1,233.61,233.78,200,150,1,2,233.53,233.8,37,25,2,1,233.45,233.85,15,200,1,1,233.4,233.9,110,27,2,1,233.39,233.94,10,200,1,1,233.31,233.98,110,44,2,3,233.3,234.0,100,154,1,7,233.25,234.13,55,400,2,1,233.24,234.17,1,1,1,1,AAPL,0,0,0,0,200,27,200,44,154,400,1,233.71
2024-10-21T11:59:05.130136063Z,2024-10-21 11:59:05.129969945+00:00,10,2,38,A,B,1,233.62,200,130,166118,11598935,233.65,233.77,1,8,1,1,233.62,233.78,200,150,1,2,233.53,233.8,37,25,2,1,233.45,233.85,15,200,1,1,233.4,233.9,110,27,2,1,233.39,233.94,10,200,1,1,233.31,233.98,110,44,2,3,233.3,234.0,100,154,1,7,233.25,234.13,55,400,2,1,233.24,234.17,1,1,1,1,AAPL,0,0,200,0,0,0,0,0,0,0,0,233.71
2024-10-21T11:59:05.149700903Z,2024-10-21 11:59:05.149534519+00:00,10,2,38,C,B,2,233.53,27,130,166384,11599037,233.65,233.77,1,8,1,1,233.62,233.78,200,150,1,2,233.53,233.8,10,25,1,1,233.45,233.85,15,200,1,1,233.4,233.9,110,27,2,1,233.39,233.94,10,200,1,1,233.31,233.98,110,44,2,3,233.3,234.0,100,154,1,7,233.25,234.13,55,400,2,1,233.24,234.17,1,1,1,1,AAPL,0,0,0,-27,0,0,0,0,0,0,0,233.71
2024-10-21T11:59:05.149791992Z,2024-10-21 11:59:05.149624943+00:00,10,2,38,A,B,2,233.54,27,130,167049,11599038,233.65,233.77,1,8,1,1,233.62,233.78,200,150,1,2,233.54,233.8,27,25,1,1,233.53,233.85,10,200,1,1,233.45,233.9,15,27,1,1,233.4,233.94,110,200,2,1,233.39,233.98,10,44,1,3,233.31,234.0,110,154,2,7,233.3,234.13,100,400,1,1,233.25,234.17,55,1,2,1,AAPL,0,0,0,27,10,15,110,10,110,100,55,233.71
2024-10-21T11:59:22.128357765Z,2024-10-21 11:59:22.128191719+00:00,10,2,38,C,B,1,233.62,200,130,166046,11607753,233.65,233.77,1,8,1,1,233.54,233.78,27,150,1,2,233.53,233.8,10,25,1,1,233.45,233.85,15,200,1,1,233.4,233.9,110,27,2,1,233.39,233.94,10,200,1,1,233.31,233.98,110,44,2,3,233.3,234.0,100,154,1,7,233.25,234.13,55,400,2,1,233.24,234.17,1,1,1,1,AAPL,0,0,-200,-27,-10,-15,-110,-10,-110,-100,-55,233.71
2024-10-21T11:59:22.128370118Z,2024-10-21 11:59:22.128203635+00:00,10,2,38,A,B,1,233.6,200,130,166483,11607754,233.65,233.77,1,8,1,1,233.6,233.78,200,150,1,2,233.54,233.8,27,25,1,1,233.53,233.85,10,200,1,1,233.45,233.9,15,27,1,1,233.4,233.94,110,200,2,1,233.39,233.98,10,44,1,3,233.31,234.0,110,154,2,7,233.3,234.13,100,400,1,1,233.25,234.17,55,1,2,1,AAPL,0,0,200,27,10,15,110,10,110,100,55,233.71
2024-10-21T11:59:22.227282918Z,2024-10-21 11:59:22.227115805+00:00,10,2,38,A,B,1,233.61,200,130,167113,11607900,233.65,233.77,1,8,1,1,233.61,233.78,200,150,1,2,233.54,233.8,27,25,1,1,233.53,233.85,10,200,1,1,233.45,233.9,15,27,1,1,233.4,233.94,110,200,2,1,233.39,233.98,10,44,1,3,233.31,234.0,110,154,2,7,233.3,234.13,100,400,1,1,233.25,234.17,55,1,2,1,AAPL,0,0,200,0,0,0,0,0,0,0,0,233.71
2024-10-21T11:59:22.702960044Z,2024-10-21 11:59:22.702793943+00:00,10,2,38,C,B,1,233.61,200,130,166101,11608195,233.65,233.77,1,8,1,1,233.54,233.78,27,150,1,2,233.53,233.8,10,25,1,1,233.45,233.85,15,200,1,1,233.4,233.9,110,27,2,1,233.39,233.94,10,200,1,1,233.31,233.98,110,44,2,3,233.3,234.0,100,154,1,7,233.25,234.13,55,400,2,1,233.24,234.17,1,1,1,1,AAPL,0,0,-200,-27,-10,-15,-110,-10,-110,-100,-55,233.71
2024-10-21T11:59:22.702972049Z,2024-10-21 11:59:22.702805375+00:00,10,2,38,A,B,1,233.59,200,130,166674,11608196,233.65,233.77,1,8,1,1,233.59,233.78,200,150,1,2,233.54,233.8,27,25,1,1,233.53,233.85,10,200,1,1,233.45,233.9,15,27,1,1,233.4,233.94,110,200,2,1,233.39,233.98,10,44,1,3,233.31,234.0,110,154,2,7,233.3,234.13,100,400,1,1,233.25,234.17,55,1,2,1,AAPL,0,0,200,27,10,15,110,10,110,100,55,233.71
2024-10-21T11:59:22.748565679Z,2024-10-21 11:59:22.748399070+00:00,10,2,38,A,A,3,233.84,200,130,166609,11608273,233.65,233.77,1,8,1,1,233.59,233.78,200,150,1,2,233.54,233.8,27,25,1,1,233.53,233.84,10,200,1,1,233.45,233.9,15,27,1,1,233.4,233.94,110,200,2,1,233.39,233.98,10,44,1,3,233.31,234.0,110,154,2,7,233.3,234.13,100,400,1,1,233.25,234.17,55,1,2,1,AAPL,0,0,0,0,200,0,0,0,0,0,0,233.71
2024-10-21T11:59:24.992377577Z,2024-10-21 11:59:24.992210687+00:00,10,2,38,A,A,3,233.84,200,130,166890,11609787,233.65,233.77,1,8,1,1,233.59,233.78,200,150,1,2,233.54,233.8,27,25,1,1,233.53,233.84,10,400,1,2,233.45,233.9,15,27,1,1,233.4,233.94,110,200,2,1,233.39,233.98,10,44,1,3,233.31,234.0,110,154,2,7,233.3,234.13,100,400,1,1,233.25,234.17,55,1,2,1,AAPL,0,0,0,0,200,0,0,0,0,0,0,233.71
2024-10-21T11:59:29.283442922Z,2024-10-21 11:59:29.283276904+00:00,10,2,38,C,A,3,233.84,200,130,166018,11611911,233.65,233.77,1,8,1,1,233.59,233.78,200,150,1,2,233.54,233.8,27,25,1,1,233.53,233.84,10,200,1,1,233.45,233.9,15,27,1,1,233.4,233.94,110,200,2,1,233.39,233.98,10,44,1,3,233.31,234.0,110,154,2,7,233.3,234.13,100,400,1,1,233.25,234.17,55,1,2,1,AAPL,0,0,0,0,-200,0,0,0,0,0,0,233.71
2024-10-21T11:59:29.283453171Z,2024-10-21 11:59:29.283287223+00:00,10,2,38,C,A,3,233.84,200,130,165948,11611912,233.65,233.77,1,8,1,1,233.59,233.78,200,150,1,2,233.54,233.8,27,25,1,1,233.53,233.9,10,27,1,1,233.45,233.94,15,200,1,1,233.4,233.98,110,44,2,3,233.39,234.0,10,154,1,7,233.31,234.13,110,400,2,1,233.3,234.17,100,1,1,1,233.25,234.41,55,600,2,2,AAPL,0,0,0,0,200,27,200,44,154,400,1,233.71
2024-10-21T11:59:29.283464537Z,2024-10-21 11:59:29.283298495+00:00,10,2,38,A,A,3,233.89,400,130,166042,11611913,233.65,233.77,1,8,1,1,233.59,233.78,200,150,1,2,233.54,233.8,27,25,1,1,233.53,233.89,10,400,1,1,233.45,233.9,15,27,1,1,233.4,233.94,110,200,2,1,233.39,233.98,10,44,1,3,233.31,234.0,110,154,2,7,233.3,234.13,100,400,1,1,233.25,234.17,55,1,2,1,AAPL,0,0,0,0,400,27,200,44,154,400,1,233.71
2024-10-21T11:59:29.341972985Z,2024-10-21 11:59:29.341806485+00:00,10,2,38,A,A,3,233.88,400,130,166500,11611985,233.65,233.77,1,8,1,1,233.59,233.78,200,150,1,2,233.54,233.8,27,25,1,1,233.53,233.88,10,400,1,1,233.45,233.9,15,27,1,1,233.4,233.94,110,200,2,1,233.39,233.98,10,44,1,3,233.31,234.0,110,154,2,7,233.3,234.13,100,400,1,1,233.25,234.17,55,1,2,1,AAPL,0,0,0,0,400,0,0,0,0,0,0,233.71
2024-10-21T11:59:29.368272089Z,2024-10-21 11:59:29.368105783+00:00,10,2,38,A,A,3,233.83,400,130,166306,11612038,233.65,233.77,1,8,1,1,233.59,233.78,200,150,1,2,233.54,233.8,27,25,1,1,233.53,233.83,10,400,1,1,233.45,233.9,15,27,1,1,233.4,233.94,110,200,2,1,233.39,233.98,10,44,1,3,233.31,234.0,110,154,2,7,233.3,234.13,100,400,1,1,233.25,234.17,55,1,2,1,AAPL,0,0,0,0,400,0,0,0,0,0,0,233.71
2024-10-21T11:59:29.441719865Z,2024-10-21 11:59:29.441553398+00:00,10,2,38,A,A,4,233.89,28,130,166467,11612272,233.65,233.77,1,8,1,1,233.59,233.78,200,150,1,2,233.54,233.8,27,25,1,1,233.53,233.83,10,400,1,1,233.45,233.89,15,28,1,1,233.4,233.9,110,27,2,1,233.39,233.94,10,200,1,1,233.31,233.98,110,44,2,3,233.3,234.0,100,154,1,7,233.25,234.13,55,400,2,1,AAPL,0,0,0,0,0,28,27,200,44,154,400,233.71
2024-10-21T11:59:29.441815353Z,2024-10-21 11:59:29.441648558+00:00,10,2,38,C,A,5,233.9,27,130,166795,11612275,233.65,233.77,1,8,1,1,233.59,233.78,200,150,1,2,233.54,233.8,27,25,1,1,233.53,233.83,10,400,1,1,233.45,233.89,15,28,1,1,233.4,233.94,110,200,2,1,233.39,233.98,10,44,1,3,233.31,234.0,110,154,2,7,233.3,234.13,100,400,1,1,233.25,234.17,55,1,2,1,AAPL,0,0,0,0,0,0,27,200,44,154,400,233.71
2024-10-21T11:59:29.504458424Z,2024-10-21 11:59:29.504292026+00:00,10,2,38,A,B,1,233.59,200,130,166398,11612308,233.65,233.77,1,8,1,1,233.59,233.78,400,150,2,2,233.54,233.8,27,25,1,1,233.53,233.83,10,400,1,1,233.45,233.89,15,28,1,1,233.4,233.94,110,200,2,1,233.39,233.98,10,44,1,3,233.31,234.0,110,154,2,7,233.3,234.13,100,400,1,1,233.25,234.17,55,1,2,1,AAPL,0,0,200,0,0,0,0,0,0,0,0,233.71
2024-10-21T11:59:29.550493679Z,2024-10-21 11:59:29.550327634+00:00,10,2,38,C,B,1,233.59,200,130,166045,11612321,233.65,233.77,1,8,1,1,233.59,233.78,200,150,1,2,233.54,233.8,27,25,1,1,233.53,233.83,10,400,1,1,233.45,233.89,15,28,1,1,233.4,233.94,110,200,2,1,233.39,233.98,10,44,1,3,233.31,234.0,110,154,2,7,233.3,234.13,100,400,1,1,233.25,234.17,55,1,2,1,AAPL,0,0,-200,0,0,0,0,0,0,0,0,233.71
2024-10-21T11:59:29.550507093Z,2024-10-21 11:59:29.550340581+00:00,10,2,38,A,B,1,233.6,200,130,166512,11612322,233.65,233.77,1,8,1,1,233.6,233.78,200,150,1,2,233.54,233.8,27,25,1,1,233.53,233.83,10,400,1,1,233.45,233.89,15,28,1,1,233.4,233.94,110,200,2,1,233.39,233.98,10,44,1,3,233.31,234.0,110,154,2,7,233.3,234.13,100,400,1,1,233.25,234.17,55,1,2,1,AAPL,0,0,200,0,0,0,0,0,0,0,0,233.71
2024-10-21T11:59:30.102880517Z,2024-10-21 11:59:30.102712999+00:00,10,2,38,T,B,0,233.77,8,130,167518,11612948,233.65,233.77,1,8,1,1,233.6,233.78,200,150,1,2,233.54,233.8,27,25,1,1,233.53,233.83,10,400,1,1,233.45,233.89,15,28,1,1,233.4,233.94,110,200,2,1,233.39,233.98,10,44,1,3,233.31,234.0,110,154,2,7,233.3,234.13,100,400,1,1,233.25,234.17,55,1,2,1,AAPL,0,0,0,0,0,0,0,0,0,0,0,233.71
2024-10-21T11:59:30.102880517Z,2024-10-21 11:59:30.102712999+00:00,10,2,38,C,A,0,233.77,8,130,167518,11612948,233.65,233.78,1,150,1,2,233.6,233.8,200,25,1,1,233.54,233.83,27,400,1,1,233.53,233.89,10,28,1,1,233.45,233.94,15,200,1,1,233.4,233.98,110,44,2,3,233.39,234.0,10,154,1,7,233.31,234.13,110,400,2,1,233.3,234.17,100,1,1,1,233.25,234.41,55,600,2,2,AAPL,8,8,150,25,400,28,200,44,154,400,1,233.715
2024-10-21T11:59:30.102902312Z,2024-10-21 11:59:30.102735583+00:00,10,2,38,A,B,0,233.68,100,130,166729,11612949,233.68,233.78,100,150,1,2,233.65,233.8,1,25,1,1,233.6,233.83,200,400,1,1,233.54,233.89,27,28,1,1,233.53,233.94,10,200,1,1,233.45,233.98,15,44,1,3,233.4,234.0,110,154,2,7,233.39,234.13,10,400,1,1,233.31,234.17,110,1,2,1,233.3,234.41,100,600,1,2,AAPL,100,100,1,200,27,10,15,110,10,110,100,233.73000000000002
2024-10-21T11:59:30.102913346Z,2024-10-21 11:59:30.102746947+00:00,10,2,38,A,B,0,233.68,100,130,166399,11612950,233.68,233.78,200,150,2,2,233.65,233.8,1,25,1,1,233.6,233.83,200,400,1,1,233.54,233.89,27,28,1,1,233.53,233.94,10,200,1,1,233.45,233.98,15,44,1,3,233.4,234.0,110,154,2,7,233.39,234.13,10,400,1,1,233.31,234.17,110,1,2,1,233.3,234.41,100,600,1,2,AAPL,100,100,0,0,0,0,0,0,0,0,0,233.73000000000002
2024-10-21T11:59:30.102919154Z,2024-10-21 11:59:30.102753002+00:00,10,2,38,A,B,0,233.71,23,130,166152,11612951,233.71,233.78,23,150,1,2,233.68,233.8,200,25,2,1,233.65,233.83,1,400,1,1,233.6,233.89,200,28,1,1,233.54,233.94,27,200,1,1,233.53,233.98,10,44,1,3,233.45,234.0,15,154,1,7,233.4,234.13,110,400,2,1,233.39,234.17,10,1,1,1,233.31,234.41,110,600,2,2,AAPL,23,23,200,1,200,27,10,15,110,10,110,233.745
2024-10-21T11:59:30.102932550Z,2024-10-21 11:59:30.102766235+00:00,10,2,38,A,B,2,233.67,23,130,166315,11612953,233.71,233.78,23,150,1,2,233.68,233.8,200,25,2,1,233.67,233.83,23,400,1,1,233.65,233.89,1,28,1,1,233.6,233.94,200,200,1,1,233.54,233.98,27,44,1,3,233.53,234.0,10,154,1,7,233.45,234.13,15,400,1,1,233.4,234.17,110,1,2,1,233.39,234.41,10,600,1,2,AAPL,0,0,0,23,1,200,27,10,15,110,10,233.745
2024-10-21T11:59:30.102947096Z,2024-10-21 11:59:30.102781049+00:00,10,2,38,C,B,1,233.68,100,130,166047,11612954,233.71,233.78,23,150,1,2,233.68,233.8,100,25,1,1,233.67,233.83,23,400,1,1,233.65,233.89,1,28,1,1,233.6,233.94,200,200,1,1,233.54,233.98,27,44,1,3,233.53,234.0,10,154,1,7,233.45,234.13,15,400,1,1,233.4,234.17,110,1,2,1,233.39,234.41,10,600,1,2,AAPL,0,0,-100,0,0,0,0,0,0,0,0,233.745
2024-10-21T11:59:30.102950618Z,2024-10-21 11:59:30.102784354+00:00,10,2,38,C,B,1,233.68,100,130,166264,11612955,233.71,233.78,23,150,1,2,233.67,233.8,23,25,1,1,233.65,233.83,1,400,1,1,233.6,233.89,200,28,1,1,233.54,233.94,27,200,1,1,233.53,233.98,10,44,1,3,233.45,234.0,15,154,1,7,233.4,234.13,110,400,2,1,233.39,234.17,10,1,1,1,233.31,234.41,110,600,2,2,AAPL,0,0,-100,-23,-1,-200,-27,-10,-15,-110,-10,233.745
2024-10-21T11:59:30.167107134Z,2024-10-21 11:59:30.166940785+00:00,10,2,38,C,A,2,233.83,200,130,166349,11613018,233.71,233.78,23,150,1,2,233.67,233.8,23,25,1,1,233.65,233.83,1,200,1,1,233.6,233.89,200,28,1,1,233.54,233.94,27,200,1,1,233.53,233.98,10,44,1,3,233.45,234.0,15,154,1,7,233.4,234.13,110,400,2,1,233.39,234.17,10,1,1,1,233.31,234.41,110,600,2,2,AAPL,0,0,0,-200,0,0,0,0,0,0,0,233.745
2024-10-21T11:59:30.203930522Z,2024-10-21 11:59:30.203764599+00:00,10,2,38,C,B,1,233.67,23,130,165923,11613033,233.71,233.78,23,150,1,2,233.65,233.8,1,25,1,1,233.6,233.83,200,200,1,1,233.54,233.89,27,28,1,1,233.53,233.94,10,200,1,1,233.45,233.98,15,44,1,3,233.4,234.0,110,154,2,7,233.39,234.13,10,400,1,1,233.31,234.17,110,1,2,1,233.3,234.41,100,600,1,2,AAPL,0,0,-23,-1,-200,-27,-10,-15,-110,-10,-110,233.745
2024-10-21T11:59:30.353929412Z,2024-10-21 11:59:30.353763576+00:00,10,2,38,C,B,0,233.71,23,130,165836,11613099,233.65,233.78,1,150,1,2,233.6,233.8,200,25,1,1,233.54,233.83,27,200,1,1,233.53,233.89,10,28,1,1,233.45,233.94,15,200,1,1,233.4,233.98,110,44,2,3,233.39,234.0,10,154,1,7,233.31,234.13,110,400,2,1,233.3,234.17,100,1,1,1,233.25,234.41,55,600,2,2,AAPL,-23,-23,-1,-200,-27,-10,-15,-110,-10,-110,-100,233.715
2024-10-21T11:59:33.215114965Z,2024-10-21 11:59:33.214948750+00:00,10,2,38,A,B,1,233.6,200,130,166215,11614193,233.65,233.78,1,150,1,2,233.6,233.8,400,25,2,1,233.54,233.83,27,200,1,1,233.53,233.89,10,28,1,1,233.45,233.94,15,200,1,1,233.4,233.98,110,44,2,3,233.39,234.0,10,154,1,7,233.31,234.13,110,400,2,1,233.3,234.17,100,1,1,1,233.25,234.41,55,600,2,2,AAPL,0,0,200,0,0,0,0,0,0,0,0,233.715
2024-10-21T11:59:33.268762813Z,2024-10-21 11:59:33.268596579+00:00,10,2,38,C,B,1,233.6,200,130,166234,11614270,233.65,233.78,1,150,1,2,233.6,233.8,200,25,1,1,233.54,233.83,27,200,1,1,233.53,233.89,10,28,1,1,233.45,233.94,15,200,1,1,233.4,233.98,110,44,2,3,233.39,234.0,10,154,1,7,233.31,234.13,110,400,2,1,233.3,234.17,100,1,1,1,233.25,234.41,55,600,2,2,AAPL,0,0,-200,0,0,0,0,0,0,0,0,233.715
2024-10-21T11:59:40.586248814Z,2024-10-21 11:59:40.586082406+00:00,10,2,38,A,B,0,233.77,1,130,166408,11618353,233.77,233.78,1,150,1,2,233.65,233.8,1,25,1,1,233.6,233.83,200,200,1,1,233.54,233.89,27,28,1,1,233.53,233.94,10,200,1,1,233.45,233.98,15,44,1,3,233.4,234.0,110,154,2,7,233.39,234.13,10,400,1,1,233.31,234.17,110,1,2,1,233.3,234.41,100,600,1,2,AAPL,1,1,1,200,27,10,15,110,10,110,100,233.775
2024-10-21T11:59:40.711629689Z,2024-10-21 11:59:40.711462280+00:00,10,2,38,T,A,0,233.77,1,130,167409,11618393,233.77,233.78,1,150,1,2,233.65,233.8,1,25,1,1,233.6,233.83,200,200,1,1,233.54,233.89,27,28,1,1,233.53,233.94,10,200,1,1,233.45,233.98,15,44,1,3,233.4,234.0,110,154,2,7,233.39,234.13,10,400,1,1,233.31,234.17,110,1,2,1,233.3,234.41,100,600,1,2,AAPL,0,0,0,0,0,0,0,0,0,0,0,233.775
2024-10-21T11:59:40.711629689Z,2024-10-21 11:59:40.711462280+00:00,10,2,38,C,B,0,233.77,1,130,167409,11618393,233.65,233.78,1,150,1,2,233.6,233.8,200,25,1,1,233.54,233.83,27,200,1,1,233.53,233.89,10,28,1,1,233.45,233.94,15,200,1,1,233.4,233.98,110,44,2,3,233.39,234.0,10,154,1,7,233.31,234.13,110,400,2,1,233.3,234.17,100,1,1,1,233.25,234.41,55,600,2,2,AAPL,-1,-1,-1,-200,-27,-10,-15,-110,-10,-110,-100,233.715
2024-10-21T11:59:44.915922829Z,2024-10-21 11:59:44.915756078+00:00,10,2,38,A,B,1,233.61,200,130,166751,11621712,233.65,233.78,1,150,1,2,233.61,233.8,200,25,1,1,233.54,233.83,27,200,1,1,233.53,233.89,10,28,1,1,233.45,233.94,15,200,1,1,233.4,233.98,110,44,2,3,233.39,234.0,10,154,1,7,233.31,234.13,110,400,2,1,233.3,234.17,100,1,1,1,233.25,234.41,55,600,2,2,AAPL,0,0,200,0,0,0,0,0,0,0,0,233.715
2024-10-21T11:59:56.140500513Z,2024-10-21 11:59:56.140334654+00:00,10,2,38,C,B,1,233.61,200,130,165859,11629360,233.65,233.78,1,150,1,2,233.54,233.8,27,25,1,1,233.53,233.83,10,200,1,1,233.45,233.89,15,28,1,1,233.4,233.94,110,200,2,1,233.39,233.98,10,44,1,3,233.31,234.0,110,154,2,7,233.3,234.13,100,400,1,1,233.25,234.17,55,1,2,1,233.24,234.41,1,600,1,2,AAPL,0,0,-200,-27,-10,-15,-110,-10,-110,-100,-55,233.715
2024-10-21T11:59:56.140515113Z,2024-10-21 11:59:56.140348516+00:00,10,2,38,A,B,1,233.59,200,130,166597,11629361,233.65,233.78,1,150,1,2,233.59,233.8,200,25,1,1,233.54,233.83,27,200,1,1,233.53,233.89,10,28,1,1,233.45,233.94,15,200,1,1,233.4,233.98,110,44,2,3,233.39,234.0,10,154,1,7,233.31,234.13,110,400,2,1,233.3,234.17,100,1,1,1,233.25,234.41,55,600,2,2,AAPL,0,0,200,27,10,15,110,10,110,100,55,233.715
2024-10-21T11:59:56.303991491Z,2024-10-21 11:59:56.303825659+00:00,10,2,38,C,A,2,233.83,200,130,165832,11629887,233.65,233.78,1,150,1,2,233.59,233.8,200,25,1,1,233.54,233.89,27,28,1,1,233.53,233.94,10,200,1,1,233.45,233.98,15,44,1,3,233.4,234.0,110,154,2,7,233.39,234.13,10,400,1,1,233.31,234.17,110,1,2,1,233.3,234.41,100,600,1,2,233.25,234.43,55,5,2,1,AAPL,0,0,0,200,28,200,44,154,400,1,600,233.715
2024-10-21T11:59:56.304004867Z,2024-10-21 11:59:56.303838548+00:00,10,2,38,A,A,2,233.85,200,130,166319,11629888,233.65,233.78,1,150,1,2,233.59,233.8,200,25,1,1,233.54,233.85,27,200,1,1,233.53,233.89,10,28,1,1,233.45,233.94,15,200,1,1,233.4,233.98,110,44,2,3,233.39,234.0,10,154,1,7,233.31,234.13,110,400,2,1,233.3,234.17,100,1,1,1,233.25,234.41,55,600,2,2,AAPL,0,0,0,200,28,200,44,154,400,1,600,233.715
2024-10-21T11:59:56.366844504Z,2024-10-21 11:59:56.366678187+00:00,10,2,38,A,A,2,233.84,200,130,166317,11630234,233.65,233.78,1,150,1,2,233.59,233.8,200,25,1,1,233.54,233.84,27,200,1,1,233.53,233.89,10,28,1,1,233.45,233.94,15,200,1,1,233.4,233.98,110,44,2,3,233.39,234.0,10,154,1,7,233.31,234.13,110,400,2,1,233.3,234.17,100,1,1,1,233.25,234.41,55,600,2,2,AAPL,0,0,0,200,0,0,0,0,0,0,0,233.715
2024-10-21T11:59:56.374489545Z,2024-10-21 11:59:56.374323675+00:00,10,2,38,C,A,3,233.89,28,130,165870,11630290,233.65,233.78,1,150,1,2,233.59,233.8,200,25,1,1,233.54,233.84,27,200,1,1,233.53,233.94,10,200,1,1,233.45,233.98,15,44,1,3,233.4,234.0,110,154,2,7,233.39,234.13,10,400,1,1,233.31,234.17,110,1,2,1,233.3,234.41,100,600,1,2,233.25,234.43,55,5,2,1,AAPL,0,0,0,0,28,200,44,154,400,1,600,233.715
2024-10-21T11:59:56.374545521Z,2024-10-21 11:59:56.374379339+00:00,10,2,38,A,A,3,233.92,27,130,166182,11630291,233.65,233.78,1,150,1,2,233.59,233.8,200,25,1,1,233.54,233.84,27,200,1,1,233.53,233.92,10,27,1,1,233.45,233.94,15,200,1,1,233.4,233.98,110,44,2,3,233.39,234.0,10,154,1,7,233.31,234.13,110,400,2,1,233.3,234.17,100,1,1,1,233.25,234.41,55,600,2,2,AAPL,0,0,0,0,27,200,44,154,400,1,600,233.715
2024-10-21T11:59:57.076425198Z,2024-10-21 11:59:57.076259289+00:00,10,2,38,C,A,3,233.92,27,130,165909,11631174,233.65,233.78,1,150,1,2,233.59,233.8,200,25,1,1,233.54,233.84,27,200,1,1,233.53,233.94,10,200,1,1,233.45,233.98,15,44,1,3,233.4,234.0,110,154,2,7,233.39,234.13,10,400,1,1,233.31,234.17,110,1,2,1,233.3,234.41,100,600,1,2,233.25,234.43,55,5,2,1,AAPL,0,0,0,0,27,200,44,154,400,1,600,233.715
2024-10-21T11:59:57.076481289Z,2024-10-21 11:59:57.076314960+00:00,10,2,38,A,A,3,233.91,26,130,166329,11631175,233.65,233.78,1,150,1,2,233.59,233.8,200,25,1,1,233.54,233.84,27,200,1,1,233.53,233.91,10,26,1,1,233.45,233.94,15,200,1,1,233.4,233.98,110,44,2,3,233.39,234.0,10,154,1,7,233.31,234.13,110,400,2,1,233.3,234.17,100,1,1,1,233.25,234.41,55,600,2,2,AAPL,0,0,0,0,26,200,44,154,400,1,600,233.715
2024-10-21T11:59:57.121963263Z,2024-10-21 11:59:57.121796841+00:00,10,2,38,A,B,1,233.61,200,130,166422,11631246,233.65,233.78,1,150,1,2,233.61,233.8,200,25,1,1,233.54,233.84,27,200,1,1,233.53,233.91,10,26,1,1,233.45,233.94,15,200,1,1,233.4,233.98,110,44,2,3,233.39,234.0,10,154,1,7,233.31,234.13,110,400,2,1,233.3,234.17,100,1,1,1,233.25,234.41,55,600,2,2,AAPL,0,0,200,0,0,0,0,0,0,0,0,233.715
2024-10-21T11:59:58.069437531Z,2024-10-21 11:59:58.069271668+00:00,10,2,38,C,B,1,233.61,200,130,165863,11632068,233.65,233.78,1,150,1,2,233.54,233.8,27,25,1,1,233.53,233.84,10,200,1,1,233.45,233.91,15,26,1,1,233.4,233.94,110,200,2,1,233.39,233.98,10,44,1,3,233.31,234.0,110,154,2,7,233.3,234.13,100,400,1,1,233.25,234.17,55,1,2,1,233.24,234.41,1,600,1,2,AAPL,0,0,-200,-27,-10,-15,-110,-10,-110,-100,-55,233.715
2024-10-21T11:59:58.069450306Z,2024-10-21 11:59:58.069284093+00:00,10,2,38,A,B,1,233.59,200,130,166213,11632069,233.65,233.78,1,150,1,2,233.59,233.8,200,25,1,1,233.54,233.84,27,200,1,1,233.53,233.91,10,26,1,1,233.45,233.94,15,200,1,1,233.4,233.98,110,44,2,3,233.39,234.0,10,154,1,7,233.31,234.13,110,400,2,1,233.3,234.17,100,1,1,1,233.25,234.41,55,600,2,2,AAPL,0,0,200,27,10,15,110,10,110,100,55,233.715
2024-10-21T12:00:01.682174453Z,2024-10-21 12:00:01.682008523+00:00,10,2,38,C,A,3,233.91,26,130,165930,11639355,233.65,233.78,1,150,1,2,233.59,233.8,200,25,1,1,233.54,233.84,27,200,1,1,233.53,233.94,10,200,1,1,233.45,233.98,15,44,1,3,233.4,234.0,110,154,2,7,233.39,234.13,10,400,1,1,233.31,234.17,110,1,2,1,233.3,234.41,100,600,1,2,233.25,234.43,55,5,2,1,AAPL,0,0,0,0,26,200,44,154,400,1,600,233.715
2024-10-21T12:00:01.682225908Z,2024-10-21 12:00:01.682052966+00:00,10,2,38,A,A,3,233.9,26,130,172942,11639356,233.65,233.78,1,150,1,2,233.59,233.8,200,25,1,1,233.54,233.84,27,200,1,1,233.53,233.9,10,26,1,1,233.45,233.94,15,200,1,1,233.4,233.98,110,44,2,3,233.39,234.0,10,154,1,7,233.31,234.13,110,400,2,1,233.3,234.17,100,1,1,1,233.25,234.41,55,600,2,2,AAPL,0,0,0,0,26,200,44,154,400,1,600,233.715
2024-10-21T12:00:01.884805082Z,2024-10-21 12:00:01.884638806+00:00,10,2,38,A,B,1,233.61,200,130,166276,11639901,233.65,233.78,1,150,1,2,233.61,233.8,200,25,1,1,233.54,233.84,27,200,1,1,233.53,233.9,10,26,1,1,233.45,233.94,15,200,1,1,233.4,233.98,110,44,2,3,233.39,234.0,10,154,1,7,233.31,234.13,110,400,2,1,233.3,234.17,100,1,1,1,233.25,234.41,55,600,2,2,AAPL,0,0,200,0,0,0,0,0,0,0,0,233.715
2024-10-21T12:00:02.064451153Z,2024-10-21 12:00:02.064285089+00:00,10,2,38,C,B,1,233.61,200,130,166064,11640243,233.65,233.78,1,150,1,2,233.54,233.8,27,25,1,1,233.53,233.84,10,200,1,1,233.45,233.9,15,26,1,1,233.4,233.94,110,200,2,1,233.39,233.98,10,44,1,3,233.31,234.0,110,154,2,7,233.3,234.13,100,400,1,1,233.25,234.17,55,1,2,1,233.24,234.41,1,600,1,2,AAPL,0,0,-200,-27,-10,-15,-110,-10,-110,-100,-55,233.715
2024-10-21T12:00:02.160522798Z,2024-10-21 12:00:02.160356498+00:00,10,2,38,C,B,1,233.54,27,130,166300,11640336,233.65,233.78,1,150,1,2,233.53,233.8,10,25,1,1,233.45,233.84,15,200,1,1,233.4,233.9,110,26,2,1,233.39,233.94,10,200,1,1,233.31,233.98,110,44,2,3,233.3,234.0,100,154,1,7,233.25,234.13,55,400,2,1,233.24,234.17,1,1,1,1,233.23,234.41,50,600,1,2,AAPL,0,0,-27,-10,-15,-110,-10,-110,-100,-55,-1,233.715
2024-10-21T12:00:02.160610908Z,2024-10-21 12:00:02.160444679+00:00,10,2,38,A,B,2,233.49,26,130,166229,11640337,233.65,233.78,1,150,1,2,233.53,233.8,10,25,1,1,233.49,233.84,26,200,1,1,233.45,233.9,15,26,1,1,233.4,233.94,110,200,2,1,233.39,233.98,10,44,1,3,233.31,234.0,110,154,2,7,233.3,234.13,100,400,1,1,233.25,234.17,55,1,2,1,233.24,234.41,1,600,1,2,AAPL,0,0,0,26,15,110,10,110,100,55,1,233.715
2024-10-21T12:00:02.178913898Z,2024-10-21 12:00:02.178747608+00:00,10,2,38,A,B,3,233.48,400,130,166290,11640354,233.65,233.78,1,150,1,2,233.53,233.8,10,25,1,1,233.49,233.84,26,200,1,1,233.48,233.9,400,26,1,1,233.45,233.94,15,200,1,1,233.4,233.98,110,44,2,3,233.39,234.0,10,154,1,7,233.31,234.13,110,400,2,1,233.3,234.17,100,1,1,1,233.25,234.41,55,600,2,2,AAPL,0,0,0,0,400,15,110,10,110,100,55,233.715
2024-10-21T12:00:02.220042789Z,2024-10-21 12:00:02.219875510+00:00,10,2,38,A,B,1,233.56,200,130,167279,11640428,233.65,233.78,1,150,1,2,233.56,233.8,200,25,1,1,233.53,233.84,10,200,1,1,233.49,233.9,26,26,1,1,233.45,233.94,15,200,1,1,233.4,233.98,110,44,2,3,233.39,234.0,10,154,1,7,233.31,234.13,110,400,2,1,233.3,234.17,100,1,1,1,233.25,234.41,55,600,2,2,AAPL,0,0,200,10,26,0,0,0,0,0,0,233.715
2024-10-21T12:00:02.605637435Z,2024-10-21 12:00:02.605471012+00:00,10,2,38,A,A,2,233.84,200,130,166423,11641451,233.65,233.78,1,150,1,2,233.56,233.8,200,25,1,1,233.53,233.84,10,400,1,2,233.49,233.9,26,26,1,1,233.45,233.94,15,200,1,1,233.4,233.98,110,44,2,3,233.39,234.0,10,154,1,7,233.31,234.13,110,400,2,1,233.3,234.17,100,1,1,1,233.25,234.41,55,600,2,2,AAPL,0,0,0,200,0,0,0,0,0,0,0,233.715
2024-10-21T12:00:02.834204113Z,2024-10-21 12:00:02.834037742+00:00,10,2,38,A,B,1,233.56,200,130,166371,11642029,233.65,233.78,1,150,1,2,233.56,233.8,400,25,2,1,233.53,233.84,10,400,1,2,233.49,233.9,26,26,1,1,233.45,233.94,15,200,1,1,233.4,233.98,110,44,2,3,233.39,234.0,10,154,1,7,233.31,234.13,110,400,2,1,233.3,234.17,100,1,1,1,233.25,234.41,55,600,2,2,AAPL,0,0,200,0,0,0,0,0,0,0,0,233.715
2024-10-21T12:00:03.047805689Z,2024-10-21 12:00:03.047639596+00:00,10,2,38,C,B,1,233.56,200,130,166093,11642521,233.65,233.78,1,150,1,2,233.56,233.8,200,25,1,1,233.53,233.84,10,400,1,2,233.49,233.9,26,26,1,1,233.45,233.94,15,200,1,1,233.4,233.98,110,44,2,3,233.39,234.0,10,154,1,7,233.31,234.13,110,400,2,1,233.3,234.17,100,1,1,1,233.25,234.41,55,600,2,2,AAPL,0,0,-200,0,0,0,0,0,0,0,0,233.715
2024-10-21T12:00:03.047816248Z,2024-10-21 12:00:03.047650452+00:00,10,2,38,C,B,1,233.56,200,130,165796,11642522,233.65,233.78,1,150,1,2,233.53,233.8,10,25,1,1,233.49,233.84,26,400,1,2,233.45,233.9,15,26,1,1,233.4,233.94,110,200,2,1,233.39,233.98,10,44,1,3,233.31,234.0,110,154,2,7,233.3,234.13,100,400,1,1,233.25,234.17,55,1,2,1,233.24,234.41,1,600,1,2,AAPL,0,0,-200,-10,-26,-15,-110,-10,-110,-100,-55,233.715
2024-10-21T12:00:03.057632178Z,2024-10-21 12:00:03.057465668+00:00,10,2,38,A,B,1,233.55,200,130,166510,11642541,233.65,233.78,1,150,1,2,233.55,233.8,200,25,1,1,233.53,233.84,10,400,1,2,233.49,233.9,26,26,1,1,233.45,233.94,15,200,1,1,233.4,233.98,110,44,2,3,233.39,234.0,10,154,1,7,233.31,234.13,110,400,2,1,233.3,234.17,100,1,1,1,233.25,234.41,55,600,2,2,AAPL,0,0,200,10,26,15,110,10,110,100,55,233.715
2024-10-21T12:00:03.060919018Z,2024-10-21 12:00:03.060752951+00:00,10,2,38,C,B,1,233.55,200,130,166067,11642554,233.65,233.78,1,150,1,2,233.53,233.8,10,25,1,1,233.49,233.84,26,400,1,2,233.45,233.9,15,26,1,1,233.4,233.94,110,200,2,1,233.39,233.98,10,44,1,3,233.31,234.0,110,154,2,7,233.3,234.13,100,400,1,1,233.25,234.17,55,1,2,1,233.24,234.41,1,600,1,2,AAPL,0,0,-200,-10,-26,-15,-110,-10,-110,-100,-55,233.715
2024-10-21T12:00:03.163064101Z,2024-10-21 12:00:03.162897564+00:00,10,2,38,A,B,1,233.55,400,130,166537,11642717,233.65,233.78,1,150,1,2,233.55,233.8,400,25,1,1,233.53,233.84,10,400,1,2,233.49,233.9,26,26,1,1,233.45,233.94,15,200,1,1,233.4,233.98,110,44,2,3,233.39,234.0,10,154,1,7,233.31,234.13,110,400,2,1,233.3,234.17,100,1,1,1,233.25,234.41,55,600,2,2,AAPL,0,0,400,10,26,15,110,10,110,100,55,233.715
2024-10-21T12:00:03.902220253Z,2024-10-21 12:00:03.902053598+00:00,10,2,38,A,B,1,233.56,400,130,166655,11643778,233.65,233.78,1,150,1,2,233.56,233.8,400,25,1,1,233.53,233.84,10,400,1,2,233.49,233.9,26,26,1,1,233.45,233.94,15,200,1,1,233.4,233.98,110,44,2,3,233.39,234.0,10,154,1,7,233.31,234.13,110,400,2,1,233.3,234.17,100,1,1,1,233.25,234.41,55,600,2,2,AAPL,0,0,400,0,0,0,0,0,0,0,0,233.715
2024-10-21T12:00:04.046984715Z,2024-10-21 12:00:04.046818528+00:00,10,2,38,C,B,1,233.56,400,130,166187,11644129,233.65,233.78,1,150,1,2,233.53,233.8,10,25,1,1,233.49,233.84,26,400,1,2,233.45,233.9,15,26,1,1,233.4,233.94,110,200,2,1,233.39,233.98,10,44,1,3,233.31,234.0,110,154,2,7,233.3,234.13,100,400,1,1,233.25,234.17,55,1,2,1,233.24,234.41,1,600,1,2,AAPL,0,0,-400,-10,-26,-15,-110,-10,-110,-100,-55,233.715
2024-10-21T12:00:04.147446688Z,2024-10-21 12:00:04.147280360+00:00,10,2,38,A,B,1,233.56,400,130,166328,11644350,233.65,233.78,1,150,1,2,233.56,233.8,400,25,1,1,233.53,233.84,10,400,1,2,233.49,233.9,26,26,1,1,233.45,233.94,15,200,1,1,233.4,233.98,110,44,2,3,233.39,234.0,10,154,1,7,233.31,234.13,110,400,2,1,233.3,234.17,100,1,1,1,233.25,234.41,55,600,2,2,AAPL,0,0,400,10,26,15,110,10,110,100,55,233.715
2024-10-21T12:00:06.012274881Z,2024-10-21 12:00:06.012108650+00:00,10,2,38,C,B,1,233.56,400,130,166231,11647927,233.65,233.78,1,150,1,2,233.53,233.8,10,25,1,1,233.49,233.84,26,400,1,2,233.45,233.9,15,26,1,1,233.4,233.94,110,200,2,1,233.39,233.98,10,44,1,3,233.31,234.0,110,154,2,7,233.3,234.13,100,400,1,1,233.25,234.17,55,1,2,1,233.24,234.41,1,600,1,2,AAPL,0,0,-400,-10,-26,-15,-110,-10,-110,-100,-55,233.715
2024-10-21T12:00:06.012288800Z,2024-10-21 12:00:06.012122140+00:00,10,2,38,A,B,2,233.52,200,130,166660,11647928,233.65,233.78,1,150,1,2,233.53,233.8,10,25,1,1,233.52,233.84,200,400,1,2,233.49,233.9,26,26,1,1,233.45,233.94,15,200,1,1,233.4,233.98,110,44,2,3,233.39,234.0,10,154,1,7,233.31,234.13,110,400,2,1,233.3,234.17,100,1,1,1,233.25,234.41,55,600,2,2,AAPL,0,0,0,200,26,15,110,10,110,100,55,233.715
2024-10-21T12:00:06.101461393Z,2024-10-21 12:00:06.101295300+00:00,10,2,38,C,B,2,233.52,200,130,166093,11648114,233.65,233.78,1,150,1,2,233.53,233.8,10,25,1,1,233.49,233.84,26,400,1,2,233.45,233.9,15,26,1,1,233.4,233.94,110,200,2,1,233.39,233.98,10,44,1,3,233.31,234.0,110,154,2,7,233.3,234.13,100,400,1,1,233.25,234.17,55,1,2,1,233.24,234.41,1,600,1,2,AAPL,0,0,0,-200,-26,-15,-110,-10,-110,-100,-55,233.715
2024-10-21T12:00:06.101473795Z,2024-10-21 12:00:06.101307454+00:00,10,2,38,A,B,2,233.5,400,130,166341,11648115,233.65,233.78,1,150,1,2,233.53,233.8,10,25,1,1,233.5,233.84,400,400,1,2,233.49,233.9,26,26,1,1,233.45,233.94,15,200,1,1,233.4,233.98,110,44,2,3,233.39,234.0,10,154,1,7,233.31,234.13,110,400,2,1,233.3,234.17,100,1,1,1,233.25,234.41,55,600,2,2,AAPL,0,0,0,400,26,15,110,10,110,100,55,233.715
2024-10-21T12:00:07.067544847Z,2024-10-21 12:00:07.067376608+00:00,10,2,38,T,A,0,233.65,1,130,168239,11649200,233.65,233.78,1,150,1,2,233.53,233.8,10,25,1,1,233.5,233.84,400,400,1,2,233.49,233.9,26,26,1,1,233.45,233.94,15,200,1,1,233.4,233.98,110,44,2,3,233.39,234.0,10,154,1,7,233.31,234.13,110,400,2,1,233.3,234.17,100,1,1,1,233.25,234.41,55,600,2,2,AAPL,0,0,0,0,0,0,0,0,0,0,0,233.715
2024-10-21T12:00:07.067544847Z,2024-10-21 12:00:07.067376608+00:00,10,2,38,C,B,0,233.65,1,130,168239,11649200,233.53,233.78,10,150,1,2,233.5,233.8,400,25,1,1,233.49,233.84,26,400,1,2,233.45,233.9,15,26,1,1,233.4,233.94,110,200,2,1,233.39,233.98,10,44,1,3,233.31,234.0,110,154,2,7,233.3,234.13,100,400,1,1,233.25,234.17,55,1,2,1,233.24,234.41,1,600,1,2,AAPL,-1,-1,-10,-400,-26,-15,-110,-10,-110,-100,-55,233.655
2024-10-21T12:00:07.067586376Z,2024-10-21 12:00:07.067419673+00:00,10,2,38,A,A,0,233.72,19,130,166703,11649202,233.53,233.72,10,19,1,1,233.5,233.78,400,150,1,2,233.49,233.8,26,25,1,1,233.45,233.84,15,400,1,2,233.4,233.9,110,26,2,1,233.39,233.94,10,200,1,1,233.31,233.98,110,44,2,3,233.3,234.0,100,154,1,7,233.25,234.13,55,400,2,1,233.24,234.17,1,1,1,1,AAPL,19,19,150,25,400,26,200,44,154,400,1,233.625
2024-10-21T12:00:07.067587561Z,2024-10-21 12:00:07.067421371+00:00,10,2,38,C,B,1,233.5,200,130,166190,11649203,233.53,233.72,10,19,1,1,233.5,233.78,200,150,1,2,233.49,233.8,26,25,1,1,233.45,233.84,15,400,1,2,233.4,233.9,110,26,2,1,233.39,233.94,10,200,1,1,233.31,233.98,110,44,2,3,233.3,234.0,100,154,1,7,233.25,234.13,55,400,2,1,233.24,234.17,1,1,1,1,AAPL,0,0,-200,0,0,0,0,0,0,0,0,233.625
2024-10-21T12:00:07.067633143Z,2024-10-21 12:00:07.067467022+00:00,10,2,38,A,A,1,233.76,19,130,166121,11649204,233.53,233.72,10,19,1,1,233.5,233.76,200,19,1,1,233.49,233.78,26,150,1,2,233.45,233.8,15,25,1,1,233.4,233.84,110,400,2,2,233.39,233.9,10,26,1,1,233.31,233.94,110,200,2,1,233.3,233.98,100,44,1,3,233.25,234.0,55,154,2,7,233.24,234.13,1,400,1,1,AAPL,0,0,19,150,25,400,26,200,44,154,400,233.625
2024-10-21T12:00:07.086844298Z,2024-10-21 12:00:07.086677914+00:00,10,2,38,A,B,1,233.5,200,130,166384,11649237,233.53,233.72,10,19,1,1,233.5,233.76,400,19,2,1,233.49,233.78,26,150,1,2,233.45,233.8,15,25,1,1,233.4,233.84,110,400,2,2,233.39,233.9,10,26,1,1,233.31,233.94,110,200,2,1,233.3,233.98,100,44,1,3,233.25,234.0,55,154,2,7,233.24,234.13,1,400,1,1,AAPL,0,0,200,0,0,0,0,0,0,0,0,233.625
2024-10-21T12:00:07.089165016Z,2024-10-21 12:00:07.088999005+00:00,10,2,38,C,B,1,233.5,200,130,166011,11649239,233.53,233.72,10,19,1,1,233.5,233.76,200,19,1,1,233.49,233.78,26,150,1,2,233.45,233.8,15,25,1,1,233.4,233.84,110,400,2,2,233.39,233.9,10,26,1,1,233.31,233.94,110,200,2,1,233.3,233.98,100,44,1,3,233.25,234.0,55,154,2,7,233.24,234.13,1,400,1,1,AAPL,0,0,-200,0,0,0,0,0,0,0,0,233.625
2024-10-21T12:00:07.089175420Z,2024-10-21 12:00:07.089009480+00:00,10,2,38,C,B,1,233.5,200,130,165940,11649240,233.53,233.72,10,19,1,1,233.49,233.76,26,19,1,1,233.45,233.78,15,150,1,2,233.4,233.8,110,25,2,1,233.39,233.84,10,400,1,2,233.31,233.9,110,26,2,1,233.3,233.94,100,200,1,1,233.25,233.98,55,44,2,3,233.24,234.0,1,154,1,7,233.23,234.13,50,400,1,1,AAPL,0,0,-200,-26,-15,-110,-10,-110,-100,-55,-1,233.625
2024-10-21T12:00:07.149755425Z,2024-10-21 12:00:07.149589050+00:00,10,2,38,C,B,1,233.49,26,130,166375,11649363,233.53,233.72,10,19,1,1,233.45,233.76,15,19,1,1,233.4,233.78,110,150,2,2,233.39,233.8,10,25,1,1,233.31,233.84,110,400,2,2,233.3,233.9,100,26,1,1,233.25,233.94,55,200,2,1,233.24,233.98,1,44,1,3,233.23,234.0,50,154,1,7,233.2,234.13,50,400,3,1,AAPL,0,0,-26,-15,-110,-10,-110,-100,-55,-1,-50,233.625
2024-10-21T12:00:07.149847104Z,2024-10-21 12:00:07.149680427+00:00,10,2,38,A,B,2,233.43,29,130,166677,11649364,233.53,233.72,10,19,1,1,233.45,233.76,15,19,1,1,233.43,233.78,29,150,1,2,233.4,233.8,110,25,2,1,233.39,233.84,10,400,1,2,233.31,233.9,110,26,2,1,233.3,233.94,100,200,1,1,233.25,233.98,55,44,2,3,233.24,234.0,1,154,1,7,233.23,234.13,50,400,1,1,AAPL,0,0,0,29,110,10,110,100,55,1,50,233.625
2024-10-21T12:00:07.173932656Z,2024-10-21 12:00:07.173766393+00:00,10,2,38,C,A,1,233.76,19,130,166263,11649378,233.53,233.72,10,19,1,1,233.45,233.78,15,150,1,2,233.43,233.8,29,25,1,1,233.4,233.84,110,400,2,2,233.39,233.9,10,26,1,1,233.31,233.94,110,200,2,1,233.3,233.98,100,44,1,3,233.25,234.0,55,154,2,7,233.24,234.13,1,400,1,1,233.23,234.17,50,1,1,1,AAPL,0,0,19,150,25,400,26,200,44,154,400,233.625
2024-10-21T12:00:07.191118135Z,2024-10-21 12:00:07.190951663+00:00,10,2,38,A,B,2,233.44,200,130,166472,11649387,233.53,233.72,10,19,1,1,233.45,233.78,15,150,1,2,233.44,233.8,200,25,1,1,233.43,233.84,29,400,1,2,233.4,233.9,110,26,2,1,233.39,233.94,10,200,1,1,233.31,233.98,110,44,2,3,233.3,234.0,100,154,1,7,233.25,234.13,55,400,2,1,233.24,234.17,1,1,1,1,AAPL,0,0,0,200,29,110,10,110,100,55,1,233.625
2024-10-21T12:00:07.323930762Z,2024-10-21 12:00:07.323764357+00:00,10,2,38,C,A,0,233.72,19,130,166405,11649551,233.53,233.78,10,150,1,2,233.45,233.8,15,25,1,1,233.44,233.84,200,400,1,2,233.43,233.9,29,26,1,1,233.4,233.94,110,200,2,1,233.39,233.98,10,44,1,3,233.31,234.0,110,154,2,7,233.3,234.13,100,400,1,1,233.25,234.17,55,1,2,1,233.24,234.41,1,600,1,2,AAPL,19,19,150,25,400,26,200,44,154,400,1,233.655
2024-10-21T12:00:07.337675975Z,2024-10-21 12:00:07.337509459+00:00,10,2,38,A,B,2,233.44,200,130,166516,11649571,233.53,233.78,10,150,1,2,233.45,233.8,15,25,1,1,233.44,233.84,400,400,2,2,233.43,233.9,29,26,1,1,233.4,233.94,110,200,2,1,233.39,233.98,10,44,1,3,233.31,234.0,110,154,2,7,233.3,234.13,100,400,1,1,233.25,234.17,55,1,2,1,233.24,234.41,1,600,1,2,AAPL,0,0,0,200,0,0,0,0,0,0,0,233.655
2024-10-21T12:00:07.338280058Z,2024-10-21 12:00:07.338114020+00:00,10,2,38,C,B,2,233.44,200,130,166038,11649572,233.53,233.78,10,150,1,2,233.45,233.8,15,25,1,1,233.44,233.84,200,400,1,2,233.43,233.9,29,26,1,1,233.4,233.94,110,200,2,1,233.39,233.98,10,44,1,3,233.31,234.0,110,154,2,7,233.3,234.13,100,400,1,1,233.25,234.17,55,1,2,1,233.24,234.41,1,600,1,2,AAPL,0,0,0,-200,0,0,0,0,0,0,0,233.655
2024-10-21T12:00:07.646887094Z,2024-10-21 12:00:07.646720038+00:00,10,2,38,T,N,0,233.66,38,130,167056,11649813,233.53,233.78,10,150,1,2,233.45,233.8,15,25,1,1,233.44,233.84,200,400,1,2,233.43,233.9,29,26,1,1,233.4,233.94,110,200,2,1,233.39,233.98,10,44,1,3,233.31,234.0,110,154,2,7,233.3,234.13,100,400,1,1,233.25,234.17,55,1,2,1,233.24,234.41,1,600,1,2,AAPL,0,0,0,0,0,0,0,0,0,0,0,233.655
2024-10-21T12:00:07.956336345Z,2024-10-21 12:00:07.956169614+00:00,10,2,38,A,B,2,233.44,200,130,166731,11650434,233.53,233.78,10,150,1,2,233.45,233.8,15,25,1,1,233.44,233.84,400,400,2,2,233.43,233.9,29,26,1,1,233.4,233.94,110,200,2,1,233.39,233.98,10,44,1,3,233.31,234.0,110,154,2,7,233.3,234.13,100,400,1,1,233.25,234.17,55,1,2,1,233.24,234.41,1,600,1,2,AAPL,0,0,0,200,0,0,0,0,0,0,0,233.655
2024-10-21T12:00:07.966018430Z,2024-10-21 12:00:07.965852395+00:00,10,2,38,C,A,2,233.84,200,130,166035,11650499,233.53,233.78,10,150,1,2,233.45,233.8,15,25,1,1,233.44,233.84,400,200,2,1,233.43,233.9,29,26,1,1,233.4,233.94,110,200,2,1,233.39,233.98,10,44,1,3,233.31,234.0,110,154,2,7,233.3,234.13,100,400,1,1,233.25,234.17,55,1,2,1,233.24,234.41,1,600,1,2,AAPL,0,0,0,-200,0,0,0,0,0,0,0,233.655
2024-10-21T12:00:07.966030960Z,2024-10-21 12:00:07.965864571+00:00,10,2,38,A,A,2,233.83,400,130,166389,11650500,233.53,233.78,10,150,1,2,233.45,233.8,15,25,1,1,233.44,233.83,400,400,2,1,233.43,233.9,29,26,1,1,233.4,233.94,110,200,2,1,233.39,233.98,10,44,1,3,233.31,234.0,110,154,2,7,233.3,234.13,100,400,1,1,233.25,234.17,55,1,2,1,233.24,234.41,1,600,1,2,AAPL,0,0,0,400,0,0,0,0,0,0,0,233.655
2024-10-21T12:00:08.010300330Z,2024-10-21 12:00:08.010134216+00:00,10,2,38,C,B,2,233.44,200,130,166114,11650572,233.53,233.78,10,150,1,2,233.45,233.8,15,25,1,1,233.44,233.83,200,400,1,1,233.43,233.9,29,26,1,1,233.4,233.94,110,200,2,1,233.39,233.98,10,44,1,3,233.31,234.0,110,154,2,7,233.3,234.13,100,400,1,1,233.25,234.17,55,1,2,1,233.24,234.41,1,600,1,2,AAPL,0,0,0,-200,0,0,0,0,0,0,0,233.655
2024-10-21T12:00:08.010312267Z,2024-10-21 12:00:08.010145977+00:00,10,2,38,A,B,1,233.45,200,130,166290,11650573,233.53,233.78,10,150,1,2,233.45,233.8,215,25,2,1,233.43,233.83,29,400,1,1,233.4,233.9,110,26,2,1,233.39,233.94,10,200,1,1,233.31,233.98,110,44,2,3,233.3,234.0,100,154,1,7,233.25,234.13,55,400,2,1,233.24,234.17,1,1,1,1,233.23,234.41,50,600,1,2,AAPL,0,0,200,-200,-29,-110,-10,-110,-100,-55,-1,233.655
2024-10-21T12:00:08.944880282Z,2024-10-21 12:00:08.944714285+00:00,10,2,38,C,A,3,233.9,26,130,165997,11651577,233.53,233.78,10,150,1,2,233.45,233.8,215,25,2,1,233.43,233.83,29,400,1,1,233.4,233.94,110,200,2,1,233.39,233.98,10,44,1,3,233.31,234.0,110,154,2,7,233.3,234.13,100,400,1,1,233.25,234.17,55,1,2,1,233.24,234.41,1,600,1,2,233.23,234.43,50,5,1,1,AAPL,0,0,0,0,26,200,44,154,400,1,600,233.655
2024-10-21T12:00:08.944922066Z,2024-10-21 12:00:08.944755705+00:00,10,2,38,A,A,3,233.89,27,130,166361,11651579,233.53,233.78,10,150,1,2,233.45,233.8,215,25,2,1,233.43,233.83,29,400,1,1,233.4,233.89,110,27,2,1,233.39,233.94,10,200,1,1,233.31,233.98,110,44,2,3,233.3,234.0,100,154,1,7,233.25,234.13,55,400,2,1,233.24,234.17,1,1,1,1,233.23,234.41,50,600,1,2,AAPL,0,0,0,0,27,200,44,154,400,1,600,233.655
2024-10-21T12:00:11.760167332Z,2024-10-21 12:00:11.760000282+00:00,10,2,38,A,B,1,233.46,200,130,167050,11654094,233.53,233.78,10,150,1,2,233.46,233.8,200,25,1,1,233.45,233.83,15,400,1,1,233.43,233.89,29,27,1,1,233.4,233.94,110,200,2,1,233.39,233.98,10,44,1,3,233.31,234.0,110,154,2,7,233.3,234.13,100,400,1,1,233.25,234.17,55,1,2,1,233.24,234.41,1,600,1,2,AAPL,0,0,200,15,29,110,10,110,100,55,1,233.655
2024-10-21T12:00:14.055899330Z,2024-10-21 12:00:14.055732875+00:00,10,2,38,C,B,1,233.46,200,130,166455,11656987,233.53,233.78,10,150,1,2,233.45,233.8,15,25,1,1,233.43,233.83,29,400,1,1,233.4,233.89,110,27,2,1,233.39,233.94,10,200,1,1,233.31,233.98,110,44,2,3,233.3,234.0,100,154,1,7,233.25,234.13,55,400,2,1,233.24,234.17,1,1,1,1,233.23,234.41,50,600,1,2,AAPL,0,0,-200,-15,-29,-110,-10,-110,-100,-55,-1,233.655
2024-10-21T12:00:14.159146604Z,2024-10-21 12:00:14.158979266+00:00,10,2,38,A,B,1,233.45,200,130,167338,11657107,233.53,233.78,10,150,1,2,233.45,233.8,215,25,2,1,233.43,233.83,29,400,1,1,233.4,233.89,110,27,2,1,233.39,233.94,10,200,1,1,233.31,233.98,110,44,2,3,233.3,234.0,100,154,1,7,233.25,234.13,55,400,2,1,233.24,234.17,1,1,1,1,233.23,234.41,50,600,1,2,AAPL,0,0,200,0,0,0,0,0,0,0,0,233.655
2024-10-21T12:00:14.450699829Z,2024-10-21 12:00:14.450532708+00:00,10,2,38,T,N,0,233.65,38,130,167121,11657642,233.53,233.78,10,150,1,2,233.45,233.8,215,25,2,1,233.43,233.83,29,400,1,1,233.4,233.89,110,27,2,1,233.39,233.94,10,200,1,1,233.31,233.98,110,44,2,3,233.3,234.0,100,154,1,7,233.25,234.13,55,400,2,1,233.24,234.17,1,1,1,1,233.23,234.41,50,600,1,2,AAPL,0,0,0,0,0,0,0,0,0,0,0,233.655
2024-10-21T12:00:15.203870674Z,2024-10-21 12:00:15.203702787+00:00,10,2,38,T,N,0,233.66,38,130,167887,11658325,233.53,233.78,10,150,1,2,233.45,233.8,215,25,2,1,233.43,233.83,29,400,1,1,233.4,233.89,110,27,2,1,233.39,233.94,10,200,1,1,233.31,233.98,110,44,2,3,233.3,234.0,100,154,1,7,233.25,234.13,55,400,2,1,233.24,234.17,1,1,1,1,233.23,234.41,50,600,1,2,AAPL,0,0,0,0,0,0,0,0,0,0,0,233.655
2024-10-21T12:00:15.820036179Z,2024-10-21 12:00:15.819869942+00:00,10,2,38,C,B,1,233.45,200,130,166237,11659423,233.53,233.78,10,150,1,2,233.45,233.8,15,25,1,1,233.43,233.83,29,400,1,1,233.4,233.89,110,27,2,1,233.39,233.94,10,200,1,1,233.31,233.98,110,44,2,3,233.3,234.0,100,154,1,7,233.25,234.13,55,400,2,1,233.24,234.17,1,1,1,1,233.23,234.41,50,600,1,2,AAPL,0,0,-200,0,0,0,0,0,0,0,0,233.655
2024-10-21T12:00:15.820048842Z,2024-10-21 12:00:15.819882720+00:00,10,2,38,A,B,2,233.43,200,130,166122,11659424,233.53,233.78,10,150,1,2,233.45,233.8,15,25,1,1,233.43,233.83,229,400,2,1,233.4,233.89,110,27,2,1,233.39,233.94,10,200,1,1,233.31,233.98,110,44,2,3,233.3,234.0,100,154,1,7,233.25,234.13,55,400,2,1,233.24,234.17,1,1,1,1,233.23,234.41,50,600,1,2,AAPL,0,0,0,200,0,0,0,0,0,0,0,233.655
2024-10-21T12:00:15.838721297Z,2024-10-21 12:00:15.838554673+00:00,10,2,38,A,A,2,233.82,400,130,166624,11659500,233.53,233.78,10,150,1,2,233.45,233.8,15,25,1,1,233.43,233.82,229,400,2,1,233.4,233.89,110,27,2,1,233.39,233.94,10,200,1,1,233.31,233.98,110,44,2,3,233.3,234.0,100,154,1,7,233.25,234.13,55,400,2,1,233.24,234.17,1,1,1,1,233.23,234.41,50,600,1,2,AAPL,0,0,0,400,0,0,0,0,0,0,0,233.655
2024-10-21T12:00:15.866744266Z,2024-10-21 12:00:15.866578232+00:00,10,2,38,C,B,2,233.43,29,130,166034,11659636,233.53,233.78,10,150,1,2,233.45,233.8,15,25,1,1,233.43,233.82,200,400,1,1,233.4,233.89,110,27,2,1,233.39,233.94,10,200,1,1,233.31,233.98,110,44,2,3,233.3,234.0,100,154,1,7,233.25,234.13,55,400,2,1,233.24,234.17,1,1,1,1,233.23,234.41,50,600,1,2,AAPL,0,0,0,-29,0,0,0,0,0,0,0,233.655
2024-10-21T12:00:15.866800115Z,2024-10-21 12:00:15.866633819+00:00,10,2,38,A,B,3,233.41,26,130,166296,11659637,233.53,233.78,10,150,1,2,233.45,233.8,15,25,1,1,233.43,233.82,200,400,1,1,233.41,233.89,26,27,1,1,233.4,233.94,110,200,2,1,233.39,233.98,10,44,1,3,233.31,234.0,110,154,2,7,233.3,234.13,100,400,1,1,233.25,234.17,55,1,2,1,233.24,234.41,1,600,1,2,AAPL,0,0,0,0,26,110,10,110,100,55,1,233.655
2024-10-21T12:00:15.951337950Z,2024-10-21 12:00:15.951171652+00:00,10,2,38,C,A,3,233.89,27,130,166298,11659913,233.53,233.78,10,150,1,2,233.45,233.8,15,25,1,1,233.43,233.82,200,400,1,1,233.41,233.94,26,200,1,1,233.4,233.98,110,44,2,3,233.39,234.0,10,154,1,7,233.31,234.13,110,400,2,1,233.3,234.17,100,1,1,1,233.25,234.41,55,600,2,2,233.24,234.43,1,5,1,1,AAPL,0,0,0,0,27,200,44,154,400,1,600,233.655
2024-10-21T12:00:15.951417682Z,2024-10-21 12:00:15.951251227+00:00,10,2,38,A,A,3,233.88,27,130,166455,11659915,233.53,233.78,10,150,1,2,233.45,233.8,15,25,1,1,233.43,233.82,200,400,1,1,233.41,233.88,26,27,1,1,233.4,233.94,110,200,2,1,233.39,233.98,10,44,1,3,233.31,234.0,110,154,2,7,233.3,234.13,100,400,1,1,233.25,234.17,55,1,2,1,233.24,234.41,1,600,1,2,AAPL,0,0,0,0,27,200,44,154,400,1,600,233.655
2024-10-21T12:00:16.054885768Z,2024-10-21 12:00:16.054719712+00:00,10,2,38,C,B,2,233.43,200,130,166056,11660064,233.53,233.78,10,150,1,2,233.45,233.8,15,25,1,1,233.41,233.82,26,400,1,1,233.4,233.88,110,27,2,1,233.39,233.94,10,200,1,1,233.31,233.98,110,44,2,3,233.3,234.0,100,154,1,7,233.25,234.13,55,400,2,1,233.24,234.17,1,1,1,1,233.23,234.41,50,600,1,2,AAPL,0,0,0,-200,-26,-110,-10,-110,-100,-55,-1,233.655
2024-10-21T12:00:16.158164700Z,2024-10-21 12:00:16.157998016+00:00,10,2,38,A,B,2,233.43,200,130,166684,11660229,233.53,233.78,10,150,1,2,233.45,233.8,15,25,1,1,233.43,233.82,200,400,1,1,233.41,233.88,26,27,1,1,233.4,233.94,110,200,2,1,233.39,233.98,10,44,1,3,233.31,234.0,110,154,2,7,233.3,234.13,100,400,1,1,233.25,234.17,55,1,2,1,233.24,234.41,1,600,1,2,AAPL,0,0,0,200,26,110,10,110,100,55,1,233.655
2024-10-21T12:00:16.339082802Z,2024-10-21 12:00:16.338916301+00:00,10,2,38,A,B,2,233.43,200,130,166501,11660347,233.53,233.78,10,150,1,2,233.45,233.8,15,25,1,1,233.43,233.82,400,400,2,1,233.41,233.88,26,27,1,1,233.4,233.94,110,200,2,1,233.39,233.98,10,44,1,3,233.31,234.0,110,154,2,7,233.3,234.13,100,400,1,1,233.25,234.17,55,1,2,1,233.24,234.41,1,600,1,2,AAPL,0,0,0,200,0,0,0,0,0,0,0,233.655
2024-10-21T12:00:16.393721035Z,2024-10-21 12:00:16.393554950+00:00,10,2,38,C,B,2,233.43,200,130,166085,11660378,233.53,233.78,10,150,1,2,233.45,233.8,15,25,1,1,233.43,233.82,200,400,1,1,233.41,233.88,26,27,1,1,233.4,233.94,110,200,2,1,233.39,233.98,10,44,1,3,233.31,234.0,110,154,2,7,233.3,234.13,100,400,1,1,233.25,234.17,55,1,2,1,233.24,234.41,1,600,1,2,AAPL,0,0,0,-200,0,0,0,0,0,0,0,233.655
2024-10-21T12:00:16.393733214Z,2024-10-21 12:00:16.393566799+00:00,10,2,38,A,B,2,233.44,200,130,166415,11660379,233.53,233.78,10,150,1,2,233.45,233.8,15,25,1,1,233.44,233.82,200,400,1,1,233.41,233.88,26,27,1,1,233.4,233.94,110,200,2,1,233.39,233.98,10,44,1,3,233.31,234.0,110,154,2,7,233.3,234.13,100,400,1,1,233.25,234.17,55,1,2,1,233.24,234.41,1,600,1,2,AAPL,0,0,0,200,0,0,0,0,0,0,0,233.655
2024-10-21T12:00:30.258048610Z,2024-10-21 12:00:30.257881806+00:00,10,2,38,A,B,1,233.45,200,130,166804,11677039,233.53,233.78,10,150,1,2,233.45,233.8,215,25,2,1,233.41,233.82,26,400,1,1,233.4,233.88,110,27,2,1,233.39,233.94,10,200,1,1,233.31,233.98,110,44,2,3,233.3,234.0,100,154,1,7,233.25,234.13,55,400,2,1,233.24,234.17,1,1,1,1,233.23,234.41,50,600,1,2,AAPL,0,0,200,-200,-26,-110,-10,-110,-100,-55,-1,233.655
2024-10-21T12:00:31.950037293Z,2024-10-21 12:00:31.949871042+00:00,10,2,38,C,B,1,233.45,200,130,166251,11678778,233.53,233.78,10,150,1,2,233.45,233.8,15,25,1,1,233.41,233.82,26,400,1,1,233.4,233.88,110,27,2,1,233.39,233.94,10,200,1,1,233.31,233.98,110,44,2,3,233.3,234.0,100,154,1,7,233.25,234.13,55,400,2,1,233.24,234.17,1,1,1,1,233.23,234.41,50,600,1,2,AAPL,0,0,-200,0,0,0,0,0,0,0,0,233.655
2024-10-21T12:00:31.950049605Z,2024-10-21 12:00:31.949883226+00:00,10,2,38,A,B,2,233.44,200,130,166379,11678779,233.53,233.78,10,150,1,2,233.45,233.8,15,25,1,1,233.44,233.82,200,400,1,1,233.41,233.88,26,27,1,1,233.4,233.94,110,200,2,1,233.39,233.98,10,44,1,3,233.31,234.0,110,154,2,7,233.3,234.13,100,400,1,1,233.25,234.17,55,1,2,1,233.24,234.41,1,600,1,2,AAPL,0,0,0,200,26,110,10,110,100,55,1,233.655
2024-10-21T12:00:34.385936218Z,2024-10-21 12:00:34.385769828+00:00,10,2,38,A,B,1,233.45,200,130,166390,11681405,233.53,233.78,10,150,1,2,233.45,233.8,215,25,2,1,233.41,233.82,26,400,1,1,233.4,233.88,110,27,2,1,233.39,233.94,10,200,1,1,233.31,233.98,110,44,2,3,233.3,234.0,100,154,1,7,233.25,234.13,55,400,2,1,233.24,234.17,1,1,1,1,233.23,234.41,50,600,1,2,AAPL,0,0,200,-200,-26,-110,-10,-110,-100,-55,-1,233.655
2024-10-21T12:00:34.428154041Z,2024-10-21 12:00:34.427987983+00:00,10,2,38,C,B,2,233.41,26,130,166058,11681603,233.53,233.78,10,150,1,2,233.45,233.8,215,25,2,1,233.4,233.82,110,400,2,1,233.39,233.88,10,27,1,1,233.31,233.94,110,200,2,1,233.3,233.98,100,44,1,3,233.25,234.0,55,154,2,7,233.24,234.13,1,400,1,1,233.23,234.17,50,1,1,1,233.2,234.41,50,600,3,2,AAPL,0,0,0,-26,-110,-10,-110,-100,-55,-1,-50,233.655
2024-10-21T12:00:34.428230329Z,2024-10-21 12:00:34.428063663+00:00,10,2,38,A,B,2,233.42,28,130,166666,11681604,233.53,233.78,10,150,1,2,233.45,233.8,215,25,2,1,233.42,233.82,28,400,1,1,233.4,233.88,110,27,2,1,233.39,233.94,10,200,1,1,233.31,233.98,110,44,2,3,233.3,234.0,100,154,1,7,233.25,234.13,55,400,2,1,233.24,234.17,1,1,1,1,233.23,234.41,50,600,1,2,AAPL,0,0,0,28,110,10,110,100,55,1,50,233.655
2024-10-21T12:00:35.519955046Z,2024-10-21 12:00:35.519789038+00:00,10,2,38,C,B,1,233.45,200,130,166008,11682997,233.53,233.78,10,150,1,2,233.45,233.8,15,25,1,1,233.42,233.82,28,400,1,1,233.4,233.88,110,27,2,1,233.39,233.94,10,200,1,1,233.31,233.98,110,44,2,3,233.3,234.0,100,154,1,7,233.25,234.13,55,400,2,1,233.24,234.17,1,1,1,1,233.23,234.41,50,600,1,2,AAPL,0,0,-200,0,0,0,0,0,0,0,0,233.655
2024-10-21T12:00:35.519967135Z,2024-10-21 12:00:35.519800735+00:00,10,2,38,A,B,2,233.44,200,130,166400,11682998,233.53,233.78,10,150,1,2,233.45,233.8,15,25,1,1,233.44,233.82,200,400,1,1,233.42,233.88,28,27,1,1,233.4,233.94,110,200,2,1,233.39,233.98,10,44,1,3,233.31,234.0,110,154,2,7,233.3,234.13,100,400,1,1,233.25,234.17,55,1,2,1,233.24,234.41,1,600,1,2,AAPL,0,0,0,200,28,110,10,110,100,55,1,233.655
2024-10-21T12:00:40.233309644Z,2024-10-21 12:00:40.233143021+00:00,10,2,38,A,A,2,233.81,400,130,166623,11688061,233.53,233.78,10,150,1,2,233.45,233.8,15,25,1,1,233.44,233.81,200,400,1,1,233.42,233.88,28,27,1,1,233.4,233.94,110,200,2,1,233.39,233.98,10,44,1,3,233.31,234.0,110,154,2,7,233.3,234.13,100,400,1,1,233.25,234.17,55,1,2,1,233.24,234.41,1,600,1,2,AAPL,0,0,0,400,0,0,0,0,0,0,0,233.655
2024-10-21T12:00:40.246205478Z,2024-10-21 12:00:40.246039339+00:00,10,2,38,C,B,2,233.44,200,130,166139,11688185,233.53,233.78,10,150,1,2,233.45,233.8,15,25,1,1,233.42,233.81,28,400,1,1,233.4,233.88,110,27,2,1,233.39,233.94,10,200,1,1,233.31,233.98,110,44,2,3,233.3,234.0,100,154,1,7,233.25,234.13,55,400,2,1,233.24,234.17,1,1,1,1,233.23,234.41,50,600,1,2,AAPL,0,0,0,-200,-28,-110,-10,-110,-100,-55,-1,233.655
2024-10-21T12:00:40.246217496Z,2024-10-21 12:00:40.246051577+00:00,10,2,38,A,B,2,233.42,200,130,165919,11688186,233.53,233.78,10,150,1,2,233.45,233.8,15,25,1,1,233.42,233.81,228,400,2,1,233.4,233.88,110,27,2,1,233.39,233.94,10,200,1,1,233.31,233.98,110,44,2,3,233.3,234.0,100,154,1,7,233.25,234.13,55,400,2,1,233.24,234.17,1,1,1,1,233.23,234.41,50,600,1,2,AAPL,0,0,0,200,0,0,0,0,0,0,0,233.655
2024-10-21T12:00:40.301271156Z,2024-10-21 12:00:40.301104866+00:00,10,2,38,A,A,1,233.8,400,130,166290,11688350,233.53,233.78,10,150,1,2,233.45,233.8,15,425,1,2,233.42,233.88,228,27,2,1,233.4,233.94,110,200,2,1,233.39,233.98,10,44,1,3,233.31,234.0,110,154,2,7,233.3,234.13,100,400,1,1,233.25,234.17,55,1,2,1,233.24,234.41,1,600,1,2,233.23,234.43,50,5,1,1,AAPL,0,0,400,400,27,200,44,154,400,1,600,233.655
2024-10-21T12:00:40.317691287Z,2024-10-21 12:00:40.317525489+00:00,10,2,38,C,B,2,233.42,28,130,165798,11688460,233.53,233.78,10,150,1,2,233.45,233.8,15,425,1,2,233.42,233.88,200,27,1,1,233.4,233.94,110,200,2,1,233.39,233.98,10,44,1,3,233.31,234.0,110,154,2,7,233.3,234.13,100,400,1,1,233.25,234.17,55,1,2,1,233.24,234.41,1,600,1,2,233.23,234.43,50,5,1,1,AAPL,0,0,0,-28,0,0,0,0,0,0,0,233.655
2024-10-21T12:00:40.317745864Z,2024-10-21 12:00:40.317579213+00:00,10,2,38,A,B,3,233.4,29,130,166651,11688461,233.53,233.78,10,150,1,2,233.45,233.8,15,425,1,2,233.42,233.88,200,27,1,1,233.4,233.94,139,200,3,1,233.39,233.98,10,44,1,3,233.31,234.0,110,154,2,7,233.3,234.13,100,400,1,1,233.25,234.17,55,1,2,1,233.24,234.41,1,600,1,2,233.23,234.43,50,5,1,1,AAPL,0,0,0,0,29,0,0,0,0,0,0,233.655
2024-10-21T12:00:40.436920479Z,2024-10-21 12:00:40.436754233+00:00,10,2,38,C,A,2,233.88,27,130,166246,11688670,233.53,233.78,10,150,1,2,233.45,233.8,15,425,1,2,233.42,233.94,200,200,1,1,233.4,233.98,139,44,3,3,233.39,234.0,10,154,1,7,233.31,234.13,110,400,2,1,233.3,234.17,100,1,1,1,233.25,234.41,55,600,2,2,233.24,234.43,1,5,1,1,233.23,234.5,50,63,1,4,AAPL,0,0,0,27,200,44,154,400,1,600,5,233.655
2024-10-21T12:00:40.436959883Z,2024-10-21 12:00:40.436793684+00:00,10,2,38,A,A,2,233.87,30,130,166199,11688671,233.53,233.78,10,150,1,2,233.45,233.8,15,425,1,2,233.42,233.87,200,30,1,1,233.4,233.94,139,200,3,1,233.39,233.98,10,44,1,3,233.31,234.0,110,154,2,7,233.3,234.13,100,400,1,1,233.25,234.17,55,1,2,1,233.24,234.41,1,600,1,2,233.23,234.43,50,5,1,1,AAPL,0,0,0,30,200,44,154,400,1,600,5,233.655
2024-10-21T12:00:51.186722645Z,2024-10-21 12:00:51.186556234+00:00,10,2,38,A,B,0,233.58,500,130,166411,11699374,233.58,233.78,500,150,1,2,233.53,233.8,10,425,1,2,233.45,233.87,15,30,1,1,233.42,233.94,200,200,1,1,233.4,233.98,139,44,3,3,233.39,234.0,10,154,1,7,233.31,234.13,110,400,2,1,233.3,234.17,100,1,1,1,233.25,234.41,55,600,2,2,233.24,234.43,1,5,1,1,AAPL,500,500,10,15,200,139,10,110,100,55,1,233.68
2024-10-21T12:00:51.249833598Z,2024-10-21 12:00:51.249667336+00:00,10,2,38,A,A,0,233.74,1,130,166262,11699412,233.58,233.74,500,1,1,1,233.53,233.78,10,150,1,2,233.45,233.8,15,425,1,2,233.42,233.87,200,30,1,1,233.4,233.94,139,200,3,1,233.39,233.98,10,44,1,3,233.31,234.0,110,154,2,7,233.3,234.13,100,400,1,1,233.25,234.17,55,1,2,1,233.24,234.41,1,600,1,2,AAPL,1,1,150,425,30,200,44,154,400,1,600,233.66000000000003
2024-10-21T12:00:51.987755445Z,2024-10-21 12:00:51.987589245+00:00,10,2,38,A,B,3,233.42,200,130,166200,11699997,233.58,233.74,500,1,1,1,233.53,233.78,10,150,1,2,233.45,233.8,15,425,1,2,233.42,233.87,400,30,2,1,233.4,233.94,139,200,3,1,233.39,233.98,10,44,1,3,233.31,234.0,110,154,2,7,233.3,234.13,100,400,1,1,233.25,234.17,55,1,2,1,233.24,234.41,1,600,1,2,AAPL,0,0,0,0,200,0,0,0,0,0,0,233.66000000000003
2024-10-21T12:00:51.987815133Z,2024-10-21 12:00:51.987648731+00:00,10,2,38,C,A,2,233.8,200,130,166402,11699998,233.58,233.74,500,1,1,1,233.53,233.78,10,150,1,2,233.45,233.8,15,225,1,2,233.42,233.87,400,30,2,1,233.4,233.94,139,200,3,1,233.39,233.98,10,44,1,3,233.31,234.0,110,154,2,7,233.3,234.13,100,400,1,1,233.25,234.17,55,1,2,1,233.24,234.41,1,600,1,2,AAPL,0,0,0,-200,0,0,0,0,0,0,0,233.66000000000003
2024-10-21T12:00:51.988333005Z,2024-10-21 12:00:51.988166858+00:00,10,2,38,C,B,4,233.4,29,130,166147,11699999,233.58,233.74,500,1,1,1,233.53,233.78,10,150,1,2,233.45,233.8,15,225,1,2,233.42,233.87,400,30,2,1,233.4,233.94,110,200,2,1,233.39,233.98,10,44,1,3,233.31,234.0,110,154,2,7,233.3,234.13,100,400,1,1,233.25,234.17,55,1,2,1,233.24,234.41,1,600,1,2,AAPL,0,0,0,0,0,-29,0,0,0,0,0,233.66000000000003
2024-10-21T12:00:51.988415192Z,2024-10-21 12:00:51.988248573+00:00,10,2,38,A,B,2,233.45,26,130,166619,11700000,233.58,233.74,500,1,1,1,233.53,233.78,10,150,1,2,233.45,233.8,41,225,2,2,233.42,233.87,400,30,2,1,233.4,233.94,110,200,2,1,233.39,233.98,10,44,1,3,233.31,234.0,110,154,2,7,233.3,234.13,100,400,1,1,233.25,234.17,55,1,2,1,233.24,234.41,1,600,1,2,AAPL,0,0,0,26,0,0,0,0,0,0,0,233.66000000000003
2024-10-21T12:00:52.042919153Z,2024-10-21 12:00:52.042752970+00:00,10,2,38,C,B,3,233.42,200,130,166183,11700053,233.58,233.74,500,1,1,1,233.53,233.78,10,150,1,2,233.45,233.8,41,225,2,2,233.42,233.87,200,30,1,1,233.4,233.94,110,200,2,1,233.39,233.98,10,44,1,3,233.31,234.0,110,154,2,7,233.3,234.13,100,400,1,1,233.25,234.17,55,1,2,1,233.24,234.41,1,600,1,2,AAPL,0,0,0,0,-200,0,0,0,0,0,0,233.66000000000003
2024-10-21T12:00:52.042931909Z,2024-10-21 12:00:52.042765437+00:00,10,2,38,A,B,2,233.49,200,130,166472,11700054,233.58,233.74,500,1,1,1,233.53,233.78,10,150,1,2,233.49,233.8,200,225,1,2,233.45,233.87,41,30,2,1,233.4,233.94,110,200,2,1,233.39,233.98,10,44,1,3,233.31,234.0,110,154,2,7,233.3,234.13,100,400,1,1,233.25,234.17,55,1,2,1,233.24,234.41,1,600,1,2,AAPL,0,0,0,200,41,0,0,0,0,0,0,233.66000000000003
2024-10-21T12:00:53.989490901Z,2024-10-21 12:00:53.989325211+00:00,10,2,38,C,B,2,233.49,200,130,165690,11702543,233.58,233.74,500,1,1,1,233.53,233.78,10,150,1,2,233.45,233.8,41,225,2,2,233.4,233.87,110,30,2,1,233.39,233.94,10,200,1,1,233.31,233.98,110,44,2,3,233.3,234.0,100,154,1,7,233.25,234.13,55,400,2,1,233.24,234.17,1,1,1,1,233.23,234.41,50,600,1,2,AAPL,0,0,0,-200,-41,-110,-10,-110,-100,-55,-1,233.66000000000003
2024-10-21T12:00:53.989503201Z,2024-10-21 12:00:53.989336874+00:00,10,2,38,A,B,2,233.47,400,130,166327,11702544,233.58,233.74,500,1,1,1,233.53,233.78,10,150,1,2,233.47,233.8,400,225,1,2,233.45,233.87,41,30,2,1,233.4,233.94,110,200,2,1,233.39,233.98,10,44,1,3,233.31,234.0,110,154,2,7,233.3,234.13,100,400,1,1,233.25,234.17,55,1,2,1,233.24,234.41,1,600,1,2,AAPL,0,0,0,400,41,110,10,110,100,55,1,233.66000000000003
2024-10-21T12:00:53.998707417Z,2024-10-21 12:00:53.998541135+00:00,10,2,38,C,B,3,233.45,26,130,166282,11702633,233.58,233.74,500,1,1,1,233.53,233.78,10,150,1,2,233.47,233.8,400,225,1,2,233.45,233.87,15,30,1,1,233.4,233.94,110,200,2,1,233.39,233.98,10,44,1,3,233.31,234.0,110,154,2,7,233.3,234.13,100,400,1,1,233.25,234.17,55,1,2,1,233.24,234.41,1,600,1,2,AAPL,0,0,0,0,-26,0,0,0,0,0,0,233.66000000000003
2024-10-21T12:00:53.998760827Z,2024-10-21 12:00:53.998594585+00:00,10,2,38,A,B,5,233.39,27,130,166242,11702634,233.58,233.74,500,1,1,1,233.53,233.78,10,150,1,2,233.47,233.8,400,225,1,2,233.45,233.87,15,30,1,1,233.4,233.94,110,200,2,1,233.39,233.98,37,44,2,3,233.31,234.0,110,154,2,7,233.3,234.13,100,400,1,1,233.25,234.17,55,1,2,1,233.24,234.41,1,600,1,2,AAPL,0,0,0,0,0,0,27,0,0,0,0,233.66000000000003
2024-10-21T12:00:57.883166284Z,2024-10-21 12:00:57.883000+00:00,10,2,38,C,B,5,233.39,27,130,166284,11706826,233.58,233.74,500,1,1,1,233.53,233.78,10,150,1,2,233.47,233.8,400,225,1,2,233.45,233.87,15,30,1,1,233.4,233.94,110,200,2,1,233.39,233.98,10,44,1,3,233.31,234.0,110,154,2,7,233.3,234.13,100,400,1,1,233.25,234.17,55,1,2,1,233.24,234.41,1,600,1,2,AAPL,0,0,0,0,0,0,-27,0,0,0,0,233.66000000000003
2024-10-21T12:00:57.883222977Z,2024-10-21 12:00:57.883056751+00:00,10,2,38,A,B,4,233.4,27,130,166226,11706827,233.58,233.74,500,1,1,1,233.53,233.78,10,150,1,2,233.47,233.8,400,225,1,2,233.45,233.87,15,30,1,1,233.4,233.94,137,200,3,1,233.39,233.98,10,44,1,3,233.31,234.0,110,154,2,7,233.3,234.13,100,400,1,1,233.25,234.17,55,1,2,1,233.24,234.41,1,600,1,2,AAPL,0,0,0,0,0,27,0,0,0,0,0,233.66000000000003
2024-10-21T12:00:58.996787112Z,2024-10-21 12:00:58.996621223+00:00,10,2,38,C,B,2,233.47,400,130,165889,11707811,233.58,233.74,500,1,1,1,233.53,233.78,10,150,1,2,233.45,233.8,15,225,1,2,233.4,233.87,137,30,3,1,233.39,233.94,10,200,1,1,233.31,233.98,110,44,2,3,233.3,234.0,100,154,1,7,233.25,234.13,55,400,2,1,233.24,234.17,1,1,1,1,233.23,234.41,50,600,1,2,AAPL,0,0,0,-400,-15,-137,-10,-110,-100,-55,-1,233.66000000000003
2024-10-21T12:00:58.996799769Z,2024-10-21 12:00:58.996633732+00:00,10,2,38,A,B,2,233.45,400,130,166037,11707812,233.58,233.74,500,1,1,1,233.53,233.78,10,150,1,2,233.45,233.8,415,225,2,2,233.4,233.87,137,30,3,1,233.39,233.94,10,200,1,1,233.31,233.98,110,44,2,3,233.3,234.0,100,154,1,7,233.25,234.13,55,400,2,1,233.24,234.17,1,1,1,1,233.23,234.41,50,600,1,2,AAPL,0,0,0,400,0,0,0,0,0,0,0,233.66000000000003
2024-10-21T12:01:00.317708313Z,2024-10-21 12:01:00.317542037+00:00,10,2,38,C,B,2,233.45,200,130,166276,11709726,233.58,233.74,500,1,1,1,233.53,233.78,10,150,1,2,233.45,233.8,215,225,2,2,233.4,233.87,137,30,3,1,233.39,233.94,10,200,1,1,233.31,233.98,110,44,2,3,233.3,234.0,100,154,1,7,233.25,234.13,55,400,2,1,233.24,234.17,1,1,1,1,233.23,234.41,50,600,1,2,AAPL,0,0,0,-200,0,0,0,0,0,0,0,233.66000000000003
2024-10-21T12:01:01.594785033Z,2024-10-21 12:01:01.594618675+00:00,10,2,38,A,B,2,233.45,200,130,166358,11711154,233.58,233.74,500,1,1,1,233.53,233.78,10,150,1,2,233.45,233.8,415,225,3,2,233.4,233.87,137,30,3,1,233.39,233.94,10,200,1,1,233.31,233.98,110,44,2,3,233.3,234.0,100,154,1,7,233.25,234.13,55,400,2,1,233.24,234.17,1,1,1,1,233.23,234.41,50,600,1,2,AAPL,0,0,0,200,0,0,0,0,0,0,0,233.66000000000003
2024-10-21T12:01:02.481581752Z,2024-10-21 12:01:02.481414409+00:00,10,2,38,C,B,2,233.45,200,130,167343,11712155,233.58,233.74,500,1,1,1,233.53,233.78,10,150,1,2,233.45,233.8,215,225,2,2,233.4,233.87,137,30,3,1,233.39,233.94,10,200,1,1,233.31,233.98,110,44,2,3,233.3,234.0,100,154,1,7,233.25,234.13,55,400,2,1,233.24,234.17,1,1,1,1,233.23,234.41,50,600,1,2,AAPL,0,0,0,-200,0,0,0,0,0,0,0,233.66000000000003
2024-10-21T12:01:02.481593552Z,2024-10-21 12:01:02.481427194+00:00,10,2,38,A,B,2,233.47,400,130,166358,11712156,233.58,233.74,500,1,1,1,233.53,233.78,10,150,1,2,233.47,233.8,400,225,1,2,233.45,233.87,15,30,1,1,233.4,233.94,137,200,3,1,233.39,233.98,10,44,1,3,233.31,234.0,110,154,2,7,233.3,234.13,100,400,1,1,233.25,234.17,55,1,2,1,233.24,234.41,1,600,1,2,AAPL,0,0,0,400,15,137,10,110,100,55,1,233.66000000000003
2024-10-21T12:01:02.481603814Z,2024-10-21 12:01:02.481437815+00:00,10,2,38,C,A,2,233.8,200,130,165999,11712157,233.58,233.74,500,1,1,1,233.53,233.78,10,150,1,2,233.47,233.8,400,25,1,1,233.45,233.87,15,30,1,1,233.4,233.94,137,200,3,1,233.39,233.98,10,44,1,3,233.31,234.0,110,154,2,7,233.3,234.13,100,400,1,1,233.25,234.17,55,1,2,1,233.24,234.41,1,600,1,2,AAPL,0,0,0,-200,0,0,0,0,0,0,0,233.66000000000003
2024-10-21T12:01:02.481616073Z,2024-10-21 12:01:02.481449719+00:00,10,2,38,A,A,3,233.82,200,130,166354,11712158,233.58,233.74,500,1,1,1,233.53,233.78,10,150,1,2,233.47,233.8,400,25,1,1,233.45,233.82,15,200,1,1,233.4,233.87,137,30,3,1,233.39,233.94,10,200,1,1,233.31,233.98,110,44,2,3,233.3,234.0,100,154,1,7,233.25,234.13,55,400,2,1,233.24,234.17,1,1,1,1,AAPL,0,0,0,0,200,30,200,44,154,400,1,233.66000000000003
2024-10-21T12:01:02.537579110Z,2024-10-21 12:01:02.537411197+00:00,10,2,38,A,A,3,233.81,200,130,167913,11712262,233.58,233.74,500,1,1,1,233.53,233.78,10,150,1,2,233.47,233.8,400,25,1,1,233.45,233.81,15,200,1,1,233.4,233.87,137,30,3,1,233.39,233.94,10,200,1,1,233.31,233.98,110,44,2,3,233.3,234.0,100,154,1,7,233.25,234.13,55,400,2,1,233.24,234.17,1,1,1,1,AAPL,0,0,0,0,200,0,0,0,0,0,0,233.66000000000003
2024-10-21T12:01:02.855371321Z,2024-10-21 12:01:02.855205010+00:00,10,2,38,A,B,2,233.48,400,130,166311,11713011,233.58,233.74,500,1,1,1,233.53,233.78,10,150,1,2,233.48,233.8,400,25,1,1,233.45,233.81,15,200,1,1,233.4,233.87,137,30,3,1,233.39,233.94,10,200,1,1,233.31,233.98,110,44,2,3,233.3,234.0,100,154,1,7,233.25,234.13,55,400,2,1,233.24,234.17,1,1,1,1,AAPL,0,0,0,400,0,0,0,0,0,0,0,233.66000000000003
2024-10-21T12:01:04.580398859Z,2024-10-21 12:01:04.580232646+00:00,10,2,38,C,B,2,233.48,400,130,166213,11716647,233.58,233.74,500,1,1,1,233.53,233.78,10,150,1,2,233.45,233.8,15,25,1,1,233.4,233.81,137,200,3,1,233.39,233.87,10,30,1,1,233.31,233.94,110,200,2,1,233.3,233.98,100,44,1,3,233.25,234.0,55,154,2,7,233.24,234.13,1,400,1,1,233.23,234.17,50,1,1,1,AAPL,0,0,0,-400,-15,-137,-10,-110,-100,-55,-1,233.66000000000003
2024-10-21T12:01:04.580410426Z,2024-10-21 12:01:04.580244325+00:00,10,2,38,A,B,2,233.46,400,130,166101,11716648,233.58,233.74,500,1,1,1,233.53,233.78,10,150,1,2,233.46,233.8,400,25,1,1,233.45,233.81,15,200,1,1,233.4,233.87,137,30,3,1,233.39,233.94,10,200,1,1,233.31,233.98,110,44,2,3,233.3,234.0,100,154,1,7,233.25,234.13,55,400,2,1,233.24,234.17,1,1,1,1,AAPL,0,0,0,400,15,137,10,110,100,55,1,233.66000000000003
2024-10-21T12:01:04.634868574Z,2024-10-21 12:01:04.634702173+00:00,10,2,38,A,A,2,233.79,200,130,166401,11716763,233.58,233.74,500,1,1,1,233.53,233.78,10,150,1,2,233.46,233.79,400,200,1,1,233.45,233.8,15,25,1,1,233.4,233.87,137,30,3,1,233.39,233.94,10,200,1,1,233.31,233.98,110,44,2,3,233.3,234.0,100,154,1,7,233.25,234.13,55,400,2,1,233.24,234.17,1,1,1,1,AAPL,0,0,0,200,25,0,0,0,0,0,0,233.66000000000003
2024-10-21T12:01:04.659147866Z,2024-10-21 12:01:04.658981181+00:00,10,2,38,C,A,4,233.87,30,130,166685,11716996,233.58,233.74,500,1,1,1,233.53,233.78,10,150,1,2,233.46,233.79,400,200,1,1,233.45,233.8,15,25,1,1,233.4,233.94,137,200,3,1,233.39,233.98,10,44,1,3,233.31,234.0,110,154,2,7,233.3,234.13,100,400,1,1,233.25,234.17,55,1,2,1,233.24,234.41,1,600,1,2,AAPL,0,0,0,0,0,30,200,44,154,400,1,233.66000000000003
2024-10-21T12:01:04.659209598Z,2024-10-21 12:01:04.659042935+00:00,10,2,38,A,A,4,233.86,30,130,166663,11716998,233.58,233.74,500,1,1,1,233.53,233.78,10,150,1,2,233.46,233.79,400,200,1,1,233.45,233.8,15,25,1,1,233.4,233.86,137,30,3,1,233.39,233.94,10,200,1,1,233.31,233.98,110,44,2,3,233.3,234.0,100,154,1,7,233.25,234.13,55,400,2,1,233.24,234.17,1,1,1,1,AAPL,0,0,0,0,0,30,200,44,154,400,1,233.66000000000003
2024-10-21T12:01:04.741795770Z,2024-10-21 12:01:04.741629959+00:00,10,2,38,C,B,2,233.46,400,130,165811,11717393,233.58,233.74,500,1,1,1,233.53,233.78,10,150,1,2,233.45,233.79,15,200,1,1,233.4,233.8,137,25,3,1,233.39,233.86,10,30,1,1,233.31,233.94,110,200,2,1,233.3,233.98,100,44,1,3,233.25,234.0,55,154,2,7,233.24,234.13,1,400,1,1,233.23,234.17,50,1,1,1,AAPL,0,0,0,-400,-15,-137,-10,-110,-100,-55,-1,233.66000000000003
2024-10-21T12:01:04.741807815Z,2024-10-21 12:01:04.741641481+00:00,10,2,38,A,B,2,233.45,400,130,166334,11717394,233.58,233.74,500,1,1,1,233.53,233.78,10,150,1,2,233.45,233.79,415,200,2,1,233.4,233.8,137,25,3,1,233.39,233.86,10,30,1,1,233.31,233.94,110,200,2,1,233.3,233.98,100,44,1,3,233.25,234.0,55,154,2,7,233.24,234.13,1,400,1,1,233.23,234.17,50,1,1,1,AAPL,0,0,0,400,0,0,0,0,0,0,0,233.66000000000003
2024-10-21T12:01:04.804593020Z,2024-10-21 12:01:04.804426665+00:00,10,2,38,A,A,1,233.78,200,130,166355,11717856,233.58,233.74,500,1,1,1,233.53,233.78,10,350,1,3,233.45,233.8,415,25,2,1,233.4,233.86,137,30,3,1,233.39,233.94,10,200,1,1,233.31,233.98,110,44,2,3,233.3,234.0,100,154,1,7,233.25,234.13,55,400,2,1,233.24,234.17,1,1,1,1,233.23,234.41,50,600,1,2,AAPL,0,0,200,200,25,30,200,44,154,400,1,233.66000000000003
2024-10-21T12:01:04.819075580Z,2024-10-21 12:01:04.818909404+00:00,10,2,38,C,B,3,233.4,27,130,166176,11717981,233.58,233.74,500,1,1,1,233.53,233.78,10,350,1,3,233.45,233.8,415,25,2,1,233.4,233.86,110,30,2,1,233.39,233.94,10,200,1,1,233.31,233.98,110,44,2,3,233.3,234.0,100,154,1,7,233.25,234.13,55,400,2,1,233.24,234.17,1,1,1,1,233.23,234.41,50,600,1,2,AAPL,0,0,0,0,-27,0,0,0,0,0,0,233.66000000000003
2024-10-21T12:01:04.819161084Z,2024-10-21 12:01:04.818994775+00:00,10,2,38,A,B,5,233.37,28,130,166309,11717982,233.58,233.74,500,1,1,1,233.53,233.78,10,350,1,3,233.45,233.8,415,25,2,1,233.4,233.86,110,30,2,1,233.39,233.94,10,200,1,1,233.37,233.98,28,44,1,3,233.31,234.0,110,154,2,7,233.3,234.13,100,400,1,1,233.25,234.17,55,1,2,1,233.24,234.41,1,600,1,2,AAPL,0,0,0,0,0,0,28,110,100,55,1,233.66000000000003
2024-10-21T12:01:04.857173618Z,2024-10-21 12:01:04.857007035+00:00,10,2,38,A,B,2,233.5,400,130,166583,11718365,233.58,233.74,500,1,1,1,233.53,233.78,10,350,1,3,233.5,233.8,400,25,1,1,233.45,233.86,15,30,1,1,233.4,233.94,110,200,2,1,233.39,233.98,10,44,1,3,233.37,234.0,28,154,1,7,233.31,234.13,110,400,2,1,233.3,234.17,100,1,1,1,233.25,234.41,55,600,2,2,AAPL,0,0,0,400,15,110,10,28,110,100,55,233.66000000000003
2024-10-21T12:01:05.923098824Z,2024-10-21 12:01:05.922932529+00:00,10,2,38,C,A,3,233.86,30,130,166295,11720081,233.58,233.74,500,1,1,1,233.53,233.78,10,350,1,3,233.5,233.8,400,25,1,1,233.45,233.94,15,200,1,1,233.4,233.98,110,44,2,3,233.39,234.0,10,154,1,7,233.37,234.13,28,400,1,1,233.31,234.17,110,1,2,1,233.3,234.41,100,600,1,2,233.25,234.43,55,5,2,1,AAPL,0,0,0,0,30,200,44,154,400,1,600,233.66000000000003
2024-10-21T12:01:05.923132218Z,2024-10-21 12:01:05.922966254+00:00,10,2,38,C,B,6,233.37,28,130,165964,11720082,233.58,233.74,500,1,1,1,233.53,233.78,10,350,1,3,233.5,233.8,400,25,1,1,233.45,233.94,15,200,1,1,233.4,233.98,110,44,2,3,233.39,234.0,10,154,1,7,233.31,234.13,110,400,2,1,233.3,234.17,100,1,1,1,233.25,234.41,55,600,2,2,233.24,234.43,1,5,1,1,AAPL,0,0,0,0,0,0,0,-28,-110,-100,-55,233.66000000000003
2024-10-21T12:01:05.923194726Z,2024-10-21 12:01:05.923028260+00:00,10,2,38,A,A,3,233.85,29,130,166466,11720083,233.58,233.74,500,1,1,1,233.53,233.78,10,350,1,3,233.5,233.8,400,25,1,1,233.45,233.85,15,29,1,1,233.4,233.94,110,200,2,1,233.39,233.98,10,44,1,3,233.31,234.0,110,154,2,7,233.3,234.13,100,400,1,1,233.25,234.17,55,1,2,1,233.24,234.41,1,600,1,2,AAPL,0,0,0,0,29,200,44,154,400,1,600,233.66000000000003
2024-10-21T12:01:05.923227216Z,2024-10-21 12:01:05.923061114+00:00,10,2,38,A,B,4,233.42,30,130,166102,11720084,233.58,233.74,500,1,1,1,233.53,233.78,10,350,1,3,233.5,233.8,400,25,1,1,233.45,233.85,15,29,1,1,233.42,233.94,30,200,1,1,233.4,233.98,110,44,2,3,233.39,234.0,10,154,1,7,233.31,234.13,110,400,2,1,233.3,234.17,100,1,1,1,233.25,234.41,55,600,2,2,AAPL,0,0,0,0,0,30,110,10,110,100,55,233.66000000000003
2024-10-21T12:01:06.781590289Z,2024-10-21 12:01:06.781424093+00:00,10,2,38,C,B,2,233.5,400,130,166196,11721177,233.58,233.74,500,1,1,1,233.53,233.78,10,350,1,3,233.45,233.8,15,25,1,1,233.42,233.85,30,29,1,1,233.4,233.94,110,200,2,1,233.39,233.98,10,44,1,3,233.31,234.0,110,154,2,7,233.3,234.13,100,400,1,1,233.25,234.17,55,1,2,1,233.24,234.41,1,600,1,2,AAPL,0,0,0,-400,-15,-30,-110,-10,-110,-100,-55,233.66000000000003
2024-10-21T12:01:06.781603653Z,2024-10-21 12:01:06.781437182+00:00,10,2,38,A,B,2,233.46,200,130,166471,11721178,233.58,233.74,500,1,1,1,233.53,233.78,10,350,1,3,233.46,233.8,200,25,1,1,233.45,233.85,15,29,1,1,233.42,233.94,30,200,1,1,233.4,233.98,110,44,2,3,233.39,234.0,10,154,1,7,233.31,234.13,110,400,2,1,233.3,234.17,100,1,1,1,233.25,234.41,55,600,2,2,AAPL,0,0,0,200,15,30,110,10,110,100,55,233.66000000000003
2024-10-21T12:01:07.185378576Z,2024-10-21 12:01:07.185212354+00:00,10,2,38,C,B,2,233.46,200,130,166222,11721941,233.58,233.74,500,1,1,1,233.53,233.78,10,350,1,3,233.45,233.8,15,25,1,1,233.42,233.85,30,29,1,1,233.4,233.94,110,200,2,1,233.39,233.98,10,44,1,3,233.31,234.0,110,154,2,7,233.3,234.13,100,400,1,1,233.25,234.17,55,1,2,1,233.24,234.41,1,600,1,2,AAPL,0,0,0,-200,-15,-30,-110,-10,-110,-100,-55,233.66000000000003
2024-10-21T12:01:07.185391192Z,2024-10-21 12:01:07.185224829+00:00,10,2,38,A,B,2,233.45,400,130,166363,11721942,233.58,233.74,500,1,1,1,233.53,233.78,10,350,1,3,233.45,233.8,415,25,2,1,233.42,233.85,30,29,1,1,233.4,233.94,110,200,2,1,233.39,233.98,10,44,1,3,233.31,234.0,110,154,2,7,233.3,234.13,100,400,1,1,233.25,234.17,55,1,2,1,233.24,234.41,1,600,1,2,AAPL,0,0,0,400,0,0,0,0,0,0,0,233.66000000000003
2024-10-21T12:01:07.565934131Z,2024-10-21 12:01:07.565767784+00:00,10,2,38,A,B,2,233.46,400,130,166347,11722744,233.58,233.74,500,1,1,1,233.53,233.78,10,350,1,3,233.46,233.8,400,25,1,1,233.45,233.85,15,29,1,1,233.42,233.94,30,200,1,1,233.4,233.98,110,44,2,3,233.39,234.0,10,154,1,7,233.31,234.13,110,400,2,1,233.3,234.17,100,1,1,1,233.25,234.41,55,600,2,2,AAPL,0,0,0,400,15,30,110,10,110,100,55,233.66000000000003
2024-10-21T12:01:07.595966036Z,2024-10-21 12:01:07.595799579+00:00,10,2,38,C,B,4,233.42,30,130,166457,11722855,233.58,233.74,500,1,1,1,233.53,233.78,10,350,1,3,233.46,233.8,400,25,1,1,233.45,233.85,15,29,1,1,233.4,233.94,110,200,2,1,233.39,233.98,10,44,1,3,233.31,234.0,110,154,2,7,233.3,234.13,100,400,1,1,233.25,234.17,55,1,2,1,233.24,234.41,1,600,1,2,AAPL,0,0,0,0,0,-30,-110,-10,-110,-100,-55,233.66000000000003
2024-10-21T12:01:07.596018631Z,2024-10-21 12:01:07.595852119+00:00,10,2,38,A,B,4,233.43,29,130,166512,11722856,233.58,233.74,500,1,1,1,233.53,233.78,10,350,1,3,233.46,233.8,400,25,1,1,233.45,233.85,15,29,1,1,233.43,233.94,29,200,1,1,233.4,233.98,110,44,2,3,233.39,234.0,10,154,1,7,233.31,234.13,110,400,2,1,233.3,234.17,100,1,1,1,233.25,234.41,55,600,2,2,AAPL,0,0,0,0,0,29,110,10,110,100,55,233.66000000000003
2024-10-21T12:01:09.438007491Z,2024-10-21 12:01:09.437841151+00:00,10,2,38,A,B,0,233.59,1,130,166340,11724947,233.59,233.74,1,1,1,1,233.58,233.78,500,350,1,3,233.53,233.8,10,25,1,1,233.46,233.85,400,29,1,1,233.45,233.94,15,200,1,1,233.43,233.98,29,44,1,3,233.4,234.0,110,154,2,7,233.39,234.13,10,400,1,1,233.31,234.17,110,1,2,1,233.3,234.41,100,600,1,2,AAPL,1,1,500,10,400,15,29,110,10,110,100,233.66500000000002
2024-10-21T12:01:11.781867916Z,2024-10-21 12:01:11.781701764+00:00,10,2,38,C,B,3,233.46,400,130,166152,11727281,233.59,233.74,1,1,1,1,233.58,233.78,500,350,1,3,233.53,233.8,10,25,1,1,233.45,233.85,15,29,1,1,233.43,233.94,29,200,1,1,233.4,233.98,110,44,2,3,233.39,234.0,10,154,1,7,233.31,234.13,110,400,2,1,233.3,234.17,100,1,1,1,233.25,234.41,55,600,2,2,AAPL,0,0,0,0,-400,-15,-29,-110,-10,-110,-100,233.66500000000002
2024-10-21T12:01:11.781879282Z,2024-10-21 12:01:11.781713240+00:00,10,2,38,A,B,3,233.45,400,130,166042,11727282,233.59,233.74,1,1,1,1,233.58,233.78,500,350,1,3,233.53,233.8,10,25,1,1,233.45,233.85,415,29,2,1,233.43,233.94,29,200,1,1,233.4,233.98,110,44,2,3,233.39,234.0,10,154,1,7,233.31,234.13,110,400,2,1,233.3,234.17,100,1,1,1,233.25,234.41,55,600,2,2,AAPL,0,0,0,0,400,0,0,0,0,0,0,233.66500000000002
2024-10-21T12:01:13.839145940Z,2024-10-21 12:01:13.838979517+00:00,10,2,38,C,B,4,233.43,29,130,166423,11728924,233.59,233.74,1,1,1,1,233.58,233.78,500,350,1,3,233.53,233.8,10,25,1,1,233.45,233.85,415,29,2,1,233.4,233.94,110,200,2,1,233.39,233.98,10,44,1,3,233.31,234.0,110,154,2,7,233.3,234.13,100,400,1,1,233.25,234.17,55,1,2,1,233.24,234.41,1,600,1,2,AAPL,0,0,0,0,0,-29,-110,-10,-110,-100,-55,233.66500000000002
2024-10-21T12:01:13.839237535Z,2024-10-21 12:01:13.839070933+00:00,10,2,38,A,B,4,233.44,28,130,166602,11728925,233.59,233.74,1,1,1,1,233.58,233.78,500,350,1,3,233.53,233.8,10,25,1,1,233.45,233.85,415,29,2,1,233.44,233.94,28,200,1,1,233.4,233.98,110,44,2,3,233.39,234.0,10,154,1,7,233.31,234.13,110,400,2,1,233.3,234.17,100,1,1,1,233.25,234.41,55,600,2,2,AAPL,0,0,0,0,0,28,110,10,110,100,55,233.66500000000002
2024-10-21T12:01:33.939462146Z,2024-10-21 12:01:33.939295458+00:00,10,2,38,A,B,3,233.5,400,130,166688,11745736,233.59,233.74,1,1,1,1,233.58,233.78,500,350,1,3,233.53,233.8,10,25,1,1,233.5,233.85,400,29,1,1,233.45,233.94,15,200,1,1,233.44,233.98,28,44,1,3,233.4,234.0,110,154,2,7,233.39,234.13,10,400,1,1,233.31,234.17,110,1,2,1,233.3,234.41,100,600,1,2,AAPL,0,0,0,0,400,15,28,110,10,110,100,233.66500000000002
2024-10-21T12:01:35.963067057Z,2024-10-21 12:01:35.962900590+00:00,10,2,38,A,A,1,233.78,200,130,166467,11747687,233.59,233.74,1,1,1,1,233.58,233.78,500,550,1,4,233.53,233.8,10,25,1,1,233.5,233.85,400,29,1,1,233.45,233.94,15,200,1,1,233.44,233.98,28,44,1,3,233.4,234.0,110,154,2,7,233.39,234.13,10,400,1,1,233.31,234.17,110,1,2,1,233.3,234.41,100,600,1,2,AAPL,0,0,200,0,0,0,0,0,0,0,0,233.66500000000002
2024-10-21T12:01:35.963634861Z,2024-10-21 12:01:35.963468384+00:00,10,2,38,A,A,2,233.8,28,130,166477,11747688,233.59,233.74,1,1,1,1,233.58,233.78,500,550,1,4,233.53,233.8,10,53,1,2,233.5,233.85,400,29,1,1,233.45,233.94,15,200,1,1,233.44,233.98,28,44,1,3,233.4,234.0,110,154,2,7,233.39,234.13,10,400,1,1,233.31,234.17,110,1,2,1,233.3,234.41,100,600,1,2,AAPL,0,0,0,28,0,0,0,0,0,0,0,233.66500000000002
2024-10-21T12:01:35.963668351Z,2024-10-21 12:01:35.963501831+00:00,10,2,38,C,A,3,233.85,29,130,166520,11747689,233.59,233.74,1,1,1,1,233.58,233.78,500,550,1,4,233.53,233.8,10,53,1,2,233.5,233.94,400,200,1,1,233.45,233.98,15,44,1,3,233.44,234.0,28,154,1,7,233.4,234.13,110,400,2,1,233.39,234.17,10,1,1,1,233.31,234.41,110,600,2,2,233.3,234.43,100,5,1,1,AAPL,0,0,0,0,29,200,44,154,400,1,600,233.66500000000002
2024-10-21T12:01:36.018160396Z,2024-10-21 12:01:36.017994443+00:00,10,2,38,C,A,1,233.78,200,130,165953,11747708,233.59,233.74,1,1,1,1,233.58,233.78,500,350,1,3,233.53,233.8,10,53,1,2,233.5,233.94,400,200,1,1,233.45,233.98,15,44,1,3,233.44,234.0,28,154,1,7,233.4,234.13,110,400,2,1,233.39,234.17,10,1,1,1,233.31,234.41,110,600,2,2,233.3,234.43,100,5,1,1,AAPL,0,0,-200,0,0,0,0,0,0,0,0,233.66500000000002
2024-10-21T12:01:36.018174483Z,2024-10-21 12:01:36.018008103+00:00,10,2,38,A,A,0,233.74,200,130,166380,11747709,233.59,233.74,1,201,1,2,233.58,233.78,500,150,1,2,233.53,233.8,10,53,1,2,233.5,233.94,400,200,1,1,233.45,233.98,15,44,1,3,233.44,234.0,28,154,1,7,233.4,234.13,110,400,2,1,233.39,234.17,10,1,1,1,233.31,234.41,110,600,2,2,233.3,234.43,100,5,1,1,AAPL,200,200,-200,0,0,0,0,0,0,0,0,233.66500000000002
2024-10-21T12:01:37.328539236Z,2024-10-21 12:01:37.328372588+00:00,10,2,38,A,A,2,233.79,28,130,166648,11748684,233.59,233.74,1,201,1,2,233.58,233.78,500,150,1,2,233.53,233.79,10,28,1,1,233.5,233.8,400,53,1,2,233.45,233.94,15,200,1,1,233.44,233.98,28,44,1,3,233.4,234.0,110,154,2,7,233.39,234.13,10,400,1,1,233.31,234.17,110,1,2,1,233.3,234.41,100,600,1,2,AAPL,0,0,0,28,53,200,44,154,400,1,600,233.66500000000002
2024-10-21T12:01:37.328615431Z,2024-10-21 12:01:37.328448858+00:00,10,2,38,A,A,0,233.73,200,130,166573,11748686,233.59,233.73,1,200,1,1,233.58,233.74,500,1,1,1,233.53,233.78,10,150,1,2,233.5,233.79,400,28,1,1,233.45,233.8,15,53,1,2,233.44,233.94,28,200,1,1,233.4,233.98,110,44,2,3,233.39,234.0,10,154,1,7,233.31,234.13,110,400,2,1,233.3,234.17,100,1,1,1,AAPL,200,200,1,150,28,53,200,44,154,400,1,233.66
2024-10-21T12:01:37.328648871Z,2024-10-21 12:01:37.328482738+00:00,10,2,38,C,A,4,233.8,28,130,166133,11748688,233.59,233.73,1,200,1,1,233.58,233.74,500,1,1,1,233.53,233.78,10,150,1,2,233.5,233.79,400,28,1,1,233.45,233.8,15,25,1,1,233.44,233.94,28,200,1,1,233.4,233.98,110,44,2,3,233.39,234.0,10,154,1,7,233.31,234.13,110,400,2,1,233.3,234.17,100,1,1,1,AAPL,0,0,0,0,0,-28,0,0,0,0,0,233.66
2024-10-21T12:01:37.359390875Z,2024-10-21 12:01:37.359224760+00:00,10,2,38,C,B,5,233.44,28,130,166115,11748965,233.59,233.73,1,200,1,1,233.58,233.74,500,1,1,1,233.53,233.78,10,150,1,2,233.5,233.79,400,28,1,1,233.45,233.8,15,25,1,1,233.4,233.94,110,200,2,1,233.39,233.98,10,44,1,3,233.31,234.0,110,154,2,7,233.3,234.13,100,400,1,1,233.25,234.17,55,1,2,1,AAPL,0,0,0,0,0,0,-28,-110,-10,-110,-100,233.66
2024-10-21T12:01:37.359504379Z,2024-10-21 12:01:37.359337685+00:00,10,2,38,A,B,5,233.42,29,130,166694,11748966,233.59,233.73,1,200,1,1,233.58,233.74,500,1,1,1,233.53,233.78,10,150,1,2,233.5,233.79,400,28,1,1,233.45,233.8,15,25,1,1,233.42,233.94,29,200,1,1,233.4,233.98,110,44,2,3,233.39,234.0,10,154,1,7,233.31,234.13,110,400,2,1,233.3,234.17,100,1,1,1,AAPL,0,0,0,0,0,0,29,110,10,110,100,233.66
2024-10-21T12:01:37.397118895Z,2024-10-21 12:01:37.396952090+00:00,10,2,38,A,B,3,233.51,200,130,166805,11749029,233.59,233.73,1,200,1,1,233.58,233.74,500,1,1,1,233.53,233.78,10,150,1,2,233.51,233.79,200,28,1,1,233.45,233.8,15,25,1,1,233.42,233.94,29,200,1,1,233.4,233.98,110,44,2,3,233.39,234.0,10,154,1,7,233.31,234.13,110,400,2,1,233.3,234.17,100,1,1,1,AAPL,0,0,0,0,200,0,0,0,0,0,0,233.66
2024-10-21T12:01:37.923172468Z,2024-10-21 12:01:37.923006207+00:00,10,2,38,C,A,3,233.79,28,130,166261,11749436,233.59,233.73,1,200,1,1,233.58,233.74,500,1,1,1,233.53,233.78,10,150,1,2,233.51,233.8,200,25,1,1,233.45,233.94,15,200,1,1,233.42,233.98,29,44,1,3,233.4,234.0,110,154,2,7,233.39,234.13,10,400,1,1,233.31,234.17,110,1,2,1,233.3,234.41,100,600,1,2,AAPL,0,0,0,0,28,25,200,44,154,400,1,233.66
