ts_recv,ts_event,rtype,publisher_id,instrument_id,action,side,depth,price,size,flags,ts_in_delta,sequence,bid_px_00,ask_px_00,bid_sz_00,ask_sz_00,bid_ct_00,ask_ct_00,bid_px_01,ask_px_01,bid_sz_01,ask_sz_01,bid_ct_01,ask_ct_01,bid_px_02,ask_px_02,bid_sz_02,ask_sz_02,bid_ct_02,ask_ct_02,bid_px_03,ask_px_03,bid_sz_03,ask_sz_03,bid_ct_03,ask_ct_03,bid_px_04,ask_px_04,bid_sz_04,ask_sz_04,bid_ct_04,ask_ct_04,bid_px_05,ask_px_05,bid_sz_05,ask_sz_05,bid_ct_05,ask_ct_05,bid_px_06,ask_px_06,bid_sz_06,ask_sz_06,bid_ct_06,ask_ct_06,bid_px_07,ask_px_07,bid_sz_07,ask_sz_07,bid_ct_07,ask_ct_07,bid_px_08,ask_px_08,bid_sz_08,ask_sz_08,bid_ct_08,ask_ct_08,bid_px_09,ask_px_09,bid_sz_09,ask_sz_09,bid_ct_09,ask_ct_09,symbol,best_level_ofi,ofi_level_0,ofi_level_1,ofi_level_2,ofi_level_3,ofi_level_4,ofi_level_5,ofi_level_6,ofi_level_7,ofi_level_8,ofi_level_9,mid_price
2024-10-21T12:22:23.088319645Z,2024-10-21 12:22:23.088151194+00:00,10,2,38,A,B,0,233.91,100,128,168451,12895372,233.91,234.0,100,2,1,1,233.8,234.09,5,27,1,1,233.74,234.1,200,100,1,1,233.73,234.13,29,400,1,1,233.7,234.17,1200,1,1,1,233.66,234.25,1,100,1,1,233.58,234.41,505,500,2,1,233.53,234.43,10,105,1,2,233.5,234.5,100,63,1,4,233.45,234.75,15,1,1,1,AAPL,100,100,5,200,29,1200,1,505,10,100,15,233.95499999999998
2024-10-21T12:22:23.116317544Z,2024-10-21 12:22:23.116151189+00:00,10,2,38,A,A,1,234.08,200,130,166355,12895511,233.91,234.0,100,2,1,1,233.8,234.08,5,200,1,1,233.74,234.09,200,27,1,1,233.73,234.1,29,100,1,1,233.7,234.13,1200,400,1,1,233.66,234.17,1,1,1,1,233.58,234.25,505,100,2,1,233.53,234.41,10,500,1,1,233.5,234.43,100,105,1,2,233.45,234.5,15,63,1,4,AAPL,0,0,200,27,100,400,1,100,500,105,63,233.95499999999998
2024-10-21T12:22:23.242021318Z,2024-10-21 12:22:23.241854315+00:00,10,2,38,A,A,1,234.07,200,130,167003,12895969,233.91,234.0,100,2,1,1,233.8,234.07,5,200,1,1,233.74,234.09,200,27,1,1,233.73,234.1,29,100,1,1,233.7,234.13,1200,400,1,1,233.66,234.17,1,1,1,1,233.58,234.25,505,100,2,1,233.53,234.41,10,500,1,1,233.5,234.43,100,105,1,2,233.45,234.5,15,63,1,4,AAPL,0,0,200,0,0,0,0,0,0,0,0,233.95499999999998
2024-10-21T12:22:26.043193578Z,2024-10-21 12:22:26.043027067+00:00,10,2,38,A,A,1,234.07,200,130,166511,12901196,233.91,234.0,100,2,1,1,233.8,234.07,5,400,1,2,233.74,234.09,200,27,1,1,233.73,234.1,29,100,1,1,233.7,234.13,1200,400,1,1,233.66,234.17,1,1,1,1,233.58,234.25,505,100,2,1,233.53,234.41,10,500,1,1,233.5,234.43,100,105,1,2,233.45,234.5,15,63,1,4,AAPL,0,0,200,0,0,0,0,0,0,0,0,233.95499999999998
2024-10-21T12:22:26.221605392Z,2024-10-21 12:22:26.221438925+00:00,10,2,38,A,B,2,233.78,200,130,166467,12901441,233.91,234.0,100,2,1,1,233.8,234.07,5,400,1,2,233.78,234.09,200,27,1,1,233.73,234.1,29,100,1,1,233.7,234.13,1200,400,1,1,233.66,234.17,1,1,1,1,233.58,234.25,505,100,2,1,233.53,234.41,10,500,1,1,233.5,234.43,100,105,1,2,233.45,234.5,15,63,1,4,AAPL,0,0,0,200,0,0,0,0,0,0,0,233.95499999999998
2024-10-21T12:22:29.394326484Z,2024-10-21 12:22:29.394160247+00:00,10,2,38,A,B,2,233.79,200,130,166237,12905660,233.91,234.0,100,2,1,1,233.8,234.07,5,400,1,2,233.79,234.09,200,27,1,1,233.73,234.1,29,100,1,1,233.7,234.13,1200,400,1,1,233.66,234.17,1,1,1,1,233.58,234.25,505,100,2,1,233.53,234.41,10,500,1,1,233.5,234.43,100,105,1,2,233.45,234.5,15,63,1,4,AAPL,0,0,0,200,0,0,0,0,0,0,0,233.95499999999998
2024-10-21T12:22:36.707629405Z,2024-10-21 12:22:36.707463498+00:00,10,2,38,C,A,2,234.09,27,130,165907,12912830,233.91,234.0,100,2,1,1,233.8,234.07,5,400,1,2,233.79,234.1,200,100,1,1,233.73,234.13,29,400,1,1,233.7,234.17,1200,1,1,1,233.66,234.25,1,100,1,1,233.58,234.41,505,500,2,1,233.53,234.43,10,105,1,2,233.5,234.5,100,63,1,4,233.45,234.75,15,1,1,1,AAPL,0,0,0,27,100,400,1,100,500,105,63,233.95499999999998
2024-10-21T12:22:36.707672458Z,2024-10-21 12:22:36.707506060+00:00,10,2,38,A,A,2,234.08,26,130,166398,12912831,233.91,234.0,100,2,1,1,233.8,234.07,5,400,1,2,233.79,234.08,200,26,1,1,233.73,234.1,29,100,1,1,233.7,234.13,1200,400,1,1,233.66,234.17,1,1,1,1,233.58,234.25,505,100,2,1,233.53,234.41,10,500,1,1,233.5,234.43,100,105,1,2,233.45,234.5,15,63,1,4,AAPL,0,0,0,26,100,400,1,100,500,105,63,233.95499999999998
2024-10-21T12:22:40.428593628Z,2024-10-21 12:22:40.428425309+00:00,10,2,38,T,N,0,233.92,100,0,168319,12916971,233.91,234.0,100,2,1,1,233.8,234.07,5,400,1,2,233.79,234.08,200,26,1,1,233.73,234.1,29,100,1,1,233.7,234.13,1200,400,1,1,233.66,234.17,1,1,1,1,233.58,234.25,505,100,2,1,233.53,234.41,10,500,1,1,233.5,234.43,100,105,1,2,233.45,234.5,15,63,1,4,AAPL,0,0,0,0,0,0,0,0,0,0,0,233.95499999999998
2024-10-21T12:22:40.428593628Z,2024-10-21 12:22:40.428425309+00:00,10,2,38,T,N,0,233.92,40,130,168319,12916972,233.91,234.0,100,2,1,1,233.8,234.07,5,400,1,2,233.79,234.08,200,26,1,1,233.73,234.1,29,100,1,1,233.7,234.13,1200,400,1,1,233.66,234.17,1,1,1,1,233.58,234.25,505,100,2,1,233.53,234.41,10,500,1,1,233.5,234.43,100,105,1,2,233.45,234.5,15,63,1,4,AAPL,0,0,0,0,0,0,0,0,0,0,0,233.95499999999998
2024-10-21T12:23:09.008779869Z,2024-10-21 12:23:09.008613373+00:00,10,2,38,A,B,0,233.93,4,130,166496,12947436,233.93,234.0,4,2,1,1,233.91,234.07,100,400,1,2,233.8,234.08,5,26,1,1,233.79,234.1,200,100,1,1,233.73,234.13,29,400,1,1,233.7,234.17,1200,1,1,1,233.66,234.25,1,100,1,1,233.58,234.41,505,500,2,1,233.53,234.43,10,105,1,2,233.5,234.5,100,63,1,4,AAPL,4,4,100,5,200,29,1200,1,505,10,100,233.965
2024-10-21T12:23:09.008787962Z,2024-10-21 12:23:09.008621599+00:00,10,2,38,A,B,1,233.92,100,130,166363,12947438,233.93,234.0,4,2,1,1,233.92,234.07,100,400,1,2,233.91,234.08,100,26,1,1,233.8,234.1,5,100,1,1,233.79,234.13,200,400,1,1,233.73,234.17,29,1,1,1,233.7,234.25,1200,100,1,1,233.66,234.41,1,500,1,1,233.58,234.43,505,105,2,2,233.53,234.5,10,63,1,4,AAPL,0,0,100,100,5,200,29,1200,1,505,10,233.965
2024-10-21T12:23:09.009139279Z,2024-10-21 12:23:09.008973422+00:00,10,2,38,C,B,1,233.92,100,130,165857,12947440,233.93,234.0,4,2,1,1,233.91,234.07,100,400,1,2,233.8,234.08,5,26,1,1,233.79,234.1,200,100,1,1,233.73,234.13,29,400,1,1,233.7,234.17,1200,1,1,1,233.66,234.25,1,100,1,1,233.58,234.41,505,500,2,1,233.53,234.43,10,105,1,2,233.5,234.5,100,63,1,4,AAPL,0,0,-100,-100,-5,-200,-29,-1200,-1,-505,-10,233.965
2024-10-21T12:23:09.009232105Z,2024-10-21 12:23:09.009065871+00:00,10,2,38,A,B,0,233.95,723,130,166234,12947441,233.95,234.0,723,2,1,1,233.93,234.07,4,400,1,2,233.91,234.08,100,26,1,1,233.8,234.1,5,100,1,1,233.79,234.13,200,400,1,1,233.73,234.17,29,1,1,1,233.7,234.25,1200,100,1,1,233.66,234.41,1,500,1,1,233.58,234.43,505,105,2,2,233.53,234.5,10,63,1,4,AAPL,723,723,4,100,5,200,29,1200,1,505,10,233.975
2024-10-21T12:23:09.047215822Z,2024-10-21 12:23:09.047049975+00:00,10,2,38,C,B,1,233.93,4,130,165847,12947464,233.95,234.0,723,2,1,1,233.91,234.07,100,400,1,2,233.8,234.08,5,26,1,1,233.79,234.1,200,100,1,1,233.73,234.13,29,400,1,1,233.7,234.17,1200,1,1,1,233.66,234.25,1,100,1,1,233.58,234.41,505,500,2,1,233.53,234.43,10,105,1,2,233.5,234.5,100,63,1,4,AAPL,0,0,-4,-100,-5,-200,-29,-1200,-1,-505,-10,233.975
2024-10-21T12:23:09.047694600Z,2024-10-21 12:23:09.047528450+00:00,10,2,38,C,B,1,233.91,100,130,166150,12947466,233.95,234.0,723,2,1,1,233.8,234.07,5,400,1,2,233.79,234.08,200,26,1,1,233.73,234.1,29,100,1,1,233.7,234.13,1200,400,1,1,233.66,234.17,1,1,1,1,233.58,234.25,505,100,2,1,233.53,234.41,10,500,1,1,233.5,234.43,100,105,1,2,233.45,234.5,15,63,1,4,AAPL,0,0,-100,-5,-200,-29,-1200,-1,-505,-10,-100,233.975
2024-10-21T12:23:09.079945758Z,2024-10-21 12:23:09.079779485+00:00,10,2,38,C,A,1,234.07,200,130,166273,12947479,233.95,234.0,723,2,1,1,233.8,234.07,5,200,1,1,233.79,234.08,200,26,1,1,233.73,234.1,29,100,1,1,233.7,234.13,1200,400,1,1,233.66,234.17,1,1,1,1,233.58,234.25,505,100,2,1,233.53,234.41,10,500,1,1,233.5,234.43,100,105,1,2,233.45,234.5,15,63,1,4,AAPL,0,0,-200,0,0,0,0,0,0,0,0,233.975
2024-10-21T12:23:09.081865026Z,2024-10-21 12:23:09.081699019+00:00,10,2,38,A,B,2,233.79,200,130,166007,12947480,233.95,234.0,723,2,1,1,233.8,234.07,5,200,1,1,233.79,234.08,400,26,2,1,233.73,234.1,29,100,1,1,233.7,234.13,1200,400,1,1,233.66,234.17,1,1,1,1,233.58,234.25,505,100,2,1,233.53,234.41,10,500,1,1,233.5,234.43,100,105,1,2,233.45,234.5,15,63,1,4,AAPL,0,0,0,200,0,0,0,0,0,0,0,233.975
2024-10-21T12:23:09.087941406Z,2024-10-21 12:23:09.087775155+00:00,10,2,38,C,B,2,233.79,200,130,166251,12947484,233.95,234.0,723,2,1,1,233.8,234.07,5,200,1,1,233.79,234.08,200,26,1,1,233.73,234.1,29,100,1,1,233.7,234.13,1200,400,1,1,233.66,234.17,1,1,1,1,233.58,234.25,505,100,2,1,233.53,234.41,10,500,1,1,233.5,234.43,100,105,1,2,233.45,234.5,15,63,1,4,AAPL,0,0,0,-200,0,0,0,0,0,0,0,233.975
2024-10-21T12:23:09.087951571Z,2024-10-21 12:23:09.087785825+00:00,10,2,38,C,B,2,233.79,200,130,165746,12947485,233.95,234.0,723,2,1,1,233.8,234.07,5,200,1,1,233.73,234.08,29,26,1,1,233.7,234.1,1200,100,1,1,233.66,234.13,1,400,1,1,233.58,234.17,505,1,2,1,233.53,234.25,10,100,1,1,233.5,234.41,100,500,1,1,233.45,234.43,15,105,1,2,233.4,234.5,110,63,2,4,AAPL,0,0,0,-200,-29,-1200,-1,-505,-10,-100,-15,233.975
2024-10-21T12:23:09.087963244Z,2024-10-21 12:23:09.087797026+00:00,10,2,38,A,B,2,233.78,200,130,166218,12947486,233.95,234.0,723,2,1,1,233.8,234.07,5,200,1,1,233.78,234.08,200,26,1,1,233.73,234.1,29,100,1,1,233.7,234.13,1200,400,1,1,233.66,234.17,1,1,1,1,233.58,234.25,505,100,2,1,233.53,234.41,10,500,1,1,233.5,234.43,100,105,1,2,233.45,234.5,15,63,1,4,AAPL,0,0,0,200,29,1200,1,505,10,100,15,233.975
2024-10-21T12:23:09.133495750Z,2024-10-21 12:23:09.133329159+00:00,10,2,38,A,B,2,233.79,200,130,166591,12947507,233.95,234.0,723,2,1,1,233.8,234.07,5,200,1,1,233.79,234.08,200,26,1,1,233.73,234.1,29,100,1,1,233.7,234.13,1200,400,1,1,233.66,234.17,1,1,1,1,233.58,234.25,505,100,2,1,233.53,234.41,10,500,1,1,233.5,234.43,100,105,1,2,233.45,234.5,15,63,1,4,AAPL,0,0,0,200,0,0,0,0,0,0,0,233.975
2024-10-21T12:23:09.155801329Z,2024-10-21 12:23:09.155634175+00:00,10,2,38,C,B,3,233.73,29,130,167154,12947520,233.95,234.0,723,2,1,1,233.8,234.07,5,200,1,1,233.79,234.08,200,26,1,1,233.7,234.1,1200,100,1,1,233.66,234.13,1,400,1,1,233.58,234.17,505,1,2,1,233.53,234.25,10,100,1,1,233.5,234.41,100,500,1,1,233.45,234.43,15,105,1,2,233.4,234.5,110,63,2,4,AAPL,0,0,0,0,-29,-1200,-1,-505,-10,-100,-15,233.975
2024-10-21T12:23:09.155898909Z,2024-10-21 12:23:09.155732424+00:00,10,2,38,A,B,3,233.77,26,130,166485,12947521,233.95,234.0,723,2,1,1,233.8,234.07,5,200,1,1,233.79,234.08,200,26,1,1,233.77,234.1,26,100,1,1,233.7,234.13,1200,400,1,1,233.66,234.17,1,1,1,1,233.58,234.25,505,100,2,1,233.53,234.41,10,500,1,1,233.5,234.43,100,105,1,2,233.45,234.5,15,63,1,4,AAPL,0,0,0,0,26,1200,1,505,10,100,15,233.975
2024-10-21T12:23:09.242988929Z,2024-10-21 12:23:09.242822823+00:00,10,2,38,C,A,2,234.08,26,130,166106,12947586,233.95,234.0,723,2,1,1,233.8,234.07,5,200,1,1,233.79,234.1,200,100,1,1,233.77,234.13,26,400,1,1,233.7,234.17,1200,1,1,1,233.66,234.25,1,100,1,1,233.58,234.41,505,500,2,1,233.53,234.43,10,105,1,2,233.5,234.5,100,63,1,4,233.45,234.75,15,1,1,1,AAPL,0,0,0,26,100,400,1,100,500,105,63,233.975
2024-10-21T12:23:09.243042523Z,2024-10-21 12:23:09.242876186+00:00,10,2,38,A,A,4,234.14,29,130,166337,12947587,233.95,234.0,723,2,1,1,233.8,234.07,5,200,1,1,233.79,234.1,200,100,1,1,233.77,234.13,26,400,1,1,233.7,234.14,1200,29,1,1,233.66,234.17,1,1,1,1,233.58,234.25,505,100,2,1,233.53,234.41,10,500,1,1,233.5,234.43,100,105,1,2,233.45,234.5,15,63,1,4,AAPL,0,0,0,0,0,29,1,100,500,105,63,233.975
2024-10-21T12:23:09.312801998Z,2024-10-21 12:23:09.312635376+00:00,10,2,38,A,B,1,233.81,200,130,166622,12947706,233.95,234.0,723,2,1,1,233.81,234.07,200,200,1,1,233.8,234.1,5,100,1,1,233.77,234.13,26,400,1,1,233.7,234.14,1200,29,1,1,233.66,234.17,1,1,1,1,233.58,234.25,505,100,2,1,233.53,234.41,10,500,1,1,233.5,234.43,100,105,1,2,233.45,234.5,15,63,1,4,AAPL,0,0,200,5,0,0,0,0,0,0,0,233.975
2024-10-21T12:23:09.319634626Z,2024-10-21 12:23:09.319468618+00:00,10,2,38,A,A,1,234.07,200,130,166008,12947710,233.95,234.0,723,2,1,1,233.81,234.07,200,400,1,2,233.8,234.1,5,100,1,1,233.77,234.13,26,400,1,1,233.7,234.14,1200,29,1,1,233.66,234.17,1,1,1,1,233.58,234.25,505,100,2,1,233.53,234.41,10,500,1,1,233.5,234.43,100,105,1,2,233.45,234.5,15,63,1,4,AAPL,0,0,200,0,0,0,0,0,0,0,0,233.975
2024-10-21T12:23:09.729631282Z,2024-10-21 12:23:09.729465211+00:00,10,2,38,C,A,1,234.07,200,130,166071,12947991,233.95,234.0,723,2,1,1,233.81,234.07,200,200,1,1,233.8,234.1,5,100,1,1,233.77,234.13,26,400,1,1,233.7,234.14,1200,29,1,1,233.66,234.17,1,1,1,1,233.58,234.25,505,100,2,1,233.53,234.41,10,500,1,1,233.5,234.43,100,105,1,2,233.45,234.5,15,63,1,4,AAPL,0,0,-200,0,0,0,0,0,0,0,0,233.975
2024-10-21T12:23:09.784241575Z,2024-10-21 12:23:09.784075201+00:00,10,2,38,A,B,1,233.82,200,130,166374,12948038,233.95,234.0,723,2,1,1,233.82,234.07,200,200,1,1,233.8,234.1,5,100,1,1,233.77,234.13,26,400,1,1,233.7,234.14,1200,29,1,1,233.66,234.17,1,1,1,1,233.58,234.25,505,100,2,1,233.53,234.41,10,500,1,1,233.5,234.43,100,105,1,2,233.45,234.5,15,63,1,4,AAPL,0,0,200,0,0,0,0,0,0,0,0,233.975
2024-10-21T12:23:11.099239175Z,2024-10-21 12:23:11.099071185+00:00,10,2,38,T,A,0,233.95,200,130,167990,12949099,233.95,234.0,723,2,1,1,233.82,234.07,200,200,1,1,233.8,234.1,5,100,1,1,233.77,234.13,26,400,1,1,233.7,234.14,1200,29,1,1,233.66,234.17,1,1,1,1,233.58,234.25,505,100,2,1,233.53,234.41,10,500,1,1,233.5,234.43,100,105,1,2,233.45,234.5,15,63,1,4,AAPL,0,0,0,0,0,0,0,0,0,0,0,233.975
2024-10-21T12:23:11.099239175Z,2024-10-21 12:23:11.099071185+00:00,10,2,38,C,B,0,233.95,200,130,167990,12949099,233.95,234.0,523,2,1,1,233.82,234.07,200,200,1,1,233.8,234.1,5,100,1,1,233.77,234.13,26,400,1,1,233.7,234.14,1200,29,1,1,233.66,234.17,1,1,1,1,233.58,234.25,505,100,2,1,233.53,234.41,10,500,1,1,233.5,234.43,100,105,1,2,233.45,234.5,15,63,1,4,AAPL,-200,-200,0,0,0,0,0,0,0,0,0,233.975
2024-10-21T12:23:11.099304941Z,2024-10-21 12:23:11.099138993+00:00,10,2,38,C,B,1,233.82,200,130,165948,12949100,233.95,234.0,523,2,1,1,233.8,234.07,5,200,1,1,233.77,234.1,26,100,1,1,233.7,234.13,1200,400,1,1,233.66,234.14,1,29,1,1,233.58,234.17,505,1,2,1,233.53,234.25,10,100,1,1,233.5,234.41,100,500,1,1,233.45,234.43,15,105,1,2,233.4,234.5,110,63,2,4,AAPL,0,0,-200,-5,-26,-1200,-1,-505,-10,-100,-15,233.975
2024-10-21T12:23:11.172041039Z,2024-10-21 12:23:11.171874633+00:00,10,2,38,A,A,1,234.07,200,130,166406,12949158,233.95,234.0,523,2,1,1,233.8,234.07,5,400,1,2,233.77,234.1,26,100,1,1,233.7,234.13,1200,400,1,1,233.66,234.14,1,29,1,1,233.58,234.17,505,1,2,1,233.53,234.25,10,100,1,1,233.5,234.41,100,500,1,1,233.45,234.43,15,105,1,2,233.4,234.5,110,63,2,4,AAPL,0,0,200,0,0,0,0,0,0,0,0,233.975
2024-10-21T12:23:11.208329414Z,2024-10-21 12:23:11.208162821+00:00,10,2,38,A,B,1,233.82,200,130,166593,12949167,233.95,234.0,523,2,1,1,233.82,234.07,200,400,1,2,233.8,234.1,5,100,1,1,233.77,234.13,26,400,1,1,233.7,234.14,1200,29,1,1,233.66,234.17,1,1,1,1,233.58,234.25,505,100,2,1,233.53,234.41,10,500,1,1,233.5,234.43,100,105,1,2,233.45,234.5,15,63,1,4,AAPL,0,0,200,5,26,1200,1,505,10,100,15,233.975
2024-10-21T12:23:12.139769418Z,2024-10-21 12:23:12.139603042+00:00,10,2,38,A,B,1,233.84,200,130,166376,12950444,233.95,234.0,523,2,1,1,233.84,234.07,200,400,1,2,233.8,234.1,5,100,1,1,233.77,234.13,26,400,1,1,233.7,234.14,1200,29,1,1,233.66,234.17,1,1,1,1,233.58,234.25,505,100,2,1,233.53,234.41,10,500,1,1,233.5,234.43,100,105,1,2,233.45,234.5,15,63,1,4,AAPL,0,0,200,0,0,0,0,0,0,0,0,233.975
2024-10-21T12:23:12.190290255Z,2024-10-21 12:23:12.190123660+00:00,10,2,38,C,A,4,234.14,29,130,166595,12950624,233.95,234.0,523,2,1,1,233.84,234.07,200,400,1,2,233.8,234.1,5,100,1,1,233.77,234.13,26,400,1,1,233.7,234.17,1200,1,1,1,233.66,234.25,1,100,1,1,233.58,234.41,505,500,2,1,233.53,234.43,10,105,1,2,233.5,234.5,100,63,1,4,233.45,234.75,15,1,1,1,AAPL,0,0,0,0,0,29,1,100,500,105,63,233.975
2024-10-21T12:23:12.190410859Z,2024-10-21 12:23:12.190244811+00:00,10,2,38,A,A,2,234.09,28,130,166048,12950625,233.95,234.0,523,2,1,1,233.84,234.07,200,400,1,2,233.8,234.09,5,28,1,1,233.77,234.1,26,100,1,1,233.7,234.13,1200,400,1,1,233.66,234.17,1,1,1,1,233.58,234.25,505,100,2,1,233.53,234.41,10,500,1,1,233.5,234.43,100,105,1,2,233.45,234.5,15,63,1,4,AAPL,0,0,0,28,100,400,1,100,500,105,63,233.975
2024-10-21T12:23:12.195419708Z,2024-10-21 12:23:12.195254017+00:00,10,2,38,C,A,2,234.09,28,130,165691,12950641,233.95,234.0,523,2,1,1,233.84,234.07,200,400,1,2,233.8,234.1,5,100,1,1,233.77,234.13,26,400,1,1,233.7,234.17,1200,1,1,1,233.66,234.25,1,100,1,1,233.58,234.41,505,500,2,1,233.53,234.43,10,105,1,2,233.5,234.5,100,63,1,4,233.45,234.75,15,1,1,1,AAPL,0,0,0,28,100,400,1,100,500,105,63,233.975
2024-10-21T12:23:13.923669862Z,2024-10-21 12:23:13.923503589+00:00,10,2,38,A,A,4,234.14,27,130,166273,12952557,233.95,234.0,523,2,1,1,233.84,234.07,200,400,1,2,233.8,234.1,5,100,1,1,233.77,234.13,26,400,1,1,233.7,234.14,1200,27,1,1,233.66,234.17,1,1,1,1,233.58,234.25,505,100,2,1,233.53,234.41,10,500,1,1,233.5,234.43,100,105,1,2,233.45,234.5,15,63,1,4,AAPL,0,0,0,0,0,27,1,100,500,105,63,233.975
2024-10-21T12:23:14.014291143Z,2024-10-21 12:23:14.014125157+00:00,10,2,38,C,B,1,233.84,200,130,165986,12953020,233.95,234.0,523,2,1,1,233.8,234.07,5,400,1,2,233.77,234.1,26,100,1,1,233.7,234.13,1200,400,1,1,233.66,234.14,1,27,1,1,233.58,234.17,505,1,2,1,233.53,234.25,10,100,1,1,233.5,234.41,100,500,1,1,233.45,234.43,15,105,1,2,233.4,234.5,110,63,2,4,AAPL,0,0,-200,-5,-26,-1200,-1,-505,-10,-100,-15,233.975
2024-10-21T12:23:14.014304377Z,2024-10-21 12:23:14.014138266+00:00,10,2,38,A,B,1,233.8,400,130,166111,12953021,233.95,234.0,523,2,1,1,233.8,234.07,405,400,2,2,233.77,234.1,26,100,1,1,233.7,234.13,1200,400,1,1,233.66,234.14,1,27,1,1,233.58,234.17,505,1,2,1,233.53,234.25,10,100,1,1,233.5,234.41,100,500,1,1,233.45,234.43,15,105,1,2,233.4,234.5,110,63,2,4,AAPL,0,0,400,0,0,0,0,0,0,0,0,233.975
2024-10-21T12:23:24.180223668Z,2024-10-21 12:23:24.180057341+00:00,10,2,38,A,B,1,233.84,200,130,166327,12963680,233.95,234.0,523,2,1,1,233.84,234.07,200,400,1,2,233.8,234.1,5,100,1,1,233.77,234.13,26,400,1,1,233.7,234.14,1200,27,1,1,233.66,234.17,1,1,1,1,233.58,234.25,505,100,2,1,233.53,234.41,10,500,1,1,233.5,234.43,100,105,1,2,233.45,234.5,15,63,1,4,AAPL,0,0,200,5,26,1200,1,505,10,100,15,233.975
2024-10-21T12:23:24.244554625Z,2024-10-21 12:23:24.244388472+00:00,10,2,38,C,B,3,233.77,26,130,166153,12963842,233.95,234.0,523,2,1,1,233.84,234.07,200,400,1,2,233.8,234.1,5,100,1,1,233.7,234.13,1200,400,1,1,233.66,234.14,1,27,1,1,233.58,234.17,505,1,2,1,233.53,234.25,10,100,1,1,233.5,234.41,100,500,1,1,233.45,234.43,15,105,1,2,233.4,234.5,110,63,2,4,AAPL,0,0,0,0,-26,-1200,-1,-505,-10,-100,-15,233.975
2024-10-21T12:23:24.244894113Z,2024-10-21 12:23:24.244727755+00:00,10,2,38,A,B,3,233.78,29,130,166358,12963846,233.95,234.0,523,2,1,1,233.84,234.07,200,400,1,2,233.8,234.1,5,100,1,1,233.78,234.13,29,400,1,1,233.7,234.14,1200,27,1,1,233.66,234.17,1,1,1,1,233.58,234.25,505,100,2,1,233.53,234.41,10,500,1,1,233.5,234.43,100,105,1,2,233.45,234.5,15,63,1,4,AAPL,0,0,0,0,29,1200,1,505,10,100,15,233.975
2024-10-21T12:23:24.253991498Z,2024-10-21 12:23:24.253824768+00:00,10,2,38,A,B,1,233.85,200,130,166730,12963873,233.95,234.0,523,2,1,1,233.85,234.07,200,400,1,2,233.8,234.1,5,100,1,1,233.78,234.13,29,400,1,1,233.7,234.14,1200,27,1,1,233.66,234.17,1,1,1,1,233.58,234.25,505,100,2,1,233.53,234.41,10,500,1,1,233.5,234.43,100,105,1,2,233.45,234.5,15,63,1,4,AAPL,0,0,200,0,0,0,0,0,0,0,0,233.975
2024-10-21T12:23:24.273314409Z,2024-10-21 12:23:24.273148439+00:00,10,2,38,C,A,4,234.14,27,130,165970,12963906,233.95,234.0,523,2,1,1,233.85,234.07,200,400,1,2,233.8,234.1,5,100,1,1,233.78,234.13,29,400,1,1,233.7,234.17,1200,1,1,1,233.66,234.25,1,100,1,1,233.58,234.41,505,500,2,1,233.53,234.43,10,105,1,2,233.5,234.5,100,63,1,4,233.45,234.75,15,1,1,1,AAPL,0,0,0,0,0,27,1,100,500,105,63,233.975
2024-10-21T12:23:24.273365393Z,2024-10-21 12:23:24.273199301+00:00,10,2,38,A,A,2,234.09,30,130,166092,12963907,233.95,234.0,523,2,1,1,233.85,234.07,200,400,1,2,233.8,234.09,5,30,1,1,233.78,234.1,29,100,1,1,233.7,234.13,1200,400,1,1,233.66,234.17,1,1,1,1,233.58,234.25,505,100,2,1,233.53,234.41,10,500,1,1,233.5,234.43,100,105,1,2,233.45,234.5,15,63,1,4,AAPL,0,0,0,30,100,400,1,100,500,105,63,233.975
2024-10-21T12:23:24.281190133Z,2024-10-21 12:23:24.281024032+00:00,10,2,38,C,A,2,234.09,30,130,166101,12963913,233.95,234.0,523,2,1,1,233.85,234.07,200,400,1,2,233.8,234.1,5,100,1,1,233.78,234.13,29,400,1,1,233.7,234.17,1200,1,1,1,233.66,234.25,1,100,1,1,233.58,234.41,505,500,2,1,233.53,234.43,10,105,1,2,233.5,234.5,100,63,1,4,233.45,234.75,15,1,1,1,AAPL,0,0,0,30,100,400,1,100,500,105,63,233.975
2024-10-21T12:23:25.923153392Z,2024-10-21 12:23:25.922987113+00:00,10,2,38,A,A,4,234.15,29,130,166279,12965330,233.95,234.0,523,2,1,1,233.85,234.07,200,400,1,2,233.8,234.1,5,100,1,1,233.78,234.13,29,400,1,1,233.7,234.15,1200,29,1,1,233.66,234.17,1,1,1,1,233.58,234.25,505,100,2,1,233.53,234.41,10,500,1,1,233.5,234.43,100,105,1,2,233.45,234.5,15,63,1,4,AAPL,0,0,0,0,0,29,1,100,500,105,63,233.975
2024-10-21T12:23:26.667650199Z,2024-10-21 12:23:26.667483730+00:00,10,2,38,C,A,4,234.15,29,130,166469,12965993,233.95,234.0,523,2,1,1,233.85,234.07,200,400,1,2,233.8,234.1,5,100,1,1,233.78,234.13,29,400,1,1,233.7,234.17,1200,1,1,1,233.66,234.25,1,100,1,1,233.58,234.41,505,500,2,1,233.53,234.43,10,105,1,2,233.5,234.5,100,63,1,4,233.45,234.75,15,1,1,1,AAPL,0,0,0,0,0,29,1,100,500,105,63,233.975
2024-10-21T12:23:26.667733223Z,2024-10-21 12:23:26.667566801+00:00,10,2,38,A,A,2,234.09,26,130,166422,12965994,233.95,234.0,523,2,1,1,233.85,234.07,200,400,1,2,233.8,234.09,5,26,1,1,233.78,234.1,29,100,1,1,233.7,234.13,1200,400,1,1,233.66,234.17,1,1,1,1,233.58,234.25,505,100,2,1,233.53,234.41,10,500,1,1,233.5,234.43,100,105,1,2,233.45,234.5,15,63,1,4,AAPL,0,0,0,26,100,400,1,100,500,105,63,233.975
2024-10-21T12:23:26.671836031Z,2024-10-21 12:23:26.671669972+00:00,10,2,38,C,A,2,234.09,26,130,166059,12965998,233.95,234.0,523,2,1,1,233.85,234.07,200,400,1,2,233.8,234.1,5,100,1,1,233.78,234.13,29,400,1,1,233.7,234.17,1200,1,1,1,233.66,234.25,1,100,1,1,233.58,234.41,505,500,2,1,233.53,234.43,10,105,1,2,233.5,234.5,100,63,1,4,233.45,234.75,15,1,1,1,AAPL,0,0,0,26,100,400,1,100,500,105,63,233.975
2024-10-21T12:23:29.923208530Z,2024-10-21 12:23:29.923042073+00:00,10,2,38,A,A,4,234.15,26,130,166457,12968315,233.95,234.0,523,2,1,1,233.85,234.07,200,400,1,2,233.8,234.1,5,100,1,1,233.78,234.13,29,400,1,1,233.7,234.15,1200,26,1,1,233.66,234.17,1,1,1,1,233.58,234.25,505,100,2,1,233.53,234.41,10,500,1,1,233.5,234.43,100,105,1,2,233.45,234.5,15,63,1,4,AAPL,0,0,0,0,0,26,1,100,500,105,63,233.975
2024-10-21T12:23:31.049437219Z,2024-10-21 12:23:31.049271170+00:00,10,2,38,C,B,1,233.85,200,130,166049,12969394,233.95,234.0,523,2,1,1,233.8,234.07,5,400,1,2,233.78,234.1,29,100,1,1,233.7,234.13,1200,400,1,1,233.66,234.15,1,26,1,1,233.58,234.17,505,1,2,1,233.53,234.25,10,100,1,1,233.5,234.41,100,500,1,1,233.45,234.43,15,105,1,2,233.4,234.5,110,63,2,4,AAPL,0,0,-200,-5,-29,-1200,-1,-505,-10,-100,-15,233.975
2024-10-21T12:23:31.049449290Z,2024-10-21 12:23:31.049283153+00:00,10,2,38,A,B,1,233.83,200,130,166137,12969395,233.95,234.0,523,2,1,1,233.83,234.07,200,400,1,2,233.8,234.1,5,100,1,1,233.78,234.13,29,400,1,1,233.7,234.15,1200,26,1,1,233.66,234.17,1,1,1,1,233.58,234.25,505,100,2,1,233.53,234.41,10,500,1,1,233.5,234.43,100,105,1,2,233.45,234.5,15,63,1,4,AAPL,0,0,200,5,29,1200,1,505,10,100,15,233.975
2024-10-21T12:23:31.105367441Z,2024-10-21 12:23:31.105200821+00:00,10,2,38,A,B,1,233.84,200,130,166620,12969432,233.95,234.0,523,2,1,1,233.84,234.07,200,400,1,2,233.8,234.1,5,100,1,1,233.78,234.13,29,400,1,1,233.7,234.15,1200,26,1,1,233.66,234.17,1,1,1,1,233.58,234.25,505,100,2,1,233.53,234.41,10,500,1,1,233.5,234.43,100,105,1,2,233.45,234.5,15,63,1,4,AAPL,0,0,200,0,0,0,0,0,0,0,0,233.975
2024-10-21T12:23:33.817991958Z,2024-10-21 12:23:33.817825903+00:00,10,2,38,C,B,1,233.84,200,130,166055,12972883,233.95,234.0,523,2,1,1,233.8,234.07,5,400,1,2,233.78,234.1,29,100,1,1,233.7,234.13,1200,400,1,1,233.66,234.15,1,26,1,1,233.58,234.17,505,1,2,1,233.53,234.25,10,100,1,1,233.5,234.41,100,500,1,1,233.45,234.43,15,105,1,2,233.4,234.5,110,63,2,4,AAPL,0,0,-200,-5,-29,-1200,-1,-505,-10,-100,-15,233.975
2024-10-21T12:23:33.818003417Z,2024-10-21 12:23:33.817837243+00:00,10,2,38,A,B,1,233.8,400,130,166174,12972884,233.95,234.0,523,2,1,1,233.8,234.07,405,400,2,2,233.78,234.1,29,100,1,1,233.7,234.13,1200,400,1,1,233.66,234.15,1,26,1,1,233.58,234.17,505,1,2,1,233.53,234.25,10,100,1,1,233.5,234.41,100,500,1,1,233.45,234.43,15,105,1,2,233.4,234.5,110,63,2,4,AAPL,0,0,400,0,0,0,0,0,0,0,0,233.975
2024-10-21T12:23:34.381839108Z,2024-10-21 12:23:34.381673108+00:00,10,2,38,C,A,4,234.15,26,130,166000,12973267,233.95,234.0,523,2,1,1,233.8,234.07,405,400,2,2,233.78,234.1,29,100,1,1,233.7,234.13,1200,400,1,1,233.66,234.17,1,1,1,1,233.58,234.25,505,100,2,1,233.53,234.41,10,500,1,1,233.5,234.43,100,105,1,2,233.45,234.5,15,63,1,4,233.4,234.75,110,1,2,1,AAPL,0,0,0,0,0,26,1,100,500,105,63,233.975
2024-10-21T12:23:34.381954269Z,2024-10-21 12:23:34.381786514+00:00,10,2,38,A,A,4,234.14,27,130,167755,12973268,233.95,234.0,523,2,1,1,233.8,234.07,405,400,2,2,233.78,234.1,29,100,1,1,233.7,234.13,1200,400,1,1,233.66,234.14,1,27,1,1,233.58,234.17,505,1,2,1,233.53,234.25,10,100,1,1,233.5,234.41,100,500,1,1,233.45,234.43,15,105,1,2,233.4,234.5,110,63,2,4,AAPL,0,0,0,0,0,27,1,100,500,105,63,233.975
2024-10-21T12:23:35.765246828Z,2024-10-21 12:23:35.765078516+00:00,10,2,38,T,A,0,233.95,100,130,168312,12974800,233.95,234.0,523,2,1,1,233.8,234.07,405,400,2,2,233.78,234.1,29,100,1,1,233.7,234.13,1200,400,1,1,233.66,234.14,1,27,1,1,233.58,234.17,505,1,2,1,233.53,234.25,10,100,1,1,233.5,234.41,100,500,1,1,233.45,234.43,15,105,1,2,233.4,234.5,110,63,2,4,AAPL,0,0,0,0,0,0,0,0,0,0,0,233.975
2024-10-21T12:23:35.765246828Z,2024-10-21 12:23:35.765078516+00:00,10,2,38,C,B,0,233.95,100,130,168312,12974800,233.95,234.0,423,2,1,1,233.8,234.07,405,400,2,2,233.78,234.1,29,100,1,1,233.7,234.13,1200,400,1,1,233.66,234.14,1,27,1,1,233.58,234.17,505,1,2,1,233.53,234.25,10,100,1,1,233.5,234.41,100,500,1,1,233.45,234.43,15,105,1,2,233.4,234.5,110,63,2,4,AAPL,-100,-100,0,0,0,0,0,0,0,0,0,233.975
2024-10-21T12:23:35.765460271Z,2024-10-21 12:23:35.765293055+00:00,10,2,38,T,A,0,233.95,423,130,167216,12974807,233.95,234.0,423,2,1,1,233.8,234.07,405,400,2,2,233.78,234.1,29,100,1,1,233.7,234.13,1200,400,1,1,233.66,234.14,1,27,1,1,233.58,234.17,505,1,2,1,233.53,234.25,10,100,1,1,233.5,234.41,100,500,1,1,233.45,234.43,15,105,1,2,233.4,234.5,110,63,2,4,AAPL,0,0,0,0,0,0,0,0,0,0,0,233.975
2024-10-21T12:23:35.765460271Z,2024-10-21 12:23:35.765293055+00:00,10,2,38,C,B,0,233.95,423,130,167216,12974807,233.8,234.0,405,2,2,1,233.78,234.07,29,400,1,2,233.7,234.1,1200,100,1,1,233.66,234.13,1,400,1,1,233.58,234.14,505,27,2,1,233.53,234.17,10,1,1,1,233.5,234.25,100,100,1,1,233.45,234.41,15,500,1,1,233.4,234.43,110,105,2,2,233.39,234.5,10,63,1,4,AAPL,-423,-423,-405,-29,-1200,-1,-505,-10,-100,-15,-110,233.9
2024-10-21T12:23:35.765484464Z,2024-10-21 12:23:35.765317844+00:00,10,2,38,A,A,0,233.98,24,130,166620,12974809,233.8,233.98,405,124,2,2,233.78,234.0,29,2,1,1,233.7,234.07,1200,400,1,2,233.66,234.1,1,100,1,1,233.58,234.13,505,400,2,1,233.53,234.14,10,27,1,1,233.5,234.17,100,1,1,1,233.45,234.25,15,100,1,1,233.4,234.41,110,500,2,1,233.39,234.43,10,105,1,2,AAPL,124,124,2,400,100,400,27,1,100,500,105,233.89
2024-10-21T12:23:35.765485889Z,2024-10-21 12:23:35.765319866+00:00,10,2,38,A,A,1,233.99,100,130,166023,12974810,233.8,233.98,405,124,2,2,233.78,233.99,29,100,1,1,233.7,234.0,1200,2,1,1,233.66,234.07,1,400,1,2,233.58,234.1,505,100,2,1,233.53,234.13,10,400,1,1,233.5,234.14,100,27,1,1,233.45,234.17,15,1,1,1,233.4,234.25,110,100,2,1,233.39,234.41,10,500,1,1,AAPL,0,0,100,2,400,100,400,27,1,100,500,233.89
2024-10-21T12:23:35.765493677Z,2024-10-21 12:23:35.765327695+00:00,10,2,38,A,A,1,233.99,100,130,165982,12974811,233.8,233.98,405,124,2,2,233.78,233.99,29,200,1,2,233.7,234.0,1200,2,1,1,233.66,234.07,1,400,1,2,233.58,234.1,505,100,2,1,233.53,234.13,10,400,1,1,233.5,234.14,100,27,1,1,233.45,234.17,15,1,1,1,233.4,234.25,110,100,2,1,233.39,234.41,10,500,1,1,AAPL,0,0,100,0,0,0,0,0,0,0,0,233.89
2024-10-21T12:23:35.765497059Z,2024-10-21 12:23:35.765330068+00:00,10,2,38,A,A,1,233.99,100,130,166991,12974812,233.8,233.98,405,124,2,2,233.78,233.99,29,300,1,3,233.7,234.0,1200,2,1,1,233.66,234.07,1,400,1,2,233.58,234.1,505,100,2,1,233.53,234.13,10,400,1,1,233.5,234.14,100,27,1,1,233.45,234.17,15,1,1,1,233.4,234.25,110,100,2,1,233.39,234.41,10,500,1,1,AAPL,0,0,100,0,0,0,0,0,0,0,0,233.89
2024-10-21T12:23:35.765503864Z,2024-10-21 12:23:35.765336405+00:00,10,2,38,A,A,1,233.99,38,130,167459,12974813,233.8,233.98,405,124,2,2,233.78,233.99,29,338,1,4,233.7,234.0,1200,2,1,1,233.66,234.07,1,400,1,2,233.58,234.1,505,100,2,1,233.53,234.13,10,400,1,1,233.5,234.14,100,27,1,1,233.45,234.17,15,1,1,1,233.4,234.25,110,100,2,1,233.39,234.41,10,500,1,1,AAPL,0,0,38,0,0,0,0,0,0,0,0,233.89
2024-10-21T12:23:35.765520554Z,2024-10-21 12:23:35.765353728+00:00,10,2,38,C,A,1,233.99,100,130,166826,12974817,233.8,233.98,405,124,2,2,233.78,233.99,29,238,1,3,233.7,234.0,1200,2,1,1,233.66,234.07,1,400,1,2,233.58,234.1,505,100,2,1,233.53,234.13,10,400,1,1,233.5,234.14,100,27,1,1,233.45,234.17,15,1,1,1,233.4,234.25,110,100,2,1,233.39,234.41,10,500,1,1,AAPL,0,0,-100,0,0,0,0,0,0,0,0,233.89
2024-10-21T12:23:35.765523939Z,2024-10-21 12:23:35.765358258+00:00,10,2,38,C,N,0,233.8,400,130,165681,12974819,233.8,233.98,5,24,1,1,233.78,233.99,29,238,1,3,233.7,234.0,1200,2,1,1,233.66,234.07,1,400,1,2,233.58,234.1,505,100,2,1,233.53,234.13,10,400,1,1,233.5,234.14,100,27,1,1,233.45,234.17,15,1,1,1,233.4,234.25,110,100,2,1,233.39,234.41,10,500,1,1,AAPL,-500,-500,0,0,0,0,0,0,0,0,0,233.89
2024-10-21T12:23:35.765545765Z,2024-10-21 12:23:35.765377342+00:00,10,2,38,C,A,1,233.99,100,128,168423,12974821,233.8,233.98,5,24,1,1,233.78,233.99,29,138,1,2,233.7,234.0,1200,2,1,1,233.66,234.07,1,400,1,2,233.58,234.1,505,100,2,1,233.53,234.13,10,400,1,1,233.5,234.14,100,27,1,1,233.45,234.17,15,1,1,1,233.4,234.25,110,100,2,1,233.39,234.41,10,500,1,1,AAPL,0,0,-100,0,0,0,0,0,0,0,0,233.89
2024-10-21T12:23:35.765878037Z,2024-10-21 12:23:35.765712149+00:00,10,2,38,C,A,1,233.99,100,130,165888,12974836,233.8,233.98,5,24,1,1,233.78,233.99,29,38,1,1,233.7,234.0,1200,2,1,1,233.66,234.07,1,400,1,2,233.58,234.1,505,100,2,1,233.53,234.13,10,400,1,1,233.5,234.14,100,27,1,1,233.45,234.17,15,1,1,1,233.4,234.25,110,100,2,1,233.39,234.41,10,500,1,1,AAPL,0,0,-100,0,0,0,0,0,0,0,0,233.89
2024-10-21T12:23:35.833393604Z,2024-10-21 12:23:35.833227941+00:00,10,2,38,C,B,1,233.78,29,130,165663,12975154,233.8,233.98,5,24,1,1,233.7,233.99,1200,38,1,1,233.66,234.0,1,2,1,1,233.58,234.07,505,400,2,2,233.53,234.1,10,100,1,1,233.5,234.13,100,400,1,1,233.45,234.14,15,27,1,1,233.4,234.17,110,1,2,1,233.39,234.25,10,100,1,1,233.31,234.41,110,500,2,1,AAPL,0,0,-29,-1200,-1,-505,-10,-100,-15,-110,-10,233.89
2024-10-21T12:23:35.833436011Z,2024-10-21 12:23:35.833269631+00:00,10,2,38,A,B,1,233.71,30,130,166380,12975155,233.8,233.98,5,24,1,1,233.71,233.99,30,38,1,1,233.7,234.0,1200,2,1,1,233.66,234.07,1,400,1,2,233.58,234.1,505,100,2,1,233.53,234.13,10,400,1,1,233.5,234.14,100,27,1,1,233.45,234.17,15,1,1,1,233.4,234.25,110,100,2,1,233.39,234.41,10,500,1,1,AAPL,0,0,30,1200,1,505,10,100,15,110,10,233.89
2024-10-21T12:23:35.833941747Z,2024-10-21 12:23:35.833775320+00:00,10,2,38,A,B,0,233.91,100,130,166427,12975156,233.91,233.98,100,24,1,1,233.8,233.99,5,38,1,1,233.71,234.0,30,2,1,1,233.7,234.07,1200,400,1,2,233.66,234.1,1,100,1,1,233.58,234.13,505,400,2,1,233.53,234.14,10,27,1,1,233.5,234.17,100,1,1,1,233.45,234.25,15,100,1,1,233.4,234.41,110,500,2,1,AAPL,100,100,5,30,1200,1,505,10,100,15,110,233.945
2024-10-21T12:23:35.833961308Z,2024-10-21 12:23:35.833795471+00:00,10,2,38,C,A,0,233.98,24,130,165837,12975157,233.91,233.99,100,38,1,1,233.8,234.0,5,2,1,1,233.71,234.07,30,400,1,2,233.7,234.1,1200,100,1,1,233.66,234.13,1,400,1,1,233.58,234.14,505,27,2,1,233.53,234.17,10,1,1,1,233.5,234.25,100,100,1,1,233.45,234.41,15,500,1,1,233.4,234.43,110,105,2,2,AAPL,24,24,38,2,400,100,400,27,1,100,500,233.95
2024-10-21T12:23:35.836968752Z,2024-10-21 12:23:35.836802755+00:00,10,2,38,C,B,2,233.71,30,130,165997,12975162,233.91,233.99,100,38,1,1,233.8,234.0,5,2,1,1,233.7,234.07,1200,400,1,2,233.66,234.1,1,100,1,1,233.58,234.13,505,400,2,1,233.53,234.14,10,27,1,1,233.5,234.17,100,1,1,1,233.45,234.25,15,100,1,1,233.4,234.41,110,500,2,1,233.39,234.43,10,105,1,2,AAPL,0,0,0,-30,-1200,-1,-505,-10,-100,-15,-110,233.95
2024-10-21T12:23:35.873928834Z,2024-10-21 12:23:35.873762810+00:00,10,2,38,C,A,0,233.99,38,130,166024,12975242,233.91,234.0,100,2,1,1,233.8,234.07,5,400,1,2,233.7,234.1,1200,100,1,1,233.66,234.13,1,400,1,1,233.58,234.14,505,27,2,1,233.53,234.17,10,1,1,1,233.5,234.25,100,100,1,1,233.45,234.41,15,500,1,1,233.4,234.43,110,105,2,2,233.39,234.5,10,63,1,4,AAPL,38,38,2,400,100,400,27,1,100,500,105,233.95499999999998
2024-10-21T12:23:35.901252464Z,2024-10-21 12:23:35.901086187+00:00,10,2,38,A,B,3,233.68,400,130,166277,12975273,233.91,234.0,100,2,1,1,233.8,234.07,5,400,1,2,233.7,234.1,1200,100,1,1,233.68,234.13,400,400,1,1,233.66,234.14,1,27,1,1,233.58,234.17,505,1,2,1,233.53,234.25,10,100,1,1,233.5,234.41,100,500,1,1,233.45,234.43,15,105,1,2,233.4,234.5,110,63,2,4,AAPL,0,0,0,0,400,1,505,10,100,15,110,233.95499999999998
2024-10-21T12:23:35.969287724Z,2024-10-21 12:23:35.969121189+00:00,10,2,38,A,B,3,233.69,400,130,166535,12975451,233.91,234.0,100,2,1,1,233.8,234.07,5,400,1,2,233.7,234.1,1200,100,1,1,233.69,234.13,400,400,1,1,233.66,234.14,1,27,1,1,233.58,234.17,505,1,2,1,233.53,234.25,10,100,1,1,233.5,234.41,100,500,1,1,233.45,234.43,15,105,1,2,233.4,234.5,110,63,2,4,AAPL,0,0,0,0,400,0,0,0,0,0,0,233.95499999999998
2024-10-21T12:23:36.000313609Z,2024-10-21 12:23:36.000147454+00:00,10,2,38,A,B,2,233.73,400,130,166155,12975478,233.91,234.0,100,2,1,1,233.8,234.07,5,400,1,2,233.73,234.1,400,100,1,1,233.7,234.13,1200,400,1,1,233.66,234.14,1,27,1,1,233.58,234.17,505,1,2,1,233.53,234.25,10,100,1,1,233.5,234.41,100,500,1,1,233.45,234.43,15,105,1,2,233.4,234.5,110,63,2,4,AAPL,0,0,0,400,1200,0,0,0,0,0,0,233.95499999999998
2024-10-21T12:23:36.364494386Z,2024-10-21 12:23:36.364328399+00:00,10,2,38,A,B,3,233.71,27,130,165987,12975884,233.91,234.0,100,2,1,1,233.8,234.07,5,400,1,2,233.73,234.1,400,100,1,1,233.71,234.13,27,400,1,1,233.7,234.14,1200,27,1,1,233.66,234.17,1,1,1,1,233.58,234.25,505,100,2,1,233.53,234.41,10,500,1,1,233.5,234.43,100,105,1,2,233.45,234.5,15,63,1,4,AAPL,0,0,0,0,27,1200,1,505,10,100,15,233.95499999999998
2024-10-21T12:23:36.418044070Z,2024-10-21 12:23:36.417876919+00:00,10,2,38,A,B,2,233.79,400,130,167151,12975910,233.91,234.0,100,2,1,1,233.8,234.07,5,400,1,2,233.79,234.1,400,100,1,1,233.71,234.13,27,400,1,1,233.7,234.14,1200,27,1,1,233.66,234.17,1,1,1,1,233.58,234.25,505,100,2,1,233.53,234.41,10,500,1,1,233.5,234.43,100,105,1,2,233.45,234.5,15,63,1,4,AAPL,0,0,0,400,0,0,0,0,0,0,0,233.95499999999998
2024-10-21T12:23:37.809565585Z,2024-10-21 12:23:37.809399308+00:00,10,2,38,C,A,1,234.07,200,130,166277,12978420,233.91,234.0,100,2,1,1,233.8,234.07,5,200,1,1,233.79,234.1,400,100,1,1,233.71,234.13,27,400,1,1,233.7,234.14,1200,27,1,1,233.66,234.17,1,1,1,1,233.58,234.25,505,100,2,1,233.53,234.41,10,500,1,1,233.5,234.43,100,105,1,2,233.45,234.5,15,63,1,4,AAPL,0,0,-200,0,0,0,0,0,0,0,0,233.95499999999998
2024-10-21T12:23:37.809578123Z,2024-10-21 12:23:37.809411756+00:00,10,2,38,A,A,1,234.02,200,130,166367,12978421,233.91,234.0,100,2,1,1,233.8,234.02,5,200,1,1,233.79,234.1,400,100,1,1,233.71,234.13,27,400,1,1,233.7,234.14,1200,27,1,1,233.66,234.17,1,1,1,1,233.58,234.25,505,100,2,1,233.53,234.41,10,500,1,1,233.5,234.43,100,105,1,2,233.45,234.5,15,63,1,4,AAPL,0,0,200,0,0,0,0,0,0,0,0,233.95499999999998
2024-10-21T12:23:37.892570179Z,2024-10-21 12:23:37.892403782+00:00,10,2,38,A,A,1,234.01,200,130,166397,12978809,233.91,234.0,100,2,1,1,233.8,234.01,5,200,1,1,233.79,234.1,400,100,1,1,233.71,234.13,27,400,1,1,233.7,234.14,1200,27,1,1,233.66,234.17,1,1,1,1,233.58,234.25,505,100,2,1,233.53,234.41,10,500,1,1,233.5,234.43,100,105,1,2,233.45,234.5,15,63,1,4,AAPL,0,0,200,0,0,0,0,0,0,0,0,233.95499999999998
2024-10-21T12:23:39.411896692Z,2024-10-21 12:23:39.411730598+00:00,10,2,38,C,A,4,234.14,27,130,166094,12981148,233.91,234.0,100,2,1,1,233.8,234.01,5,200,1,1,233.79,234.1,400,100,1,1,233.71,234.13,27,400,1,1,233.7,234.17,1200,1,1,1,233.66,234.25,1,100,1,1,233.58,234.41,505,500,2,1,233.53,234.43,10,105,1,2,233.5,234.5,100,63,1,4,233.45,234.75,15,1,1,1,AAPL,0,0,0,0,0,27,1,100,500,105,63,233.95499999999998
2024-10-21T12:23:39.411955539Z,2024-10-21 12:23:39.411789045+00:00,10,2,38,A,A,2,234.08,30,130,166494,12981149,233.91,234.0,100,2,1,1,233.8,234.01,5,200,1,1,233.79,234.08,400,30,1,1,233.71,234.1,27,100,1,1,233.7,234.13,1200,400,1,1,233.66,234.17,1,1,1,1,233.58,234.25,505,100,2,1,233.53,234.41,10,500,1,1,233.5,234.43,100,105,1,2,233.45,234.5,15,63,1,4,AAPL,0,0,0,30,100,400,1,100,500,105,63,233.95499999999998
2024-10-21T12:23:40.838628426Z,2024-10-21 12:23:40.838462060+00:00,10,2,38,C,B,3,233.71,27,130,166366,12982424,233.91,234.0,100,2,1,1,233.8,234.01,5,200,1,1,233.79,234.08,400,30,1,1,233.7,234.1,1200,100,1,1,233.66,234.13,1,400,1,1,233.58,234.17,505,1,2,1,233.53,234.25,10,100,1,1,233.5,234.41,100,500,1,1,233.45,234.43,15,105,1,2,233.4,234.5,110,63,2,4,AAPL,0,0,0,0,-27,-1200,-1,-505,-10,-100,-15,233.95499999999998
2024-10-21T12:23:40.838662378Z,2024-10-21 12:23:40.838495937+00:00,10,2,38,A,B,3,233.77,28,130,166441,12982425,233.91,234.0,100,2,1,1,233.8,234.01,5,200,1,1,233.79,234.08,400,30,1,1,233.77,234.1,28,100,1,1,233.7,234.13,1200,400,1,1,233.66,234.17,1,1,1,1,233.58,234.25,505,100,2,1,233.53,234.41,10,500,1,1,233.5,234.43,100,105,1,2,233.45,234.5,15,63,1,4,AAPL,0,0,0,0,28,1200,1,505,10,100,15,233.95499999999998
2024-10-21T12:23:40.884021980Z,2024-10-21 12:23:40.883854903+00:00,10,2,38,A,B,1,233.82,200,130,167077,12982474,233.91,234.0,100,2,1,1,233.82,234.01,200,200,1,1,233.8,234.08,5,30,1,1,233.77,234.1,28,100,1,1,233.7,234.13,1200,400,1,1,233.66,234.17,1,1,1,1,233.58,234.25,505,100,2,1,233.53,234.41,10,500,1,1,233.5,234.43,100,105,1,2,233.45,234.5,15,63,1,4,AAPL,0,0,200,5,0,0,0,0,0,0,0,233.95499999999998
2024-10-21T12:23:53.580666026Z,2024-10-21 12:23:53.580500087+00:00,10,2,38,A,A,0,233.97,4,130,165939,12991980,233.91,233.97,100,4,1,1,233.82,234.0,200,2,1,1,233.8,234.01,5,200,1,1,233.77,234.08,28,30,1,1,233.7,234.1,1200,100,1,1,233.66,234.13,1,400,1,1,233.58,234.17,505,1,2,1,233.53,234.25,10,100,1,1,233.5,234.41,100,500,1,1,233.45,234.43,15,105,1,2,AAPL,4,4,2,200,30,100,400,1,100,500,105,233.94
2024-10-21T12:23:53.580697675Z,2024-10-21 12:23:53.580531557+00:00,10,2,38,C,B,1,233.82,200,130,166118,12991981,233.91,233.97,100,4,1,1,233.8,234.0,5,2,1,1,233.77,234.01,28,200,1,1,233.7,234.08,1200,30,1,1,233.66,234.1,1,100,1,1,233.58,234.13,505,400,2,1,233.53,234.17,10,1,1,1,233.5,234.25,100,100,1,1,233.45,234.41,15,500,1,1,233.4,234.43,110,105,2,2,AAPL,0,0,-200,-5,-28,-1200,-1,-505,-10,-100,-15,233.94
2024-10-21T12:23:53.584756226Z,2024-10-21 12:23:53.584590487+00:00,10,2,38,C,A,0,233.97,4,130,165739,12991991,233.91,234.0,100,2,1,1,233.8,234.01,5,200,1,1,233.77,234.08,28,30,1,1,233.7,234.1,1200,100,1,1,233.66,234.13,1,400,1,1,233.58,234.17,505,1,2,1,233.53,234.25,10,100,1,1,233.5,234.41,100,500,1,1,233.45,234.43,15,105,1,2,233.4,234.5,110,63,2,4,AAPL,4,4,2,200,30,100,400,1,100,500,105,233.95499999999998
2024-10-21T12:23:53.687484901Z,2024-10-21 12:23:53.687318686+00:00,10,2,38,A,B,1,233.82,200,130,166215,12992039,233.91,234.0,100,2,1,1,233.82,234.01,200,200,1,1,233.8,234.08,5,30,1,1,233.77,234.1,28,100,1,1,233.7,234.13,1200,400,1,1,233.66,234.17,1,1,1,1,233.58,234.25,505,100,2,1,233.53,234.41,10,500,1,1,233.5,234.43,100,105,1,2,233.45,234.5,15,63,1,4,AAPL,0,0,200,5,28,1200,1,505,10,100,15,233.95499999999998
2024-10-21T12:23:56.151884878Z,2024-10-21 12:23:56.151717030+00:00,10,2,38,T,A,0,233.91,100,130,167848,12994141,233.91,234.0,100,2,1,1,233.82,234.01,200,200,1,1,233.8,234.08,5,30,1,1,233.77,234.1,28,100,1,1,233.7,234.13,1200,400,1,1,233.66,234.17,1,1,1,1,233.58,234.25,505,100,2,1,233.53,234.41,10,500,1,1,233.5,234.43,100,105,1,2,233.45,234.5,15,63,1,4,AAPL,0,0,0,0,0,0,0,0,0,0,0,233.95499999999998
2024-10-21T12:23:56.151884878Z,2024-10-21 12:23:56.151717030+00:00,10,2,38,C,B,0,233.91,100,130,167848,12994141,233.82,234.0,200,2,1,1,233.8,234.01,5,200,1,1,233.77,234.08,28,30,1,1,233.7,234.1,1200,100,1,1,233.66,234.13,1,400,1,1,233.58,234.17,505,1,2,1,233.53,234.25,10,100,1,1,233.5,234.41,100,500,1,1,233.45,234.43,15,105,1,2,233.4,234.5,110,63,2,4,AAPL,-100,-100,-200,-5,-28,-1200,-1,-505,-10,-100,-15,233.91
2024-10-21T12:23:56.151905940Z,2024-10-21 12:23:56.151739820+00:00,10,2,38,A,A,0,233.95,100,130,166120,12994142,233.82,233.95,200,100,1,1,233.8,234.0,5,2,1,1,233.77,234.01,28,200,1,1,233.7,234.08,1200,30,1,1,233.66,234.1,1,100,1,1,233.58,234.13,505,400,2,1,233.53,234.17,10,1,1,1,233.5,234.25,100,100,1,1,233.45,234.41,15,500,1,1,233.4,234.43,110,105,2,2,AAPL,100,100,2,200,30,100,400,1,100,500,105,233.885
2024-10-21T12:23:56.151909152Z,2024-10-21 12:23:56.151743006+00:00,10,2,38,A,A,1,233.98,100,130,166146,12994143,233.82,233.95,200,100,1,1,233.8,233.98,5,100,1,1,233.77,234.0,28,2,1,1,233.7,234.01,1200,200,1,1,233.66,234.08,1,30,1,1,233.58,234.1,505,100,2,1,233.53,234.13,10,400,1,1,233.5,234.17,100,1,1,1,233.45,234.25,15,100,1,1,233.4,234.41,110,500,2,1,AAPL,0,0,100,2,200,30,100,400,1,100,500,233.885
2024-10-21T12:23:56.151910443Z,2024-10-21 12:23:56.151744249+00:00,10,2,38,A,A,1,233.96,25,130,166194,12994144,233.82,233.95,200,100,1,1,233.8,233.96,5,25,1,1,233.77,233.98,28,100,1,1,233.7,234.0,1200,2,1,1,233.66,234.01,1,200,1,1,233.58,234.08,505,30,2,1,233.53,234.1,10,100,1,1,233.5,234.13,100,400,1,1,233.45,234.17,15,1,1,1,233.4,234.25,110,100,2,1,AAPL,0,0,25,100,2,200,30,100,400,1,100,233.885
2024-10-21T12:23:56.151917914Z,2024-10-21 12:23:56.151751835+00:00,10,2,38,A,A,2,233.98,100,130,166079,12994145,233.82,233.95,200,100,1,1,233.8,233.96,5,25,1,1,233.77,233.98,28,200,1,2,233.7,234.0,1200,2,1,1,233.66,234.01,1,200,1,1,233.58,234.08,505,30,2,1,233.53,234.1,10,100,1,1,233.5,234.13,100,400,1,1,233.45,234.17,15,1,1,1,233.4,234.25,110,100,2,1,AAPL,0,0,0,100,0,0,0,0,0,0,0,233.885
2024-10-21T12:23:56.151922395Z,2024-10-21 12:23:56.151753407+00:00,10,2,38,C,B,0,233.82,200,130,168988,12994147,233.8,233.95,5,100,1,1,233.77,233.96,28,25,1,1,233.7,233.98,1200,300,1,3,233.66,234.0,1,2,1,1,233.58,234.01,505,200,2,1,233.53,234.08,10,30,1,1,233.5,234.1,100,100,1,1,233.45,234.13,15,400,1,1,233.4,234.17,110,1,2,1,233.39,234.25,10,100,1,1,AAPL,-200,-200,-5,72,-1200,-1,-505,-10,-100,-15,-110,233.875
2024-10-21T12:23:56.151926634Z,2024-10-21 12:23:56.151760470+00:00,10,2,38,A,A,1,233.96,30,130,166164,12994148,233.8,233.95,5,100,1,1,233.77,233.96,28,55,1,2,233.7,233.98,1200,300,1,3,233.66,234.0,1,2,1,1,233.58,234.01,505,200,2,1,233.53,234.08,10,30,1,1,233.5,234.1,100,100,1,1,233.45,234.13,15,400,1,1,233.4,234.17,110,1,2,1,233.39,234.25,10,100,1,1,AAPL,0,0,30,0,0,0,0,0,0,0,0,233.875
2024-10-21T12:23:56.151940792Z,2024-10-21 12:23:56.151774406+00:00,10,2,38,C,A,2,233.98,100,130,166386,12994150,233.8,233.95,5,100,1,1,233.77,233.96,28,55,1,2,233.7,233.98,1200,200,1,2,233.66,233.99,1,30,1,1,233.58,234.0,505,2,2,1,233.53,234.01,10,200,1,1,233.5,234.08,100,30,1,1,233.45,234.1,15,100,1,1,233.4,234.13,110,400,2,1,233.39,234.17,10,1,1,1,AAPL,0,0,0,-100,30,2,200,30,100,400,1,233.875
2024-10-21T12:23:56.151962295Z,2024-10-21 12:23:56.151794726+00:00,10,2,38,C,A,0,233.95,100,130,167569,12994152,233.8,233.96,5,55,1,2,233.77,233.98,28,200,1,2,233.7,233.99,1200,30,1,1,233.66,234.0,1,2,1,1,233.58,234.01,505,200,2,1,233.53,234.08,10,30,1,1,233.5,234.1,100,100,1,1,233.45,234.13,15,400,1,1,233.4,234.17,110,1,2,1,233.39,234.25,10,100,1,1,AAPL,100,100,55,200,30,2,200,30,100,400,1,233.88
2024-10-21T12:23:56.151983196Z,2024-10-21 12:23:56.151815406+00:00,10,2,38,C,A,0,233.96,25,128,167790,12994153,233.8,233.96,5,30,1,1,233.77,233.98,28,200,1,2,233.7,233.99,1200,30,1,1,233.66,234.0,1,2,1,1,233.58,234.01,505,200,2,1,233.53,234.08,10,30,1,1,233.5,234.1,100,100,1,1,233.45,234.13,15,400,1,1,233.4,234.17,110,1,2,1,233.39,234.25,10,100,1,1,AAPL,-25,-25,0,0,0,0,0,0,0,0,0,233.88
2024-10-21T12:23:56.151984267Z,2024-10-21 12:23:56.151818053+00:00,10,2,38,C,A,1,233.98,100,130,166214,12994155,233.8,233.96,5,30,1,1,233.77,233.98,28,100,1,1,233.7,233.99,1200,30,1,1,233.66,234.0,1,2,1,1,233.58,234.01,505,200,2,1,233.53,234.08,10,30,1,1,233.5,234.1,100,100,1,1,233.45,234.13,15,400,1,1,233.4,234.17,110,1,2,1,233.39,234.25,10,100,1,1,AAPL,0,0,-100,0,0,0,0,0,0,0,0,233.88
2024-10-21T12:23:56.152075526Z,2024-10-21 12:23:56.151908869+00:00,10,2,38,A,A,0,233.95,100,130,166657,12994157,233.8,233.95,5,100,1,1,233.77,233.96,28,30,1,1,233.7,233.98,1200,100,1,1,233.66,233.99,1,30,1,1,233.58,234.0,505,2,2,1,233.53,234.01,10,200,1,1,233.5,234.08,100,30,1,1,233.45,234.1,15,100,1,1,233.4,234.13,110,400,2,1,233.39,234.17,10,1,1,1,AAPL,100,100,30,100,30,2,200,30,100,400,1,233.875
2024-10-21T12:23:56.152225403Z,2024-10-21 12:23:56.152059304+00:00,10,2,38,C,A,2,233.98,100,130,166099,12994158,233.8,233.95,5,100,1,1,233.77,233.96,28,30,1,1,233.7,233.99,1200,30,1,1,233.66,234.0,1,2,1,1,233.58,234.01,505,200,2,1,233.53,234.08,10,30,1,1,233.5,234.1,100,100,1,1,233.45,234.13,15,400,1,1,233.4,234.17,110,1,2,1,233.39,234.25,10,100,1,1,AAPL,0,0,0,100,30,2,200,30,100,400,1,233.875
2024-10-21T12:23:56.152267246Z,2024-10-21 12:23:56.152100943+00:00,10,2,38,A,A,0,233.95,7,130,166303,12994159,233.8,233.95,5,107,1,2,233.77,233.96,28,30,1,1,233.7,233.99,1200,30,1,1,233.66,234.0,1,2,1,1,233.58,234.01,505,200,2,1,233.53,234.08,10,30,1,1,233.5,234.1,100,100,1,1,233.45,234.13,15,400,1,1,233.4,234.17,110,1,2,1,233.39,234.25,10,100,1,1,AAPL,7,7,0,0,0,0,0,0,0,0,0,233.875
2024-10-21T12:23:56.152492907Z,2024-10-21 12:23:56.152326897+00:00,10,2,38,C,A,0,233.95,100,130,166010,12994160,233.8,233.95,5,7,1,1,233.77,233.96,28,30,1,1,233.7,233.99,1200,30,1,1,233.66,234.0,1,2,1,1,233.58,234.01,505,200,2,1,233.53,234.08,10,30,1,1,233.5,234.1,100,100,1,1,233.45,234.13,15,400,1,1,233.4,234.17,110,1,2,1,233.39,234.25,10,100,1,1,AAPL,-100,-100,0,0,0,0,0,0,0,0,0,233.875
2024-10-21T12:23:56.156361100Z,2024-10-21 12:23:56.156195112+00:00,10,2,38,C,A,0,233.95,7,130,165988,12994163,233.8,233.96,5,30,1,1,233.77,233.99,28,30,1,1,233.7,234.0,1200,2,1,1,233.66,234.01,1,200,1,1,233.58,234.08,505,30,2,1,233.53,234.1,10,100,1,1,233.5,234.13,100,400,1,1,233.45,234.17,15,1,1,1,233.4,234.25,110,100,2,1,233.39,234.41,10,500,1,1,AAPL,7,7,30,30,2,200,30,100,400,1,100,233.88
2024-10-21T12:23:56.223030277Z,2024-10-21 12:23:56.222863616+00:00,10,2,38,A,B,2,233.73,400,130,166661,12994197,233.8,233.96,5,30,1,1,233.77,233.99,28,30,1,1,233.73,234.0,400,2,1,1,233.7,234.01,1200,200,1,1,233.66,234.08,1,30,1,1,233.58,234.1,505,100,2,1,233.53,234.13,10,400,1,1,233.5,234.17,100,1,1,1,233.45,234.25,15,100,1,1,233.4,234.41,110,500,2,1,AAPL,0,0,0,400,1200,1,505,10,100,15,110,233.88
2024-10-21T12:23:56.223543885Z,2024-10-21 12:23:56.223377764+00:00,10,2,38,C,B,1,233.77,28,130,166121,12994198,233.8,233.96,5,30,1,1,233.73,233.99,400,30,1,1,233.7,234.0,1200,2,1,1,233.66,234.01,1,200,1,1,233.58,234.08,505,30,2,1,233.53,234.1,10,100,1,1,233.5,234.13,100,400,1,1,233.45,234.17,15,1,1,1,233.4,234.25,110,100,2,1,233.39,234.41,10,500,1,1,AAPL,0,0,-28,-400,-1200,-1,-505,-10,-100,-15,-110,233.88
2024-10-21T12:23:56.223614225Z,2024-10-21 12:23:56.223447893+00:00,10,2,38,A,B,2,233.71,29,130,166332,12994199,233.8,233.96,5,30,1,1,233.73,233.99,400,30,1,1,233.71,234.0,29,2,1,1,233.7,234.01,1200,200,1,1,233.66,234.08,1,30,1,1,233.58,234.1,505,100,2,1,233.53,234.13,10,400,1,1,233.5,234.17,100,1,1,1,233.45,234.25,15,100,1,1,233.4,234.41,110,500,2,1,AAPL,0,0,0,29,1200,1,505,10,100,15,110,233.88
2024-10-21T12:23:56.253930823Z,2024-10-21 12:23:56.253764723+00:00,10,2,38,C,A,1,233.99,30,130,166100,12994211,233.8,233.96,5,30,1,1,233.73,234.0,400,2,1,1,233.71,234.01,29,200,1,1,233.7,234.08,1200,30,1,1,233.66,234.1,1,100,1,1,233.58,234.13,505,400,2,1,233.53,234.17,10,1,1,1,233.5,234.25,100,100,1,1,233.45,234.41,15,500,1,1,233.4,234.43,110,105,2,2,AAPL,0,0,30,2,200,30,100,400,1,100,500,233.88
2024-10-21T12:23:56.403930641Z,2024-10-21 12:23:56.403764720+00:00,10,2,38,C,A,0,233.96,30,130,165921,12994800,233.8,234.0,5,2,1,1,233.73,234.01,400,200,1,1,233.71,234.08,29,30,1,1,233.7,234.1,1200,100,1,1,233.66,234.13,1,400,1,1,233.58,234.17,505,1,2,1,233.53,234.25,10,100,1,1,233.5,234.41,100,500,1,1,233.45,234.43,15,105,1,2,233.4,234.5,110,63,2,4,AAPL,30,30,2,200,30,100,400,1,100,500,105,233.9
2024-10-21T12:23:59.005077193Z,2024-10-21 12:23:59.004911131+00:00,10,2,38,C,B,1,233.73,400,130,166062,12997239,233.8,234.0,5,2,1,1,233.71,234.01,29,200,1,1,233.7,234.08,1200,30,1,1,233.66,234.1,1,100,1,1,233.58,234.13,505,400,2,1,233.53,234.17,10,1,1,1,233.5,234.25,100,100,1,1,233.45,234.41,15,500,1,1,233.4,234.43,110,105,2,2,233.39,234.5,10,63,1,4,AAPL,0,0,-400,-29,-1200,-1,-505,-10,-100,-15,-110,233.9
2024-10-21T12:23:59.005089751Z,2024-10-21 12:23:59.004923443+00:00,10,2,38,A,B,3,233.68,400,130,166308,12997240,233.8,234.0,5,2,1,1,233.71,234.01,29,200,1,1,233.7,234.08,1200,30,1,1,233.68,234.1,400,100,1,1,233.66,234.13,1,400,1,1,233.58,234.17,505,1,2,1,233.53,234.25,10,100,1,1,233.5,234.41,100,500,1,1,233.45,234.43,15,105,1,2,233.4,234.5,110,63,2,4,AAPL,0,0,0,0,400,1,505,10,100,15,110,233.9
2024-10-21T12:23:59.008446995Z,2024-10-21 12:23:59.008280403+00:00,10,2,38,A,A,2,234.03,29,130,166592,12997243,233.8,234.0,5,2,1,1,233.71,234.01,29,200,1,1,233.7,234.03,1200,29,1,1,233.68,234.08,400,30,1,1,233.66,234.1,1,100,1,1,233.58,234.13,505,400,2,1,233.53,234.17,10,1,1,1,233.5,234.25,100,100,1,1,233.45,234.41,15,500,1,1,233.4,234.43,110,105,2,2,AAPL,0,0,0,29,30,100,400,1,100,500,105,233.9
2024-10-21T12:23:59.008489006Z,2024-10-21 12:23:59.008322912+00:00,10,2,38,C,A,3,234.08,30,130,166094,12997244,233.8,234.0,5,2,1,1,233.71,234.01,29,200,1,1,233.7,234.03,1200,29,1,1,233.68,234.1,400,100,1,1,233.66,234.13,1,400,1,1,233.58,234.17,505,1,2,1,233.53,234.25,10,100,1,1,233.5,234.41,100,500,1,1,233.45,234.43,15,105,1,2,233.4,234.5,110,63,2,4,AAPL,0,0,0,0,30,100,400,1,100,500,105,233.9
2024-10-21T12:23:59.012113870Z,2024-10-21 12:23:59.011947596+00:00,10,2,38,C,A,1,234.01,200,130,166274,12997249,233.8,234.0,5,2,1,1,233.71,234.03,29,29,1,1,233.7,234.1,1200,100,1,1,233.68,234.13,400,400,1,1,233.66,234.17,1,1,1,1,233.58,234.25,505,100,2,1,233.53,234.41,10,500,1,1,233.5,234.43,100,105,1,2,233.45,234.5,15,63,1,4,233.4,234.75,110,1,2,1,AAPL,0,0,200,29,100,400,1,100,500,105,63,233.9
2024-10-21T12:23:59.012126464Z,2024-10-21 12:23:59.011960403+00:00,10,2,38,A,A,2,234.04,200,130,166061,12997250,233.8,234.0,5,2,1,1,233.71,234.03,29,29,1,1,233.7,234.04,1200,200,1,1,233.68,234.1,400,100,1,1,233.66,234.13,1,400,1,1,233.58,234.17,505,1,2,1,233.53,234.25,10,100,1,1,233.5,234.41,100,500,1,1,233.45,234.43,15,105,1,2,233.4,234.5,110,63,2,4,AAPL,0,0,0,200,100,400,1,100,500,105,63,233.9
2024-10-21T12:23:59.013684039Z,2024-10-21 12:23:59.013517894+00:00,10,2,38,C,A,2,234.04,200,130,166145,12997253,233.8,234.0,5,2,1,1,233.71,234.03,29,29,1,1,233.7,234.1,1200,100,1,1,233.68,234.13,400,400,1,1,233.66,234.17,1,1,1,1,233.58,234.25,505,100,2,1,233.53,234.41,10,500,1,1,233.5,234.43,100,105,1,2,233.45,234.5,15,63,1,4,233.4,234.75,110,1,2,1,AAPL,0,0,0,200,100,400,1,100,500,105,63,233.9
2024-10-21T12:23:59.013696792Z,2024-10-21 12:23:59.013530559+00:00,10,2,38,A,A,2,234.07,400,130,166233,12997254,233.8,234.0,5,2,1,1,233.71,234.03,29,29,1,1,233.7,234.07,1200,400,1,1,233.68,234.1,400,100,1,1,233.66,234.13,1,400,1,1,233.58,234.17,505,1,2,1,233.53,234.25,10,100,1,1,233.5,234.41,100,500,1,1,233.45,234.43,15,105,1,2,233.4,234.5,110,63,2,4,AAPL,0,0,0,400,100,400,1,100,500,105,63,233.9
2024-10-21T12:23:59.014404565Z,2024-10-21 12:23:59.014238552+00:00,10,2,38,C,A,1,234.03,29,130,166013,12997255,233.8,234.0,5,2,1,1,233.71,234.07,29,400,1,1,233.7,234.1,1200,100,1,1,233.68,234.13,400,400,1,1,233.66,234.17,1,1,1,1,233.58,234.25,505,100,2,1,233.53,234.41,10,500,1,1,233.5,234.43,100,105,1,2,233.45,234.5,15,63,1,4,233.4,234.75,110,1,2,1,AAPL,0,0,29,400,100,400,1,100,500,105,63,233.9
2024-10-21T12:23:59.017362837Z,2024-10-21 12:23:59.017196811+00:00,10,2,38,C,B,1,233.71,29,130,166026,12997256,233.8,234.0,5,2,1,1,233.7,234.07,1200,400,1,1,233.68,234.1,400,100,1,1,233.66,234.13,1,400,1,1,233.58,234.17,505,1,2,1,233.53,234.25,10,100,1,1,233.5,234.41,100,500,1,1,233.45,234.43,15,105,1,2,233.4,234.5,110,63,2,4,233.39,234.75,10,1,1,1,AAPL,0,0,-29,-1200,-400,-1,-505,-10,-100,-15,-110,233.9
2024-10-21T12:23:59.017449096Z,2024-10-21 12:23:59.017282783+00:00,10,2,38,A,B,4,233.61,27,130,166313,12997257,233.8,234.0,5,2,1,1,233.7,234.07,1200,400,1,1,233.68,234.1,400,100,1,1,233.66,234.13,1,400,1,1,233.61,234.17,27,1,1,1,233.58,234.25,505,100,2,1,233.53,234.41,10,500,1,1,233.5,234.43,100,105,1,2,233.45,234.5,15,63,1,4,233.4,234.75,110,1,2,1,AAPL,0,0,0,0,0,27,505,10,100,15,110,233.9
2024-10-21T12:23:59.074684910Z,2024-10-21 12:23:59.074518650+00:00,10,2,38,A,A,1,234.02,200,130,166260,12997280,233.8,234.0,5,2,1,1,233.7,234.02,1200,200,1,1,233.68,234.1,400,100,1,1,233.66,234.13,1,400,1,1,233.61,234.17,27,1,1,1,233.58,234.25,505,100,2,1,233.53,234.41,10,500,1,1,233.5,234.43,100,105,1,2,233.45,234.5,15,63,1,4,233.4,234.75,110,1,2,1,AAPL,0,0,200,0,0,0,0,0,0,0,0,233.9
2024-10-21T12:24:00.591711571Z,2024-10-21 12:24:00.591545399+00:00,10,2,38,A,B,3,233.66,27,130,166172,12999539,233.8,234.0,5,2,1,1,233.7,234.02,1200,200,1,1,233.68,234.1,400,100,1,1,233.66,234.13,28,400,2,1,233.61,234.17,27,1,1,1,233.58,234.25,505,100,2,1,233.53,234.41,10,500,1,1,233.5,234.43,100,105,1,2,233.45,234.5,15,63,1,4,233.4,234.75,110,1,2,1,AAPL,0,0,0,0,27,0,0,0,0,0,0,233.9
2024-10-21T12:24:00.591743978Z,2024-10-21 12:24:00.591577923+00:00,10,2,38,C,B,4,233.61,27,130,166055,12999540,233.8,234.0,5,2,1,1,233.7,234.02,1200,200,1,1,233.68,234.1,400,100,1,1,233.66,234.13,28,400,2,1,233.58,234.17,505,1,2,1,233.53,234.25,10,100,1,1,233.5,234.41,100,500,1,1,233.45,234.43,15,105,1,2,233.4,234.5,110,63,2,4,233.39,234.75,10,1,1,1,AAPL,0,0,0,0,0,-27,-505,-10,-100,-15,-110,233.9
2024-10-21T12:24:00.591786574Z,2024-10-21 12:24:00.591620074+00:00,10,2,38,A,A,2,234.08,26,130,166500,12999541,233.8,234.0,5,2,1,1,233.7,234.02,1200,200,1,1,233.68,234.08,400,26,1,1,233.66,234.1,28,100,2,1,233.58,234.13,505,400,2,1,233.53,234.17,10,1,1,1,233.5,234.25,100,100,1,1,233.45,234.41,15,500,1,1,233.4,234.43,110,105,2,2,233.39,234.5,10,63,1,4,AAPL,0,0,0,26,100,400,1,100,500,105,63,233.9
2024-10-21T12:24:00.639172304Z,2024-10-21 12:24:00.639005885+00:00,10,2,38,A,B,1,233.72,400,130,166419,12999658,233.8,234.0,5,2,1,1,233.72,234.02,400,200,1,1,233.7,234.08,1200,26,1,1,233.66,234.1,28,100,2,1,233.58,234.13,505,400,2,1,233.53,234.17,10,1,1,1,233.5,234.25,100,100,1,1,233.45,234.41,15,500,1,1,233.4,234.43,110,105,2,2,233.39,234.5,10,63,1,4,AAPL,0,0,400,1200,0,0,0,0,0,0,0,233.9
2024-10-21T12:24:00.649223162Z,2024-10-21 12:24:00.649056842+00:00,10,2,38,A,A,1,234.01,200,130,166320,12999723,233.8,234.0,5,2,1,1,233.72,234.01,400,200,1,1,233.7,234.08,1200,26,1,1,233.66,234.1,28,100,2,1,233.58,234.13,505,400,2,1,233.53,234.17,10,1,1,1,233.5,234.25,100,100,1,1,233.45,234.41,15,500,1,1,233.4,234.43,110,105,2,2,233.39,234.5,10,63,1,4,AAPL,0,0,200,0,0,0,0,0,0,0,0,233.9
2024-10-21T12:24:02.009559726Z,2024-10-21 12:24:02.009392935+00:00,10,2,38,A,A,1,234.01,200,130,166791,13001036,233.8,234.0,5,2,1,1,233.72,234.01,400,400,1,2,233.7,234.08,1200,26,1,1,233.66,234.1,28,100,2,1,233.58,234.13,505,400,2,1,233.53,234.17,10,1,1,1,233.5,234.25,100,100,1,1,233.45,234.41,15,500,1,1,233.4,234.43,110,105,2,2,233.39,234.5,10,63,1,4,AAPL,0,0,200,0,0,0,0,0,0,0,0,233.9
2024-10-21T12:24:03.014397743Z,2024-10-21 12:24:03.014231244+00:00,10,2,38,A,B,1,233.73,400,130,166499,13002474,233.8,234.0,5,2,1,1,233.73,234.01,400,400,1,2,233.7,234.08,1200,26,1,1,233.66,234.1,28,100,2,1,233.58,234.13,505,400,2,1,233.53,234.17,10,1,1,1,233.5,234.25,100,100,1,1,233.45,234.41,15,500,1,1,233.4,234.43,110,105,2,2,233.39,234.5,10,63,1,4,AAPL,0,0,400,0,0,0,0,0,0,0,0,233.9
2024-10-21T12:24:12.705919587Z,2024-10-21 12:24:12.705753370+00:00,10,2,38,C,A,2,234.08,26,130,166217,13011148,233.8,234.0,5,2,1,1,233.73,234.01,400,400,1,2,233.7,234.1,1200,100,1,1,233.66,234.13,28,400,2,1,233.58,234.17,505,1,2,1,233.53,234.25,10,100,1,1,233.5,234.41,100,500,1,1,233.45,234.43,15,105,1,2,233.4,234.5,110,63,2,4,233.39,234.75,10,1,1,1,AAPL,0,0,0,26,100,400,1,100,500,105,63,233.9
2024-10-21T12:24:12.705959304Z,2024-10-21 12:24:12.705792927+00:00,10,2,38,A,A,2,234.03,27,130,166377,13011149,233.8,234.0,5,2,1,1,233.73,234.01,400,400,1,2,233.7,234.03,1200,27,1,1,233.66,234.1,28,100,2,1,233.58,234.13,505,400,2,1,233.53,234.17,10,1,1,1,233.5,234.25,100,100,1,1,233.45,234.41,15,500,1,1,233.4,234.43,110,105,2,2,233.39,234.5,10,63,1,4,AAPL,0,0,0,27,100,400,1,100,500,105,63,233.9
2024-10-21T12:24:12.758818645Z,2024-10-21 12:24:12.758652350+00:00,10,2,38,C,A,1,234.01,200,130,166295,13011180,233.8,234.0,5,2,1,1,233.73,234.01,400,200,1,1,233.7,234.03,1200,27,1,1,233.66,234.1,28,100,2,1,233.58,234.13,505,400,2,1,233.53,234.17,10,1,1,1,233.5,234.25,100,100,1,1,233.45,234.41,15,500,1,1,233.4,234.43,110,105,2,2,233.39,234.5,10,63,1,4,AAPL,0,0,-200,0,0,0,0,0,0,0,0,233.9
2024-10-21T12:24:12.758831773Z,2024-10-21 12:24:12.758665302+00:00,10,2,38,A,A,0,233.96,200,130,166471,13011181,233.8,233.96,5,200,1,1,233.73,234.0,400,2,1,1,233.7,234.03,1200,27,1,1,233.66,234.1,28,100,2,1,233.58,234.13,505,400,2,1,233.53,234.17,10,1,1,1,233.5,234.25,100,100,1,1,233.45,234.41,15,500,1,1,233.4,234.43,110,105,2,2,233.39,234.5,10,63,1,4,AAPL,200,200,2,0,0,0,0,0,0,0,0,233.88
2024-10-21T12:24:12.829962896Z,2024-10-21 12:24:12.829796906+00:00,10,2,38,C,B,1,233.73,400,130,165990,13011209,233.8,233.96,5,200,1,1,233.7,234.0,1200,2,1,1,233.66,234.03,28,27,2,1,233.58,234.1,505,100,2,1,233.53,234.13,10,400,1,1,233.5,234.17,100,1,1,1,233.45,234.25,15,100,1,1,233.4,234.41,110,500,2,1,233.39,234.43,10,105,1,2,233.31,234.5,110,63,2,4,AAPL,0,0,-400,-1200,-28,-505,-10,-100,-15,-110,-10,233.88
2024-10-21T12:24:12.829976396Z,2024-10-21 12:24:12.829810064+00:00,10,2,38,A,B,2,233.68,400,130,166332,13011211,233.8,233.96,5,200,1,1,233.7,234.0,1200,2,1,1,233.68,234.03,400,27,1,1,233.66,234.1,28,100,2,1,233.58,234.13,505,400,2,1,233.53,234.17,10,1,1,1,233.5,234.25,100,100,1,1,233.45,234.41,15,500,1,1,233.4,234.43,110,105,2,2,233.39,234.5,10,63,1,4,AAPL,0,0,0,400,28,505,10,100,15,110,10,233.88
2024-10-21T12:24:12.887926720Z,2024-10-21 12:24:12.887759925+00:00,10,2,38,A,B,1,233.71,200,130,166795,13011280,233.8,233.96,5,200,1,1,233.71,234.0,200,2,1,1,233.7,234.03,1200,27,1,1,233.66,234.1,28,100,2,1,233.58,234.13,505,400,2,1,233.53,234.17,10,1,1,1,233.5,234.25,100,100,1,1,233.45,234.41,15,500,1,1,233.4,234.43,110,105,2,2,233.39,234.5,10,63,1,4,AAPL,0,0,200,1200,0,0,0,0,0,0,0,233.88
2024-10-21T12:24:12.974238049Z,2024-10-21 12:24:12.974071654+00:00,10,2,38,A,A,0,233.96,200,130,166395,13011303,233.8,233.96,5,400,1,2,233.71,234.0,200,2,1,1,233.7,234.03,1200,27,1,1,233.66,234.1,28,100,2,1,233.58,234.13,505,400,2,1,233.53,234.17,10,1,1,1,233.5,234.25,100,100,1,1,233.45,234.41,15,500,1,1,233.4,234.43,110,105,2,2,233.39,234.5,10,63,1,4,AAPL,200,200,0,0,0,0,0,0,0,0,0,233.88
2024-10-21T12:24:12.981903881Z,2024-10-21 12:24:12.981737142+00:00,10,2,38,A,A,0,233.94,6,130,166739,13011309,233.8,233.94,5,6,1,1,233.71,233.96,200,400,1,2,233.7,234.0,1200,2,1,1,233.66,234.03,28,27,2,1,233.58,234.1,505,100,2,1,233.53,234.13,10,400,1,1,233.5,234.17,100,1,1,1,233.45,234.25,15,100,1,1,233.4,234.41,110,500,2,1,233.39,234.43,10,105,1,2,AAPL,6,6,400,2,27,100,400,1,100,500,105,233.87
2024-10-21T12:24:12.981949530Z,2024-10-21 12:24:12.981783591+00:00,10,2,38,C,B,1,233.71,200,130,165939,13011310,233.8,233.94,5,6,1,1,233.7,233.96,1200,400,1,2,233.66,234.0,28,2,2,1,233.58,234.03,505,27,2,1,233.53,234.1,10,100,1,1,233.5,234.13,100,400,1,1,233.45,234.17,15,1,1,1,233.4,234.25,110,100,2,1,233.39,234.41,10,500,1,1,233.31,234.43,110,105,2,2,AAPL,0,0,-200,-1200,-28,-505,-10,-100,-15,-110,-10,233.87
2024-10-21T12:24:12.985997932Z,2024-10-21 12:24:12.985831565+00:00,10,2,38,C,A,0,233.94,6,130,166367,13011317,233.8,233.96,5,400,1,2,233.7,234.0,1200,2,1,1,233.66,234.03,28,27,2,1,233.58,234.1,505,100,2,1,233.53,234.13,10,400,1,1,233.5,234.17,100,1,1,1,233.45,234.25,15,100,1,1,233.4,234.41,110,500,2,1,233.39,234.43,10,105,1,2,233.31,234.5,110,63,2,4,AAPL,6,6,400,2,27,100,400,1,100,500,105,233.88
2024-10-21T12:24:13.052769828Z,2024-10-21 12:24:13.052603423+00:00,10,2,38,A,B,3,233.62,400,130,166405,13011374,233.8,233.96,5,400,1,2,233.7,234.0,1200,2,1,1,233.66,234.03,28,27,2,1,233.62,234.1,400,100,1,1,233.58,234.13,505,400,2,1,233.53,234.17,10,1,1,1,233.5,234.25,100,100,1,1,233.45,234.41,15,500,1,1,233.4,234.43,110,105,2,2,233.39,234.5,10,63,1,4,AAPL,0,0,0,0,400,505,10,100,15,110,10,233.88
2024-10-21T12:24:13.053294920Z,2024-10-21 12:24:13.053128647+00:00,10,2,38,A,B,5,233.55,27,130,166273,13011375,233.8,233.96,5,400,1,2,233.7,234.0,1200,2,1,1,233.66,234.03,28,27,2,1,233.62,234.1,400,100,1,1,233.58,234.13,505,400,2,1,233.55,234.17,27,1,1,1,233.53,234.25,10,100,1,1,233.5,234.41,100,500,1,1,233.45,234.43,15,105,1,2,233.4,234.5,110,63,2,4,AAPL,0,0,0,0,0,0,27,10,100,15,110,233.88
2024-10-21T12:24:13.053320162Z,2024-10-21 12:24:13.053154026+00:00,10,2,38,C,B,2,233.66,27,130,166136,13011376,233.8,233.96,5,400,1,2,233.7,234.0,1200,2,1,1,233.66,234.03,1,27,1,1,233.62,234.1,400,100,1,1,233.58,234.13,505,400,2,1,233.55,234.17,27,1,1,1,233.53,234.25,10,100,1,1,233.5,234.41,100,500,1,1,233.45,234.43,15,105,1,2,233.4,234.5,110,63,2,4,AAPL,0,0,0,-27,0,0,0,0,0,0,0,233.88
2024-10-21T12:24:13.185024995Z,2024-10-21 12:24:13.184858615+00:00,10,2,38,A,B,3,233.63,200,130,166380,13011463,233.8,233.96,5,400,1,2,233.7,234.0,1200,2,1,1,233.66,234.03,1,27,1,1,233.63,234.1,200,100,1,1,233.58,234.13,505,400,2,1,233.55,234.17,27,1,1,1,233.53,234.25,10,100,1,1,233.5,234.41,100,500,1,1,233.45,234.43,15,105,1,2,233.4,234.5,110,63,2,4,AAPL,0,0,0,0,200,0,0,0,0,0,0,233.88
2024-10-21T12:24:13.203151981Z,2024-10-21 12:24:13.202985661+00:00,10,2,38,A,B,2,233.68,200,130,166320,13011562,233.8,233.96,5,400,1,2,233.7,234.0,1200,2,1,1,233.68,234.03,200,27,1,1,233.66,234.1,1,100,1,1,233.58,234.13,505,400,2,1,233.55,234.17,27,1,1,1,233.53,234.25,10,100,1,1,233.5,234.41,100,500,1,1,233.45,234.43,15,105,1,2,233.4,234.5,110,63,2,4,AAPL,0,0,0,200,1,0,0,0,0,0,0,233.88
2024-10-21T12:24:13.538567140Z,2024-10-21 12:24:13.538400660+00:00,10,2,38,A,B,2,233.68,200,130,166480,13011788,233.8,233.96,5,400,1,2,233.7,234.0,1200,2,1,1,233.68,234.03,400,27,2,1,233.66,234.1,1,100,1,1,233.58,234.13,505,400,2,1,233.55,234.17,27,1,1,1,233.53,234.25,10,100,1,1,233.5,234.41,100,500,1,1,233.45,234.43,15,105,1,2,233.4,234.5,110,63,2,4,AAPL,0,0,0,200,0,0,0,0,0,0,0,233.88
2024-10-21T12:24:13.589336955Z,2024-10-21 12:24:13.589170912+00:00,10,2,38,C,B,2,233.68,200,130,166043,13011843,233.8,233.96,5,400,1,2,233.7,234.0,1200,2,1,1,233.68,234.03,200,27,1,1,233.66,234.1,1,100,1,1,233.58,234.13,505,400,2,1,233.55,234.17,27,1,1,1,233.53,234.25,10,100,1,1,233.5,234.41,100,500,1,1,233.45,234.43,15,105,1,2,233.4,234.5,110,63,2,4,AAPL,0,0,0,-200,0,0,0,0,0,0,0,233.88
2024-10-21T12:24:13.589349547Z,2024-10-21 12:24:13.589183060+00:00,10,2,38,A,B,1,233.71,200,130,166487,13011844,233.8,233.96,5,400,1,2,233.71,234.0,200,2,1,1,233.7,234.03,1200,27,1,1,233.66,234.1,1,100,1,1,233.58,234.13,505,400,2,1,233.55,234.17,27,1,1,1,233.53,234.25,10,100,1,1,233.5,234.41,100,500,1,1,233.45,234.43,15,105,1,2,233.4,234.5,110,63,2,4,AAPL,0,0,200,1200,0,0,0,0,0,0,0,233.88
2024-10-21T12:24:13.923159059Z,2024-10-21 12:24:13.922992508+00:00,10,2,38,C,B,5,233.55,27,130,166551,13011979,233.8,233.96,5,400,1,2,233.71,234.0,200,2,1,1,233.7,234.03,1200,27,1,1,233.66,234.1,1,100,1,1,233.58,234.13,505,400,2,1,233.53,234.17,10,1,1,1,233.5,234.25,100,100,1,1,233.45,234.41,15,500,1,1,233.4,234.43,110,105,2,2,233.39,234.5,10,63,1,4,AAPL,0,0,0,0,0,0,-27,-10,-100,-15,-110,233.88
2024-10-21T12:24:13.923293151Z,2024-10-21 12:24:13.923126726+00:00,10,2,38,A,B,3,233.66,30,130,166425,13011980,233.8,233.96,5,400,1,2,233.71,234.0,200,2,1,1,233.7,234.03,1200,27,1,1,233.66,234.1,31,100,2,1,233.58,234.13,505,400,2,1,233.53,234.17,10,1,1,1,233.5,234.25,100,100,1,1,233.45,234.41,15,500,1,1,233.4,234.43,110,105,2,2,233.39,234.5,10,63,1,4,AAPL,0,0,0,0,30,0,0,0,0,0,0,233.88
2024-10-21T12:24:15.709004892Z,2024-10-21 12:24:15.708838775+00:00,10,2,38,C,A,2,234.03,27,130,166117,13013886,233.8,233.96,5,400,1,2,233.71,234.0,200,2,1,1,233.7,234.1,1200,100,1,1,233.66,234.13,31,400,2,1,233.58,234.17,505,1,2,1,233.53,234.25,10,100,1,1,233.5,234.41,100,500,1,1,233.45,234.43,15,105,1,2,233.4,234.5,110,63,2,4,233.39,234.75,10,1,1,1,AAPL,0,0,0,27,100,400,1,100,500,105,63,233.88
2024-10-21T12:24:15.709139884Z,2024-10-21 12:24:15.708973640+00:00,10,2,38,A,A,1,233.98,29,130,166244,13013888,233.8,233.96,5,400,1,2,233.71,233.98,200,29,1,1,233.7,234.0,1200,2,1,1,233.66,234.1,31,100,2,1,233.58,234.13,505,400,2,1,233.53,234.17,10,1,1,1,233.5,234.25,100,100,1,1,233.45,234.41,15,500,1,1,233.4,234.43,110,105,2,2,233.39,234.5,10,63,1,4,AAPL,0,0,29,2,100,400,1,100,500,105,63,233.88
2024-10-21T12:24:15.716746619Z,2024-10-21 12:24:15.716580295+00:00,10,2,38,C,A,1,233.98,29,130,166324,13013896,233.8,233.96,5,400,1,2,233.71,234.0,200,2,1,1,233.7,234.1,1200,100,1,1,233.66,234.13,31,400,2,1,233.58,234.17,505,1,2,1,233.53,234.25,10,100,1,1,233.5,234.41,100,500,1,1,233.45,234.43,15,105,1,2,233.4,234.5,110,63,2,4,233.39,234.75,10,1,1,1,AAPL,0,0,29,2,100,400,1,100,500,105,63,233.88
2024-10-21T12:24:17.552123107Z,2024-10-21 12:24:17.551956961+00:00,10,2,38,A,A,2,234.03,27,130,166146,13015292,233.8,233.96,5,400,1,2,233.71,234.0,200,2,1,1,233.7,234.03,1200,27,1,1,233.66,234.1,31,100,2,1,233.58,234.13,505,400,2,1,233.53,234.17,10,1,1,1,233.5,234.25,100,100,1,1,233.45,234.41,15,500,1,1,233.4,234.43,110,105,2,2,233.39,234.5,10,63,1,4,AAPL,0,0,0,27,100,400,1,100,500,105,63,233.88
2024-10-21T12:24:18.858293636Z,2024-10-21 12:24:18.858127605+00:00,10,2,38,A,B,0,233.8,100,130,166031,13016509,233.8,233.96,105,400,2,2,233.71,234.0,200,2,1,1,233.7,234.03,1200,27,1,1,233.66,234.1,31,100,2,1,233.58,234.13,505,400,2,1,233.53,234.17,10,1,1,1,233.5,234.25,100,100,1,1,233.45,234.41,15,500,1,1,233.4,234.43,110,105,2,2,233.39,234.5,10,63,1,4,AAPL,100,100,0,0,0,0,0,0,0,0,0,233.88
2024-10-21T12:24:25.049504145Z,2024-10-21 12:24:25.049338154+00:00,10,2,38,C,A,2,234.03,27,130,165991,13021095,233.8,233.96,105,400,2,2,233.71,234.0,200,2,1,1,233.7,234.1,1200,100,1,1,233.66,234.13,31,400,2,1,233.58,234.17,505,1,2,1,233.53,234.25,10,100,1,1,233.5,234.41,100,500,1,1,233.45,234.43,15,105,1,2,233.4,234.5,110,63,2,4,233.39,234.75,10,1,1,1,AAPL,0,0,0,27,100,400,1,100,500,105,63,233.88
2024-10-21T12:24:25.049548880Z,2024-10-21 12:24:25.049382422+00:00,10,2,38,A,A,1,233.98,28,130,166458,13021096,233.8,233.96,105,400,2,2,233.71,233.98,200,28,1,1,233.7,234.0,1200,2,1,1,233.66,234.1,31,100,2,1,233.58,234.13,505,400,2,1,233.53,234.17,10,1,1,1,233.5,234.25,100,100,1,1,233.45,234.41,15,500,1,1,233.4,234.43,110,105,2,2,233.39,234.5,10,63,1,4,AAPL,0,0,28,2,100,400,1,100,500,105,63,233.88
2024-10-21T12:24:25.060245863Z,2024-10-21 12:24:25.060079940+00:00,10,2,38,C,A,1,233.98,28,130,165923,13021116,233.8,233.96,105,400,2,2,233.71,234.0,200,2,1,1,233.7,234.1,1200,100,1,1,233.66,234.13,31,400,2,1,233.58,234.17,505,1,2,1,233.53,234.25,10,100,1,1,233.5,234.41,100,500,1,1,233.45,234.43,15,105,1,2,233.4,234.5,110,63,2,4,233.39,234.75,10,1,1,1,AAPL,0,0,28,2,100,400,1,100,500,105,63,233.88
2024-10-21T12:24:25.923090996Z,2024-10-21 12:24:25.922924503+00:00,10,2,38,A,A,2,234.03,26,130,166493,13021866,233.8,233.96,105,400,2,2,233.71,234.0,200,2,1,1,233.7,234.03,1200,26,1,1,233.66,234.1,31,100,2,1,233.58,234.13,505,400,2,1,233.53,234.17,10,1,1,1,233.5,234.25,100,100,1,1,233.45,234.41,15,500,1,1,233.4,234.43,110,105,2,2,233.39,234.5,10,63,1,4,AAPL,0,0,0,26,100,400,1,100,500,105,63,233.88
2024-10-21T12:24:33.385339105Z,2024-10-21 12:24:33.385173258+00:00,10,2,38,C,A,2,234.03,26,130,165847,13026898,233.8,233.96,105,400,2,2,233.71,234.0,200,2,1,1,233.7,234.1,1200,100,1,1,233.66,234.13,31,400,2,1,233.58,234.17,505,1,2,1,233.53,234.25,10,100,1,1,233.5,234.41,100,500,1,1,233.45,234.43,15,105,1,2,233.4,234.5,110,63,2,4,233.39,234.75,10,1,1,1,AAPL,0,0,0,26,100,400,1,100,500,105,63,233.88
2024-10-21T12:24:33.385363270Z,2024-10-21 12:24:33.385196713+00:00,10,2,38,A,A,1,233.98,29,130,166557,13026899,233.8,233.96,105,400,2,2,233.71,233.98,200,29,1,1,233.7,234.0,1200,2,1,1,233.66,234.1,31,100,2,1,233.58,234.13,505,400,2,1,233.53,234.17,10,1,1,1,233.5,234.25,100,100,1,1,233.45,234.41,15,500,1,1,233.4,234.43,110,105,2,2,233.39,234.5,10,63,1,4,AAPL,0,0,29,2,100,400,1,100,500,105,63,233.88
2024-10-21T12:24:33.391357628Z,2024-10-21 12:24:33.391191505+00:00,10,2,38,C,A,1,233.98,29,130,166123,13026904,233.8,233.96,105,400,2,2,233.71,234.0,200,2,1,1,233.7,234.1,1200,100,1,1,233.66,234.13,31,400,2,1,233.58,234.17,505,1,2,1,233.53,234.25,10,100,1,1,233.5,234.41,100,500,1,1,233.45,234.43,15,105,1,2,233.4,234.5,110,63,2,4,233.39,234.75,10,1,1,1,AAPL,0,0,29,2,100,400,1,100,500,105,63,233.88
2024-10-21T12:24:33.923269202Z,2024-10-21 12:24:33.923102791+00:00,10,2,38,A,A,2,234.03,26,130,166411,13027549,233.8,233.96,105,400,2,2,233.71,234.0,200,2,1,1,233.7,234.03,1200,26,1,1,233.66,234.1,31,100,2,1,233.58,234.13,505,400,2,1,233.53,234.17,10,1,1,1,233.5,234.25,100,100,1,1,233.45,234.41,15,500,1,1,233.4,234.43,110,105,2,2,233.39,234.5,10,63,1,4,AAPL,0,0,0,26,100,400,1,100,500,105,63,233.88
2024-10-21T12:24:37.923110609Z,2024-10-21 12:24:37.922944460+00:00,10,2,38,C,A,2,234.03,26,130,166149,13030243,233.8,233.96,105,400,2,2,233.71,234.0,200,2,1,1,233.7,234.1,1200,100,1,1,233.66,234.13,31,400,2,1,233.58,234.17,505,1,2,1,233.53,234.25,10,100,1,1,233.5,234.41,100,500,1,1,233.45,234.43,15,105,1,2,233.4,234.5,110,63,2,4,233.39,234.75,10,1,1,1,AAPL,0,0,0,26,100,400,1,100,500,105,63,233.88
2024-10-21T12:24:37.923194567Z,2024-10-21 12:24:37.923028006+00:00,10,2,38,A,A,1,233.98,27,130,166561,13030244,233.8,233.96,105,400,2,2,233.71,233.98,200,27,1,1,233.7,234.0,1200,2,1,1,233.66,234.1,31,100,2,1,233.58,234.13,505,400,2,1,233.53,234.17,10,1,1,1,233.5,234.25,100,100,1,1,233.45,234.41,15,500,1,1,233.4,234.43,110,105,2,2,233.39,234.5,10,63,1,4,AAPL,0,0,27,2,100,400,1,100,500,105,63,233.88
2024-10-21T12:24:40.307842089Z,2024-10-21 12:24:40.307674730+00:00,10,2,38,T,N,0,233.84,127,130,167359,13031847,233.8,233.96,105,400,2,2,233.71,233.98,200,27,1,1,233.7,234.0,1200,2,1,1,233.66,234.1,31,100,2,1,233.58,234.13,505,400,2,1,233.53,234.17,10,1,1,1,233.5,234.25,100,100,1,1,233.45,234.41,15,500,1,1,233.4,234.43,110,105,2,2,233.39,234.5,10,63,1,4,AAPL,0,0,0,0,0,0,0,0,0,0,0,233.88
2024-10-21T12:24:40.308161486Z,2024-10-21 12:24:40.307995193+00:00,10,2,38,A,B,0,233.8,2,130,166293,13031848,233.8,233.96,107,400,3,2,233.71,233.98,200,27,1,1,233.7,234.0,1200,2,1,1,233.66,234.1,31,100,2,1,233.58,234.13,505,400,2,1,233.53,234.17,10,1,1,1,233.5,234.25,100,100,1,1,233.45,234.41,15,500,1,1,233.4,234.43,110,105,2,2,233.39,234.5,10,63,1,4,AAPL,2,2,0,0,0,0,0,0,0,0,0,233.88
2024-10-21T12:24:40.308163000Z,2024-10-21 12:24:40.307996031+00:00,10,2,38,A,B,1,233.79,100,130,166969,13031849,233.8,233.96,107,400,3,2,233.79,233.98,100,27,1,1,233.71,234.0,200,2,1,1,233.7,234.1,1200,100,1,1,233.66,234.13,31,400,2,1,233.58,234.17,505,1,2,1,233.53,234.25,10,100,1,1,233.5,234.41,100,500,1,1,233.45,234.43,15,105,1,2,233.4,234.5,110,63,2,4,AAPL,0,0,100,200,1200,31,505,10,100,15,110,233.88
2024-10-21T12:24:40.308173860Z,2024-10-21 12:24:40.308007727+00:00,10,2,38,C,B,0,233.8,2,130,166133,13031850,233.8,233.96,105,400,2,2,233.79,233.98,100,27,1,1,233.71,234.0,200,2,1,1,233.7,234.1,1200,100,1,1,233.66,234.13,31,400,2,1,233.58,234.17,505,1,2,1,233.53,234.25,10,100,1,1,233.5,234.41,100,500,1,1,233.45,234.43,15,105,1,2,233.4,234.5,110,63,2,4,AAPL,-2,-2,0,0,0,0,0,0,0,0,0,233.88
2024-10-21T12:24:40.308191984Z,2024-10-21 12:24:40.308025276+00:00,10,2,38,C,A,0,233.96,200,130,166708,13031851,233.8,233.96,105,200,2,1,233.79,233.98,100,27,1,1,233.71,234.0,200,2,1,1,233.7,234.1,1200,100,1,1,233.66,234.13,31,400,2,1,233.58,234.17,505,1,2,1,233.53,234.25,10,100,1,1,233.5,234.41,100,500,1,1,233.45,234.43,15,105,1,2,233.4,234.5,110,63,2,4,AAPL,-200,-200,0,0,0,0,0,0,0,0,0,233.88
2024-10-21T12:24:40.308202091Z,2024-10-21 12:24:40.308036005+00:00,10,2,38,C,A,0,233.96,200,130,166086,13031852,233.8,233.98,105,27,2,1,233.79,234.0,100,2,1,1,233.71,234.1,200,100,1,1,233.7,234.13,1200,400,1,1,233.66,234.17,31,1,2,1,233.58,234.25,505,100,2,1,233.53,234.41,10,500,1,1,233.5,234.43,100,105,1,2,233.45,234.5,15,63,1,4,233.4,234.75,110,1,2,1,AAPL,200,200,27,2,100,400,1,100,500,105,63,233.89
2024-10-21T12:24:40.308571346Z,2024-10-21 12:24:40.308405475+00:00,10,2,38,C,B,1,233.79,100,130,165871,13031857,233.8,233.98,105,27,2,1,233.71,234.0,200,2,1,1,233.7,234.1,1200,100,1,1,233.66,234.13,31,400,2,1,233.58,234.17,505,1,2,1,233.53,234.25,10,100,1,1,233.5,234.41,100,500,1,1,233.45,234.43,15,105,1,2,233.4,234.5,110,63,2,4,233.39,234.75,10,1,1,1,AAPL,0,0,-100,-200,-1200,-31,-505,-10,-100,-15,-110,233.89
2024-10-21T12:24:40.309914708Z,2024-10-21 12:24:40.309748359+00:00,10,2,38,A,B,1,233.79,100,130,166349,13031868,233.8,233.98,105,27,2,1,233.79,234.0,100,2,1,1,233.71,234.1,200,100,1,1,233.7,234.13,1200,400,1,1,233.66,234.17,31,1,2,1,233.58,234.25,505,100,2,1,233.53,234.41,10,500,1,1,233.5,234.43,100,105,1,2,233.45,234.5,15,63,1,4,233.4,234.75,110,1,2,1,AAPL,0,0,100,200,1200,31,505,10,100,15,110,233.89
2024-10-21T12:24:40.310359600Z,2024-10-21 12:24:40.310193512+00:00,10,2,38,C,B,1,233.79,100,130,166088,13031873,233.8,233.98,105,27,2,1,233.71,234.0,200,2,1,1,233.7,234.1,1200,100,1,1,233.66,234.13,31,400,2,1,233.58,234.17,505,1,2,1,233.53,234.25,10,100,1,1,233.5,234.41,100,500,1,1,233.45,234.43,15,105,1,2,233.4,234.5,110,63,2,4,233.39,234.75,10,1,1,1,AAPL,0,0,-100,-200,-1200,-31,-505,-10,-100,-15,-110,233.89
2024-10-21T12:24:40.353976280Z,2024-10-21 12:24:40.353810051+00:00,10,2,38,A,A,0,233.96,200,130,166229,13031906,233.8,233.96,105,200,2,1,233.71,233.98,200,27,1,1,233.7,234.0,1200,2,1,1,233.66,234.1,31,100,2,1,233.58,234.13,505,400,2,1,233.53,234.17,10,1,1,1,233.5,234.25,100,100,1,1,233.45,234.41,15,500,1,1,233.4,234.43,110,105,2,2,233.39,234.5,10,63,1,4,AAPL,200,200,27,2,100,400,1,100,500,105,63,233.88
2024-10-21T12:24:40.377414086Z,2024-10-21 12:24:40.377247665+00:00,10,2,38,C,A,0,233.96,200,130,166421,13031918,233.8,233.98,105,27,2,1,233.71,234.0,200,2,1,1,233.7,234.1,1200,100,1,1,233.66,234.13,31,400,2,1,233.58,234.17,505,1,2,1,233.53,234.25,10,100,1,1,233.5,234.41,100,500,1,1,233.45,234.43,15,105,1,2,233.4,234.5,110,63,2,4,233.39,234.75,10,1,1,1,AAPL,200,200,27,2,100,400,1,100,500,105,63,233.89
2024-10-21T12:24:40.379975554Z,2024-10-21 12:24:40.379809120+00:00,10,2,38,C,A,0,233.98,27,130,166434,13031919,233.8,234.0,105,2,2,1,233.71,234.1,200,100,1,1,233.7,234.13,1200,400,1,1,233.66,234.17,31,1,2,1,233.58,234.25,505,100,2,1,233.53,234.41,10,500,1,1,233.5,234.43,100,105,1,2,233.45,234.5,15,63,1,4,233.4,234.75,110,1,2,1,233.39,234.79,10,2000,1,1,AAPL,27,27,2,100,400,1,100,500,105,63,1,233.9
2024-10-21T12:24:40.416037866Z,2024-10-21 12:24:40.415871461+00:00,10,2,38,A,A,1,234.02,200,130,166405,13031935,233.8,234.0,105,2,2,1,233.71,234.02,200,200,1,1,233.7,234.1,1200,100,1,1,233.66,234.13,31,400,2,1,233.58,234.17,505,1,2,1,233.53,234.25,10,100,1,1,233.5,234.41,100,500,1,1,233.45,234.43,15,105,1,2,233.4,234.5,110,63,2,4,233.39,234.75,10,1,1,1,AAPL,0,0,200,100,400,1,100,500,105,63,1,233.9
2024-10-21T12:24:40.464995283Z,2024-10-21 12:24:40.464828695+00:00,10,2,38,A,A,1,234.02,200,130,166588,13031977,233.8,234.0,105,2,2,1,233.71,234.02,200,400,1,2,233.7,234.1,1200,100,1,1,233.66,234.13,31,400,2,1,233.58,234.17,505,1,2,1,233.53,234.25,10,100,1,1,233.5,234.41,100,500,1,1,233.45,234.43,15,105,1,2,233.4,234.5,110,63,2,4,233.39,234.75,10,1,1,1,AAPL,0,0,200,0,0,0,0,0,0,0,0,233.9
2024-10-21T12:24:40.657004232Z,2024-10-21 12:24:40.656837789+00:00,10,2,38,C,B,1,233.71,200,130,166443,13032132,233.8,234.0,105,2,2,1,233.7,234.02,1200,400,1,2,233.66,234.1,31,100,2,1,233.58,234.13,505,400,2,1,233.53,234.17,10,1,1,1,233.5,234.25,100,100,1,1,233.45,234.41,15,500,1,1,233.4,234.43,110,105,2,2,233.39,234.5,10,63,1,4,233.31,234.75,110,1,2,1,AAPL,0,0,-200,-1200,-31,-505,-10,-100,-15,-110,-10,233.9
2024-10-21T12:24:40.763757375Z,2024-10-21 12:24:40.763590881+00:00,10,2,38,A,B,1,233.71,200,130,166494,13032319,233.8,234.0,105,2,2,1,233.71,234.02,200,400,1,2,233.7,234.1,1200,100,1,1,233.66,234.13,31,400,2,1,233.58,234.17,505,1,2,1,233.53,234.25,10,100,1,1,233.5,234.41,100,500,1,1,233.45,234.43,15,105,1,2,233.4,234.5,110,63,2,4,233.39,234.75,10,1,1,1,AAPL,0,0,200,1200,31,505,10,100,15,110,10,233.9
2024-10-21T12:24:43.066523534Z,2024-10-21 12:24:43.066357159+00:00,10,2,38,A,B,0,233.88,1,130,166375,13033852,233.88,234.0,1,2,1,1,233.8,234.02,105,400,2,2,233.71,234.1,200,100,1,1,233.7,234.13,1200,400,1,1,233.66,234.17,31,1,2,1,233.58,234.25,505,100,2,1,233.53,234.41,10,500,1,1,233.5,234.43,100,105,1,2,233.45,234.5,15,63,1,4,233.4,234.75,110,1,2,1,AAPL,1,1,105,200,1200,31,505,10,100,15,110,233.94
2024-10-21T12:24:43.129607008Z,2024-10-21 12:24:43.129440388+00:00,10,2,38,A,A,2,234.09,27,130,166620,13033910,233.88,234.0,1,2,1,1,233.8,234.02,105,400,2,2,233.71,234.09,200,27,1,1,233.7,234.1,1200,100,1,1,233.66,234.13,31,400,2,1,233.58,234.17,505,1,2,1,233.53,234.25,10,100,1,1,233.5,234.41,100,500,1,1,233.45,234.43,15,105,1,2,233.4,234.5,110,63,2,4,AAPL,0,0,0,27,100,400,1,100,500,105,63,233.94
2024-10-21T12:24:55.150110202Z,2024-10-21 12:24:55.149943017+00:00,10,2,38,T,A,0,233.88,1,130,167185,13042533,233.88,234.0,1,2,1,1,233.8,234.02,105,400,2,2,233.71,234.09,200,27,1,1,233.7,234.1,1200,100,1,1,233.66,234.13,31,400,2,1,233.58,234.17,505,1,2,1,233.53,234.25,10,100,1,1,233.5,234.41,100,500,1,1,233.45,234.43,15,105,1,2,233.4,234.5,110,63,2,4,AAPL,0,0,0,0,0,0,0,0,0,0,0,233.94
2024-10-21T12:24:55.150110202Z,2024-10-21 12:24:55.149943017+00:00,10,2,38,C,B,0,233.88,1,130,167185,13042533,233.8,234.0,105,2,2,1,233.71,234.02,200,400,1,2,233.7,234.09,1200,27,1,1,233.66,234.1,31,100,2,1,233.58,234.13,505,400,2,1,233.53,234.17,10,1,1,1,233.5,234.25,100,100,1,1,233.45,234.41,15,500,1,1,233.4,234.43,110,105,2,2,233.39,234.5,10,63,1,4,AAPL,-1,-1,-105,-200,-1200,-31,-505,-10,-100,-15,-110,233.9
2024-10-21T12:24:55.150138721Z,2024-10-21 12:24:55.149972348+00:00,10,2,38,A,A,0,233.94,38,130,166373,13042534,233.8,233.94,105,38,2,1,233.71,234.0,200,2,1,1,233.7,234.02,1200,400,1,2,233.66,234.09,31,27,2,1,233.58,234.1,505,100,2,1,233.53,234.13,10,400,1,1,233.5,234.17,100,1,1,1,233.45,234.25,15,100,1,1,233.4,234.41,110,500,2,1,233.39,234.43,10,105,1,2,AAPL,38,38,2,400,27,100,400,1,100,500,105,233.87
2024-10-21T12:24:55.150156298Z,2024-10-21 12:24:55.149990092+00:00,10,2,38,A,A,0,233.94,26,130,166206,13042535,233.8,233.94,105,64,2,2,233.71,234.0,200,2,1,1,233.7,234.02,1200,400,1,2,233.66,234.09,31,27,2,1,233.58,234.1,505,100,2,1,233.53,234.13,10,400,1,1,233.5,234.17,100,1,1,1,233.45,234.25,15,100,1,1,233.4,234.41,110,500,2,1,233.39,234.43,10,105,1,2,AAPL,26,26,0,0,0,0,0,0,0,0,0,233.87
2024-10-21T12:24:55.150170265Z,2024-10-21 12:24:55.150004189+00:00,10,2,38,A,A,1,233.98,26,130,166076,13042536,233.8,233.94,105,64,2,2,233.71,233.98,200,26,1,1,233.7,234.0,1200,2,1,1,233.66,234.02,31,400,2,2,233.58,234.09,505,27,2,1,233.53,234.1,10,100,1,1,233.5,234.13,100,400,1,1,233.45,234.17,15,1,1,1,233.4,234.25,110,100,2,1,233.39,234.41,10,500,1,1,AAPL,0,0,26,2,400,27,100,400,1,100,500,233.87
2024-10-21T12:24:55.250218188Z,2024-10-21 12:24:55.250051974+00:00,10,2,38,C,A,0,233.94,38,130,166214,13042633,233.8,233.94,105,26,2,1,233.71,233.98,200,26,1,1,233.7,234.0,1200,2,1,1,233.66,234.02,31,400,2,2,233.58,234.09,505,27,2,1,233.53,234.1,10,100,1,1,233.5,234.13,100,400,1,1,233.45,234.17,15,1,1,1,233.4,234.25,110,100,2,1,233.39,234.41,10,500,1,1,AAPL,-38,-38,0,0,0,0,0,0,0,0,0,233.87
2024-10-21T12:24:55.250245636Z,2024-10-21 12:24:55.250079517+00:00,10,2,38,C,A,1,233.98,26,130,166119,13042634,233.8,233.94,105,26,2,1,233.71,234.0,200,2,1,1,233.7,234.02,1200,400,1,2,233.66,234.09,31,27,2,1,233.58,234.1,505,100,2,1,233.53,234.13,10,400,1,1,233.5,234.17,100,1,1,1,233.45,234.25,15,100,1,1,233.4,234.41,110,500,2,1,233.39,234.43,10,105,1,2,AAPL,0,0,26,2,400,27,100,400,1,100,500,233.87
2024-10-21T12:24:55.403930872Z,2024-10-21 12:24:55.403764807+00:00,10,2,38,C,A,0,233.94,26,130,166065,13042985,233.8,234.0,105,2,2,1,233.71,234.02,200,400,1,2,233.7,234.09,1200,27,1,1,233.66,234.1,31,100,2,1,233.58,234.13,505,400,2,1,233.53,234.17,10,1,1,1,233.5,234.25,100,100,1,1,233.45,234.41,15,500,1,1,233.4,234.43,110,105,2,2,233.39,234.5,10,63,1,4,AAPL,26,26,2,400,27,100,400,1,100,500,105,233.9
2024-10-21T12:24:58.867150506Z,2024-10-21 12:24:58.866984470+00:00,10,2,38,A,A,0,233.95,200,130,166036,13044827,233.8,233.95,105,200,2,1,233.71,234.0,200,2,1,1,233.7,234.02,1200,400,1,2,233.66,234.09,31,27,2,1,233.58,234.1,505,100,2,1,233.53,234.13,10,400,1,1,233.5,234.17,100,1,1,1,233.45,234.25,15,100,1,1,233.4,234.41,110,500,2,1,233.39,234.43,10,105,1,2,AAPL,200,200,2,400,27,100,400,1,100,500,105,233.875
2024-10-21T12:25:00.039367879Z,2024-10-21 12:25:00.039201756+00:00,10,2,38,C,A,3,234.09,27,130,166123,13045779,233.8,233.95,105,200,2,1,233.71,234.0,200,2,1,1,233.7,234.02,1200,400,1,2,233.66,234.1,31,100,2,1,233.58,234.13,505,400,2,1,233.53,234.17,10,1,1,1,233.5,234.25,100,100,1,1,233.45,234.41,15,500,1,1,233.4,234.43,110,105,2,2,233.39,234.5,10,63,1,4,AAPL,0,0,0,0,27,100,400,1,100,500,105,233.875
2024-10-21T12:25:00.039422307Z,2024-10-21 12:25:00.039255807+00:00,10,2,38,C,B,3,233.66,30,130,166500,13045782,233.8,233.95,105,200,2,1,233.71,234.0,200,2,1,1,233.7,234.02,1200,400,1,2,233.66,234.1,1,100,1,1,233.58,234.13,505,400,2,1,233.53,234.17,10,1,1,1,233.5,234.25,100,100,1,1,233.45,234.41,15,500,1,1,233.4,234.43,110,105,2,2,233.39,234.5,10,63,1,4,AAPL,0,0,0,0,-30,0,0,0,0,0,0,233.875
2024-10-21T12:25:00.940467712Z,2024-10-21 12:25:00.940301280+00:00,10,2,38,A,B,0,233.81,1,130,166432,13048050,233.81,233.95,1,200,1,1,233.8,234.0,105,2,2,1,233.71,234.02,200,400,1,2,233.7,234.1,1200,100,1,1,233.66,234.13,1,400,1,1,233.58,234.17,505,1,2,1,233.53,234.25,10,100,1,1,233.5,234.41,100,500,1,1,233.45,234.43,15,105,1,2,233.4,234.5,110,63,2,4,AAPL,1,1,105,200,1200,1,505,10,100,15,110,233.88
2024-10-21T12:25:03.426126208Z,2024-10-21 12:25:03.425959742+00:00,10,2,38,A,A,1,233.97,7,130,166466,13052492,233.81,233.95,1,200,1,1,233.8,233.97,105,7,2,1,233.71,234.0,200,2,1,1,233.7,234.02,1200,400,1,2,233.66,234.1,1,100,1,1,233.58,234.13,505,400,2,1,233.53,234.17,10,1,1,1,233.5,234.25,100,100,1,1,233.45,234.41,15,500,1,1,233.4,234.43,110,105,2,2,AAPL,0,0,7,2,400,100,400,1,100,500,105,233.88
2024-10-21T12:25:07.929188046Z,2024-10-21 12:25:07.929021771+00:00,10,2,38,C,A,3,234.02,200,130,166275,13057385,233.81,233.95,1,200,1,1,233.8,233.97,105,7,2,1,233.71,234.0,200,2,1,1,233.7,234.02,1200,200,1,1,233.66,234.1,1,100,1,1,233.58,234.13,505,400,2,1,233.53,234.17,10,1,1,1,233.5,234.25,100,100,1,1,233.45,234.41,15,500,1,1,233.4,234.43,110,105,2,2,AAPL,0,0,0,0,-200,0,0,0,0,0,0,233.88
2024-10-21T12:25:07.929203389Z,2024-10-21 12:25:07.929036599+00:00,10,2,38,A,A,3,234.01,400,130,166790,13057386,233.81,233.95,1,200,1,1,233.8,233.97,105,7,2,1,233.71,234.0,200,2,1,1,233.7,234.01,1200,400,1,1,233.66,234.1,1,100,1,1,233.58,234.13,505,400,2,1,233.53,234.17,10,1,1,1,233.5,234.25,100,100,1,1,233.45,234.41,15,500,1,1,233.4,234.43,110,105,2,2,AAPL,0,0,0,0,400,0,0,0,0,0,0,233.88
2024-10-21T12:25:08.719128994Z,2024-10-21 12:25:08.718962947+00:00,10,2,38,C,A,1,233.97,7,130,166047,13057965,233.81,233.95,1,200,1,1,233.8,234.0,105,2,2,1,233.71,234.01,200,400,1,1,233.7,234.1,1200,100,1,1,233.66,234.13,1,400,1,1,233.58,234.17,505,1,2,1,233.53,234.25,10,100,1,1,233.5,234.41,100,500,1,1,233.45,234.43,15,105,1,2,233.4,234.5,110,63,2,4,AAPL,0,0,7,2,400,100,400,1,100,500,105,233.88
2024-10-21T12:25:08.828580021Z,2024-10-21 12:25:08.828413687+00:00,10,2,38,A,B,0,233.85,100,130,166334,13058052,233.85,233.95,100,200,1,1,233.81,234.0,1,2,1,1,233.8,234.01,105,400,2,1,233.71,234.1,200,100,1,1,233.7,234.13,1200,400,1,1,233.66,234.17,1,1,1,1,233.58,234.25,505,100,2,1,233.53,234.41,10,500,1,1,233.5,234.43,100,105,1,2,233.45,234.5,15,63,1,4,AAPL,100,100,1,105,200,1200,1,505,10,100,15,233.89999999999998
2024-10-21T12:25:09.010032581Z,2024-10-21 12:25:09.009866477+00:00,10,2,38,C,B,3,233.71,200,130,166104,13058226,233.85,233.95,100,200,1,1,233.81,234.0,1,2,1,1,233.8,234.01,105,400,2,1,233.7,234.1,1200,100,1,1,233.66,234.13,1,400,1,1,233.58,234.17,505,1,2,1,233.53,234.25,10,100,1,1,233.5,234.41,100,500,1,1,233.45,234.43,15,105,1,2,233.4,234.5,110,63,2,4,AAPL,0,0,0,0,-200,-1200,-1,-505,-10,-100,-15,233.89999999999998
2024-10-21T12:25:09.010056790Z,2024-10-21 12:25:09.009890544+00:00,10,2,38,A,B,4,233.69,200,130,166246,13058227,233.85,233.95,100,200,1,1,233.81,234.0,1,2,1,1,233.8,234.01,105,400,2,1,233.7,234.1,1200,100,1,1,233.69,234.13,200,400,1,1,233.66,234.17,1,1,1,1,233.58,234.25,505,100,2,1,233.53,234.41,10,500,1,1,233.5,234.43,100,105,1,2,233.45,234.5,15,63,1,4,AAPL,0,0,0,0,0,200,1,505,10,100,15,233.89999999999998
2024-10-21T12:25:09.088943398Z,2024-10-21 12:25:09.088777165+00:00,10,2,38,A,B,4,233.69,200,130,166233,13058312,233.85,233.95,100,200,1,1,233.81,234.0,1,2,1,1,233.8,234.01,105,400,2,1,233.7,234.1,1200,100,1,1,233.69,234.13,400,400,2,1,233.66,234.17,1,1,1,1,233.58,234.25,505,100,2,1,233.53,234.41,10,500,1,1,233.5,234.43,100,105,1,2,233.45,234.5,15,63,1,4,AAPL,0,0,0,0,0,200,0,0,0,0,0,233.89999999999998
2024-10-21T12:25:09.146843023Z,2024-10-21 12:25:09.146677151+00:00,10,2,38,C,B,4,233.69,200,130,165872,13058371,233.85,233.95,100,200,1,1,233.81,234.0,1,2,1,1,233.8,234.01,105,400,2,1,233.7,234.1,1200,100,1,1,233.69,234.13,200,400,1,1,233.66,234.17,1,1,1,1,233.58,234.25,505,100,2,1,233.53,234.41,10,500,1,1,233.5,234.43,100,105,1,2,233.45,234.5,15,63,1,4,AAPL,0,0,0,0,0,-200,0,0,0,0,0,233.89999999999998
2024-10-21T12:25:09.146855993Z,2024-10-21 12:25:09.146689798+00:00,10,2,38,A,B,3,233.72,400,130,166195,13058372,233.85,233.95,100,200,1,1,233.81,234.0,1,2,1,1,233.8,234.01,105,400,2,1,233.72,234.1,400,100,1,1,233.7,234.13,1200,400,1,1,233.66,234.17,1,1,1,1,233.58,234.25,505,100,2,1,233.53,234.41,10,500,1,1,233.5,234.43,100,105,1,2,233.45,234.5,15,63,1,4,AAPL,0,0,0,0,400,1200,0,0,0,0,0,233.89999999999998
2024-10-21T12:25:09.325402278Z,2024-10-21 12:25:09.325236301+00:00,10,2,38,C,B,3,233.72,400,130,165977,13058695,233.85,233.95,100,200,1,1,233.81,234.0,1,2,1,1,233.8,234.01,105,400,2,1,233.7,234.1,1200,100,1,1,233.66,234.13,1,400,1,1,233.58,234.17,505,1,2,1,233.53,234.25,10,100,1,1,233.5,234.41,100,500,1,1,233.45,234.43,15,105,1,2,233.4,234.5,110,63,2,4,AAPL,0,0,0,0,-400,-1200,-1,-505,-10,-100,-15,233.89999999999998
2024-10-21T12:25:09.325415366Z,2024-10-21 12:25:09.325248668+00:00,10,2,38,A,B,4,233.69,200,130,166698,13058696,233.85,233.95,100,200,1,1,233.81,234.0,1,2,1,1,233.8,234.01,105,400,2,1,233.7,234.1,1200,100,1,1,233.69,234.13,200,400,1,1,233.66,234.17,1,1,1,1,233.58,234.25,505,100,2,1,233.53,234.41,10,500,1,1,233.5,234.43,100,105,1,2,233.45,234.5,15,63,1,4,AAPL,0,0,0,0,0,200,1,505,10,100,15,233.89999999999998
2024-10-21T12:25:09.630196737Z,2024-10-21 12:25:09.630030450+00:00,10,2,38,A,B,4,233.69,200,130,166287,13059010,233.85,233.95,100,200,1,1,233.81,234.0,1,2,1,1,233.8,234.01,105,400,2,1,233.7,234.1,1200,100,1,1,233.69,234.13,400,400,2,1,233.66,234.17,1,1,1,1,233.58,234.25,505,100,2,1,233.53,234.41,10,500,1,1,233.5,234.43,100,105,1,2,233.45,234.5,15,63,1,4,AAPL,0,0,0,0,0,200,0,0,0,0,0,233.89999999999998
2024-10-21T12:25:09.684458949Z,2024-10-21 12:25:09.684292780+00:00,10,2,38,C,B,4,233.69,200,130,166169,13059061,233.85,233.95,100,200,1,1,233.81,234.0,1,2,1,1,233.8,234.01,105,400,2,1,233.7,234.1,1200,100,1,1,233.69,234.13,200,400,1,1,233.66,234.17,1,1,1,1,233.58,234.25,505,100,2,1,233.53,234.41,10,500,1,1,233.5,234.43,100,105,1,2,233.45,234.5,15,63,1,4,AAPL,0,0,0,0,0,-200,0,0,0,0,0,233.89999999999998
2024-10-21T12:25:09.684472400Z,2024-10-21 12:25:09.684305729+00:00,10,2,38,A,B,3,233.72,400,130,166671,13059062,233.85,233.95,100,200,1,1,233.81,234.0,1,2,1,1,233.8,234.01,105,400,2,1,233.72,234.1,400,100,1,1,233.7,234.13,1200,400,1,1,233.66,234.17,1,1,1,1,233.58,234.25,505,100,2,1,233.53,234.41,10,500,1,1,233.5,234.43,100,105,1,2,233.45,234.5,15,63,1,4,AAPL,0,0,0,0,400,1200,0,0,0,0,0,233.89999999999998
2024-10-21T12:25:10.726294001Z,2024-10-21 12:25:10.726127491+00:00,10,2,38,A,A,1,233.98,7,130,166510,13060271,233.85,233.95,100,200,1,1,233.81,233.98,1,7,1,1,233.8,234.0,105,2,2,1,233.72,234.01,400,400,1,1,233.7,234.1,1200,100,1,1,233.66,234.13,1,400,1,1,233.58,234.17,505,1,2,1,233.53,234.25,10,100,1,1,233.5,234.41,100,500,1,1,233.45,234.43,15,105,1,2,AAPL,0,0,7,2,400,100,400,1,100,500,105,233.89999999999998
2024-10-21T12:25:16.348450351Z,2024-10-21 12:25:16.348283664+00:00,10,2,38,A,B,3,233.77,200,130,166687,13064852,233.85,233.95,100,200,1,1,233.81,233.98,1,7,1,1,233.8,234.0,105,2,2,1,233.77,234.01,200,400,1,1,233.7,234.1,1200,100,1,1,233.66,234.13,1,400,1,1,233.58,234.17,505,1,2,1,233.53,234.25,10,100,1,1,233.5,234.41,100,500,1,1,233.45,234.43,15,105,1,2,AAPL,0,0,0,0,200,0,0,0,0,0,0,233.89999999999998
2024-10-21T12:25:25.279574162Z,2024-10-21 12:25:25.279408267+00:00,10,2,38,C,B,3,233.77,200,130,165895,13072236,233.85,233.95,100,200,1,1,233.81,233.98,1,7,1,1,233.8,234.0,105,2,2,1,233.7,234.01,1200,400,1,1,233.66,234.1,1,100,1,1,233.58,234.13,505,400,2,1,233.53,234.17,10,1,1,1,233.5,234.25,100,100,1,1,233.45,234.41,15,500,1,1,233.4,234.43,110,105,2,2,AAPL,0,0,0,0,-200,-1200,-1,-505,-10,-100,-15,233.89999999999998
2024-10-21T12:25:25.279586508Z,2024-10-21 12:25:25.279420038+00:00,10,2,38,A,B,3,233.75,200,130,166470,13072237,233.85,233.95,100,200,1,1,233.81,233.98,1,7,1,1,233.8,234.0,105,2,2,1,233.75,234.01,200,400,1,1,233.7,234.1,1200,100,1,1,233.66,234.13,1,400,1,1,233.58,234.17,505,1,2,1,233.53,234.25,10,100,1,1,233.5,234.41,100,500,1,1,233.45,234.43,15,105,1,2,AAPL,0,0,0,0,200,1200,1,505,10,100,15,233.89999999999998
2024-10-21T12:25:25.341710080Z,2024-10-21 12:25:25.341543400+00:00,10,2,38,A,A,2,234.0,400,130,166680,13072382,233.85,233.95,100,200,1,1,233.81,233.98,1,7,1,1,233.8,234.0,105,402,2,2,233.75,234.1,200,100,1,1,233.7,234.13,1200,400,1,1,233.66,234.17,1,1,1,1,233.58,234.25,505,100,2,1,233.53,234.41,10,500,1,1,233.5,234.43,100,105,1,2,233.45,234.5,15,63,1,4,AAPL,0,0,0,400,400,100,400,1,100,500,105,233.89999999999998
2024-10-21T12:25:26.789385215Z,2024-10-21 12:25:26.789218710+00:00,10,2,38,A,A,2,233.99,400,130,166505,13074488,233.85,233.95,100,200,1,1,233.81,233.98,1,7,1,1,233.8,233.99,105,400,2,1,233.75,234.0,200,2,1,1,233.7,234.1,1200,100,1,1,233.66,234.13,1,400,1,1,233.58,234.17,505,1,2,1,233.53,234.25,10,100,1,1,233.5,234.41,100,500,1,1,233.45,234.43,15,105,1,2,AAPL,0,0,0,400,2,100,400,1,100,500,105,233.89999999999998
2024-10-21T12:25:34.806070616Z,2024-10-21 12:25:34.805904261+00:00,10,2,38,A,B,0,233.86,4,130,166355,13082761,233.86,233.95,4,200,1,1,233.85,233.98,100,7,1,1,233.81,233.99,1,400,1,1,233.8,234.0,105,2,2,1,233.75,234.1,200,100,1,1,233.7,234.13,1200,400,1,1,233.66,234.17,1,1,1,1,233.58,234.25,505,100,2,1,233.53,234.41,10,500,1,1,233.5,234.43,100,105,1,2,AAPL,4,4,100,1,105,200,1200,1,505,10,100,233.905
2024-10-21T12:25:34.806829112Z,2024-10-21 12:25:34.806661445+00:00,10,2,38,C,B,0,233.86,4,130,167667,13082762,233.85,233.95,100,200,1,1,233.81,233.98,1,7,1,1,233.8,233.99,105,400,2,1,233.75,234.0,200,2,1,1,233.7,234.1,1200,100,1,1,233.66,234.13,1,400,1,1,233.58,234.17,505,1,2,1,233.53,234.25,10,100,1,1,233.5,234.41,100,500,1,1,233.45,234.43,15,105,1,2,AAPL,-4,-4,-100,-1,-105,-200,-1200,-1,-505,-10,-100,233.89999999999998
2024-10-21T12:25:34.807157514Z,2024-10-21 12:25:34.806990464+00:00,10,2,38,T,N,0,233.93,100,130,167050,13082763,233.85,233.95,100,200,1,1,233.81,233.98,1,7,1,1,233.8,233.99,105,400,2,1,233.75,234.0,200,2,1,1,233.7,234.1,1200,100,1,1,233.66,234.13,1,400,1,1,233.58,234.17,505,1,2,1,233.53,234.25,10,100,1,1,233.5,234.41,100,500,1,1,233.45,234.43,15,105,1,2,AAPL,0,0,0,0,0,0,0,0,0,0,0,233.89999999999998
2024-10-21T12:25:35.054650784Z,2024-10-21 12:25:35.054480586+00:00,10,2,38,T,N,0,233.91,101,0,170198,13083003,233.85,233.95,100,200,1,1,233.81,233.98,1,7,1,1,233.8,233.99,105,400,2,1,233.75,234.0,200,2,1,1,233.7,234.1,1200,100,1,1,233.66,234.13,1,400,1,1,233.58,234.17,505,1,2,1,233.53,234.25,10,100,1,1,233.5,234.41,100,500,1,1,233.45,234.43,15,105,1,2,AAPL,0,0,0,0,0,0,0,0,0,0,0,233.89999999999998
2024-10-21T12:25:35.054650784Z,2024-10-21 12:25:35.054480586+00:00,10,2,38,T,N,0,233.93,50,0,170198,13083004,233.85,233.95,100,200,1,1,233.81,233.98,1,7,1,1,233.8,233.99,105,400,2,1,233.75,234.0,200,2,1,1,233.7,234.1,1200,100,1,1,233.66,234.13,1,400,1,1,233.58,234.17,505,1,2,1,233.53,234.25,10,100,1,1,233.5,234.41,100,500,1,1,233.45,234.43,15,105,1,2,AAPL,0,0,0,0,0,0,0,0,0,0,0,233.89999999999998
2024-10-21T12:25:35.054650784Z,2024-10-21 12:25:35.054480586+00:00,10,2,38,T,B,0,233.95,79,130,170198,13083005,233.85,233.95,100,200,1,1,233.81,233.98,1,7,1,1,233.8,233.99,105,400,2,1,233.75,234.0,200,2,1,1,233.7,234.1,1200,100,1,1,233.66,234.13,1,400,1,1,233.58,234.17,505,1,2,1,233.53,234.25,10,100,1,1,233.5,234.41,100,500,1,1,233.45,234.43,15,105,1,2,AAPL,0,0,0,0,0,0,0,0,0,0,0,233.89999999999998
2024-10-21T12:25:35.054650784Z,2024-10-21 12:25:35.054480586+00:00,10,2,38,C,A,0,233.95,79,130,170198,13083005,233.85,233.95,100,121,1,1,233.81,233.98,1,7,1,1,233.8,233.99,105,400,2,1,233.75,234.0,200,2,1,1,233.7,234.1,1200,100,1,1,233.66,234.13,1,400,1,1,233.58,234.17,505,1,2,1,233.53,234.25,10,100,1,1,233.5,234.41,100,500,1,1,233.45,234.43,15,105,1,2,AAPL,-79,-79,0,0,0,0,0,0,0,0,0,233.89999999999998
2024-10-21T12:25:35.054724289Z,2024-10-21 12:25:35.054558163+00:00,10,2,38,C,A,2,233.99,400,130,166126,13083006,233.85,233.95,100,121,1,1,233.81,233.98,1,7,1,1,233.8,234.0,105,2,2,1,233.75,234.1,200,100,1,1,233.7,234.13,1200,400,1,1,233.66,234.17,1,1,1,1,233.58,234.25,505,100,2,1,233.53,234.41,10,500,1,1,233.5,234.43,100,105,1,2,233.45,234.5,15,63,1,4,AAPL,0,0,0,400,2,100,400,1,100,500,105,233.89999999999998
2024-10-21T12:25:35.065068431Z,2024-10-21 12:25:35.064902310+00:00,10,2,38,A,A,2,234.0,200,130,166121,13083015,233.85,233.95,100,121,1,1,233.81,233.98,1,7,1,1,233.8,234.0,105,202,2,2,233.75,234.1,200,100,1,1,233.7,234.13,1200,400,1,1,233.66,234.17,1,1,1,1,233.58,234.25,505,100,2,1,233.53,234.41,10,500,1,1,233.5,234.43,100,105,1,2,233.45,234.5,15,63,1,4,AAPL,0,0,0,200,0,0,0,0,0,0,0,233.89999999999998
2024-10-21T12:25:35.147837274Z,2024-10-21 12:25:35.147671307+00:00,10,2,38,A,A,2,234.0,200,130,165967,13083092,233.85,233.95,100,121,1,1,233.81,233.98,1,7,1,1,233.8,234.0,105,402,2,3,233.75,234.1,200,100,1,1,233.7,234.13,1200,400,1,1,233.66,234.17,1,1,1,1,233.58,234.25,505,100,2,1,233.53,234.41,10,500,1,1,233.5,234.43,100,105,1,2,233.45,234.5,15,63,1,4,AAPL,0,0,0,200,0,0,0,0,0,0,0,233.89999999999998
2024-10-21T12:25:37.149278847Z,2024-10-21 12:25:37.149112390+00:00,10,2,38,C,A,1,233.98,7,130,166457,13084951,233.85,233.95,100,121,1,1,233.81,234.0,1,402,1,3,233.8,234.1,105,100,2,1,233.75,234.13,200,400,1,1,233.7,234.17,1200,1,1,1,233.66,234.25,1,100,1,1,233.58,234.41,505,500,2,1,233.53,234.43,10,105,1,2,233.5,234.5,100,63,1,4,233.45,234.59,15,60,1,1,AAPL,0,0,7,402,100,400,1,100,500,105,63,233.89999999999998
2024-10-21T12:25:39.151956133Z,2024-10-21 12:25:39.151789847+00:00,10,2,38,A,A,8,234.44,7,130,166286,13087130,233.85,233.95,100,121,1,1,233.81,234.0,1,402,1,3,233.8,234.1,105,100,2,1,233.75,234.13,200,400,1,1,233.7,234.17,1200,1,1,1,233.66,234.25,1,100,1,1,233.58,234.41,505,500,2,1,233.53,234.43,10,105,1,2,233.5,234.44,100,7,1,1,233.45,234.5,15,63,1,4,AAPL,0,0,0,0,0,0,0,0,0,7,63,233.89999999999998
2024-10-21T12:25:43.597553367Z,2024-10-21 12:25:43.597387033+00:00,10,2,38,A,B,3,233.76,200,130,166334,13091002,233.85,233.95,100,121,1,1,233.81,234.0,1,402,1,3,233.8,234.1,105,100,2,1,233.76,234.13,200,400,1,1,233.7,234.17,1200,1,1,1,233.66,234.25,1,100,1,1,233.58,234.41,505,500,2,1,233.53,234.43,10,105,1,2,233.5,234.44,100,7,1,1,233.45,234.5,15,63,1,4,AAPL,0,0,0,0,200,0,0,0,0,0,0,233.89999999999998
2024-10-21T12:25:45.063614991Z,2024-10-21 12:25:45.063448661+00:00,10,2,38,A,B,3,233.77,200,130,166330,13092718,233.85,233.95,100,121,1,1,233.81,234.0,1,402,1,3,233.8,234.1,105,100,2,1,233.77,234.13,200,400,1,1,233.7,234.17,1200,1,1,1,233.66,234.25,1,100,1,1,233.58,234.41,505,500,2,1,233.53,234.43,10,105,1,2,233.5,234.44,100,7,1,1,233.45,234.5,15,63,1,4,AAPL,0,0,0,0,200,0,0,0,0,0,0,233.89999999999998
2024-10-21T12:25:52.757457183Z,2024-10-21 12:25:52.757291105+00:00,10,2,38,C,B,3,233.77,200,130,166078,13098338,233.85,233.95,100,121,1,1,233.81,234.0,1,402,1,3,233.8,234.1,105,100,2,1,233.7,234.13,1200,400,1,1,233.66,234.17,1,1,1,1,233.58,234.25,505,100,2,1,233.53,234.41,10,500,1,1,233.5,234.43,100,105,1,2,233.45,234.44,15,7,1,1,233.4,234.5,110,63,2,4,AAPL,0,0,0,0,-200,-1200,-1,-505,-10,-100,-15,233.89999999999998
2024-10-21T12:25:52.757470818Z,2024-10-21 12:25:52.757304269+00:00,10,2,38,A,B,3,233.75,200,130,166549,13098339,233.85,233.95,100,121,1,1,233.81,234.0,1,402,1,3,233.8,234.1,105,100,2,1,233.75,234.13,200,400,1,1,233.7,234.17,1200,1,1,1,233.66,234.25,1,100,1,1,233.58,234.41,505,500,2,1,233.53,234.43,10,105,1,2,233.5,234.44,100,7,1,1,233.45,234.5,15,63,1,4,AAPL,0,0,0,0,200,1200,1,505,10,100,15,233.89999999999998
2024-10-21T12:25:54.873403967Z,2024-10-21 12:25:54.873237392+00:00,10,2,38,A,B,1,233.81,1,130,166575,13100599,233.85,233.95,100,121,1,1,233.81,234.0,2,402,2,3,233.8,234.1,105,100,2,1,233.75,234.13,200,400,1,1,233.7,234.17,1200,1,1,1,233.66,234.25,1,100,1,1,233.58,234.41,505,500,2,1,233.53,234.43,10,105,1,2,233.5,234.44,100,7,1,1,233.45,234.5,15,63,1,4,AAPL,0,0,1,0,0,0,0,0,0,0,0,233.89999999999998
2024-10-21T12:26:00.405862083Z,2024-10-21 12:26:00.405695962+00:00,10,2,38,C,A,8,234.44,7,130,166121,13106337,233.85,233.95,100,121,1,1,233.81,234.0,2,402,2,3,233.8,234.1,105,100,2,1,233.75,234.13,200,400,1,1,233.7,234.17,1200,1,1,1,233.66,234.25,1,100,1,1,233.58,234.41,505,500,2,1,233.53,234.43,10,105,1,2,233.5,234.5,100,63,1,4,233.45,234.59,15,60,1,1,AAPL,0,0,0,0,0,0,0,0,0,7,63,233.89999999999998
2024-10-21T12:26:01.715446829Z,2024-10-21 12:26:01.715279752+00:00,10,2,38,A,B,3,233.76,200,130,167077,13108880,233.85,233.95,100,121,1,1,233.81,234.0,2,402,2,3,233.8,234.1,105,100,2,1,233.76,234.13,200,400,1,1,233.7,234.17,1200,1,1,1,233.66,234.25,1,100,1,1,233.58,234.41,505,500,2,1,233.53,234.43,10,105,1,2,233.5,234.5,100,63,1,4,233.45,234.59,15,60,1,1,AAPL,0,0,0,0,200,0,0,0,0,0,0,233.89999999999998
2024-10-21T12:26:02.222090992Z,2024-10-21 12:26:02.221924482+00:00,10,2,38,A,B,3,233.77,200,130,166510,13109908,233.85,233.95,100,121,1,1,233.81,234.0,2,402,2,3,233.8,234.1,105,100,2,1,233.77,234.13,200,400,1,1,233.7,234.17,1200,1,1,1,233.66,234.25,1,100,1,1,233.58,234.41,505,500,2,1,233.53,234.43,10,105,1,2,233.5,234.5,100,63,1,4,233.45,234.59,15,60,1,1,AAPL,0,0,0,0,200,0,0,0,0,0,0,233.89999999999998
2024-10-21T12:26:02.408702630Z,2024-10-21 12:26:02.408536304+00:00,10,2,38,A,A,2,234.07,7,130,166326,13110618,233.85,233.95,100,121,1,1,233.81,234.0,2,402,2,3,233.8,234.07,105,7,2,1,233.77,234.1,200,100,1,1,233.7,234.13,1200,400,1,1,233.66,234.17,1,1,1,1,233.58,234.25,505,100,2,1,233.53,234.41,10,500,1,1,233.5,234.43,100,105,1,2,233.45,234.5,15,63,1,4,AAPL,0,0,0,7,100,400,1,100,500,105,63,233.89999999999998
2024-10-21T12:26:05.174048295Z,2024-10-21 12:26:05.173881544+00:00,10,2,38,A,B,0,233.86,100,130,166751,13112718,233.86,233.95,100,121,1,1,233.85,234.0,100,402,1,3,233.81,234.07,2,7,2,1,233.8,234.1,105,100,2,1,233.77,234.13,200,400,1,1,233.7,234.17,1200,1,1,1,233.66,234.25,1,100,1,1,233.58,234.41,505,500,2,1,233.53,234.43,10,105,1,2,233.5,234.5,100,63,1,4,AAPL,100,100,100,2,105,200,1200,1,505,10,100,233.905
2024-10-21T12:26:05.247381714Z,2024-10-21 12:26:05.247215441+00:00,10,2,38,C,A,1,234.0,200,130,166273,13112835,233.86,233.95,100,121,1,1,233.85,234.0,100,202,1,2,233.81,234.07,2,7,2,1,233.8,234.1,105,100,2,1,233.77,234.13,200,400,1,1,233.7,234.17,1200,1,1,1,233.66,234.25,1,100,1,1,233.58,234.41,505,500,2,1,233.53,234.43,10,105,1,2,233.5,234.5,100,63,1,4,AAPL,0,0,-200,0,0,0,0,0,0,0,0,233.905
2024-10-21T12:26:05.247392056Z,2024-10-21 12:26:05.247226039+00:00,10,2,38,C,A,1,234.0,200,130,166017,13112836,233.86,233.95,100,121,1,1,233.85,234.0,100,2,1,1,233.81,234.07,2,7,2,1,233.8,234.1,105,100,2,1,233.77,234.13,200,400,1,1,233.7,234.17,1200,1,1,1,233.66,234.25,1,100,1,1,233.58,234.41,505,500,2,1,233.53,234.43,10,105,1,2,233.5,234.5,100,63,1,4,AAPL,0,0,-200,0,0,0,0,0,0,0,0,233.905
2024-10-21T12:26:05.247404052Z,2024-10-21 12:26:05.247237168+00:00,10,2,38,A,A,2,234.01,200,130,166884,13112837,233.86,233.95,100,121,1,1,233.85,234.0,100,2,1,1,233.81,234.01,2,200,2,1,233.8,234.07,105,7,2,1,233.77,234.1,200,100,1,1,233.7,234.13,1200,400,1,1,233.66,234.17,1,1,1,1,233.58,234.25,505,100,2,1,233.53,234.41,10,500,1,1,233.5,234.43,100,105,1,2,AAPL,0,0,0,200,7,100,400,1,100,500,105,233.905
2024-10-21T12:26:08.272617784Z,2024-10-21 12:26:08.272451351+00:00,10,2,38,A,B,4,233.78,200,130,166433,13116250,233.86,233.95,100,121,1,1,233.85,234.0,100,2,1,1,233.81,234.01,2,200,2,1,233.8,234.07,105,7,2,1,233.78,234.1,200,100,1,1,233.7,234.13,1200,400,1,1,233.66,234.17,1,1,1,1,233.58,234.25,505,100,2,1,233.53,234.41,10,500,1,1,233.5,234.43,100,105,1,2,AAPL,0,0,0,0,0,200,0,0,0,0,0,233.905
2024-10-21T12:26:09.611069894Z,2024-10-21 12:26:09.610903498+00:00,10,2,38,C,B,1,233.85,100,130,166396,13117941,233.86,233.95,100,121,1,1,233.81,234.0,2,2,2,1,233.8,234.01,105,200,2,1,233.78,234.07,200,7,1,1,233.7,234.1,1200,100,1,1,233.66,234.13,1,400,1,1,233.58,234.17,505,1,2,1,233.53,234.25,10,100,1,1,233.5,234.41,100,500,1,1,233.45,234.43,15,105,1,2,AAPL,0,0,-100,-2,-105,-200,-1200,-1,-505,-10,-100,233.905
2024-10-21T12:26:11.689942070Z,2024-10-21 12:26:11.689776041+00:00,10,2,38,C,A,2,234.01,200,130,166029,13119493,233.86,233.95,100,121,1,1,233.81,234.0,2,2,2,1,233.8,234.07,105,7,2,1,233.78,234.1,200,100,1,1,233.7,234.13,1200,400,1,1,233.66,234.17,1,1,1,1,233.58,234.25,505,100,2,1,233.53,234.41,10,500,1,1,233.5,234.43,100,105,1,2,233.45,234.5,15,63,1,4,AAPL,0,0,0,200,7,100,400,1,100,500,105,233.905
2024-10-21T12:26:11.689954364Z,2024-10-21 12:26:11.689788127+00:00,10,2,38,A,A,2,234.03,200,130,166237,13119494,233.86,233.95,100,121,1,1,233.81,234.0,2,2,2,1,233.8,234.03,105,200,2,1,233.78,234.07,200,7,1,1,233.7,234.1,1200,100,1,1,233.66,234.13,1,400,1,1,233.58,234.17,505,1,2,1,233.53,234.25,10,100,1,1,233.5,234.41,100,500,1,1,233.45,234.43,15,105,1,2,AAPL,0,0,0,200,7,100,400,1,100,500,105,233.905
2024-10-21T12:26:11.691953516Z,2024-10-21 12:26:11.691787041+00:00,10,2,38,A,A,2,234.03,200,130,166475,13119500,233.86,233.95,100,121,1,1,233.81,234.0,2,2,2,1,233.8,234.03,105,400,2,2,233.78,234.07,200,7,1,1,233.7,234.1,1200,100,1,1,233.66,234.13,1,400,1,1,233.58,234.17,505,1,2,1,233.53,234.25,10,100,1,1,233.5,234.41,100,500,1,1,233.45,234.43,15,105,1,2,AAPL,0,0,0,200,0,0,0,0,0,0,0,233.905
2024-10-21T12:26:11.746463267Z,2024-10-21 12:26:11.746296162+00:00,10,2,38,C,A,2,234.03,200,130,167105,13119630,233.86,233.95,100,121,1,1,233.81,234.0,2,2,2,1,233.8,234.03,105,200,2,1,233.78,234.07,200,7,1,1,233.7,234.1,1200,100,1,1,233.66,234.13,1,400,1,1,233.58,234.17,505,1,2,1,233.53,234.25,10,100,1,1,233.5,234.41,100,500,1,1,233.45,234.43,15,105,1,2,AAPL,0,0,0,-200,0,0,0,0,0,0,0,233.905
2024-10-21T12:26:11.746474261Z,2024-10-21 12:26:11.746308007+00:00,10,2,38,A,A,2,234.02,200,130,166254,13119632,233.86,233.95,100,121,1,1,233.81,234.0,2,2,2,1,233.8,234.02,105,200,2,1,233.78,234.07,200,7,1,1,233.7,234.1,1200,100,1,1,233.66,234.13,1,400,1,1,233.58,234.17,505,1,2,1,233.53,234.25,10,100,1,1,233.5,234.41,100,500,1,1,233.45,234.43,15,105,1,2,AAPL,0,0,0,200,0,0,0,0,0,0,0,233.905
2024-10-21T12:26:13.045453100Z,2024-10-21 12:26:13.045285946+00:00,10,2,38,A,B,3,233.79,200,130,167154,13120862,233.86,233.95,100,121,1,1,233.81,234.0,2,2,2,1,233.8,234.02,105,200,2,1,233.79,234.07,200,7,1,1,233.7,234.1,1200,100,1,1,233.66,234.13,1,400,1,1,233.58,234.17,505,1,2,1,233.53,234.25,10,100,1,1,233.5,234.41,100,500,1,1,233.45,234.43,15,105,1,2,AAPL,0,0,0,0,200,0,0,0,0,0,0,233.905
2024-10-21T12:26:20.829403397Z,2024-10-21 12:26:20.829236958+00:00,10,2,38,A,A,1,234.0,15,130,166439,13126283,233.86,233.95,100,121,1,1,233.81,234.0,2,17,2,2,233.8,234.02,105,200,2,1,233.79,234.07,200,7,1,1,233.7,234.1,1200,100,1,1,233.66,234.13,1,400,1,1,233.58,234.17,505,1,2,1,233.53,234.25,10,100,1,1,233.5,234.41,100,500,1,1,233.45,234.43,15,105,1,2,AAPL,0,0,15,0,0,0,0,0,0,0,0,233.905
2024-10-21T12:26:22.496516455Z,2024-10-21 12:26:22.496350258+00:00,10,2,38,C,A,3,234.07,7,130,166197,13127351,233.86,233.95,100,121,1,1,233.81,234.0,2,17,2,2,233.8,234.02,105,200,2,1,233.79,234.1,200,100,1,1,233.7,234.13,1200,400,1,1,233.66,234.17,1,1,1,1,233.58,234.25,505,100,2,1,233.53,234.41,10,500,1,1,233.5,234.43,100,105,1,2,233.45,234.5,15,63,1,4,AAPL,0,0,0,0,7,100,400,1,100,500,105,233.905
2024-10-21T12:26:23.489058780Z,2024-10-21 12:26:23.488892465+00:00,10,2,38,C,B,3,233.79,200,130,166315,13128004,233.86,233.95,100,121,1,1,233.81,234.0,2,17,2,2,233.8,234.02,105,200,2,1,233.7,234.1,1200,100,1,1,233.66,234.13,1,400,1,1,233.58,234.17,505,1,2,1,233.53,234.25,10,100,1,1,233.5,234.41,100,500,1,1,233.45,234.43,15,105,1,2,233.4,234.5,110,63,2,4,AAPL,0,0,0,0,-200,-1200,-1,-505,-10,-100,-15,233.905
2024-10-21T12:26:23.498527505Z,2024-10-21 12:26:23.498360877+00:00,10,2,38,A,B,3,233.78,200,130,166628,13128006,233.86,233.95,100,121,1,1,233.81,234.0,2,17,2,2,233.8,234.02,105,200,2,1,233.78,234.1,200,100,1,1,233.7,234.13,1200,400,1,1,233.66,234.17,1,1,1,1,233.58,234.25,505,100,2,1,233.53,234.41,10,500,1,1,233.5,234.43,100,105,1,2,233.45,234.5,15,63,1,4,AAPL,0,0,0,0,200,1200,1,505,10,100,15,233.905
2024-10-21T12:26:24.504603959Z,2024-10-21 12:26:24.504437465+00:00,10,2,38,A,A,7,234.41,7,130,166494,13128603,233.86,233.95,100,121,1,1,233.81,234.0,2,17,2,2,233.8,234.02,105,200,2,1,233.78,234.1,200,100,1,1,233.7,234.13,1200,400,1,1,233.66,234.17,1,1,1,1,233.58,234.25,505,100,2,1,233.53,234.41,10,507,1,2,233.5,234.43,100,105,1,2,233.45,234.5,15,63,1,4,AAPL,0,0,0,0,0,0,0,0,7,0,0,233.905
2024-10-21T12:26:25.077623504Z,2024-10-21 12:26:25.077457400+00:00,10,2,38,C,B,3,233.78,200,130,166104,13129240,233.86,233.95,100,121,1,1,233.81,234.0,2,17,2,2,233.8,234.02,105,200,2,1,233.7,234.1,1200,100,1,1,233.66,234.13,1,400,1,1,233.58,234.17,505,1,2,1,233.53,234.25,10,100,1,1,233.5,234.41,100,507,1,2,233.45,234.43,15,105,1,2,233.4,234.5,110,63,2,4,AAPL,0,0,0,0,-200,-1200,-1,-505,-10,-100,-15,233.905
2024-10-21T12:26:25.077635518Z,2024-10-21 12:26:25.077469095+00:00,10,2,38,A,B,3,233.76,200,130,166423,13129241,233.86,233.95,100,121,1,1,233.81,234.0,2,17,2,2,233.8,234.02,105,200,2,1,233.76,234.1,200,100,1,1,233.7,234.13,1200,400,1,1,233.66,234.17,1,1,1,1,233.58,234.25,505,100,2,1,233.53,234.41,10,507,1,2,233.5,234.43,100,105,1,2,233.45,234.5,15,63,1,4,AAPL,0,0,0,0,200,1200,1,505,10,100,15,233.905
2024-10-21T12:26:25.077648690Z,2024-10-21 12:26:25.077482593+00:00,10,2,38,A,A,2,234.02,200,130,166097,13129242,233.86,233.95,100,121,1,1,233.81,234.0,2,17,2,2,233.8,234.02,105,400,2,2,233.76,234.1,200,100,1,1,233.7,234.13,1200,400,1,1,233.66,234.17,1,1,1,1,233.58,234.25,505,100,2,1,233.53,234.41,10,507,1,2,233.5,234.43,100,105,1,2,233.45,234.5,15,63,1,4,AAPL,0,0,0,200,0,0,0,0,0,0,0,233.905
2024-10-21T12:26:25.129478069Z,2024-10-21 12:26:25.129312037+00:00,10,2,38,C,A,2,234.02,200,130,166032,13129411,233.86,233.95,100,121,1,1,233.81,234.0,2,17,2,2,233.8,234.02,105,200,2,1,233.76,234.1,200,100,1,1,233.7,234.13,1200,400,1,1,233.66,234.17,1,1,1,1,233.58,234.25,505,100,2,1,233.53,234.41,10,507,1,2,233.5,234.43,100,105,1,2,233.45,234.5,15,63,1,4,AAPL,0,0,0,-200,0,0,0,0,0,0,0,233.905
2024-10-21T12:26:25.129491036Z,2024-10-21 12:26:25.129324093+00:00,10,2,38,A,A,1,234.0,200,130,166943,13129412,233.86,233.95,100,121,1,1,233.81,234.0,2,217,2,3,233.8,234.1,105,100,2,1,233.76,234.13,200,400,1,1,233.7,234.17,1200,1,1,1,233.66,234.25,1,100,1,1,233.58,234.41,505,507,2,2,233.53,234.43,10,105,1,2,233.5,234.5,100,63,1,4,233.45,234.59,15,60,1,1,AAPL,0,0,200,200,100,400,1,100,507,105,63,233.905
2024-10-21T12:26:25.268804920Z,2024-10-21 12:26:25.268638479+00:00,10,2,38,A,B,3,233.77,200,130,166441,13129838,233.86,233.95,100,121,1,1,233.81,234.0,2,217,2,3,233.8,234.1,105,100,2,1,233.77,234.13,200,400,1,1,233.7,234.17,1200,1,1,1,233.66,234.25,1,100,1,1,233.58,234.41,505,507,2,2,233.53,234.43,10,105,1,2,233.5,234.5,100,63,1,4,233.45,234.59,15,60,1,1,AAPL,0,0,0,0,200,0,0,0,0,0,0,233.905
2024-10-21T12:26:25.384254820Z,2024-10-21 12:26:25.384088744+00:00,10,2,38,C,A,1,234.0,200,130,166076,13130001,233.86,233.95,100,121,1,1,233.81,234.0,2,17,2,2,233.8,234.1,105,100,2,1,233.77,234.13,200,400,1,1,233.7,234.17,1200,1,1,1,233.66,234.25,1,100,1,1,233.58,234.41,505,507,2,2,233.53,234.43,10,105,1,2,233.5,234.5,100,63,1,4,233.45,234.59,15,60,1,1,AAPL,0,0,-200,0,0,0,0,0,0,0,0,233.905
2024-10-21T12:26:25.384266211Z,2024-10-21 12:26:25.384100277+00:00,10,2,38,A,A,2,234.02,200,130,165934,13130002,233.86,233.95,100,121,1,1,233.81,234.0,2,17,2,2,233.8,234.02,105,200,2,1,233.77,234.1,200,100,1,1,233.7,234.13,1200,400,1,1,233.66,234.17,1,1,1,1,233.58,234.25,505,100,2,1,233.53,234.41,10,507,1,2,233.5,234.43,100,105,1,2,233.45,234.5,15,63,1,4,AAPL,0,0,0,200,100,400,1,100,507,105,63,233.905
2024-10-21T12:26:25.439053026Z,2024-10-21 12:26:25.438886764+00:00,10,2,38,A,B,3,233.78,200,130,166262,13130072,233.86,233.95,100,121,1,1,233.81,234.0,2,17,2,2,233.8,234.02,105,200,2,1,233.78,234.1,200,100,1,1,233.7,234.13,1200,400,1,1,233.66,234.17,1,1,1,1,233.58,234.25,505,100,2,1,233.53,234.41,10,507,1,2,233.5,234.43,100,105,1,2,233.45,234.5,15,63,1,4,AAPL,0,0,0,0,200,0,0,0,0,0,0,233.905
2024-10-21T12:26:25.519068296Z,2024-10-21 12:26:25.518902005+00:00,10,2,38,A,A,2,234.01,200,130,166291,13130195,233.86,233.95,100,121,1,1,233.81,234.0,2,17,2,2,233.8,234.01,105,200,2,1,233.78,234.1,200,100,1,1,233.7,234.13,1200,400,1,1,233.66,234.17,1,1,1,1,233.58,234.25,505,100,2,1,233.53,234.41,10,507,1,2,233.5,234.43,100,105,1,2,233.45,234.5,15,63,1,4,AAPL,0,0,0,200,0,0,0,0,0,0,0,233.905
2024-10-21T12:26:31.593057846Z,2024-10-21 12:26:31.592891536+00:00,10,2,38,C,A,7,234.41,7,130,166310,13135066,233.86,233.95,100,121,1,1,233.81,234.0,2,17,2,2,233.8,234.01,105,200,2,1,233.78,234.1,200,100,1,1,233.7,234.13,1200,400,1,1,233.66,234.17,1,1,1,1,233.58,234.25,505,100,2,1,233.53,234.41,10,500,1,1,233.5,234.43,100,105,1,2,233.45,234.5,15,63,1,4,AAPL,0,0,0,0,0,0,0,0,-7,0,0,233.905
2024-10-21T12:26:32.717599837Z,2024-10-21 12:26:32.717433050+00:00,10,2,38,A,A,0,233.95,10,130,166787,13137148,233.86,233.95,100,131,1,2,233.81,234.0,2,17,2,2,233.8,234.01,105,200,2,1,233.78,234.1,200,100,1,1,233.7,234.13,1200,400,1,1,233.66,234.17,1,1,1,1,233.58,234.25,505,100,2,1,233.53,234.41,10,500,1,1,233.5,234.43,100,105,1,2,233.45,234.5,15,63,1,4,AAPL,10,10,0,0,0,0,0,0,0,0,0,233.905
2024-10-21T12:26:32.717638955Z,2024-10-21 12:26:32.717472823+00:00,10,2,38,C,B,3,233.78,200,130,166132,13137150,233.86,233.95,100,131,1,2,233.81,234.0,2,17,2,2,233.8,234.01,105,200,2,1,233.7,234.1,1200,100,1,1,233.66,234.13,1,400,1,1,233.58,234.17,505,1,2,1,233.53,234.25,10,100,1,1,233.5,234.41,100,500,1,1,233.45,234.43,15,105,1,2,233.4,234.5,110,63,2,4,AAPL,0,0,0,0,-200,-1200,-1,-505,-10,-100,-15,233.905
2024-10-21T12:26:32.721694410Z,2024-10-21 12:26:32.721528057+00:00,10,2,38,C,A,0,233.95,10,130,166353,13137153,233.86,233.95,100,121,1,1,233.81,234.0,2,17,2,2,233.8,234.01,105,200,2,1,233.7,234.1,1200,100,1,1,233.66,234.13,1,400,1,1,233.58,234.17,505,1,2,1,233.53,234.25,10,100,1,1,233.5,234.41,100,500,1,1,233.45,234.43,15,105,1,2,233.4,234.5,110,63,2,4,AAPL,-10,-10,0,0,0,0,0,0,0,0,0,233.905
2024-10-21T12:26:32.820850700Z,2024-10-21 12:26:32.820683999+00:00,10,2,38,A,B,3,233.78,200,130,166701,13137257,233.86,233.95,100,121,1,1,233.81,234.0,2,17,2,2,233.8,234.01,105,200,2,1,233.78,234.1,200,100,1,1,233.7,234.13,1200,400,1,1,233.66,234.17,1,1,1,1,233.58,234.25,505,100,2,1,233.53,234.41,10,500,1,1,233.5,234.43,100,105,1,2,233.45,234.5,15,63,1,4,AAPL,0,0,0,0,200,1200,1,505,10,100,15,233.905
2024-10-21T12:26:33.596226968Z,2024-10-21 12:26:33.596060481+00:00,10,2,38,A,A,7,234.41,7,130,166487,13137944,233.86,233.95,100,121,1,1,233.81,234.0,2,17,2,2,233.8,234.01,105,200,2,1,233.78,234.1,200,100,1,1,233.7,234.13,1200,400,1,1,233.66,234.17,1,1,1,1,233.58,234.25,505,100,2,1,233.53,234.41,10,507,1,2,233.5,234.43,100,105,1,2,233.45,234.5,15,63,1,4,AAPL,0,0,0,0,0,0,0,0,7,0,0,233.905
2024-10-21T12:26:33.705462618Z,2024-10-21 12:26:33.705296257+00:00,10,2,38,C,B,3,233.78,200,130,166361,13138040,233.86,233.95,100,121,1,1,233.81,234.0,2,17,2,2,233.8,234.01,105,200,2,1,233.7,234.1,1200,100,1,1,233.66,234.13,1,400,1,1,233.58,234.17,505,1,2,1,233.53,234.25,10,100,1,1,233.5,234.41,100,507,1,2,233.45,234.43,15,105,1,2,233.4,234.5,110,63,2,4,AAPL,0,0,0,0,-200,-1200,-1,-505,-10,-100,-15,233.905
2024-10-21T12:26:33.705475821Z,2024-10-21 12:26:33.705309399+00:00,10,2,38,A,B,3,233.73,400,130,166422,13138041,233.86,233.95,100,121,1,1,233.81,234.0,2,17,2,2,233.8,234.01,105,200,2,1,233.73,234.1,400,100,1,1,233.7,234.13,1200,400,1,1,233.66,234.17,1,1,1,1,233.58,234.25,505,100,2,1,233.53,234.41,10,507,1,2,233.5,234.43,100,105,1,2,233.45,234.5,15,63,1,4,AAPL,0,0,0,0,400,1200,1,505,10,100,15,233.905
2024-10-21T12:26:40.656300037Z,2024-10-21 12:26:40.656134264+00:00,10,2,38,C,A,2,234.01,200,130,165773,13145962,233.86,233.95,100,121,1,1,233.81,234.0,2,17,2,2,233.8,234.1,105,100,2,1,233.73,234.13,400,400,1,1,233.7,234.17,1200,1,1,1,233.66,234.25,1,100,1,1,233.58,234.41,505,507,2,2,233.53,234.43,10,105,1,2,233.5,234.5,100,63,1,4,233.45,234.59,15,60,1,1,AAPL,0,0,0,200,100,400,1,100,507,105,63,233.905
2024-10-21T12:26:40.656313085Z,2024-10-21 12:26:40.656147028+00:00,10,2,38,A,A,2,234.03,400,130,166057,13145963,233.86,233.95,100,121,1,1,233.81,234.0,2,17,2,2,233.8,234.03,105,400,2,1,233.73,234.1,400,100,1,1,233.7,234.13,1200,400,1,1,233.66,234.17,1,1,1,1,233.58,234.25,505,100,2,1,233.53,234.41,10,507,1,2,233.5,234.43,100,105,1,2,233.45,234.5,15,63,1,4,AAPL,0,0,0,400,100,400,1,100,507,105,63,233.905
2024-10-21T12:26:40.707673608Z,2024-10-21 12:26:40.707506986+00:00,10,2,38,A,B,3,233.74,400,130,166622,13146198,233.86,233.95,100,121,1,1,233.81,234.0,2,17,2,2,233.8,234.03,105,400,2,1,233.74,234.1,400,100,1,1,233.7,234.13,1200,400,1,1,233.66,234.17,1,1,1,1,233.58,234.25,505,100,2,1,233.53,234.41,10,507,1,2,233.5,234.43,100,105,1,2,233.45,234.5,15,63,1,4,AAPL,0,0,0,0,400,0,0,0,0,0,0,233.905
2024-10-21T12:26:40.896702274Z,2024-10-21 12:26:40.896535785+00:00,10,2,38,A,A,2,234.02,400,130,166489,13146521,233.86,233.95,100,121,1,1,233.81,234.0,2,17,2,2,233.8,234.02,105,400,2,1,233.74,234.1,400,100,1,1,233.7,234.13,1200,400,1,1,233.66,234.17,1,1,1,1,233.58,234.25,505,100,2,1,233.53,234.41,10,507,1,2,233.5,234.43,100,105,1,2,233.45,234.5,15,63,1,4,AAPL,0,0,0,400,0,0,0,0,0,0,0,233.905
2024-10-21T12:26:42.392700431Z,2024-10-21 12:26:42.392534365+00:00,10,2,38,C,A,7,234.41,7,130,166066,13148175,233.86,233.95,100,121,1,1,233.81,234.0,2,17,2,2,233.8,234.02,105,400,2,1,233.74,234.1,400,100,1,1,233.7,234.13,1200,400,1,1,233.66,234.17,1,1,1,1,233.58,234.25,505,100,2,1,233.53,234.41,10,500,1,1,233.5,234.43,100,105,1,2,233.45,234.5,15,63,1,4,AAPL,0,0,0,0,0,0,0,0,-7,0,0,233.905
2024-10-21T12:26:43.555781301Z,2024-10-21 12:26:43.555613825+00:00,10,2,38,T,A,0,233.86,100,130,167476,13148963,233.86,233.95,100,121,1,1,233.81,234.0,2,17,2,2,233.8,234.02,105,400,2,1,233.74,234.1,400,100,1,1,233.7,234.13,1200,400,1,1,233.66,234.17,1,1,1,1,233.58,234.25,505,100,2,1,233.53,234.41,10,500,1,1,233.5,234.43,100,105,1,2,233.45,234.5,15,63,1,4,AAPL,0,0,0,0,0,0,0,0,0,0,0,233.905
2024-10-21T12:26:43.555781301Z,2024-10-21 12:26:43.555613825+00:00,10,2,38,C,B,0,233.86,100,130,167476,13148963,233.81,233.95,2,121,2,1,233.8,234.0,105,17,2,2,233.74,234.02,400,400,1,1,233.7,234.1,1200,100,1,1,233.66,234.13,1,400,1,1,233.58,234.17,505,1,2,1,233.53,234.25,10,100,1,1,233.5,234.41,100,500,1,1,233.45,234.43,15,105,1,2,233.4,234.5,110,63,2,4,AAPL,-100,-100,-2,-105,-400,-1200,-1,-505,-10,-100,-15,233.88
2024-10-21T12:26:43.555792717Z,2024-10-21 12:26:43.555625145+00:00,10,2,38,A,B,0,233.86,100,130,167572,13148964,233.86,233.95,100,121,1,1,233.81,234.0,2,17,2,2,233.8,234.02,105,400,2,1,233.74,234.1,400,100,1,1,233.7,234.13,1200,400,1,1,233.66,234.17,1,1,1,1,233.58,234.25,505,100,2,1,233.53,234.41,10,500,1,1,233.5,234.43,100,105,1,2,233.45,234.5,15,63,1,4,AAPL,100,100,2,105,400,1200,1,505,10,100,15,233.905
2024-10-21T12:26:43.555803052Z,2024-10-21 12:26:43.555636531+00:00,10,2,38,A,A,0,233.9,100,130,166521,13148965,233.86,233.9,100,100,1,1,233.81,233.95,2,121,2,1,233.8,234.0,105,17,2,2,233.74,234.02,400,400,1,1,233.7,234.1,1200,100,1,1,233.66,234.13,1,400,1,1,233.58,234.17,505,1,2,1,233.53,234.25,10,100,1,1,233.5,234.41,100,500,1,1,233.45,234.43,15,105,1,2,AAPL,100,100,121,17,400,100,400,1,100,500,105,233.88
2024-10-21T12:26:43.555807607Z,2024-10-21 12:26:43.555641373+00:00,10,2,38,A,A,1,233.91,200,130,166234,13148967,233.86,233.9,100,100,1,1,233.81,233.91,2,200,2,1,233.8,233.93,105,100,2,1,233.74,233.95,400,121,1,1,233.7,234.0,1200,17,1,2,233.66,234.02,1,400,1,1,233.58,234.1,505,100,2,1,233.53,234.13,10,400,1,1,233.5,234.17,100,1,1,1,233.45,234.25,15,100,1,1,AAPL,0,0,200,100,121,17,400,100,400,1,100,233.88
2024-10-21T12:26:43.555814614Z,2024-10-21 12:26:43.555648065+00:00,10,2,38,A,A,2,233.93,100,130,166549,13148968,233.86,233.9,100,100,1,1,233.81,233.91,2,200,2,1,233.8,233.93,105,200,2,2,233.74,233.95,400,121,1,1,233.7,234.0,1200,17,1,2,233.66,234.02,1,400,1,1,233.58,234.1,505,100,2,1,233.53,234.13,10,400,1,1,233.5,234.17,100,1,1,1,233.45,234.25,15,100,1,1,AAPL,0,0,0,100,0,0,0,0,0,0,0,233.88
2024-10-21T12:26:43.555816268Z,2024-10-21 12:26:43.555650058+00:00,10,2,38,A,A,2,233.93,100,130,166210,13148969,233.86,233.9,100,100,1,1,233.81,233.91,2,200,2,1,233.8,233.93,105,300,2,3,233.74,233.95,400,121,1,1,233.7,234.0,1200,17,1,2,233.66,234.02,1,400,1,1,233.58,234.1,505,100,2,1,233.53,234.13,10,400,1,1,233.5,234.17,100,1,1,1,233.45,234.25,15,100,1,1,AAPL,0,0,0,100,0,0,0,0,0,0,0,233.88
2024-10-21T12:26:43.555819727Z,2024-10-21 12:26:43.555653371+00:00,10,2,38,C,A,1,233.91,200,130,166356,13148970,233.86,233.9,100,100,1,1,233.81,233.93,2,300,2,3,233.8,233.95,105,121,2,1,233.74,234.0,400,17,1,2,233.7,234.02,1200,400,1,1,233.66,234.1,1,100,1,1,233.58,234.13,505,400,2,1,233.53,234.17,10,1,1,1,233.5,234.25,100,100,1,1,233.45,234.41,15,500,1,1,AAPL,0,0,200,300,121,17,400,100,400,1,100,233.88
2024-10-21T12:26:43.555829005Z,2024-10-21 12:26:43.555663089+00:00,10,2,38,A,A,1,233.91,23,130,165916,13148971,233.86,233.9,100,100,1,1,233.81,233.91,2,23,2,1,233.8,233.93,105,300,2,3,233.74,233.95,400,121,1,1,233.7,234.0,1200,17,1,2,233.66,234.02,1,400,1,1,233.58,234.1,505,100,2,1,233.53,234.13,10,400,1,1,233.5,234.17,100,1,1,1,233.45,234.25,15,100,1,1,AAPL,0,0,23,300,121,17,400,100,400,1,100,233.88
2024-10-21T12:26:43.555844094Z,2024-10-21 12:26:43.555678324+00:00,10,2,38,C,A,0,233.9,100,130,165770,13148972,233.86,233.91,100,23,1,1,233.81,233.93,2,300,2,3,233.8,233.95,105,121,2,1,233.74,234.0,400,17,1,2,233.7,234.02,1200,400,1,1,233.66,234.1,1,100,1,1,233.58,234.13,505,400,2,1,233.53,234.17,10,1,1,1,233.5,234.25,100,100,1,1,233.45,234.41,15,500,1,1,AAPL,100,100,23,300,121,17,400,100,400,1,100,233.885
2024-10-21T12:26:43.555858526Z,2024-10-21 12:26:43.555692383+00:00,10,2,38,C,A,1,233.93,100,130,166143,13148974,233.86,233.91,100,23,1,1,233.81,233.93,2,200,2,2,233.8,233.95,105,121,2,1,233.74,234.0,400,17,1,2,233.7,234.02,1200,400,1,1,233.66,234.1,1,100,1,1,233.58,234.13,505,400,2,1,233.53,234.17,10,1,1,1,233.5,234.25,100,100,1,1,233.45,234.41,15,500,1,1,AAPL,0,0,-100,0,0,0,0,0,0,0,0,233.885
2024-10-21T12:26:43.555866497Z,2024-10-21 12:26:43.555700148+00:00,10,2,38,C,A,1,233.93,100,130,166349,13148976,233.86,233.91,100,23,1,1,233.81,233.93,2,100,2,1,233.8,233.94,105,23,2,1,233.74,233.95,400,121,1,1,233.7,234.0,1200,17,1,2,233.66,234.02,1,400,1,1,233.58,234.1,505,100,2,1,233.53,234.13,10,400,1,1,233.5,234.17,100,1,1,1,233.45,234.25,15,100,1,1,AAPL,0,0,-100,23,121,17,400,100,400,1,100,233.885
2024-10-21T12:26:43.555879570Z,2024-10-21 12:26:43.555711164+00:00,10,2,38,T,A,0,233.86,50,130,168406,13148979,233.86,233.91,100,23,1,1,233.81,233.93,2,100,2,1,233.8,233.94,105,23,2,1,233.74,233.95,400,121,1,1,233.7,234.0,1200,17,1,2,233.66,234.02,1,400,1,1,233.58,234.1,505,100,2,1,233.53,234.13,10,400,1,1,233.5,234.17,100,1,1,1,233.45,234.25,15,100,1,1,AAPL,0,0,0,0,0,0,0,0,0,0,0,233.885
2024-10-21T12:26:43.555879570Z,2024-10-21 12:26:43.555711164+00:00,10,2,38,C,B,0,233.86,50,130,168406,13148979,233.86,233.91,50,23,1,1,233.81,233.93,2,100,2,1,233.8,233.94,105,23,2,1,233.74,233.95,400,121,1,1,233.7,234.0,1200,17,1,2,233.66,234.02,1,400,1,1,233.58,234.1,505,100,2,1,233.53,234.13,10,400,1,1,233.5,234.17,100,1,1,1,233.45,234.25,15,100,1,1,AAPL,-50,-50,0,0,0,0,0,0,0,0,0,233.885
2024-10-21T12:26:43.555892512Z,2024-10-21 12:26:43.555724858+00:00,10,2,38,A,B,0,233.86,100,130,167654,13148980,233.86,233.91,150,23,2,1,233.81,233.93,2,100,2,1,233.8,233.94,105,23,2,1,233.74,233.95,400,121,1,1,233.7,234.0,1200,17,1,2,233.66,234.02,1,400,1,1,233.58,234.1,505,100,2,1,233.53,234.13,10,400,1,1,233.5,234.17,100,1,1,1,233.45,234.25,15,100,1,1,AAPL,100,100,0,0,0,0,0,0,0,0,0,233.885
2024-10-21T12:26:43.555904815Z,2024-10-21 12:26:43.555737821+00:00,10,2,38,T,A,0,233.86,50,130,166994,13148981,233.86,233.91,150,23,2,1,233.81,233.93,2,100,2,1,233.8,233.94,105,23,2,1,233.74,233.95,400,121,1,1,233.7,234.0,1200,17,1,2,233.66,234.02,1,400,1,1,233.58,234.1,505,100,2,1,233.53,234.13,10,400,1,1,233.5,234.17,100,1,1,1,233.45,234.25,15,100,1,1,AAPL,0,0,0,0,0,0,0,0,0,0,0,233.885
2024-10-21T12:26:43.555904815Z,2024-10-21 12:26:43.555737821+00:00,10,2,38,C,B,0,233.86,50,130,166994,13148981,233.86,233.91,100,23,1,1,233.81,233.93,2,100,2,1,233.8,233.94,105,23,2,1,233.74,233.95,400,121,1,1,233.7,234.0,1200,17,1,2,233.66,234.02,1,400,1,1,233.58,234.1,505,100,2,1,233.53,234.13,10,400,1,1,233.5,234.17,100,1,1,1,233.45,234.25,15,100,1,1,AAPL,-50,-50,0,0,0,0,0,0,0,0,0,233.885
2024-10-21T12:26:43.555933449Z,2024-10-21 12:26:43.555767270+00:00,10,2,38,C,B,3,233.74,200,130,166179,13148982,233.86,233.91,100,23,1,1,233.81,233.93,2,100,2,1,233.8,233.94,105,23,2,1,233.74,233.95,200,121,1,1,233.7,234.0,1200,17,1,2,233.66,234.02,1,400,1,1,233.58,234.1,505,100,2,1,233.53,234.13,10,400,1,1,233.5,234.17,100,1,1,1,233.45,234.25,15,100,1,1,AAPL,0,0,0,0,-200,0,0,0,0,0,0,233.885
2024-10-21T12:26:43.555956286Z,2024-10-21 12:26:43.555789284+00:00,10,2,38,C,B,3,233.74,200,130,167002,13148983,233.86,233.91,100,23,1,1,233.81,233.93,2,100,2,1,233.8,233.94,105,23,2,1,233.7,233.95,1200,121,1,1,233.66,234.0,1,17,1,2,233.58,234.02,505,400,2,1,233.53,234.1,10,100,1,1,233.5,234.13,100,400,1,1,233.45,234.17,15,1,1,1,233.4,234.25,110,100,2,1,AAPL,0,0,0,0,-200,-1200,-1,-505,-10,-100,-15,233.885
2024-10-21T12:26:43.556155095Z,2024-10-21 12:26:43.555989102+00:00,10,2,38,C,A,1,233.93,100,130,165993,13148984,233.86,233.91,100,23,1,1,233.81,233.94,2,23,2,1,233.8,233.95,105,121,2,1,233.7,234.0,1200,17,1,2,233.66,234.02,1,400,1,1,233.58,234.1,505,100,2,1,233.53,234.13,10,400,1,1,233.5,234.17,100,1,1,1,233.45,234.25,15,100,1,1,233.4,234.41,110,500,2,1,AAPL,0,0,100,23,121,17,400,100,400,1,100,233.885
2024-10-21T12:26:43.556502258Z,2024-10-21 12:26:43.556335122+00:00,10,2,38,T,A,0,233.86,5,130,167136,13148985,233.86,233.91,100,23,1,1,233.81,233.94,2,23,2,1,233.8,233.95,105,121,2,1,233.7,234.0,1200,17,1,2,233.66,234.02,1,400,1,1,233.58,234.1,505,100,2,1,233.53,234.13,10,400,1,1,233.5,234.17,100,1,1,1,233.45,234.25,15,100,1,1,233.4,234.41,110,500,2,1,AAPL,0,0,0,0,0,0,0,0,0,0,0,233.885
2024-10-21T12:26:43.556502258Z,2024-10-21 12:26:43.556335122+00:00,10,2,38,C,B,0,233.86,5,130,167136,13148985,233.86,233.91,95,23,1,1,233.81,233.94,2,23,2,1,233.8,233.95,105,121,2,1,233.7,234.0,1200,17,1,2,233.66,234.02,1,400,1,1,233.58,234.1,505,100,2,1,233.53,234.13,10,400,1,1,233.5,234.17,100,1,1,1,233.45,234.25,15,100,1,1,233.4,234.41,110,500,2,1,AAPL,-5,-5,0,0,0,0,0,0,0,0,0,233.885
2024-10-21T12:26:43.556510636Z,2024-10-21 12:26:43.556344203+00:00,10,2,38,A,B,0,233.86,100,130,166433,13148986,233.86,233.91,195,23,2,1,233.81,233.94,2,23,2,1,233.8,233.95,105,121,2,1,233.7,234.0,1200,17,1,2,233.66,234.02,1,400,1,1,233.58,234.1,505,100,2,1,233.53,234.13,10,400,1,1,233.5,234.17,100,1,1,1,233.45,234.25,15,100,1,1,233.4,234.41,110,500,2,1,AAPL,100,100,0,0,0,0,0,0,0,0,0,233.885
2024-10-21T12:26:43.603087151Z,2024-10-21 12:26:43.602920183+00:00,10,2,38,A,B,3,233.74,200,130,166968,13149063,233.86,233.91,195,23,2,1,233.81,233.94,2,23,2,1,233.8,233.95,105,121,2,1,233.74,234.0,200,17,1,2,233.7,234.02,1200,400,1,1,233.66,234.1,1,100,1,1,233.58,234.13,505,400,2,1,233.53,234.17,10,1,1,1,233.5,234.25,100,100,1,1,233.45,234.41,15,500,1,1,AAPL,0,0,0,0,200,1200,1,505,10,100,15,233.885
2024-10-21T12:26:43.633097364Z,2024-10-21 12:26:43.632931005+00:00,10,2,38,A,B,3,233.74,200,130,166359,13149078,233.86,233.91,195,23,2,1,233.81,233.94,2,23,2,1,233.8,233.95,105,121,2,1,233.74,234.0,400,17,2,2,233.7,234.02,1200,400,1,1,233.66,234.1,1,100,1,1,233.58,234.13,505,400,2,1,233.53,234.17,10,1,1,1,233.5,234.25,100,100,1,1,233.45,234.41,15,500,1,1,AAPL,0,0,0,0,200,0,0,0,0,0,0,233.885
2024-10-21T12:26:43.663930696Z,2024-10-21 12:26:43.663764676+00:00,10,2,38,C,A,1,233.94,23,130,166020,13149095,233.86,233.91,195,23,2,1,233.81,233.95,2,121,2,1,233.8,234.0,105,17,2,2,233.74,234.02,400,400,2,1,233.7,234.1,1200,100,1,1,233.66,234.13,1,400,1,1,233.58,234.17,505,1,2,1,233.53,234.25,10,100,1,1,233.5,234.41,100,500,1,1,233.45,234.43,15,105,1,2,AAPL,0,0,23,121,17,400,100,400,1,100,500,233.885
2024-10-21T12:26:43.813930819Z,2024-10-21 12:26:43.813764689+00:00,10,2,38,C,A,0,233.91,23,130,166130,13149215,233.86,233.95,195,121,2,1,233.81,234.0,2,17,2,2,233.8,234.02,105,400,2,1,233.74,234.1,400,100,2,1,233.7,234.13,1200,400,1,1,233.66,234.17,1,1,1,1,233.58,234.25,505,100,2,1,233.53,234.41,10,500,1,1,233.5,234.43,100,105,1,2,233.45,234.5,15,63,1,4,AAPL,23,23,121,17,400,100,400,1,100,500,105,233.905
2024-10-21T12:26:44.395306900Z,2024-10-21 12:26:44.395140599+00:00,10,2,38,A,A,1,233.97,7,130,166301,13149756,233.86,233.95,195,121,2,1,233.81,233.97,2,7,2,1,233.8,234.0,105,17,2,2,233.74,234.02,400,400,2,1,233.7,234.1,1200,100,1,1,233.66,234.13,1,400,1,1,233.58,234.17,505,1,2,1,233.53,234.25,10,100,1,1,233.5,234.41,100,500,1,1,233.45,234.43,15,105,1,2,AAPL,0,0,7,17,400,100,400,1,100,500,105,233.905
2024-10-21T12:26:47.317000869Z,2024-10-21 12:26:47.316834945+00:00,10,2,38,C,A,3,234.02,400,130,165924,13152409,233.86,233.95,195,121,2,1,233.81,233.97,2,7,2,1,233.8,234.0,105,17,2,2,233.74,234.1,400,100,2,1,233.7,234.13,1200,400,1,1,233.66,234.17,1,1,1,1,233.58,234.25,505,100,2,1,233.53,234.41,10,500,1,1,233.5,234.43,100,105,1,2,233.45,234.5,15,63,1,4,AAPL,0,0,0,0,400,100,400,1,100,500,105,233.905
2024-10-21T12:26:47.317013569Z,2024-10-21 12:26:47.316847348+00:00,10,2,38,A,A,3,234.04,400,130,166221,13152410,233.86,233.95,195,121,2,1,233.81,233.97,2,7,2,1,233.8,234.0,105,17,2,2,233.74,234.04,400,400,2,1,233.7,234.1,1200,100,1,1,233.66,234.13,1,400,1,1,233.58,234.17,505,1,2,1,233.53,234.25,10,100,1,1,233.5,234.41,100,500,1,1,233.45,234.43,15,105,1,2,AAPL,0,0,0,0,400,100,400,1,100,500,105,233.905
2024-10-21T12:26:47.371614290Z,2024-10-21 12:26:47.371448271+00:00,10,2,38,C,B,3,233.74,200,130,166019,13152673,233.86,233.95,195,121,2,1,233.81,233.97,2,7,2,1,233.8,234.0,105,17,2,2,233.74,234.04,200,400,1,1,233.7,234.1,1200,100,1,1,233.66,234.13,1,400,1,1,233.58,234.17,505,1,2,1,233.53,234.25,10,100,1,1,233.5,234.41,100,500,1,1,233.45,234.43,15,105,1,2,AAPL,0,0,0,0,-200,0,0,0,0,0,0,233.905
2024-10-21T12:26:47.371627679Z,2024-10-21 12:26:47.371461367+00:00,10,2,38,A,B,3,233.76,400,130,166312,13152674,233.86,233.95,195,121,2,1,233.81,233.97,2,7,2,1,233.8,234.0,105,17,2,2,233.76,234.04,400,400,1,1,233.7,234.1,1200,100,1,1,233.66,234.13,1,400,1,1,233.58,234.17,505,1,2,1,233.53,234.25,10,100,1,1,233.5,234.41,100,500,1,1,233.45,234.43,15,105,1,2,AAPL,0,0,0,0,400,0,0,0,0,0,0,233.905
2024-10-21T12:26:53.381817361Z,2024-10-21 12:26:53.381650546+00:00,10,2,38,A,B,3,233.77,400,130,166815,13157627,233.86,233.95,195,121,2,1,233.81,233.97,2,7,2,1,233.8,234.0,105,17,2,2,233.77,234.04,400,400,1,1,233.7,234.1,1200,100,1,1,233.66,234.13,1,400,1,1,233.58,234.17,505,1,2,1,233.53,234.25,10,100,1,1,233.5,234.41,100,500,1,1,233.45,234.43,15,105,1,2,AAPL,0,0,0,0,400,0,0,0,0,0,0,233.905
2024-10-21T12:26:54.545889324Z,2024-10-21 12:26:54.545723322+00:00,10,2,38,C,B,3,233.77,400,130,166002,13158660,233.86,233.95,195,121,2,1,233.81,233.97,2,7,2,1,233.8,234.0,105,17,2,2,233.7,234.04,1200,400,1,1,233.66,234.1,1,100,1,1,233.58,234.13,505,400,2,1,233.53,234.17,10,1,1,1,233.5,234.25,100,100,1,1,233.45,234.41,15,500,1,1,233.4,234.43,110,105,2,2,AAPL,0,0,0,0,-400,-1200,-1,-505,-10,-100,-15,233.905
2024-10-21T12:26:54.545901500Z,2024-10-21 12:26:54.545735230+00:00,10,2,38,A,B,3,233.76,400,130,166270,13158661,233.86,233.95,195,121,2,1,233.81,233.97,2,7,2,1,233.8,234.0,105,17,2,2,233.76,234.04,400,400,1,1,233.7,234.1,1200,100,1,1,233.66,234.13,1,400,1,1,233.58,234.17,505,1,2,1,233.53,234.25,10,100,1,1,233.5,234.41,100,500,1,1,233.45,234.43,15,105,1,2,AAPL,0,0,0,0,400,1200,1,505,10,100,15,233.905
2024-10-21T12:27:04.677969002Z,2024-10-21 12:27:04.677802802+00:00,10,2,38,A,B,3,233.77,400,130,166200,13168438,233.86,233.95,195,121,2,1,233.81,233.97,2,7,2,1,233.8,234.0,105,17,2,2,233.77,234.04,400,400,1,1,233.7,234.1,1200,100,1,1,233.66,234.13,1,400,1,1,233.58,234.17,505,1,2,1,233.53,234.25,10,100,1,1,233.5,234.41,100,500,1,1,233.45,234.43,15,105,1,2,AAPL,0,0,0,0,400,0,0,0,0,0,0,233.905
2024-10-21T12:27:04.858352610Z,2024-10-21 12:27:04.858186427+00:00,10,2,38,C,B,3,233.77,200,130,166183,13168809,233.86,233.95,195,121,2,1,233.81,233.97,2,7,2,1,233.8,234.0,105,17,2,2,233.77,234.04,200,400,1,1,233.7,234.1,1200,100,1,1,233.66,234.13,1,400,1,1,233.58,234.17,505,1,2,1,233.53,234.25,10,100,1,1,233.5,234.41,100,500,1,1,233.45,234.43,15,105,1,2,AAPL,0,0,0,0,-200,0,0,0,0,0,0,233.905
2024-10-21T12:27:08.140351417Z,2024-10-21 12:27:08.140184917+00:00,10,2,38,A,B,0,233.86,100,130,166500,13171896,233.86,233.95,295,121,3,1,233.81,233.97,2,7,2,1,233.8,234.0,105,17,2,2,233.77,234.04,200,400,1,1,233.7,234.1,1200,100,1,1,233.66,234.13,1,400,1,1,233.58,234.17,505,1,2,1,233.53,234.25,10,100,1,1,233.5,234.41,100,500,1,1,233.45,234.43,15,105,1,2,AAPL,100,100,0,0,0,0,0,0,0,0,0,233.905
2024-10-21T12:27:08.267404175Z,2024-10-21 12:27:08.267237597+00:00,10,2,38,A,A,2,233.99,200,130,166578,13172040,233.86,233.95,295,121,3,1,233.81,233.97,2,7,2,1,233.8,233.99,105,200,2,1,233.77,234.0,200,17,1,2,233.7,234.1,1200,100,1,1,233.66,234.13,1,400,1,1,233.58,234.17,505,1,2,1,233.53,234.25,10,100,1,1,233.5,234.41,100,500,1,1,233.45,234.43,15,105,1,2,AAPL,0,0,0,200,17,0,0,0,0,0,0,233.905
2024-10-21T12:27:08.904013328Z,2024-10-21 12:27:08.903847050+00:00,10,2,38,A,B,3,233.77,200,130,166278,13172666,233.86,233.95,295,121,3,1,233.81,233.97,2,7,2,1,233.8,233.99,105,200,2,1,233.77,234.0,400,17,2,2,233.7,234.1,1200,100,1,1,233.66,234.13,1,400,1,1,233.58,234.17,505,1,2,1,233.53,234.25,10,100,1,1,233.5,234.41,100,500,1,1,233.45,234.43,15,105,1,2,AAPL,0,0,0,0,200,0,0,0,0,0,0,233.905
2024-10-21T12:27:15.211190007Z,2024-10-21 12:27:15.211023662+00:00,10,2,38,C,A,1,233.97,7,130,166345,13177973,233.86,233.95,295,121,3,1,233.81,233.99,2,200,2,1,233.8,234.0,105,17,2,2,233.77,234.1,400,100,2,1,233.7,234.13,1200,400,1,1,233.66,234.17,1,1,1,1,233.58,234.25,505,100,2,1,233.53,234.41,10,500,1,1,233.5,234.43,100,105,1,2,233.45,234.5,15,63,1,4,AAPL,0,0,7,200,17,100,400,1,100,500,105,233.905
2024-10-21T12:27:16.357351976Z,2024-10-21 12:27:16.357185731+00:00,10,2,38,C,A,0,233.95,121,130,166245,13178747,233.86,233.99,295,200,3,1,233.81,234.0,2,17,2,2,233.8,234.1,105,100,2,1,233.77,234.13,400,400,2,1,233.7,234.17,1200,1,1,1,233.66,234.25,1,100,1,1,233.58,234.41,505,500,2,1,233.53,234.43,10,105,1,2,233.5,234.5,100,63,1,4,233.45,234.59,15,60,1,1,AAPL,121,121,200,17,100,400,1,100,500,105,63,233.925
2024-10-21T12:27:16.384048756Z,2024-10-21 12:27:16.383880298+00:00,10,2,38,T,N,0,233.87,50,0,168458,13178752,233.86,233.99,295,200,3,1,233.81,234.0,2,17,2,2,233.8,234.1,105,100,2,1,233.77,234.13,400,400,2,1,233.7,234.17,1200,1,1,1,233.66,234.25,1,100,1,1,233.58,234.41,505,500,2,1,233.53,234.43,10,105,1,2,233.5,234.5,100,63,1,4,233.45,234.59,15,60,1,1,AAPL,0,0,0,0,0,0,0,0,0,0,0,233.925
2024-10-21T12:27:16.384048756Z,2024-10-21 12:27:16.383880298+00:00,10,2,38,T,N,0,233.87,71,130,168458,13178753,233.86,233.99,295,200,3,1,233.81,234.0,2,17,2,2,233.8,234.1,105,100,2,1,233.77,234.13,400,400,2,1,233.7,234.17,1200,1,1,1,233.66,234.25,1,100,1,1,233.58,234.41,505,500,2,1,233.53,234.43,10,105,1,2,233.5,234.5,100,63,1,4,233.45,234.59,15,60,1,1,AAPL,0,0,0,0,0,0,0,0,0,0,0,233.925
2024-10-21T12:27:17.218399628Z,2024-10-21 12:27:17.218233083+00:00,10,2,38,A,A,0,233.98,7,130,166545,13179063,233.86,233.98,295,7,3,1,233.81,233.99,2,200,2,1,233.8,234.0,105,17,2,2,233.77,234.1,400,100,2,1,233.7,234.13,1200,400,1,1,233.66,234.17,1,1,1,1,233.58,234.25,505,100,2,1,233.53,234.41,10,500,1,1,233.5,234.43,100,105,1,2,233.45,234.5,15,63,1,4,AAPL,7,7,200,17,100,400,1,100,500,105,63,233.92000000000002
2024-10-21T12:27:21.556157771Z,2024-10-21 12:27:21.555991612+00:00,10,2,38,C,B,3,233.77,200,130,166159,13183172,233.86,233.98,295,7,3,1,233.81,233.99,2,200,2,1,233.8,234.0,105,17,2,2,233.77,234.1,200,100,1,1,233.7,234.13,1200,400,1,1,233.66,234.17,1,1,1,1,233.58,234.25,505,100,2,1,233.53,234.41,10,500,1,1,233.5,234.43,100,105,1,2,233.45,234.5,15,63,1,4,AAPL,0,0,0,0,-200,0,0,0,0,0,0,233.92000000000002
2024-10-21T12:27:21.556172659Z,2024-10-21 12:27:21.556005910+00:00,10,2,38,A,B,1,233.81,200,130,166749,13183173,233.86,233.98,295,7,3,1,233.81,233.99,202,200,3,1,233.8,234.0,105,17,2,2,233.7,234.1,1200,100,1,1,233.66,234.13,1,400,1,1,233.58,234.17,505,1,2,1,233.53,234.25,10,100,1,1,233.5,234.41,100,500,1,1,233.45,234.43,15,105,1,2,233.4,234.5,110,63,2,4,AAPL,0,0,200,0,-200,-1200,-1,-505,-10,-100,-15,233.92000000000002
2024-10-21T12:27:21.983295309Z,2024-10-21 12:27:21.983129451+00:00,10,2,38,C,B,1,233.81,200,130,165858,13183374,233.86,233.98,295,7,3,1,233.81,233.99,2,200,2,1,233.8,234.0,105,17,2,2,233.7,234.1,1200,100,1,1,233.66,234.13,1,400,1,1,233.58,234.17,505,1,2,1,233.53,234.25,10,100,1,1,233.5,234.41,100,500,1,1,233.45,234.43,15,105,1,2,233.4,234.5,110,63,2,4,AAPL,0,0,-200,0,0,0,0,0,0,0,0,233.92000000000002
2024-10-21T12:27:21.983308878Z,2024-10-21 12:27:21.983142748+00:00,10,2,38,A,B,3,233.77,400,130,166130,13183375,233.86,233.98,295,7,3,1,233.81,233.99,2,200,2,1,233.8,234.0,105,17,2,2,233.77,234.1,400,100,1,1,233.7,234.13,1200,400,1,1,233.66,234.17,1,1,1,1,233.58,234.25,505,100,2,1,233.53,234.41,10,500,1,1,233.5,234.43,100,105,1,2,233.45,234.5,15,63,1,4,AAPL,0,0,0,0,400,1200,1,505,10,100,15,233.92000000000002
2024-10-21T12:27:22.989069356Z,2024-10-21 12:27:22.988903196+00:00,10,2,38,C,A,0,233.98,7,130,166160,13184098,233.86,233.99,295,200,3,1,233.81,234.0,2,17,2,2,233.8,234.1,105,100,2,1,233.77,234.13,400,400,1,1,233.7,234.17,1200,1,1,1,233.66,234.25,1,100,1,1,233.58,234.41,505,500,2,1,233.53,234.43,10,105,1,2,233.5,234.5,100,63,1,4,233.45,234.59,15,60,1,1,AAPL,7,7,200,17,100,400,1,100,500,105,63,233.925
2024-10-21T12:27:23.025873698Z,2024-10-21 12:27:23.025707565+00:00,10,2,38,C,B,3,233.77,400,130,166133,13184133,233.86,233.99,295,200,3,1,233.81,234.0,2,17,2,2,233.8,234.1,105,100,2,1,233.7,234.13,1200,400,1,1,233.66,234.17,1,1,1,1,233.58,234.25,505,100,2,1,233.53,234.41,10,500,1,1,233.5,234.43,100,105,1,2,233.45,234.5,15,63,1,4,233.4,234.59,110,60,2,1,AAPL,0,0,0,0,-400,-1200,-1,-505,-10,-100,-15,233.925
2024-10-21T12:27:23.025886464Z,2024-10-21 12:27:23.025720316+00:00,10,2,38,A,B,3,233.74,200,130,166148,13184134,233.86,233.99,295,200,3,1,233.81,234.0,2,17,2,2,233.8,234.1,105,100,2,1,233.74,234.13,200,400,1,1,233.7,234.17,1200,1,1,1,233.66,234.25,1,100,1,1,233.58,234.41,505,500,2,1,233.53,234.43,10,105,1,2,233.5,234.5,100,63,1,4,233.45,234.59,15,60,1,1,AAPL,0,0,0,0,200,1200,1,505,10,100,15,233.925
2024-10-21T12:27:24.992972792Z,2024-10-21 12:27:24.992239712+00:00,10,2,38,A,A,0,233.99,7,130,733080,13186020,233.86,233.99,295,207,3,2,233.81,234.0,2,17,2,2,233.8,234.1,105,100,2,1,233.74,234.13,200,400,1,1,233.7,234.17,1200,1,1,1,233.66,234.25,1,100,1,1,233.58,234.41,505,500,2,1,233.53,234.43,10,105,1,2,233.5,234.5,100,63,1,4,233.45,234.59,15,60,1,1,AAPL,7,7,0,0,0,0,0,0,0,0,0,233.925
2024-10-21T12:27:25.038852343Z,2024-10-21 12:27:25.038119028+00:00,10,2,38,A,B,3,233.77,200,130,733315,13186052,233.86,233.99,295,207,3,2,233.81,234.0,2,17,2,2,233.8,234.1,105,100,2,1,233.77,234.13,200,400,1,1,233.7,234.17,1200,1,1,1,233.66,234.25,1,100,1,1,233.58,234.41,505,500,2,1,233.53,234.43,10,105,1,2,233.5,234.5,100,63,1,4,233.45,234.59,15,60,1,1,AAPL,0,0,0,0,200,0,0,0,0,0,0,233.925
2024-10-21T12:27:26.131472457Z,2024-10-21 12:27:26.130738899+00:00,10,2,38,A,B,3,233.77,200,130,733558,13186986,233.86,233.99,295,207,3,2,233.81,234.0,2,17,2,2,233.8,234.1,105,100,2,1,233.77,234.13,400,400,2,1,233.7,234.17,1200,1,1,1,233.66,234.25,1,100,1,1,233.58,234.41,505,500,2,1,233.53,234.43,10,105,1,2,233.5,234.5,100,63,1,4,233.45,234.59,15,60,1,1,AAPL,0,0,0,0,200,0,0,0,0,0,0,233.925
2024-10-21T12:27:28.579136710Z,2024-10-21 12:27:28.578403729+00:00,10,2,38,C,A,0,233.99,7,130,732981,13188280,233.86,233.99,295,200,3,1,233.81,234.0,2,17,2,2,233.8,234.1,105,100,2,1,233.77,234.13,400,400,2,1,233.7,234.17,1200,1,1,1,233.66,234.25,1,100,1,1,233.58,234.41,505,500,2,1,233.53,234.43,10,105,1,2,233.5,234.5,100,63,1,4,233.45,234.59,15,60,1,1,AAPL,-7,-7,0,0,0,0,0,0,0,0,0,233.925
2024-10-21T12:27:29.136296936Z,2024-10-21 12:27:29.135563917+00:00,10,2,38,C,A,0,233.99,200,130,733019,13188524,233.86,234.0,295,17,3,2,233.81,234.1,2,100,2,1,233.8,234.13,105,400,2,1,233.77,234.17,400,1,2,1,233.7,234.25,1200,100,1,1,233.66,234.41,1,500,1,1,233.58,234.43,505,105,2,2,233.53,234.5,10,63,1,4,233.5,234.59,100,60,1,1,233.45,234.75,15,1,1,1,AAPL,200,200,17,100,400,1,100,500,105,63,60,233.93
2024-10-21T12:27:29.136314635Z,2024-10-21 12:27:29.135580379+00:00,10,2,38,A,A,1,234.05,400,130,734256,13188525,233.86,234.0,295,17,3,2,233.81,234.05,2,400,2,1,233.8,234.1,105,100,2,1,233.77,234.13,400,400,2,1,233.7,234.17,1200,1,1,1,233.66,234.25,1,100,1,1,233.58,234.41,505,500,2,1,233.53,234.43,10,105,1,2,233.5,234.5,100,63,1,4,233.45,234.59,15,60,1,1,AAPL,0,0,400,100,400,1,100,500,105,63,60,233.93
2024-10-21T12:27:30.582343028Z,2024-10-21 12:27:30.581609917+00:00,10,2,38,A,A,6,234.41,7,130,733111,13189750,233.86,234.0,295,17,3,2,233.81,234.05,2,400,2,1,233.8,234.1,105,100,2,1,233.77,234.13,400,400,2,1,233.7,234.17,1200,1,1,1,233.66,234.25,1,100,1,1,233.58,234.41,505,507,2,2,233.53,234.43,10,105,1,2,233.5,234.5,100,63,1,4,233.45,234.59,15,60,1,1,AAPL,0,0,0,0,0,0,0,7,0,0,0,233.93
2024-10-21T12:27:37.149919392Z,2024-10-21 12:27:37.149186319+00:00,10,2,38,C,B,3,233.77,200,130,733073,13194254,233.86,234.0,295,17,3,2,233.81,234.05,2,400,2,1,233.8,234.1,105,100,2,1,233.77,234.13,200,400,1,1,233.7,234.17,1200,1,1,1,233.66,234.25,1,100,1,1,233.58,234.41,505,507,2,2,233.53,234.43,10,105,1,2,233.5,234.5,100,63,1,4,233.45,234.59,15,60,1,1,AAPL,0,0,0,0,-200,0,0,0,0,0,0,233.93
2024-10-21T12:27:37.149931822Z,2024-10-21 12:27:37.149198552+00:00,10,2,38,A,B,3,233.78,400,130,733270,13194255,233.86,234.0,295,17,3,2,233.81,234.05,2,400,2,1,233.8,234.1,105,100,2,1,233.78,234.13,400,400,1,1,233.7,234.17,1200,1,1,1,233.66,234.25,1,100,1,1,233.58,234.41,505,507,2,2,233.53,234.43,10,105,1,2,233.5,234.5,100,63,1,4,233.45,234.59,15,60,1,1,AAPL,0,0,0,0,400,0,0,0,0,0,0,233.93
2024-10-21T12:27:37.282093181Z,2024-10-21 12:27:37.281359883+00:00,10,2,38,A,A,1,234.02,200,130,733298,13194447,233.86,234.0,295,17,3,2,233.81,234.02,2,200,2,1,233.8,234.1,105,100,2,1,233.78,234.13,400,400,1,1,233.7,234.17,1200,1,1,1,233.66,234.25,1,100,1,1,233.58,234.41,505,507,2,2,233.53,234.43,10,105,1,2,233.5,234.5,100,63,1,4,233.45,234.59,15,60,1,1,AAPL,0,0,200,0,0,0,0,0,0,0,0,233.93
2024-10-21T12:27:37.731855277Z,2024-10-21 12:27:37.731121489+00:00,10,2,38,A,B,3,233.79,400,130,733788,13195199,233.86,234.0,295,17,3,2,233.81,234.02,2,200,2,1,233.8,234.1,105,100,2,1,233.79,234.13,400,400,1,1,233.7,234.17,1200,1,1,1,233.66,234.25,1,100,1,1,233.58,234.41,505,507,2,2,233.53,234.43,10,105,1,2,233.5,234.5,100,63,1,4,233.45,234.59,15,60,1,1,AAPL,0,0,0,0,400,0,0,0,0,0,0,233.93
2024-10-21T12:27:37.764573144Z,2024-10-21 12:27:37.763839849+00:00,10,2,38,C,B,3,233.79,200,130,733295,13195270,233.86,234.0,295,17,3,2,233.81,234.02,2,200,2,1,233.8,234.1,105,100,2,1,233.79,234.13,200,400,1,1,233.7,234.17,1200,1,1,1,233.66,234.25,1,100,1,1,233.58,234.41,505,507,2,2,233.53,234.43,10,105,1,2,233.5,234.5,100,63,1,4,233.45,234.59,15,60,1,1,AAPL,0,0,0,0,-200,0,0,0,0,0,0,233.93
2024-10-21T12:27:37.767686766Z,2024-10-21 12:27:37.766952915+00:00,10,2,38,A,A,1,234.02,200,130,733851,13195276,233.86,234.0,295,17,3,2,233.81,234.02,2,400,2,2,233.8,234.1,105,100,2,1,233.79,234.13,200,400,1,1,233.7,234.17,1200,1,1,1,233.66,234.25,1,100,1,1,233.58,234.41,505,507,2,2,233.53,234.43,10,105,1,2,233.5,234.5,100,63,1,4,233.45,234.59,15,60,1,1,AAPL,0,0,200,0,0,0,0,0,0,0,0,233.93
2024-10-21T12:27:39.526116351Z,2024-10-21 12:27:39.525383410+00:00,10,2,38,C,A,1,234.02,200,130,732941,13197083,233.86,234.0,295,17,3,2,233.81,234.02,2,200,2,1,233.8,234.1,105,100,2,1,233.79,234.13,200,400,1,1,233.7,234.17,1200,1,1,1,233.66,234.25,1,100,1,1,233.58,234.41,505,507,2,2,233.53,234.43,10,105,1,2,233.5,234.5,100,63,1,4,233.45,234.59,15,60,1,1,AAPL,0,0,-200,0,0,0,0,0,0,0,0,233.93
2024-10-21T12:27:39.526127909Z,2024-10-21 12:27:39.525394818+00:00,10,2,38,C,A,1,234.02,200,130,733091,13197084,233.86,234.0,295,17,3,2,233.81,234.1,2,100,2,1,233.8,234.13,105,400,2,1,233.79,234.17,200,1,1,1,233.7,234.25,1200,100,1,1,233.66,234.41,1,507,1,2,233.58,234.43,505,105,2,2,233.53,234.5,10,63,1,4,233.5,234.59,100,60,1,1,233.45,234.75,15,1,1,1,AAPL,0,0,200,100,400,1,100,507,105,63,60,233.93
2024-10-21T12:27:39.527631797Z,2024-10-21 12:27:39.526899044+00:00,10,2,38,C,A,5,234.41,7,130,732753,13197088,233.86,234.0,295,17,3,2,233.81,234.1,2,100,2,1,233.8,234.13,105,400,2,1,233.79,234.17,200,1,1,1,233.7,234.25,1200,100,1,1,233.66,234.41,1,500,1,1,233.58,234.43,505,105,2,2,233.53,234.5,10,63,1,4,233.5,234.59,100,60,1,1,233.45,234.75,15,1,1,1,AAPL,0,0,0,0,0,0,-7,0,0,0,0,233.93
2024-10-21T12:27:39.593636447Z,2024-10-21 12:27:39.592903496+00:00,10,2,38,A,B,1,233.84,100,130,732951,13197554,233.86,234.0,295,17,3,2,233.84,234.1,100,100,1,1,233.81,234.13,2,400,2,1,233.8,234.17,105,1,2,1,233.79,234.25,200,100,1,1,233.7,234.41,1200,500,1,1,233.66,234.43,1,105,1,2,233.58,234.5,505,63,2,4,233.53,234.59,10,60,1,1,233.5,234.75,100,1,1,1,AAPL,0,0,100,2,105,200,1200,1,505,10,100,233.93
2024-10-21T12:27:39.593996622Z,2024-10-21 12:27:39.593262886+00:00,10,2,38,C,B,1,233.84,100,130,733736,13197558,233.86,234.0,295,17,3,2,233.81,234.1,2,100,2,1,233.8,234.13,105,400,2,1,233.79,234.17,200,1,1,1,233.7,234.25,1200,100,1,1,233.66,234.41,1,500,1,1,233.58,234.43,505,105,2,2,233.53,234.5,10,63,1,4,233.5,234.59,100,60,1,1,233.45,234.75,15,1,1,1,AAPL,0,0,-100,-2,-105,-200,-1200,-1,-505,-10,-100,233.93
2024-10-21T12:27:39.712483751Z,2024-10-21 12:27:39.711750527+00:00,10,2,38,A,A,1,234.02,400,130,733224,13197970,233.86,234.0,295,17,3,2,233.81,234.02,2,400,2,1,233.8,234.1,105,100,2,1,233.79,234.13,200,400,1,1,233.7,234.17,1200,1,1,1,233.66,234.25,1,100,1,1,233.58,234.41,505,500,2,1,233.53,234.43,10,105,1,2,233.5,234.5,100,63,1,4,233.45,234.59,15,60,1,1,AAPL,0,0,400,100,400,1,100,500,105,63,60,233.93
2024-10-21T12:27:40.732061815Z,2024-10-21 12:27:40.731328339+00:00,10,2,38,A,A,1,234.01,400,130,733476,13198996,233.86,234.0,295,17,3,2,233.81,234.01,2,400,2,1,233.8,234.1,105,100,2,1,233.79,234.13,200,400,1,1,233.7,234.17,1200,1,1,1,233.66,234.25,1,100,1,1,233.58,234.41,505,500,2,1,233.53,234.43,10,105,1,2,233.5,234.5,100,63,1,4,233.45,234.59,15,60,1,1,AAPL,0,0,400,0,0,0,0,0,0,0,0,233.93
2024-10-21T12:27:40.758541085Z,2024-10-21 12:27:40.757807867+00:00,10,2,38,C,A,1,234.01,400,130,733218,13199068,233.86,234.0,295,17,3,2,233.81,234.1,2,100,2,1,233.8,234.13,105,400,2,1,233.79,234.17,200,1,1,1,233.7,234.25,1200,100,1,1,233.66,234.41,1,500,1,1,233.58,234.43,505,105,2,2,233.53,234.5,10,63,1,4,233.5,234.59,100,60,1,1,233.45,234.75,15,1,1,1,AAPL,0,0,400,100,400,1,100,500,105,63,60,233.93
2024-10-21T12:27:40.758553589Z,2024-10-21 12:27:40.757820402+00:00,10,2,38,A,A,1,234.02,200,130,733187,13199069,233.86,234.0,295,17,3,2,233.81,234.02,2,200,2,1,233.8,234.1,105,100,2,1,233.79,234.13,200,400,1,1,233.7,234.17,1200,1,1,1,233.66,234.25,1,100,1,1,233.58,234.41,505,500,2,1,233.53,234.43,10,105,1,2,233.5,234.5,100,63,1,4,233.45,234.59,15,60,1,1,AAPL,0,0,200,100,400,1,100,500,105,63,60,233.93
2024-10-21T12:27:41.106714797Z,2024-10-21 12:27:41.105981707+00:00,10,2,38,C,A,1,234.02,200,130,733090,13199310,233.86,234.0,295,17,3,2,233.81,234.1,2,100,2,1,233.8,234.13,105,400,2,1,233.79,234.17,200,1,1,1,233.7,234.25,1200,100,1,1,233.66,234.41,1,500,1,1,233.58,234.43,505,105,2,2,233.53,234.5,10,63,1,4,233.5,234.59,100,60,1,1,233.45,234.75,15,1,1,1,AAPL,0,0,200,100,400,1,100,500,105,63,60,233.93
2024-10-21T12:27:41.176308255Z,2024-10-21 12:27:41.175574942+00:00,10,2,38,A,A,1,234.06,200,130,733313,13199399,233.86,234.0,295,17,3,2,233.81,234.06,2,200,2,1,233.8,234.1,105,100,2,1,233.79,234.13,200,400,1,1,233.7,234.17,1200,1,1,1,233.66,234.25,1,100,1,1,233.58,234.41,505,500,2,1,233.53,234.43,10,105,1,2,233.5,234.5,100,63,1,4,233.45,234.59,15,60,1,1,AAPL,0,0,200,100,400,1,100,500,105,63,60,233.93
2024-10-21T12:27:41.223548018Z,2024-10-21 12:27:41.222814573+00:00,10,2,38,A,A,1,234.06,200,130,733445,13199432,233.86,234.0,295,17,3,2,233.81,234.06,2,400,2,2,233.8,234.1,105,100,2,1,233.79,234.13,200,400,1,1,233.7,234.17,1200,1,1,1,233.66,234.25,1,100,1,1,233.58,234.41,505,500,2,1,233.53,234.43,10,105,1,2,233.5,234.5,100,63,1,4,233.45,234.59,15,60,1,1,AAPL,0,0,200,0,0,0,0,0,0,0,0,233.93
2024-10-21T12:27:41.320586998Z,2024-10-21 12:27:41.319854032+00:00,10,2,38,C,A,1,234.06,200,130,732966,13199474,233.86,234.0,295,17,3,2,233.81,234.06,2,200,2,1,233.8,234.1,105,100,2,1,233.79,234.13,200,400,1,1,233.7,234.17,1200,1,1,1,233.66,234.25,1,100,1,1,233.58,234.41,505,500,2,1,233.53,234.43,10,105,1,2,233.5,234.5,100,63,1,4,233.45,234.59,15,60,1,1,AAPL,0,0,-200,0,0,0,0,0,0,0,0,233.93
2024-10-21T12:27:41.320600607Z,2024-10-21 12:27:41.319866876+00:00,10,2,38,A,A,1,234.04,200,130,733731,13199475,233.86,234.0,295,17,3,2,233.81,234.04,2,200,2,1,233.8,234.1,105,100,2,1,233.79,234.13,200,400,1,1,233.7,234.17,1200,1,1,1,233.66,234.25,1,100,1,1,233.58,234.41,505,500,2,1,233.53,234.43,10,105,1,2,233.5,234.5,100,63,1,4,233.45,234.59,15,60,1,1,AAPL,0,0,200,0,0,0,0,0,0,0,0,233.93
2024-10-21T12:27:41.530250934Z,2024-10-21 12:27:41.529517717+00:00,10,2,38,A,A,6,234.38,7,130,733217,13199682,233.86,234.0,295,17,3,2,233.81,234.04,2,200,2,1,233.8,234.1,105,100,2,1,233.79,234.13,200,400,1,1,233.7,234.17,1200,1,1,1,233.66,234.25,1,100,1,1,233.58,234.38,505,7,2,1,233.53,234.41,10,500,1,1,233.5,234.43,100,105,1,2,233.45,234.5,15,63,1,4,AAPL,0,0,0,0,0,0,0,7,500,105,63,233.93
2024-10-21T12:27:46.418013842Z,2024-10-21 12:27:46.417280824+00:00,10,2,38,C,B,3,233.79,200,130,733018,13203166,233.86,234.0,295,17,3,2,233.81,234.04,2,200,2,1,233.8,234.1,105,100,2,1,233.7,234.13,1200,400,1,1,233.66,234.17,1,1,1,1,233.58,234.25,505,100,2,1,233.53,234.38,10,7,1,1,233.5,234.41,100,500,1,1,233.45,234.43,15,105,1,2,233.4,234.5,110,63,2,4,AAPL,0,0,0,0,-200,-1200,-1,-505,-10,-100,-15,233.93
2024-10-21T12:27:46.418026002Z,2024-10-21 12:27:46.417292639+00:00,10,2,38,A,B,3,233.77,400,130,733363,13203167,233.86,234.0,295,17,3,2,233.81,234.04,2,200,2,1,233.8,234.1,105,100,2,1,233.77,234.13,400,400,1,1,233.7,234.17,1200,1,1,1,233.66,234.25,1,100,1,1,233.58,234.38,505,7,2,1,233.53,234.41,10,500,1,1,233.5,234.43,100,105,1,2,233.45,234.5,15,63,1,4,AAPL,0,0,0,0,400,1200,1,505,10,100,15,233.93
2024-10-21T12:27:46.473030357Z,2024-10-21 12:27:46.472297071+00:00,10,2,38,A,A,1,234.03,200,130,733286,13203213,233.86,234.0,295,17,3,2,233.81,234.03,2,200,2,1,233.8,234.1,105,100,2,1,233.77,234.13,400,400,1,1,233.7,234.17,1200,1,1,1,233.66,234.25,1,100,1,1,233.58,234.38,505,7,2,1,233.53,234.41,10,500,1,1,233.5,234.43,100,105,1,2,233.45,234.5,15,63,1,4,AAPL,0,0,200,0,0,0,0,0,0,0,0,233.93
2024-10-21T12:27:47.209450267Z,2024-10-21 12:27:47.208717142+00:00,10,2,38,C,A,1,234.03,200,130,733125,13204087,233.86,234.0,295,17,3,2,233.81,234.1,2,100,2,1,233.8,234.13,105,400,2,1,233.77,234.17,400,1,1,1,233.7,234.25,1200,100,1,1,233.66,234.38,1,7,1,1,233.58,234.41,505,500,2,1,233.53,234.43,10,105,1,2,233.5,234.5,100,63,1,4,233.45,234.59,15,60,1,1,AAPL,0,0,200,100,400,1,100,7,500,105,63,233.93
2024-10-21T12:27:47.310139513Z,2024-10-21 12:27:47.309406274+00:00,10,2,38,A,A,1,234.03,200,130,733239,13204445,233.86,234.0,295,17,3,2,233.81,234.03,2,200,2,1,233.8,234.1,105,100,2,1,233.77,234.13,400,400,1,1,233.7,234.17,1200,1,1,1,233.66,234.25,1,100,1,1,233.58,234.38,505,7,2,1,233.53,234.41,10,500,1,1,233.5,234.43,100,105,1,2,233.45,234.5,15,63,1,4,AAPL,0,0,200,100,400,1,100,7,500,105,63,233.93
2024-10-21T12:27:47.985465401Z,2024-10-21 12:27:47.985298442+00:00,10,2,38,A,B,3,233.78,400,130,166959,13205236,233.86,234.0,295,17,3,2,233.81,234.03,2,200,2,1,233.8,234.1,105,100,2,1,233.78,234.13,400,400,1,1,233.7,234.17,1200,1,1,1,233.66,234.25,1,100,1,1,233.58,234.38,505,7,2,1,233.53,234.41,10,500,1,1,233.5,234.43,100,105,1,2,233.45,234.5,15,63,1,4,AAPL,0,0,0,0,400,0,0,0,0,0,0,233.93
2024-10-21T12:27:50.060871934Z,2024-10-21 12:27:50.060705561+00:00,10,2,38,C,A,1,234.03,200,130,166373,13206376,233.86,234.0,295,17,3,2,233.81,234.1,2,100,2,1,233.8,234.13,105,400,2,1,233.78,234.17,400,1,1,1,233.7,234.25,1200,100,1,1,233.66,234.38,1,7,1,1,233.58,234.41,505,500,2,1,233.53,234.43,10,105,1,2,233.5,234.5,100,63,1,4,233.45,234.59,15,60,1,1,AAPL,0,0,200,100,400,1,100,7,500,105,63,233.93
2024-10-21T12:27:50.061591231Z,2024-10-21 12:27:50.061424726+00:00,10,2,38,A,B,0,233.87,4,130,166505,13206379,233.87,234.0,4,17,1,2,233.86,234.1,295,100,3,1,233.81,234.13,2,400,2,1,233.8,234.17,105,1,2,1,233.78,234.25,400,100,1,1,233.7,234.38,1200,7,1,1,233.66,234.41,1,500,1,1,233.58,234.43,505,105,2,2,233.53,234.5,10,63,1,4,233.5,234.59,100,60,1,1,AAPL,4,4,295,2,105,400,1200,1,505,10,100,233.935
2024-10-21T12:27:50.061891362Z,2024-10-21 12:27:50.061724093+00:00,10,2,38,A,B,0,233.87,100,128,167269,13206382,233.87,234.0,104,17,2,2,233.86,234.1,295,100,3,1,233.81,234.13,2,400,2,1,233.8,234.17,105,1,2,1,233.78,234.25,400,100,1,1,233.7,234.38,1200,7,1,1,233.66,234.41,1,500,1,1,233.58,234.43,505,105,2,2,233.53,234.5,10,63,1,4,233.5,234.59,100,60,1,1,AAPL,100,100,0,0,0,0,0,0,0,0,0,233.935
2024-10-21T12:27:50.062283396Z,2024-10-21 12:27:50.062117451+00:00,10,2,38,C,B,0,233.87,100,130,165945,13206387,233.87,234.0,4,17,1,2,233.86,234.1,295,100,3,1,233.81,234.13,2,400,2,1,233.8,234.17,105,1,2,1,233.78,234.25,400,100,1,1,233.7,234.38,1200,7,1,1,233.66,234.41,1,500,1,1,233.58,234.43,505,105,2,2,233.53,234.5,10,63,1,4,233.5,234.59,100,60,1,1,AAPL,-100,-100,0,0,0,0,0,0,0,0,0,233.935
2024-10-21T12:27:50.063258837Z,2024-10-21 12:27:50.063092822+00:00,10,2,38,C,A,5,234.38,7,130,166015,13206393,233.87,234.0,4,17,1,2,233.86,234.1,295,100,3,1,233.81,234.13,2,400,2,1,233.8,234.17,105,1,2,1,233.78,234.25,400,100,1,1,233.7,234.41,1200,500,1,1,233.66,234.43,1,105,1,2,233.58,234.5,505,63,2,4,233.53,234.59,10,60,1,1,233.5,234.75,100,1,1,1,AAPL,0,0,0,0,0,0,7,500,105,63,60,233.935
2024-10-21T12:27:50.065683975Z,2024-10-21 12:27:50.065517946+00:00,10,2,38,C,B,0,233.87,4,130,166029,13206394,233.86,234.0,295,17,3,2,233.81,234.1,2,100,2,1,233.8,234.13,105,400,2,1,233.78,234.17,400,1,1,1,233.7,234.25,1200,100,1,1,233.66,234.41,1,500,1,1,233.58,234.43,505,105,2,2,233.53,234.5,10,63,1,4,233.5,234.59,100,60,1,1,233.45,234.75,15,1,1,1,AAPL,-4,-4,-295,-2,-105,-400,-1200,-1,-505,-10,-100,233.93
2024-10-21T12:27:50.072777187Z,2024-10-21 12:27:50.072608485+00:00,10,2,38,T,N,0,233.92,250,0,168702,13206395,233.86,234.0,295,17,3,2,233.81,234.1,2,100,2,1,233.8,234.13,105,400,2,1,233.78,234.17,400,1,1,1,233.7,234.25,1200,100,1,1,233.66,234.41,1,500,1,1,233.58,234.43,505,105,2,2,233.53,234.5,10,63,1,4,233.5,234.59,100,60,1,1,233.45,234.75,15,1,1,1,AAPL,0,0,0,0,0,0,0,0,0,0,0,233.93
2024-10-21T12:27:50.072777187Z,2024-10-21 12:27:50.072608485+00:00,10,2,38,T,N,0,233.87,73,130,168702,13206396,233.86,234.0,295,17,3,2,233.81,234.1,2,100,2,1,233.8,234.13,105,400,2,1,233.78,234.17,400,1,1,1,233.7,234.25,1200,100,1,1,233.66,234.41,1,500,1,1,233.58,234.43,505,105,2,2,233.53,234.5,10,63,1,4,233.5,234.59,100,60,1,1,233.45,234.75,15,1,1,1,AAPL,0,0,0,0,0,0,0,0,0,0,0,233.93
2024-10-21T12:27:50.167562575Z,2024-10-21 12:27:50.167395987+00:00,10,2,38,A,A,1,234.06,200,130,166588,13206479,233.86,234.0,295,17,3,2,233.81,234.06,2,200,2,1,233.8,234.1,105,100,2,1,233.78,234.13,400,400,1,1,233.7,234.17,1200,1,1,1,233.66,234.25,1,100,1,1,233.58,234.41,505,500,2,1,233.53,234.43,10,105,1,2,233.5,234.5,100,63,1,4,233.45,234.59,15,60,1,1,AAPL,0,0,200,100,400,1,100,500,105,63,60,233.93
2024-10-21T12:27:51.736371710Z,2024-10-21 12:27:51.736205355+00:00,10,2,38,A,A,1,234.06,200,130,166355,13207413,233.86,234.0,295,17,3,2,233.81,234.06,2,400,2,2,233.8,234.1,105,100,2,1,233.78,234.13,400,400,1,1,233.7,234.17,1200,1,1,1,233.66,234.25,1,100,1,1,233.58,234.41,505,500,2,1,233.53,234.43,10,105,1,2,233.5,234.5,100,63,1,4,233.45,234.59,15,60,1,1,AAPL,0,0,200,0,0,0,0,0,0,0,0,233.93
2024-10-21T12:27:51.790967984Z,2024-10-21 12:27:51.790801843+00:00,10,2,38,C,A,1,234.06,200,130,166141,13207602,233.86,234.0,295,17,3,2,233.81,234.06,2,200,2,1,233.8,234.1,105,100,2,1,233.78,234.13,400,400,1,1,233.7,234.17,1200,1,1,1,233.66,234.25,1,100,1,1,233.58,234.41,505,500,2,1,233.53,234.43,10,105,1,2,233.5,234.5,100,63,1,4,233.45,234.59,15,60,1,1,AAPL,0,0,-200,0,0,0,0,0,0,0,0,233.93
2024-10-21T12:27:51.790980861Z,2024-10-21 12:27:51.790814229+00:00,10,2,38,A,A,1,234.05,200,130,166632,13207603,233.86,234.0,295,17,3,2,233.81,234.05,2,200,2,1,233.8,234.1,105,100,2,1,233.78,234.13,400,400,1,1,233.7,234.17,1200,1,1,1,233.66,234.25,1,100,1,1,233.58,234.41,505,500,2,1,233.53,234.43,10,105,1,2,233.5,234.5,100,63,1,4,233.45,234.59,15,60,1,1,AAPL,0,0,200,0,0,0,0,0,0,0,0,233.93
2024-10-21T12:27:52.065722099Z,2024-10-21 12:27:52.065555514+00:00,10,2,38,A,A,6,234.41,7,130,166585,13207879,233.86,234.0,295,17,3,2,233.81,234.05,2,200,2,1,233.8,234.1,105,100,2,1,233.78,234.13,400,400,1,1,233.7,234.17,1200,1,1,1,233.66,234.25,1,100,1,1,233.58,234.41,505,507,2,2,233.53,234.43,10,105,1,2,233.5,234.5,100,63,1,4,233.45,234.59,15,60,1,1,AAPL,0,0,0,0,0,0,0,7,0,0,0,233.93
2024-10-21T12:27:52.393306163Z,2024-10-21 12:27:52.393140055+00:00,10,2,38,A,B,0,233.91,100,130,166108,13208151,233.91,234.0,100,17,1,2,233.86,234.05,295,200,3,1,233.81,234.1,2,100,2,1,233.8,234.13,105,400,2,1,233.78,234.17,400,1,1,1,233.7,234.25,1200,100,1,1,233.66,234.41,1,507,1,2,233.58,234.43,505,105,2,2,233.53,234.5,10,63,1,4,233.5,234.59,100,60,1,1,AAPL,100,100,295,2,105,400,1200,1,505,10,100,233.95499999999998
2024-10-21T12:27:52.393974163Z,2024-10-21 12:27:52.393807534+00:00,10,2,38,C,B,0,233.91,100,130,166629,13208153,233.86,234.0,295,17,3,2,233.81,234.05,2,200,2,1,233.8,234.1,105,100,2,1,233.78,234.13,400,400,1,1,233.7,234.17,1200,1,1,1,233.66,234.25,1,100,1,1,233.58,234.41,505,507,2,2,233.53,234.43,10,105,1,2,233.5,234.5,100,63,1,4,233.45,234.59,15,60,1,1,AAPL,-100,-100,-295,-2,-105,-400,-1200,-1,-505,-10,-100,233.93
2024-10-21T12:27:53.197081371Z,2024-10-21 12:27:53.196914522+00:00,10,2,38,A,B,1,233.81,200,130,166849,13208530,233.86,234.0,295,17,3,2,233.81,234.05,202,200,3,1,233.8,234.1,105,100,2,1,233.7,234.13,1200,400,1,1,233.66,234.17,1,1,1,1,233.58,234.25,505,100,2,1,233.53,234.41,10,507,1,2,233.5,234.43,100,105,1,2,233.45,234.5,15,63,1,4,233.4,234.59,110,60,2,1,AAPL,0,0,200,0,-400,-1200,-1,-505,-10,-100,-15,233.93
2024-10-21T12:27:55.777527005Z,2024-10-21 12:27:55.777360755+00:00,10,2,38,A,B,1,233.82,200,130,166250,13210010,233.86,234.0,295,17,3,2,233.82,234.05,200,200,1,1,233.81,234.1,2,100,2,1,233.8,234.13,105,400,2,1,233.7,234.17,1200,1,1,1,233.66,234.25,1,100,1,1,233.58,234.41,505,507,2,2,233.53,234.43,10,105,1,2,233.5,234.5,100,63,1,4,233.45,234.59,15,60,1,1,AAPL,0,0,200,2,105,1200,1,505,10,100,15,233.93
2024-10-21T12:27:57.069810253Z,2024-10-21 12:27:57.069644133+00:00,10,2,38,C,A,6,234.41,7,130,166120,13211098,233.86,234.0,295,17,3,2,233.82,234.05,200,200,1,1,233.81,234.1,2,100,2,1,233.8,234.13,105,400,2,1,233.7,234.17,1200,1,1,1,233.66,234.25,1,100,1,1,233.58,234.41,505,500,2,1,233.53,234.43,10,105,1,2,233.5,234.5,100,63,1,4,233.45,234.59,15,60,1,1,AAPL,0,0,0,0,0,0,0,-7,0,0,0,233.93
2024-10-21T12:27:59.075099035Z,2024-10-21 12:27:59.074932933+00:00,10,2,38,A,A,2,234.08,7,130,166102,13212016,233.86,234.0,295,17,3,2,233.82,234.05,200,200,1,1,233.81,234.08,2,7,2,1,233.8,234.1,105,100,2,1,233.7,234.13,1200,400,1,1,233.66,234.17,1,1,1,1,233.58,234.25,505,100,2,1,233.53,234.41,10,500,1,1,233.5,234.43,100,105,1,2,233.45,234.5,15,63,1,4,AAPL,0,0,0,7,100,400,1,100,500,105,63,233.93
2024-10-21T12:28:13.140654755Z,2024-10-21 12:28:13.140488443+00:00,10,2,38,C,A,2,234.08,7,130,166312,13223358,233.86,234.0,295,17,3,2,233.82,234.05,200,200,1,1,233.81,234.1,2,100,2,1,233.8,234.13,105,400,2,1,233.7,234.17,1200,1,1,1,233.66,234.25,1,100,1,1,233.58,234.41,505,500,2,1,233.53,234.43,10,105,1,2,233.5,234.5,100,63,1,4,233.45,234.59,15,60,1,1,AAPL,0,0,0,7,100,400,1,100,500,105,63,233.93
2024-10-21T12:28:13.787785757Z,2024-10-21 12:28:13.787619066+00:00,10,2,38,C,B,0,233.86,100,130,166691,13223694,233.86,234.0,195,17,2,2,233.82,234.05,200,200,1,1,233.81,234.1,2,100,2,1,233.8,234.13,105,400,2,1,233.7,234.17,1200,1,1,1,233.66,234.25,1,100,1,1,233.58,234.41,505,500,2,1,233.53,234.43,10,105,1,2,233.5,234.5,100,63,1,4,233.45,234.59,15,60,1,1,AAPL,-100,-100,0,0,0,0,0,0,0,0,0,233.93
2024-10-21T12:28:15.143565718Z,2024-10-21 12:28:15.143399309+00:00,10,2,38,A,A,2,234.07,7,130,166409,13224881,233.86,234.0,195,17,2,2,233.82,234.05,200,200,1,1,233.81,234.07,2,7,2,1,233.8,234.1,105,100,2,1,233.7,234.13,1200,400,1,1,233.66,234.17,1,1,1,1,233.58,234.25,505,100,2,1,233.53,234.41,10,500,1,1,233.5,234.43,100,105,1,2,233.45,234.5,15,63,1,4,AAPL,0,0,0,7,100,400,1,100,500,105,63,233.93
2024-10-21T12:28:15.998678832Z,2024-10-21 12:28:15.998512488+00:00,10,2,38,A,A,1,234.05,200,130,166344,13225383,233.86,234.0,195,17,2,2,233.82,234.05,200,400,1,2,233.81,234.07,2,7,2,1,233.8,234.1,105,100,2,1,233.7,234.13,1200,400,1,1,233.66,234.17,1,1,1,1,233.58,234.25,505,100,2,1,233.53,234.41,10,500,1,1,233.5,234.43,100,105,1,2,233.45,234.5,15,63,1,4,AAPL,0,0,200,0,0,0,0,0,0,0,0,233.93
2024-10-21T12:28:16.004651224Z,2024-10-21 12:28:16.004484708+00:00,10,2,38,C,A,1,234.05,200,130,166516,13225389,233.86,234.0,195,17,2,2,233.82,234.05,200,200,1,1,233.81,234.07,2,7,2,1,233.8,234.1,105,100,2,1,233.7,234.13,1200,400,1,1,233.66,234.17,1,1,1,1,233.58,234.25,505,100,2,1,233.53,234.41,10,500,1,1,233.5,234.43,100,105,1,2,233.45,234.5,15,63,1,4,AAPL,0,0,-200,0,0,0,0,0,0,0,0,233.93
2024-10-21T12:28:16.009541505Z,2024-10-21 12:28:16.009375121+00:00,10,2,38,A,A,1,234.05,200,130,166384,13225390,233.86,234.0,195,17,2,2,233.82,234.05,200,400,1,2,233.81,234.07,2,7,2,1,233.8,234.1,105,100,2,1,233.7,234.13,1200,400,1,1,233.66,234.17,1,1,1,1,233.58,234.25,505,100,2,1,233.53,234.41,10,500,1,1,233.5,234.43,100,105,1,2,233.45,234.5,15,63,1,4,AAPL,0,0,200,0,0,0,0,0,0,0,0,233.93
2024-10-21T12:28:18.439960157Z,2024-10-21 12:28:18.439793678+00:00,10,2,38,C,B,1,233.82,200,130,166479,13226392,233.86,234.0,195,17,2,2,233.81,234.05,2,400,2,2,233.8,234.07,105,7,2,1,233.7,234.1,1200,100,1,1,233.66,234.13,1,400,1,1,233.58,234.17,505,1,2,1,233.53,234.25,10,100,1,1,233.5,234.41,100,500,1,1,233.45,234.43,15,105,1,2,233.4,234.5,110,63,2,4,AAPL,0,0,-200,-2,-105,-1200,-1,-505,-10,-100,-15,233.93
2024-10-21T12:28:18.439973348Z,2024-10-21 12:28:18.439806868+00:00,10,2,38,A,B,3,233.77,400,130,166480,13226393,233.86,234.0,195,17,2,2,233.81,234.05,2,400,2,2,233.8,234.07,105,7,2,1,233.77,234.1,400,100,1,1,233.7,234.13,1200,400,1,1,233.66,234.17,1,1,1,1,233.58,234.25,505,100,2,1,233.53,234.41,10,500,1,1,233.5,234.43,100,105,1,2,233.45,234.5,15,63,1,4,AAPL,0,0,0,0,400,1200,1,505,10,100,15,233.93
2024-10-21T12:28:18.595699607Z,2024-10-21 12:28:18.595532956+00:00,10,2,38,A,B,3,233.78,400,130,166651,13226507,233.86,234.0,195,17,2,2,233.81,234.05,2,400,2,2,233.8,234.07,105,7,2,1,233.78,234.1,400,100,1,1,233.7,234.13,1200,400,1,1,233.66,234.17,1,1,1,1,233.58,234.25,505,100,2,1,233.53,234.41,10,500,1,1,233.5,234.43,100,105,1,2,233.45,234.5,15,63,1,4,AAPL,0,0,0,0,400,0,0,0,0,0,0,233.93
2024-10-21T12:28:21.754746040Z,2024-10-21 12:28:21.754579574+00:00,10,2,38,C,A,1,234.05,200,130,166466,13230028,233.86,234.0,195,17,2,2,233.81,234.05,2,200,2,1,233.8,234.07,105,7,2,1,233.78,234.1,400,100,1,1,233.7,234.13,1200,400,1,1,233.66,234.17,1,1,1,1,233.58,234.25,505,100,2,1,233.53,234.41,10,500,1,1,233.5,234.43,100,105,1,2,233.45,234.5,15,63,1,4,AAPL,0,0,-200,0,0,0,0,0,0,0,0,233.93
2024-10-21T12:28:21.754755709Z,2024-10-21 12:28:21.754589712+00:00,10,2,38,C,A,1,234.05,200,130,165997,13230029,233.86,234.0,195,17,2,2,233.81,234.07,2,7,2,1,233.8,234.1,105,100,2,1,233.78,234.13,400,400,1,1,233.7,234.17,1200,1,1,1,233.66,234.25,1,100,1,1,233.58,234.41,505,500,2,1,233.53,234.43,10,105,1,2,233.5,234.5,100,63,1,4,233.45,234.59,15,60,1,1,AAPL,0,0,200,7,100,400,1,100,500,105,63,233.93
2024-10-21T12:28:21.754767171Z,2024-10-21 12:28:21.754600821+00:00,10,2,38,A,A,1,234.07,400,130,166350,13230030,233.86,234.0,195,17,2,2,233.81,234.07,2,407,2,2,233.8,234.1,105,100,2,1,233.78,234.13,400,400,1,1,233.7,234.17,1200,1,1,1,233.66,234.25,1,100,1,1,233.58,234.41,505,500,2,1,233.53,234.43,10,105,1,2,233.5,234.5,100,63,1,4,233.45,234.59,15,60,1,1,AAPL,0,0,400,0,0,0,0,0,0,0,0,233.93
2024-10-21T12:28:21.805412137Z,2024-10-21 12:28:21.805245495+00:00,10,2,38,A,B,3,233.79,400,130,166642,13230137,233.86,234.0,195,17,2,2,233.81,234.07,2,407,2,2,233.8,234.1,105,100,2,1,233.79,234.13,400,400,1,1,233.7,234.17,1200,1,1,1,233.66,234.25,1,100,1,1,233.58,234.41,505,500,2,1,233.53,234.43,10,105,1,2,233.5,234.5,100,63,1,4,233.45,234.59,15,60,1,1,AAPL,0,0,0,0,400,0,0,0,0,0,0,233.93
2024-10-21T12:28:21.865391217Z,2024-10-21 12:28:21.865225042+00:00,10,2,38,C,B,3,233.79,200,130,166175,13230295,233.86,234.0,195,17,2,2,233.81,234.07,2,407,2,2,233.8,234.1,105,100,2,1,233.79,234.13,200,400,1,1,233.7,234.17,1200,1,1,1,233.66,234.25,1,100,1,1,233.58,234.41,505,500,2,1,233.53,234.43,10,105,1,2,233.5,234.5,100,63,1,4,233.45,234.59,15,60,1,1,AAPL,0,0,0,0,-200,0,0,0,0,0,0,233.93
2024-10-21T12:28:32.979289251Z,2024-10-21 12:28:32.979122877+00:00,10,2,38,A,B,2,233.8,200,130,166374,13238520,233.86,234.0,195,17,2,2,233.81,234.07,2,407,2,2,233.8,234.1,305,100,3,1,233.7,234.13,1200,400,1,1,233.66,234.17,1,1,1,1,233.58,234.25,505,100,2,1,233.53,234.41,10,500,1,1,233.5,234.43,100,105,1,2,233.45,234.5,15,63,1,4,233.4,234.59,110,60,2,1,AAPL,0,0,0,200,-200,-1200,-1,-505,-10,-100,-15,233.93
2024-10-21T12:28:35.114875495Z,2024-10-21 12:28:35.114709429+00:00,10,2,38,C,B,2,233.8,200,130,166066,13241058,233.86,234.0,195,17,2,2,233.81,234.07,2,407,2,2,233.8,234.1,105,100,2,1,233.7,234.13,1200,400,1,1,233.66,234.17,1,1,1,1,233.58,234.25,505,100,2,1,233.53,234.41,10,500,1,1,233.5,234.43,100,105,1,2,233.45,234.5,15,63,1,4,233.4,234.59,110,60,2,1,AAPL,0,0,0,-200,0,0,0,0,0,0,0,233.93
2024-10-21T12:28:35.114888161Z,2024-10-21 12:28:35.114721686+00:00,10,2,38,A,B,3,233.78,200,130,166475,13241059,233.86,234.0,195,17,2,2,233.81,234.07,2,407,2,2,233.8,234.1,105,100,2,1,233.78,234.13,200,400,1,1,233.7,234.17,1200,1,1,1,233.66,234.25,1,100,1,1,233.58,234.41,505,500,2,1,233.53,234.43,10,105,1,2,233.5,234.5,100,63,1,4,233.45,234.59,15,60,1,1,AAPL,0,0,0,0,200,1200,1,505,10,100,15,233.93
2024-10-21T12:28:35.213164931Z,2024-10-21 12:28:35.212998331+00:00,10,2,38,A,A,1,234.06,400,130,166600,13241339,233.86,234.0,195,17,2,2,233.81,234.06,2,400,2,1,233.8,234.07,105,7,2,1,233.78,234.1,200,100,1,1,233.7,234.13,1200,400,1,1,233.66,234.17,1,1,1,1,233.58,234.25,505,100,2,1,233.53,234.41,10,500,1,1,233.5,234.43,100,105,1,2,233.45,234.5,15,63,1,4,AAPL,0,0,400,7,100,400,1,100,500,105,63,233.93
2024-10-21T12:28:35.345220081Z,2024-10-21 12:28:35.345053997+00:00,10,2,38,A,B,3,233.78,200,130,166084,13241459,233.86,234.0,195,17,2,2,233.81,234.06,2,400,2,1,233.8,234.07,105,7,2,1,233.78,234.1,400,100,2,1,233.7,234.13,1200,400,1,1,233.66,234.17,1,1,1,1,233.58,234.25,505,100,2,1,233.53,234.41,10,500,1,1,233.5,234.43,100,105,1,2,233.45,234.5,15,63,1,4,AAPL,0,0,0,0,200,0,0,0,0,0,0,233.93
2024-10-21T12:28:42.162258578Z,2024-10-21 12:28:42.162092040+00:00,10,2,38,C,B,3,233.78,200,130,166538,13247773,233.86,234.0,195,17,2,2,233.81,234.06,2,400,2,1,233.8,234.07,105,7,2,1,233.78,234.1,200,100,1,1,233.7,234.13,1200,400,1,1,233.66,234.17,1,1,1,1,233.58,234.25,505,100,2,1,233.53,234.41,10,500,1,1,233.5,234.43,100,105,1,2,233.45,234.5,15,63,1,4,AAPL,0,0,0,0,-200,0,0,0,0,0,0,233.93
2024-10-21T12:28:42.162271836Z,2024-10-21 12:28:42.162105350+00:00,10,2,38,A,B,1,233.82,200,130,166486,13247774,233.86,234.0,195,17,2,2,233.82,234.06,200,400,1,1,233.81,234.07,2,7,2,1,233.8,234.1,105,100,2,1,233.7,234.13,1200,400,1,1,233.66,234.17,1,1,1,1,233.58,234.25,505,100,2,1,233.53,234.41,10,500,1,1,233.5,234.43,100,105,1,2,233.45,234.5,15,63,1,4,AAPL,0,0,200,2,105,0,0,0,0,0,0,233.93
2024-10-21T12:28:45.429450324Z,2024-10-21 12:28:45.429284120+00:00,10,2,38,C,B,1,233.82,200,130,166204,13250330,233.86,234.0,195,17,2,2,233.81,234.06,2,400,2,1,233.8,234.07,105,7,2,1,233.7,234.1,1200,100,1,1,233.66,234.13,1,400,1,1,233.58,234.17,505,1,2,1,233.53,234.25,10,100,1,1,233.5,234.41,100,500,1,1,233.45,234.43,15,105,1,2,233.4,234.5,110,63,2,4,AAPL,0,0,-200,-2,-105,-1200,-1,-505,-10,-100,-15,233.93
2024-10-21T12:28:45.429463288Z,2024-10-21 12:28:45.429297045+00:00,10,2,38,A,B,3,233.78,400,130,166243,13250331,233.86,234.0,195,17,2,2,233.81,234.06,2,400,2,1,233.8,234.07,105,7,2,1,233.78,234.1,400,100,1,1,233.7,234.13,1200,400,1,1,233.66,234.17,1,1,1,1,233.58,234.25,505,100,2,1,233.53,234.41,10,500,1,1,233.5,234.43,100,105,1,2,233.45,234.5,15,63,1,4,AAPL,0,0,0,0,400,1200,1,505,10,100,15,233.93
2024-10-21T12:28:48.483286864Z,2024-10-21 12:28:48.483119828+00:00,10,2,38,A,B,1,233.82,200,130,167036,13252635,233.86,234.0,195,17,2,2,233.82,234.06,200,400,1,1,233.81,234.07,2,7,2,1,233.8,234.1,105,100,2,1,233.7,234.13,1200,400,1,1,233.66,234.17,1,1,1,1,233.58,234.25,505,100,2,1,233.53,234.41,10,500,1,1,233.5,234.43,100,105,1,2,233.45,234.5,15,63,1,4,AAPL,0,0,200,2,105,0,0,0,0,0,0,233.93
2024-10-21T12:28:55.560984753Z,2024-10-21 12:28:55.560815833+00:00,10,2,38,T,A,0,233.86,10,0,168920,13258219,233.86,234.0,195,17,2,2,233.82,234.06,200,400,1,1,233.81,234.07,2,7,2,1,233.8,234.1,105,100,2,1,233.7,234.13,1200,400,1,1,233.66,234.17,1,1,1,1,233.58,234.25,505,100,2,1,233.53,234.41,10,500,1,1,233.5,234.43,100,105,1,2,233.45,234.5,15,63,1,4,AAPL,0,0,0,0,0,0,0,0,0,0,0,233.93
2024-10-21T12:28:55.560984753Z,2024-10-21 12:28:55.560817191+00:00,10,2,38,A,N,0,233.9,100,130,167562,13258220,233.86,233.9,185,100,2,1,233.82,234.0,200,17,1,2,233.81,234.06,2,400,2,1,233.8,234.07,105,7,2,1,233.7,234.1,1200,100,1,1,233.66,234.13,1,400,1,1,233.58,234.17,505,1,2,1,233.53,234.25,10,100,1,1,233.5,234.41,100,500,1,1,233.45,234.43,15,105,1,2,AAPL,90,90,17,400,7,100,400,1,100,500,105,233.88
2024-10-21T12:28:55.561007655Z,2024-10-21 12:28:55.560841422+00:00,10,2,38,A,A,0,233.9,100,130,166233,13258221,233.86,233.9,185,200,2,2,233.82,234.0,200,17,1,2,233.81,234.06,2,400,2,1,233.8,234.07,105,7,2,1,233.7,234.1,1200,100,1,1,233.66,234.13,1,400,1,1,233.58,234.17,505,1,2,1,233.53,234.25,10,100,1,1,233.5,234.41,100,500,1,1,233.45,234.43,15,105,1,2,AAPL,100,100,0,0,0,0,0,0,0,0,0,233.88
2024-10-21T12:28:55.561058773Z,2024-10-21 12:28:55.560892756+00:00,10,2,38,C,B,1,233.82,200,130,166017,13258225,233.86,233.9,185,200,2,2,233.81,234.0,2,17,2,2,233.8,234.06,105,400,2,1,233.7,234.07,1200,7,1,1,233.66,234.1,1,100,1,1,233.58,234.13,505,400,2,1,233.53,234.17,10,1,1,1,233.5,234.25,100,100,1,1,233.45,234.41,15,500,1,1,233.4,234.43,110,105,2,2,AAPL,0,0,-200,-2,-105,-1200,-1,-505,-10,-100,-15,233.88
2024-10-21T12:28:55.561286132Z,2024-10-21 12:28:55.561120579+00:00,10,2,38,C,A,0,233.9,100,130,165553,13258227,233.86,233.9,185,100,2,1,233.81,234.0,2,17,2,2,233.8,234.06,105,400,2,1,233.7,234.07,1200,7,1,1,233.66,234.1,1,100,1,1,233.58,234.13,505,400,2,1,233.53,234.17,10,1,1,1,233.5,234.25,100,100,1,1,233.45,234.41,15,500,1,1,233.4,234.43,110,105,2,2,AAPL,-100,-100,0,0,0,0,0,0,0,0,0,233.88
2024-10-21T12:28:55.561361290Z,2024-10-21 12:28:55.561195478+00:00,10,2,38,C,A,0,233.9,100,130,165812,13258228,233.86,234.0,185,17,2,2,233.81,234.06,2,400,2,1,233.8,234.07,105,7,2,1,233.7,234.1,1200,100,1,1,233.66,234.13,1,400,1,1,233.58,234.17,505,1,2,1,233.53,234.25,10,100,1,1,233.5,234.41,100,500,1,1,233.45,234.43,15,105,1,2,233.4,234.5,110,63,2,4,AAPL,100,100,17,400,7,100,400,1,100,500,105,233.93
2024-10-21T12:28:55.562326440Z,2024-10-21 12:28:55.562160475+00:00,10,2,38,C,A,2,234.07,7,130,165965,13258230,233.86,234.0,185,17,2,2,233.81,234.06,2,400,2,1,233.8,234.1,105,100,2,1,233.7,234.13,1200,400,1,1,233.66,234.17,1,1,1,1,233.58,234.25,505,100,2,1,233.53,234.41,10,500,1,1,233.5,234.43,100,105,1,2,233.45,234.5,15,63,1,4,233.4,234.59,110,60,2,1,AAPL,0,0,0,7,100,400,1,100,500,105,63,233.93
2024-10-21T12:28:55.639858396Z,2024-10-21 12:28:55.639691686+00:00,10,2,38,A,B,3,233.72,400,130,166710,13258325,233.86,234.0,185,17,2,2,233.81,234.06,2,400,2,1,233.8,234.1,105,100,2,1,233.72,234.13,400,400,1,1,233.7,234.17,1200,1,1,1,233.66,234.25,1,100,1,1,233.58,234.41,505,500,2,1,233.53,234.43,10,105,1,2,233.5,234.5,100,63,1,4,233.45,234.59,15,60,1,1,AAPL,0,0,0,0,400,1200,1,505,10,100,15,233.93
2024-10-21T12:28:55.964596099Z,2024-10-21 12:28:55.964429174+00:00,10,2,38,A,B,3,233.75,200,130,166925,13258541,233.86,234.0,185,17,2,2,233.81,234.06,2,400,2,1,233.8,234.1,105,100,2,1,233.75,234.13,200,400,1,1,233.7,234.17,1200,1,1,1,233.66,234.25,1,100,1,1,233.58,234.41,505,500,2,1,233.53,234.43,10,105,1,2,233.5,234.5,100,63,1,4,233.45,234.59,15,60,1,1,AAPL,0,0,0,0,200,0,0,0,0,0,0,233.93
2024-10-21T12:28:56.442773675Z,2024-10-21 12:28:56.442607241+00:00,10,2,38,A,A,1,234.05,400,130,166434,13258927,233.86,234.0,185,17,2,2,233.81,234.05,2,400,2,1,233.8,234.1,105,100,2,1,233.75,234.13,200,400,1,1,233.7,234.17,1200,1,1,1,233.66,234.25,1,100,1,1,233.58,234.41,505,500,2,1,233.53,234.43,10,105,1,2,233.5,234.5,100,63,1,4,233.45,234.59,15,60,1,1,AAPL,0,0,400,0,0,0,0,0,0,0,0,233.93
2024-10-21T12:28:57.565514672Z,2024-10-21 12:28:57.565348157+00:00,10,2,38,A,A,2,234.07,7,130,166515,13259953,233.86,234.0,185,17,2,2,233.81,234.05,2,400,2,1,233.8,234.07,105,7,2,1,233.75,234.1,200,100,1,1,233.7,234.13,1200,400,1,1,233.66,234.17,1,1,1,1,233.58,234.25,505,100,2,1,233.53,234.41,10,500,1,1,233.5,234.43,100,105,1,2,233.45,234.5,15,63,1,4,AAPL,0,0,0,7,100,400,1,100,500,105,63,233.93
2024-10-21T12:28:57.831005951Z,2024-10-21 12:28:57.830839869+00:00,10,2,38,A,A,1,234.01,200,130,166082,13260122,233.86,234.0,185,17,2,2,233.81,234.01,2,200,2,1,233.8,234.07,105,7,2,1,233.75,234.1,200,100,1,1,233.7,234.13,1200,400,1,1,233.66,234.17,1,1,1,1,233.58,234.25,505,100,2,1,233.53,234.41,10,500,1,1,233.5,234.43,100,105,1,2,233.45,234.5,15,63,1,4,AAPL,0,0,200,0,0,0,0,0,0,0,0,233.93
2024-10-21T12:28:57.891061549Z,2024-10-21 12:28:57.890894861+00:00,10,2,38,A,A,0,234.0,200,130,166688,13260139,233.86,234.0,185,217,2,3,233.81,234.07,2,7,2,1,233.8,234.1,105,100,2,1,233.75,234.13,200,400,1,1,233.7,234.17,1200,1,1,1,233.66,234.25,1,100,1,1,233.58,234.41,505,500,2,1,233.53,234.43,10,105,1,2,233.5,234.5,100,63,1,4,233.45,234.59,15,60,1,1,AAPL,200,200,200,7,100,400,1,100,500,105,63,233.93
2024-10-21T12:28:58.006126423Z,2024-10-21 12:28:58.005959828+00:00,10,2,38,A,A,0,233.99,200,130,166595,13260238,233.86,233.99,185,200,2,1,233.81,234.0,2,17,2,2,233.8,234.07,105,7,2,1,233.75,234.1,200,100,1,1,233.7,234.13,1200,400,1,1,233.66,234.17,1,1,1,1,233.58,234.25,505,100,2,1,233.53,234.41,10,500,1,1,233.5,234.43,100,105,1,2,233.45,234.5,15,63,1,4,AAPL,200,200,17,7,100,400,1,100,500,105,63,233.925
2024-10-21T12:28:58.694606149Z,2024-10-21 12:28:58.694439582+00:00,10,2,38,A,B,1,233.81,200,130,166567,13260587,233.86,233.99,185,200,2,1,233.81,234.0,202,17,3,2,233.8,234.07,105,7,2,1,233.7,234.1,1200,100,1,1,233.66,234.13,1,400,1,1,233.58,234.17,505,1,2,1,233.53,234.25,10,100,1,1,233.5,234.41,100,500,1,1,233.45,234.43,15,105,1,2,233.4,234.5,110,63,2,4,AAPL,0,0,200,0,-200,-1200,-1,-505,-10,-100,-15,233.925
2024-10-21T12:29:01.022290262Z,2024-10-21 12:29:01.022123658+00:00,10,2,38,C,B,1,233.81,200,130,166604,13262995,233.86,233.99,185,200,2,1,233.81,234.0,2,17,2,2,233.8,234.07,105,7,2,1,233.7,234.1,1200,100,1,1,233.66,234.13,1,400,1,1,233.58,234.17,505,1,2,1,233.53,234.25,10,100,1,1,233.5,234.41,100,500,1,1,233.45,234.43,15,105,1,2,233.4,234.5,110,63,2,4,AAPL,0,0,-200,0,0,0,0,0,0,0,0,233.925
2024-10-21T12:29:01.022303152Z,2024-10-21 12:29:01.022136915+00:00,10,2,38,A,B,3,233.76,400,130,166237,13262996,233.86,233.99,185,200,2,1,233.81,234.0,2,17,2,2,233.8,234.07,105,7,2,1,233.76,234.1,400,100,1,1,233.7,234.13,1200,400,1,1,233.66,234.17,1,1,1,1,233.58,234.25,505,100,2,1,233.53,234.41,10,500,1,1,233.5,234.43,100,105,1,2,233.45,234.5,15,63,1,4,AAPL,0,0,0,0,400,1200,1,505,10,100,15,233.925
2024-10-21T12:29:01.158549246Z,2024-10-21 12:29:01.158380499+00:00,10,2,38,T,A,0,233.86,85,0,168747,13263131,233.86,233.99,185,200,2,1,233.81,234.0,2,17,2,2,233.8,234.07,105,7,2,1,233.76,234.1,400,100,1,1,233.7,234.13,1200,400,1,1,233.66,234.17,1,1,1,1,233.58,234.25,505,100,2,1,233.53,234.41,10,500,1,1,233.5,234.43,100,105,1,2,233.45,234.5,15,63,1,4,AAPL,0,0,0,0,0,0,0,0,0,0,0,233.925
2024-10-21T12:29:01.158549246Z,2024-10-21 12:29:01.158380499+00:00,10,2,38,T,A,0,233.86,100,130,168747,13263132,233.86,233.99,100,200,1,1,233.81,234.0,2,17,2,2,233.8,234.07,105,7,2,1,233.76,234.1,400,100,1,1,233.7,234.13,1200,400,1,1,233.66,234.17,1,1,1,1,233.58,234.25,505,100,2,1,233.53,234.41,10,500,1,1,233.5,234.43,100,105,1,2,233.45,234.5,15,63,1,4,AAPL,-85,-85,0,0,0,0,0,0,0,0,0,233.925
2024-10-21T12:29:01.158549246Z,2024-10-21 12:29:01.158380499+00:00,10,2,38,C,B,0,233.86,100,130,168747,13263132,233.81,233.99,2,200,2,1,233.8,234.0,105,17,2,2,233.76,234.07,400,7,1,1,233.7,234.1,1200,100,1,1,233.66,234.13,1,400,1,1,233.58,234.17,505,1,2,1,233.53,234.25,10,100,1,1,233.5,234.41,100,500,1,1,233.45,234.43,15,105,1,2,233.4,234.5,110,63,2,4,AAPL,-100,-100,-2,-105,-400,-1200,-1,-505,-10,-100,-15,233.9
2024-10-21T12:29:01.158567848Z,2024-10-21 12:29:01.158396024+00:00,10,2,38,A,B,0,233.86,100,128,171824,13263141,233.86,233.99,100,200,1,1,233.81,234.0,2,17,2,2,233.8,234.07,105,7,2,1,233.76,234.1,400,100,1,1,233.7,234.13,1200,400,1,1,233.66,234.17,1,1,1,1,233.58,234.25,505,100,2,1,233.53,234.41,10,500,1,1,233.5,234.43,100,105,1,2,233.45,234.5,15,63,1,4,AAPL,100,100,2,105,400,1200,1,505,10,100,15,233.925
2024-10-21T12:29:01.158571366Z,2024-10-21 12:29:01.158404180+00:00,10,2,38,A,A,0,233.92,100,130,167186,13263148,233.86,233.92,100,100,1,1,233.81,233.99,2,200,2,1,233.8,234.0,105,17,2,2,233.76,234.07,400,7,1,1,233.7,234.1,1200,100,1,1,233.66,234.13,1,400,1,1,233.58,234.17,505,1,2,1,233.53,234.25,10,100,1,1,233.5,234.41,100,500,1,1,233.45,234.43,15,105,1,2,AAPL,100,100,200,17,7,100,400,1,100,500,105,233.89
2024-10-21T12:29:01.158576809Z,2024-10-21 12:29:01.158408745+00:00,10,2,38,A,A,1,233.96,100,128,168064,13263151,233.86,233.92,100,100,1,1,233.81,233.93,2,130,2,1,233.8,233.96,105,100,2,1,233.76,233.99,400,200,1,1,233.7,234.0,1200,17,1,2,233.66,234.07,1,7,1,1,233.58,234.1,505,100,2,1,233.53,234.13,10,400,1,1,233.5,234.17,100,1,1,1,233.45,234.25,15,100,1,1,AAPL,0,0,130,100,200,17,7,100,400,1,100,233.89
2024-10-21T12:29:01.158585584Z,2024-10-21 12:29:01.158418184+00:00,10,2,38,A,A,0,233.92,100,128,167400,13263156,233.86,233.92,100,200,1,2,233.81,233.93,2,130,2,1,233.8,233.96,105,100,2,1,233.76,233.99,400,200,1,1,233.7,234.0,1200,17,1,2,233.66,234.07,1,7,1,1,233.58,234.1,505,100,2,1,233.53,234.13,10,400,1,1,233.5,234.17,100,1,1,1,233.45,234.25,15,100,1,1,AAPL,100,100,0,0,0,0,0,0,0,0,0,233.89
2024-10-21T12:29:01.158586865Z,2024-10-21 12:29:01.158419809+00:00,10,2,38,A,A,2,233.96,100,130,167056,13263158,233.86,233.92,100,200,1,2,233.81,233.93,2,130,2,1,233.8,233.96,105,200,2,2,233.76,233.99,400,200,1,1,233.7,234.0,1200,17,1,2,233.66,234.07,1,7,1,1,233.58,234.1,505,100,2,1,233.53,234.13,10,400,1,1,233.5,234.17,100,1,1,1,233.45,234.25,15,100,1,1,AAPL,0,0,0,100,0,0,0,0,0,0,0,233.89
2024-10-21T12:29:01.158590064Z,2024-10-21 12:29:01.158423515+00:00,10,2,38,A,A,1,233.93,26,130,166549,13263160,233.86,233.92,100,200,1,2,233.81,233.93,2,156,2,2,233.8,233.96,105,200,2,2,233.76,233.99,400,200,1,1,233.7,234.0,1200,17,1,2,233.66,234.07,1,7,1,1,233.58,234.1,505,100,2,1,233.53,234.13,10,400,1,1,233.5,234.17,100,1,1,1,233.45,234.25,15,100,1,1,AAPL,0,0,26,0,0,0,0,0,0,0,0,233.89
2024-10-21T12:29:01.158592348Z,2024-10-21 12:29:01.158424717+00:00,10,2,38,T,A,0,233.86,100,0,167631,13263161,233.86,233.92,100,200,1,2,233.81,233.93,2,156,2,2,233.8,233.96,105,200,2,2,233.76,233.99,400,200,1,1,233.7,234.0,1200,17,1,2,233.66,234.07,1,7,1,1,233.58,234.1,505,100,2,1,233.53,234.13,10,400,1,1,233.5,234.17,100,1,1,1,233.45,234.25,15,100,1,1,AAPL,0,0,0,0,0,0,0,0,0,0,0,233.89
2024-10-21T12:29:01.158592348Z,2024-10-21 12:29:01.158424717+00:00,10,2,38,T,N,0,233.86,150,130,167631,13263162,233.81,233.92,2,200,2,2,233.8,233.93,105,156,2,2,233.76,233.96,400,200,1,2,233.7,233.99,1200,200,1,1,233.66,234.0,1,17,1,2,233.58,234.07,505,7,2,1,233.53,234.1,10,100,1,1,233.5,234.13,100,400,1,1,233.45,234.17,15,1,1,1,233.4,234.25,110,100,2,1,AAPL,-100,-100,-2,-105,-400,-1200,-1,-505,-10,-100,-15,233.865
2024-10-21T12:29:01.158594194Z,2024-10-21 12:29:01.158426997+00:00,10,2,38,T,N,0,233.86,50,0,167197,13263163,233.81,233.92,2,200,2,2,233.8,233.93,105,156,2,2,233.76,233.96,400,200,1,2,233.7,233.99,1200,200,1,1,233.66,234.0,1,17,1,2,233.58,234.07,505,7,2,1,233.53,234.1,10,100,1,1,233.5,234.13,100,400,1,1,233.45,234.17,15,1,1,1,233.4,234.25,110,100,2,1,AAPL,0,0,0,0,0,0,0,0,0,0,0,233.865
2024-10-21T12:29:01.158594194Z,2024-10-21 12:29:01.158427442+00:00,10,2,38,C,A,1,233.93,130,130,166752,13263164,233.81,233.92,2,200,2,2,233.8,233.93,105,26,2,1,233.76,233.96,400,200,1,2,233.7,233.99,1200,200,1,1,233.66,234.0,1,17,1,2,233.58,234.07,505,7,2,1,233.53,234.1,10,100,1,1,233.5,234.13,100,400,1,1,233.45,234.17,15,1,1,1,233.4,234.25,110,100,2,1,AAPL,0,0,-130,0,0,0,0,0,0,0,0,233.865
2024-10-21T12:29:01.158598557Z,2024-10-21 12:29:01.158431288+00:00,10,2,38,A,A,2,233.96,100,130,167269,13263165,233.81,233.92,2,200,2,2,233.8,233.93,105,26,2,1,233.76,233.96,400,300,1,3,233.7,233.99,1200,200,1,1,233.66,234.0,1,17,1,2,233.58,234.07,505,7,2,1,233.53,234.1,10,100,1,1,233.5,234.13,100,400,1,1,233.45,234.17,15,1,1,1,233.4,234.25,110,100,2,1,AAPL,0,0,0,100,0,0,0,0,0,0,0,233.865
2024-10-21T12:29:01.158601250Z,2024-10-21 12:29:01.158434916+00:00,10,2,38,A,B,0,233.86,100,130,166334,13263166,233.86,233.92,100,200,1,2,233.81,233.93,2,26,2,1,233.8,233.96,105,300,2,3,233.76,233.99,400,200,1,1,233.7,234.0,1200,17,1,2,233.66,234.07,1,7,1,1,233.58,234.1,505,100,2,1,233.53,234.13,10,400,1,1,233.5,234.17,100,1,1,1,233.45,234.25,15,100,1,1,AAPL,100,100,2,105,400,1200,1,505,10,100,15,233.89
2024-10-21T12:29:01.158603851Z,2024-10-21 12:29:01.158437825+00:00,10,2,38,A,A,3,233.97,26,130,166026,13263167,233.86,233.92,100,200,1,2,233.81,233.93,2,26,2,1,233.8,233.96,105,300,2,3,233.76,233.97,400,26,1,1,233.7,233.99,1200,200,1,1,233.66,234.0,1,17,1,2,233.58,234.07,505,7,2,1,233.53,234.1,10,100,1,1,233.5,234.13,100,400,1,1,233.45,234.17,15,1,1,1,AAPL,0,0,0,0,26,200,17,7,100,400,1,233.89
2024-10-21T12:29:01.158622043Z,2024-10-21 12:29:01.158453404+00:00,10,2,38,C,B,3,233.76,400,130,168639,13263171,233.86,233.92,100,200,1,2,233.81,233.93,2,26,2,1,233.8,233.96,105,300,2,3,233.7,233.97,1200,26,1,1,233.66,233.99,1,200,1,1,233.58,234.0,505,17,2,2,233.53,234.07,10,7,1,1,233.5,234.1,100,100,1,1,233.45,234.13,15,400,1,1,233.4,234.17,110,1,2,1,AAPL,0,0,0,0,-400,-1200,-1,-505,-10,-100,-15,233.89
2024-10-21T12:29:01.158626083Z,2024-10-21 12:29:01.158458726+00:00,10,2,38,C,A,0,233.92,100,128,167357,13263172,233.86,233.92,100,100,1,1,233.81,233.93,2,26,2,1,233.8,233.96,105,300,2,3,233.7,233.97,1200,26,1,1,233.66,233.99,1,200,1,1,233.58,234.0,505,17,2,2,233.53,234.07,10,7,1,1,233.5,234.1,100,100,1,1,233.45,234.13,15,400,1,1,233.4,234.17,110,1,2,1,AAPL,-100,-100,0,0,0,0,0,0,0,0,0,233.89
2024-10-21T12:29:01.158642773Z,2024-10-21 12:29:01.158475713+00:00,10,2,38,C,A,0,233.92,100,128,167060,13263180,233.86,233.93,100,26,1,1,233.81,233.96,2,300,2,3,233.8,233.97,105,26,2,1,233.7,233.99,1200,200,1,1,233.66,234.0,1,17,1,2,233.58,234.07,505,7,2,1,233.53,234.1,10,100,1,1,233.5,234.13,100,400,1,1,233.45,234.17,15,1,1,1,233.4,234.25,110,100,2,1,AAPL,100,100,26,300,26,200,17,7,100,400,1,233.895
2024-10-21T12:29:01.158651784Z,2024-10-21 12:29:01.158485485+00:00,10,2,38,A,A,0,233.91,26,130,166299,13263183,233.86,233.91,100,26,1,1,233.81,233.93,2,26,2,1,233.8,233.96,105,300,2,3,233.7,233.97,1200,26,1,1,233.66,233.99,1,200,1,1,233.58,234.0,505,17,2,2,233.53,234.07,10,7,1,1,233.5,234.1,100,100,1,1,233.45,234.13,15,400,1,1,233.4,234.17,110,1,2,1,AAPL,26,26,26,300,26,200,17,7,100,400,1,233.885
2024-10-21T12:29:01.158666241Z,2024-10-21 12:29:01.158498852+00:00,10,2,38,T,A,0,233.86,50,128,167389,13263184,233.86,233.91,100,26,1,1,233.81,233.93,2,26,2,1,233.8,233.96,105,300,2,3,233.7,233.97,1200,26,1,1,233.66,233.99,1,200,1,1,233.58,234.0,505,17,2,2,233.53,234.07,10,7,1,1,233.5,234.1,100,100,1,1,233.45,234.13,15,400,1,1,233.4,234.17,110,1,2,1,AAPL,0,0,0,0,0,0,0,0,0,0,0,233.885
2024-10-21T12:29:01.158666241Z,2024-10-21 12:29:01.158498852+00:00,10,2,38,C,B,0,233.86,50,128,167389,13263184,233.86,233.91,50,26,1,1,233.81,233.93,2,26,2,1,233.8,233.96,105,300,2,3,233.7,233.97,1200,26,1,1,233.66,233.99,1,200,1,1,233.58,234.0,505,17,2,2,233.53,234.07,10,7,1,1,233.5,234.1,100,100,1,1,233.45,234.13,15,400,1,1,233.4,234.17,110,1,2,1,AAPL,-50,-50,0,0,0,0,0,0,0,0,0,233.885
2024-10-21T12:29:01.158674864Z,2024-10-21 12:29:01.158508412+00:00,10,2,38,A,B,0,233.86,100,130,166452,13263188,233.86,233.91,150,26,2,1,233.81,233.93,2,26,2,1,233.8,233.96,105,300,2,3,233.7,233.97,1200,26,1,1,233.66,233.99,1,200,1,1,233.58,234.0,505,17,2,2,233.53,234.07,10,7,1,1,233.5,234.1,100,100,1,1,233.45,234.13,15,400,1,1,233.4,234.17,110,1,2,1,AAPL,100,100,0,0,0,0,0,0,0,0,0,233.885
2024-10-21T12:29:01.158688501Z,2024-10-21 12:29:01.158520941+00:00,10,2,38,T,A,0,233.86,50,0,167560,13263189,233.86,233.91,150,26,2,1,233.81,233.93,2,26,2,1,233.8,233.96,105,300,2,3,233.7,233.97,1200,26,1,1,233.66,233.99,1,200,1,1,233.58,234.0,505,17,2,2,233.53,234.07,10,7,1,1,233.5,234.1,100,100,1,1,233.45,234.13,15,400,1,1,233.4,234.17,110,1,2,1,AAPL,0,0,0,0,0,0,0,0,0,0,0,233.885
2024-10-21T12:29:01.158688501Z,2024-10-21 12:29:01.158520941+00:00,10,2,38,T,A,0,233.86,50,130,167560,13263190,233.86,233.91,100,26,1,1,233.81,233.93,2,26,2,1,233.8,233.96,105,300,2,3,233.7,233.97,1200,26,1,1,233.66,233.99,1,200,1,1,233.58,234.0,505,17,2,2,233.53,234.07,10,7,1,1,233.5,234.1,100,100,1,1,233.45,234.13,15,400,1,1,233.4,234.17,110,1,2,1,AAPL,-50,-50,0,0,0,0,0,0,0,0,0,233.885
2024-10-21T12:29:01.158688501Z,2024-10-21 12:29:01.158520941+00:00,10,2,38,C,B,0,233.86,50,130,167560,13263190,233.86,233.91,50,26,1,1,233.81,233.93,2,26,2,1,233.8,233.96,105,300,2,3,233.7,233.97,1200,26,1,1,233.66,233.99,1,200,1,1,233.58,234.0,505,17,2,2,233.53,234.07,10,7,1,1,233.5,234.1,100,100,1,1,233.45,234.13,15,400,1,1,233.4,234.17,110,1,2,1,AAPL,-50,-50,0,0,0,0,0,0,0,0,0,233.885
2024-10-21T12:29:01.158696696Z,2024-10-21 12:29:01.158530490+00:00,10,2,38,C,A,2,233.96,100,130,166206,13263192,233.86,233.91,50,26,1,1,233.81,233.93,2,26,2,1,233.8,233.96,105,200,2,2,233.7,233.97,1200,26,1,1,233.66,233.99,1,200,1,1,233.58,234.0,505,17,2,2,233.53,234.07,10,7,1,1,233.5,234.1,100,100,1,1,233.45,234.13,15,400,1,1,233.4,234.17,110,1,2,1,AAPL,0,0,0,-100,0,0,0,0,0,0,0,233.885
2024-10-21T12:29:01.158698384Z,2024-10-21 12:29:01.158531815+00:00,10,2,38,C,B,0,233.96,100,130,166569,13263194,233.86,233.91,150,26,2,1,233.81,233.93,2,26,2,1,233.8,233.96,105,100,2,1,233.7,233.97,1200,26,1,1,233.66,233.99,1,200,1,1,233.58,234.0,505,17,2,2,233.53,234.07,10,7,1,1,233.5,234.1,100,100,1,1,233.45,234.13,15,400,1,1,233.4,234.17,110,1,2,1,AAPL,100,100,0,-100,0,0,0,0,0,0,0,233.885
2024-10-21T12:29:01.158723924Z,2024-10-21 12:29:01.158554739+00:00,10,2,38,T,A,0,233.86,50,128,169185,13263197,233.86,233.91,150,26,2,1,233.81,233.93,2,26,2,1,233.8,233.96,105,100,2,1,233.7,233.97,1200,26,1,1,233.66,233.99,1,200,1,1,233.58,234.0,505,17,2,2,233.53,234.07,10,7,1,1,233.5,234.1,100,100,1,1,233.45,234.13,15,400,1,1,233.4,234.17,110,1,2,1,AAPL,0,0,0,0,0,0,0,0,0,0,0,233.885
2024-10-21T12:29:01.158723924Z,2024-10-21 12:29:01.158554739+00:00,10,2,38,C,B,0,233.86,50,128,169185,13263197,233.86,233.91,100,26,1,1,233.81,233.93,2,26,2,1,233.8,233.96,105,100,2,1,233.7,233.97,1200,26,1,1,233.66,233.99,1,200,1,1,233.58,234.0,505,17,2,2,233.53,234.07,10,7,1,1,233.5,234.1,100,100,1,1,233.45,234.13,15,400,1,1,233.4,234.17,110,1,2,1,AAPL,-50,-50,0,0,0,0,0,0,0,0,0,233.885
2024-10-21T12:29:01.159002676Z,2024-10-21 12:29:01.158835732+00:00,10,2,38,C,A,2,233.96,100,130,166944,13263231,233.86,233.91,100,26,1,1,233.81,233.93,2,26,2,1,233.8,233.97,105,26,2,1,233.7,233.99,1200,200,1,1,233.66,234.0,1,17,1,2,233.58,234.07,505,7,2,1,233.53,234.1,10,100,1,1,233.5,234.13,100,400,1,1,233.45,234.17,15,1,1,1,233.4,234.25,110,100,2,1,AAPL,0,0,0,100,26,200,17,7,100,400,1,233.885
2024-10-21T12:29:01.260977964Z,2024-10-21 12:29:01.260812083+00:00,10,2,38,C,A,2,233.97,26,130,165881,13263664,233.86,233.91,100,26,1,1,233.81,233.93,2,26,2,1,233.8,233.99,105,200,2,1,233.7,234.0,1200,17,1,2,233.66,234.07,1,7,1,1,233.58,234.1,505,100,2,1,233.53,234.13,10,400,1,1,233.5,234.17,100,1,1,1,233.45,234.25,15,100,1,1,233.4,234.41,110,500,2,1,AAPL,0,0,0,26,200,17,7,100,400,1,100,233.885
2024-10-21T12:29:01.260986860Z,2024-10-21 12:29:01.260820985+00:00,10,2,38,C,A,0,233.91,26,130,165875,13263665,233.86,233.93,100,26,1,1,233.81,233.99,2,200,2,1,233.8,234.0,105,17,2,2,233.7,234.07,1200,7,1,1,233.66,234.1,1,100,1,1,233.58,234.13,505,400,2,1,233.53,234.17,10,1,1,1,233.5,234.25,100,100,1,1,233.45,234.41,15,500,1,1,233.4,234.43,110,105,2,2,AAPL,26,26,26,200,17,7,100,400,1,100,500,233.895
2024-10-21T12:29:01.261039132Z,2024-10-21 12:29:01.260872777+00:00,10,2,38,A,B,3,233.74,200,130,166355,13263667,233.86,233.93,100,26,1,1,233.81,233.99,2,200,2,1,233.8,234.0,105,17,2,2,233.74,234.07,200,7,1,1,233.7,234.1,1200,100,1,1,233.66,234.13,1,400,1,1,233.58,234.17,505,1,2,1,233.53,234.25,10,100,1,1,233.5,234.41,100,500,1,1,233.45,234.43,15,105,1,2,AAPL,0,0,0,0,200,1200,1,505,10,100,15,233.895
2024-10-21T12:29:01.411202852Z,2024-10-21 12:29:01.411037140+00:00,10,2,38,C,A,0,233.93,26,130,165712,13264096,233.86,233.99,100,200,1,1,233.81,234.0,2,17,2,2,233.8,234.07,105,7,2,1,233.74,234.1,200,100,1,1,233.7,234.13,1200,400,1,1,233.66,234.17,1,1,1,1,233.58,234.25,505,100,2,1,233.53,234.41,10,500,1,1,233.5,234.43,100,105,1,2,233.45,234.5,15,63,1,4,AAPL,26,26,200,17,7,100,400,1,100,500,105,233.925
2024-10-21T12:29:01.477305998Z,2024-10-21 12:29:01.477138444+00:00,10,2,38,T,A,0,233.86,50,130,167554,13264991,233.86,233.99,100,200,1,1,233.81,234.0,2,17,2,2,233.8,234.07,105,7,2,1,233.74,234.1,200,100,1,1,233.7,234.13,1200,400,1,1,233.66,234.17,1,1,1,1,233.58,234.25,505,100,2,1,233.53,234.41,10,500,1,1,233.5,234.43,100,105,1,2,233.45,234.5,15,63,1,4,AAPL,0,0,0,0,0,0,0,0,0,0,0,233.925
2024-10-21T12:29:01.477305998Z,2024-10-21 12:29:01.477138444+00:00,10,2,38,C,B,0,233.86,50,130,167554,13264991,233.86,233.99,50,200,1,1,233.81,234.0,2,17,2,2,233.8,234.07,105,7,2,1,233.74,234.1,200,100,1,1,233.7,234.13,1200,400,1,1,233.66,234.17,1,1,1,1,233.58,234.25,505,100,2,1,233.53,234.41,10,500,1,1,233.5,234.43,100,105,1,2,233.45,234.5,15,63,1,4,AAPL,-50,-50,0,0,0,0,0,0,0,0,0,233.925
2024-10-21T12:29:01.477315667Z,2024-10-21 12:29:01.477149422+00:00,10,2,38,A,B,0,233.86,100,130,166245,13264992,233.86,233.99,150,200,2,1,233.81,234.0,2,17,2,2,233.8,234.07,105,7,2,1,233.74,234.1,200,100,1,1,233.7,234.13,1200,400,1,1,233.66,234.17,1,1,1,1,233.58,234.25,505,100,2,1,233.53,234.41,10,500,1,1,233.5,234.43,100,105,1,2,233.45,234.5,15,63,1,4,AAPL,100,100,0,0,0,0,0,0,0,0,0,233.925
2024-10-21T12:29:01.477365108Z,2024-10-21 12:29:01.477199123+00:00,10,2,38,C,B,3,233.74,200,130,165985,13264994,233.86,233.99,150,200,2,1,233.81,234.0,2,17,2,2,233.8,234.07,105,7,2,1,233.7,234.1,1200,100,1,1,233.66,234.13,1,400,1,1,233.58,234.17,505,1,2,1,233.53,234.25,10,100,1,1,233.5,234.41,100,500,1,1,233.45,234.43,15,105,1,2,233.4,234.5,110,63,2,4,AAPL,0,0,0,0,-200,-1200,-1,-505,-10,-100,-15,233.925
2024-10-21T12:29:01.541193716Z,2024-10-21 12:29:01.541027344+00:00,10,2,38,A,B,4,233.66,400,130,166372,13265322,233.86,233.99,150,200,2,1,233.81,234.0,2,17,2,2,233.8,234.07,105,7,2,1,233.7,234.1,1200,100,1,1,233.66,234.13,401,400,2,1,233.58,234.17,505,1,2,1,233.53,234.25,10,100,1,1,233.5,234.41,100,500,1,1,233.45,234.43,15,105,1,2,233.4,234.5,110,63,2,4,AAPL,0,0,0,0,0,400,0,0,0,0,0,233.925
2024-10-21T12:29:01.544861244Z,2024-10-21 12:29:01.544694740+00:00,10,2,38,A,A,0,233.99,200,130,166504,13265329,233.86,233.99,150,400,2,2,233.81,234.0,2,17,2,2,233.8,234.07,105,7,2,1,233.7,234.1,1200,100,1,1,233.66,234.13,401,400,2,1,233.58,234.17,505,1,2,1,233.53,234.25,10,100,1,1,233.5,234.41,100,500,1,1,233.45,234.43,15,105,1,2,233.4,234.5,110,63,2,4,AAPL,200,200,0,0,0,0,0,0,0,0,0,233.925
2024-10-21T12:29:01.602737737Z,2024-10-21 12:29:01.602571884+00:00,10,2,38,C,A,0,233.99,200,130,165853,13265457,233.86,233.99,150,200,2,1,233.81,234.0,2,17,2,2,233.8,234.07,105,7,2,1,233.7,234.1,1200,100,1,1,233.66,234.13,401,400,2,1,233.58,234.17,505,1,2,1,233.53,234.25,10,100,1,1,233.5,234.41,100,500,1,1,233.45,234.43,15,105,1,2,233.4,234.5,110,63,2,4,AAPL,-200,-200,0,0,0,0,0,0,0,0,0,233.925
2024-10-21T12:29:01.602775080Z,2024-10-21 12:29:01.602608635+00:00,10,2,38,A,A,0,233.94,400,130,166445,13265458,233.86,233.94,150,400,2,1,233.81,234.0,2,17,2,2,233.8,234.07,105,7,2,1,233.7,234.1,1200,100,1,1,233.66,234.13,401,400,2,1,233.58,234.17,505,1,2,1,233.53,234.25,10,100,1,1,233.5,234.41,100,500,1,1,233.45,234.43,15,105,1,2,233.4,234.5,110,63,2,4,AAPL,400,400,0,0,0,0,0,0,0,0,0,233.9
2024-10-21T12:29:01.646283514Z,2024-10-21 12:29:01.646117074+00:00,10,2,38,C,A,0,233.94,400,130,166440,13265552,233.86,234.0,150,17,2,2,233.81,234.07,2,7,2,1,233.8,234.1,105,100,2,1,233.7,234.13,1200,400,1,1,233.66,234.17,401,1,2,1,233.58,234.25,505,100,2,1,233.53,234.41,10,500,1,1,233.5,234.43,100,105,1,2,233.45,234.5,15,63,1,4,233.4,234.59,110,60,2,1,AAPL,400,400,17,7,100,400,1,100,500,105,63,233.93
2024-10-21T12:29:01.646296993Z,2024-10-21 12:29:01.646130641+00:00,10,2,38,A,A,0,233.95,200,130,166352,13265553,233.86,233.95,150,200,2,1,233.81,234.0,2,17,2,2,233.8,234.07,105,7,2,1,233.7,234.1,1200,100,1,1,233.66,234.13,401,400,2,1,233.58,234.17,505,1,2,1,233.53,234.25,10,100,1,1,233.5,234.41,100,500,1,1,233.45,234.43,15,105,1,2,233.4,234.5,110,63,2,4,AAPL,200,200,17,7,100,400,1,100,500,105,63,233.905
2024-10-21T12:29:01.700803405Z,2024-10-21 12:29:01.700637009+00:00,10,2,38,A,B,3,233.71,200,130,166396,13265636,233.86,233.95,150,200,2,1,233.81,234.0,2,17,2,2,233.8,234.07,105,7,2,1,233.71,234.1,200,100,1,1,233.7,234.13,1200,400,1,1,233.66,234.17,1,1,1,1,233.58,234.25,505,100,2,1,233.53,234.41,10,500,1,1,233.5,234.43,100,105,1,2,233.45,234.5,15,63,1,4,AAPL,0,0,0,0,200,1200,1,505,10,100,15,233.905
2024-10-21T12:29:01.702597558Z,2024-10-21 12:29:01.702431410+00:00,10,2,38,C,A,0,233.95,200,130,166148,13265638,233.86,234.0,150,17,2,2,233.81,234.07,2,7,2,1,233.8,234.1,105,100,2,1,233.71,234.13,200,400,1,1,233.7,234.17,1200,1,1,1,233.66,234.25,1,100,1,1,233.58,234.41,505,500,2,1,233.53,234.43,10,105,1,2,233.5,234.5,100,63,1,4,233.45,234.59,15,60,1,1,AAPL,200,200,17,7,100,400,1,100,500,105,63,233.93
2024-10-21T12:29:01.702610835Z,2024-10-21 12:29:01.702443831+00:00,10,2,38,A,A,0,233.99,200,130,167004,13265639,233.86,233.99,150,200,2,1,233.81,234.0,2,17,2,2,233.8,234.07,105,7,2,1,233.71,234.1,200,100,1,1,233.7,234.13,1200,400,1,1,233.66,234.17,1,1,1,1,233.58,234.25,505,100,2,1,233.53,234.41,10,500,1,1,233.5,234.43,100,105,1,2,233.45,234.5,15,63,1,4,AAPL,200,200,17,7,100,400,1,100,500,105,63,233.925
2024-10-21T12:29:01.829025695Z,2024-10-21 12:29:01.828859341+00:00,10,2,38,A,B,3,233.71,200,130,166354,13265781,233.86,233.99,150,200,2,1,233.81,234.0,2,17,2,2,233.8,234.07,105,7,2,1,233.71,234.1,400,100,2,1,233.7,234.13,1200,400,1,1,233.66,234.17,1,1,1,1,233.58,234.25,505,100,2,1,233.53,234.41,10,500,1,1,233.5,234.43,100,105,1,2,233.45,234.5,15,63,1,4,AAPL,0,0,0,0,200,0,0,0,0,0,0,233.925
2024-10-21T12:29:01.883954105Z,2024-10-21 12:29:01.883788028+00:00,10,2,38,C,B,3,233.71,200,130,166077,13265824,233.86,233.99,150,200,2,1,233.81,234.0,2,17,2,2,233.8,234.07,105,7,2,1,233.71,234.1,200,100,1,1,233.7,234.13,1200,400,1,1,233.66,234.17,1,1,1,1,233.58,234.25,505,100,2,1,233.53,234.41,10,500,1,1,233.5,234.43,100,105,1,2,233.45,234.5,15,63,1,4,AAPL,0,0,0,0,-200,0,0,0,0,0,0,233.925
2024-10-21T12:29:01.883967618Z,2024-10-21 12:29:01.883801296+00:00,10,2,38,A,B,3,233.76,400,130,166322,13265825,233.86,233.99,150,200,2,1,233.81,234.0,2,17,2,2,233.8,234.07,105,7,2,1,233.76,234.1,400,100,1,1,233.7,234.13,1200,400,1,1,233.66,234.17,1,1,1,1,233.58,234.25,505,100,2,1,233.53,234.41,10,500,1,1,233.5,234.43,100,105,1,2,233.45,234.5,15,63,1,4,AAPL,0,0,0,0,400,0,0,0,0,0,0,233.925
2024-10-21T12:29:04.074542032Z,2024-10-21 12:29:04.074375510+00:00,10,2,38,A,B,1,233.81,200,130,166522,13268362,233.86,233.99,150,200,2,1,233.81,234.0,202,17,3,2,233.8,234.07,105,7,2,1,233.7,234.1,1200,100,1,1,233.66,234.13,1,400,1,1,233.58,234.17,505,1,2,1,233.53,234.25,10,100,1,1,233.5,234.41,100,500,1,1,233.45,234.43,15,105,1,2,233.4,234.5,110,63,2,4,AAPL,0,0,200,0,-400,-1200,-1,-505,-10,-100,-15,233.925
2024-10-21T12:29:04.429667694Z,2024-10-21 12:29:04.429500359+00:00,10,2,38,T,A,0,233.86,3,130,167335,13268523,233.86,233.99,150,200,2,1,233.81,234.0,202,17,3,2,233.8,234.07,105,7,2,1,233.7,234.1,1200,100,1,1,233.66,234.13,1,400,1,1,233.58,234.17,505,1,2,1,233.53,234.25,10,100,1,1,233.5,234.41,100,500,1,1,233.45,234.43,15,105,1,2,233.4,234.5,110,63,2,4,AAPL,0,0,0,0,0,0,0,0,0,0,0,233.925
2024-10-21T12:29:04.429667694Z,2024-10-21 12:29:04.429500359+00:00,10,2,38,C,B,0,233.86,3,130,167335,13268523,233.86,233.99,147,200,2,1,233.81,234.0,202,17,3,2,233.8,234.07,105,7,2,1,233.7,234.1,1200,100,1,1,233.66,234.13,1,400,1,1,233.58,234.17,505,1,2,1,233.53,234.25,10,100,1,1,233.5,234.41,100,500,1,1,233.45,234.43,15,105,1,2,233.4,234.5,110,63,2,4,AAPL,-3,-3,0,0,0,0,0,0,0,0,0,233.925
2024-10-21T12:29:04.493717825Z,2024-10-21 12:29:04.493551721+00:00,10,2,38,C,B,1,233.81,200,130,166104,13268610,233.86,233.99,147,200,2,1,233.81,234.0,2,17,2,2,233.8,234.07,105,7,2,1,233.7,234.1,1200,100,1,1,233.66,234.13,1,400,1,1,233.58,234.17,505,1,2,1,233.53,234.25,10,100,1,1,233.5,234.41,100,500,1,1,233.45,234.43,15,105,1,2,233.4,234.5,110,63,2,4,AAPL,0,0,-200,0,0,0,0,0,0,0,0,233.925
2024-10-21T12:29:04.493730953Z,2024-10-21 12:29:04.493564498+00:00,10,2,38,A,B,3,233.78,200,130,166455,13268611,233.86,233.99,147,200,2,1,233.81,234.0,2,17,2,2,233.8,234.07,105,7,2,1,233.78,234.1,200,100,1,1,233.7,234.13,1200,400,1,1,233.66,234.17,1,1,1,1,233.58,234.25,505,100,2,1,233.53,234.41,10,500,1,1,233.5,234.43,100,105,1,2,233.45,234.5,15,63,1,4,AAPL,0,0,0,0,200,1200,1,505,10,100,15,233.925
2024-10-21T12:29:04.660589203Z,2024-10-21 12:29:04.660423222+00:00,10,2,38,C,B,3,233.78,200,130,165981,13268807,233.86,233.99,147,200,2,1,233.81,234.0,2,17,2,2,233.8,234.07,105,7,2,1,233.7,234.1,1200,100,1,1,233.66,234.13,1,400,1,1,233.58,234.17,505,1,2,1,233.53,234.25,10,100,1,1,233.5,234.41,100,500,1,1,233.45,234.43,15,105,1,2,233.4,234.5,110,63,2,4,AAPL,0,0,0,0,-200,-1200,-1,-505,-10,-100,-15,233.925
2024-10-21T12:29:04.660602729Z,2024-10-21 12:29:04.660436269+00:00,10,2,38,A,B,4,233.66,400,130,166460,13268808,233.86,233.99,147,200,2,1,233.81,234.0,2,17,2,2,233.8,234.07,105,7,2,1,233.7,234.1,1200,100,1,1,233.66,234.13,401,400,2,1,233.58,234.17,505,1,2,1,233.53,234.25,10,100,1,1,233.5,234.41,100,500,1,1,233.45,234.43,15,105,1,2,233.4,234.5,110,63,2,4,AAPL,0,0,0,0,0,400,0,0,0,0,0,233.925
2024-10-21T12:29:04.679306243Z,2024-10-21 12:29:04.679139876+00:00,10,2,38,A,A,0,233.99,200,130,166367,13268819,233.86,233.99,147,400,2,2,233.81,234.0,2,17,2,2,233.8,234.07,105,7,2,1,233.7,234.1,1200,100,1,1,233.66,234.13,401,400,2,1,233.58,234.17,505,1,2,1,233.53,234.25,10,100,1,1,233.5,234.41,100,500,1,1,233.45,234.43,15,105,1,2,233.4,234.5,110,63,2,4,AAPL,200,200,0,0,0,0,0,0,0,0,0,233.925
2024-10-21T12:29:04.736956452Z,2024-10-21 12:29:04.736790546+00:00,10,2,38,C,A,0,233.99,200,130,165906,13268859,233.86,233.99,147,200,2,1,233.81,234.0,2,17,2,2,233.8,234.07,105,7,2,1,233.7,234.1,1200,100,1,1,233.66,234.13,401,400,2,1,233.58,234.17,505,1,2,1,233.53,234.25,10,100,1,1,233.5,234.41,100,500,1,1,233.45,234.43,15,105,1,2,233.4,234.5,110,63,2,4,AAPL,-200,-200,0,0,0,0,0,0,0,0,0,233.925
2024-10-21T12:29:04.736969863Z,2024-10-21 12:29:04.736803679+00:00,10,2,38,A,A,0,233.94,200,130,166184,13268860,233.86,233.94,147,200,2,1,233.81,234.0,2,17,2,2,233.8,234.07,105,7,2,1,233.7,234.1,1200,100,1,1,233.66,234.13,401,400,2,1,233.58,234.17,505,1,2,1,233.53,234.25,10,100,1,1,233.5,234.41,100,500,1,1,233.45,234.43,15,105,1,2,233.4,234.5,110,63,2,4,AAPL,200,200,0,0,0,0,0,0,0,0,0,233.9
2024-10-21T12:29:04.942576593Z,2024-10-21 12:29:04.942410445+00:00,10,2,38,C,A,0,233.94,200,130,166148,13269072,233.86,234.0,147,17,2,2,233.81,234.07,2,7,2,1,233.8,234.1,105,100,2,1,233.7,234.13,1200,400,1,1,233.66,234.17,401,1,2,1,233.58,234.25,505,100,2,1,233.53,234.41,10,500,1,1,233.5,234.43,100,105,1,2,233.45,234.5,15,63,1,4,233.4,234.59,110,60,2,1,AAPL,200,200,17,7,100,400,1,100,500,105,63,233.93
2024-10-21T12:29:04.942589417Z,2024-10-21 12:29:04.942423141+00:00,10,2,38,A,A,0,233.99,200,130,166276,13269073,233.86,233.99,147,200,2,1,233.81,234.0,2,17,2,2,233.8,234.07,105,7,2,1,233.7,234.1,1200,100,1,1,233.66,234.13,401,400,2,1,233.58,234.17,505,1,2,1,233.53,234.25,10,100,1,1,233.5,234.41,100,500,1,1,233.45,234.43,15,105,1,2,233.4,234.5,110,63,2,4,AAPL,200,200,17,7,100,400,1,100,500,105,63,233.925
2024-10-21T12:29:04.997130813Z,2024-10-21 12:29:04.996963888+00:00,10,2,38,A,B,3,233.76,400,130,166925,13269127,233.86,233.99,147,200,2,1,233.81,234.0,2,17,2,2,233.8,234.07,105,7,2,1,233.76,234.1,400,100,1,1,233.7,234.13,1200,400,1,1,233.66,234.17,1,1,1,1,233.58,234.25,505,100,2,1,233.53,234.41,10,500,1,1,233.5,234.43,100,105,1,2,233.45,234.5,15,63,1,4,AAPL,0,0,0,0,400,1200,1,505,10,100,15,233.925
2024-10-21T12:29:07.476323268Z,2024-10-21 12:29:07.476155585+00:00,10,2,38,T,A,0,233.86,30,130,167683,13271447,233.86,233.99,147,200,2,1,233.81,234.0,2,17,2,2,233.8,234.07,105,7,2,1,233.76,234.1,400,100,1,1,233.7,234.13,1200,400,1,1,233.66,234.17,1,1,1,1,233.58,234.25,505,100,2,1,233.53,234.41,10,500,1,1,233.5,234.43,100,105,1,2,233.45,234.5,15,63,1,4,AAPL,0,0,0,0,0,0,0,0,0,0,0,233.925
2024-10-21T12:29:07.476323268Z,2024-10-21 12:29:07.476155585+00:00,10,2,38,C,B,0,233.86,30,130,167683,13271447,233.86,233.99,117,200,2,1,233.81,234.0,2,17,2,2,233.8,234.07,105,7,2,1,233.76,234.1,400,100,1,1,233.7,234.13,1200,400,1,1,233.66,234.17,1,1,1,1,233.58,234.25,505,100,2,1,233.53,234.41,10,500,1,1,233.5,234.43,100,105,1,2,233.45,234.5,15,63,1,4,AAPL,-30,-30,0,0,0,0,0,0,0,0,0,233.925
2024-10-21T12:29:07.543978531Z,2024-10-21 12:29:07.543812287+00:00,10,2,38,C,B,3,233.76,400,130,166244,13271500,233.86,233.99,117,200,2,1,233.81,234.0,2,17,2,2,233.8,234.07,105,7,2,1,233.7,234.1,1200,100,1,1,233.66,234.13,1,400,1,1,233.58,234.17,505,1,2,1,233.53,234.25,10,100,1,1,233.5,234.41,100,500,1,1,233.45,234.43,15,105,1,2,233.4,234.5,110,63,2,4,AAPL,0,0,0,0,-400,-1200,-1,-505,-10,-100,-15,233.925
2024-10-21T12:29:07.573087456Z,2024-10-21 12:29:07.572921012+00:00,10,2,38,C,A,2,234.07,7,130,166444,13271562,233.86,233.99,117,200,2,1,233.81,234.0,2,17,2,2,233.8,234.1,105,100,2,1,233.7,234.13,1200,400,1,1,233.66,234.17,1,1,1,1,233.58,234.25,505,100,2,1,233.53,234.41,10,500,1,1,233.5,234.43,100,105,1,2,233.45,234.5,15,63,1,4,233.4,234.59,110,60,2,1,AAPL,0,0,0,7,100,400,1,100,500,105,63,233.925
